Workbook

Sheet Cover
A1: Administrator's Command Toolkit — Texas Edition
A2: Clear Path Education Group, LLC · clearpathedgroup.com
A3: Built for Texas campus administrators, APs, and Campus Behavior Coordinators.
A4: One incident intake → everything else auto-populates. Investigation notes, evidence chain of custody, parent call scripts, 10-day SPED compliance alerts, discipline trends, Monday morning briefings — all in one file. Built to survive a legal challenge, eliminate re-entry work, and save administrators 30+ minutes per incident.
A6: ▸ DISTRICT & CAMPUS INFORMATION
B7: District Name
B8: Campus Name
B9: Department / Team
B10: Coordinator
B11: School Year | C11: 2025–2026
B12: Prepared By
A14: ▸ HOW TO USE THIS TRACKER
B15: 1. ⚡ Command Dashboard | C15: Live campus summary. Open incidents, 10-day SPED flags, investigation status, parent contact gaps — all in one view. Print in 30 seconds.
B16: 2. Incident Intake | C16: ONE ROW per incident. Enter it once here and every other tab auto-populates. This is your master record for every case.
B17: 3. Investigation Tracker | C17: Structured 5-stage workflow from intake to closed. Integrity checklist prevents premature case closure. Timeline auto-builds as you work.
B18: 4. 10-Day Compliance | C18: Auto-tracks cumulative SPED removal days. Alerts at day 7 (warning), day 9 (urgent), day 10+ (exceeded). Never get caught off guard.
B19: 5. Evidence Tracker | C19: Chain of custody log for every piece of evidence. Legal hold flag. Admins lose cases because evidence isn't documented — this closes that gap.
B20: 6. Parent Contact Log | C20: Every call logged with date, method, and outcome. Select the offense → a phone script auto-populates. 15 scripts for 15 offense types.
B21: 7. Discipline Trends | C21: Auto-built from Incident Intake. Offense frequency, monthly patterns, repeat offender flags, SPED breakdown. No manual data entry needed.
B22: 8. 📋 Monday Briefing | C22: Print-ready weekly briefing: open cases, investigation deadlines, parent follow-ups due, students returning from placement this week.
B23: 9. Investigation Notes | C23: Structured template for witness interviews, evidence review, and findings. Separate from the Intake record — legally important distinction.
B24: 10. Outcome & Letters | C24: Consequence decisions, outcome letter drafts, appeal deadlines, appeal tracking. Never miss a response deadline again.
A26: ⚠ FOR ORGANIZATIONAL USE ONLY — Not legal advice. Consult district counsel for all placement and consequence decisions.
A28: 🚀 Ready to scale? Visit clearpathedgroup.com to upgrade to the full platform

Sheet Incident Intake
A1: Incident Intake — Master Record · Enter once, auto-fills everywhere
A2: ⚙ Gray columns auto-calculate. White columns = your input. Enter Incident ID, Date, and Student ID first — they drive everything else.
A3: FORMAT: Incident ID = INC-2025-001 · Time = HH:MM · Student ID must match your student roster
A4: Incident ID | B4: Date | C4: Time | D4: ⚙ Day of Week | E4: Student ID | F4: Last Name | G4: First Name | H4: Grade | I4: Campus | J4: Offense Category | K4: Offense Description | L4: TEC Reference | M4: Location | N4: Witnesses Named? | O4: # Witnesses | P4: Injury Reported? | Q4: Medical Attention? | R4: Property Damage? | S4: Law Enforcement Notified? | T4: LE Arrival Time | U4: SPED Status | V4: ⚙ 10-Day Running Total | W4: ⚙ 10-Day Flag | X4: Investigation Status | Y4: Assigned Investigator | Z4: ⚙ Days Case Open | AA4: Parent Notified? | AB4: Parent Notified Date | AC4: Consequence Assigned | AD4: Consequence Start | AE4: Consequence End | AF4: Appeal Filed? | AG4: ⚙ Case Age (days) | AH4: Notes
D5: =IF(B5="","",TEXT(B5,"DDDD")) | V5: =IF(E5="","",IFERROR(SUMIF('10-Day Compliance'!$A:$A,E5,'10-Day Compliance'!$E:$E),0)) | W5: =IF(U5="No","",IF(V5="","",IF(V5>=10,"🔴 EXCEEDED — MDR NOW",IF(V5>=9,"🟠 URGENT — DAY "&V5,IF(V5>=7,"🟡 WARNING — DAY "&V5,"✅ OK — Day "&V5))))) | Z5: =IF(OR(B5="",X5="Closed"),"",TODAY()-B5) | AG5: =IF(B5="","",TODAY()-B5)
D6: =IF(B6="","",TEXT(B6,"DDDD")) | V6: =IF(E6="","",IFERROR(SUMIF('10-Day Compliance'!$A:$A,E6,'10-Day Compliance'!$E:$E),0)) | W6: =IF(U6="No","",IF(V6="","",IF(V6>=10,"🔴 EXCEEDED — MDR NOW",IF(V6>=9,"🟠 URGENT — DAY "&V6,IF(V6>=7,"🟡 WARNING — DAY "&V6,"✅ OK — Day "&V6))))) | Z6: =IF(OR(B6="",X6="Closed"),"",TODAY()-B6) | AG6: =IF(B6="","",TODAY()-B6)
D7: =IF(B7="","",TEXT(B7,"DDDD")) | V7: =IF(E7="","",IFERROR(SUMIF('10-Day Compliance'!$A:$A,E7,'10-Day Compliance'!$E:$E),0)) | W7: =IF(U7="No","",IF(V7="","",IF(V7>=10,"🔴 EXCEEDED — MDR NOW",IF(V7>=9,"🟠 URGENT — DAY "&V7,IF(V7>=7,"🟡 WARNING — DAY "&V7,"✅ OK — Day "&V7))))) | Z7: =IF(OR(B7="",X7="Closed"),"",TODAY()-B7) | AG7: =IF(B7="","",TODAY()-B7)
D8: =IF(B8="","",TEXT(B8,"DDDD")) | V8: =IF(E8="","",IFERROR(SUMIF('10-Day Compliance'!$A:$A,E8,'10-Day Compliance'!$E:$E),0)) | W8: =IF(U8="No","",IF(V8="","",IF(V8>=10,"🔴 EXCEEDED — MDR NOW",IF(V8>=9,"🟠 URGENT — DAY "&V8,IF(V8>=7,"🟡 WARNING — DAY "&V8,"✅ OK — Day "&V8))))) | Z8: =IF(OR(B8="",X8="Closed"),"",TODAY()-B8) | AG8: =IF(B8="","",TODAY()-B8)
D9: =IF(B9="","",TEXT(B9,"DDDD")) | V9: =IF(E9="","",IFERROR(SUMIF('10-Day Compliance'!$A:$A,E9,'10-Day Compliance'!$E:$E),0)) | W9: =IF(U9="No","",IF(V9="","",IF(V9>=10,"🔴 EXCEEDED — MDR NOW",IF(V9>=9,"🟠 URGENT — DAY "&V9,IF(V9>=7,"🟡 WARNING — DAY "&V9,"✅ OK — Day "&V9))))) | Z9: =IF(OR(B9="",X9="Closed"),"",TODAY()-B9) | AG9: =IF(B9="","",TODAY()-B9)
D10: =IF(B10="","",TEXT(B10,"DDDD")) | V10: =IF(E10="","",IFERROR(SUMIF('10-Day Compliance'!$A:$A,E10,'10-Day Compliance'!$E:$E),0)) | W10: =IF(U10="No","",IF(V10="","",IF(V10>=10,"🔴 EXCEEDED — MDR NOW",IF(V10>=9,"🟠 URGENT — DAY "&V10,IF(V10>=7,"🟡 WARNING — DAY "&V10,"✅ OK — Day "&V10))))) | Z10: =IF(OR(B10="",X10="Closed"),"",TODAY()-B10) | AG10: =IF(B10="","",TODAY()-B10)
D11: =IF(B11="","",TEXT(B11,"DDDD")) | V11: =IF(E11="","",IFERROR(SUMIF('10-Day Compliance'!$A:$A,E11,'10-Day Compliance'!$E:$E),0)) | W11: =IF(U11="No","",IF(V11="","",IF(V11>=10,"🔴 EXCEEDED — MDR NOW",IF(V11>=9,"🟠 URGENT — DAY "&V11,IF(V11>=7,"🟡 WARNING — DAY "&V11,"✅ OK — Day "&V11))))) | Z11: =IF(OR(B11="",X11="Closed"),"",TODAY()-B11) | AG11: =IF(B11="","",TODAY()-B11)
D12: =IF(B12="","",TEXT(B12,"DDDD")) | V12: =IF(E12="","",IFERROR(SUMIF('10-Day Compliance'!$A:$A,E12,'10-Day Compliance'!$E:$E),0)) | W12: =IF(U12="No","",IF(V12="","",IF(V12>=10,"🔴 EXCEEDED — MDR NOW",IF(V12>=9,"🟠 URGENT — DAY "&V12,IF(V12>=7,"🟡 WARNING — DAY "&V12,"✅ OK — Day "&V12))))) | Z12: =IF(OR(B12="",X12="Closed"),"",TODAY()-B12) | AG12: =IF(B12="","",TODAY()-B12)
D13: =IF(B13="","",TEXT(B13,"DDDD")) | V13: =IF(E13="","",IFERROR(SUMIF('10-Day Compliance'!$A:$A,E13,'10-Day Compliance'!$E:$E),0)) | W13: =IF(U13="No","",IF(V13="","",IF(V13>=10,"🔴 EXCEEDED — MDR NOW",IF(V13>=9,"🟠 URGENT — DAY "&V13,IF(V13>=7,"🟡 WARNING — DAY "&V13,"✅ OK — Day "&V13))))) | Z13: =IF(OR(B13="",X13="Closed"),"",TODAY()-B13) | AG13: =IF(B13="","",TODAY()-B13)
D14: =IF(B14="","",TEXT(B14,"DDDD")) | V14: =IF(E14="","",IFERROR(SUMIF('10-Day Compliance'!$A:$A,E14,'10-Day Compliance'!$E:$E),0)) | W14: =IF(U14="No","",IF(V14="","",IF(V14>=10,"🔴 EXCEEDED — MDR NOW",IF(V14>=9,"🟠 URGENT — DAY "&V14,IF(V14>=7,"🟡 WARNING — DAY "&V14,"✅ OK — Day "&V14))))) | Z14: =IF(OR(B14="",X14="Closed"),"",TODAY()-B14) | AG14: =IF(B14="","",TODAY()-B14)
D15: =IF(B15="","",TEXT(B15,"DDDD")) | V15: =IF(E15="","",IFERROR(SUMIF('10-Day Compliance'!$A:$A,E15,'10-Day Compliance'!$E:$E),0)) | W15: =IF(U15="No","",IF(V15="","",IF(V15>=10,"🔴 EXCEEDED — MDR NOW",IF(V15>=9,"🟠 URGENT — DAY "&V15,IF(V15>=7,"🟡 WARNING — DAY "&V15,"✅ OK — Day "&V15))))) | Z15: =IF(OR(B15="",X15="Closed"),"",TODAY()-B15) | AG15: =IF(B15="","",TODAY()-B15)
D16: =IF(B16="","",TEXT(B16,"DDDD")) | V16: =IF(E16="","",IFERROR(SUMIF('10-Day Compliance'!$A:$A,E16,'10-Day Compliance'!$E:$E),0)) | W16: =IF(U16="No","",IF(V16="","",IF(V16>=10,"🔴 EXCEEDED — MDR NOW",IF(V16>=9,"🟠 URGENT — DAY "&V16,IF(V16>=7,"🟡 WARNING — DAY "&V16,"✅ OK — Day "&V16))))) | Z16: =IF(OR(B16="",X16="Closed"),"",TODAY()-B16) | AG16: =IF(B16="","",TODAY()-B16)
... D304: =IF(B304="","",TEXT(B304,"DDDD")) | V304: =IF(E304="","",IFERROR(SUMIF('10-Day Compliance'!$A:$A,E304,'10-Day Compliance'!$E:$E),0)) | W304: =IF(U304="No","",IF(V304="","",IF(V304>=10,"🔴 EXCEEDED — MDR NOW",IF(V304>=9,"🟠 URGENT — DAY "&V304,IF(V304>=7,"🟡 WARNING — DAY "&V304,"✅ OK — Day "&V304))))) | Z304: =IF(OR(B304="",X304="Closed"),"",TODAY()-B304) | AG304: =IF(B304="","",TODAY()-B304)
A305: 🚀 Upgrade to the full platform · clearpathedgroup.com · Clear Path Education Group, LLC

Sheet ⚡ Command Dashboard
A1: ⚡ ADMINISTRATOR'S COMMAND DASHBOARD — Texas Edition
B2: ="As of: "&TEXT(TODAY(),"DDDD, MMMM D, YYYY")&" · Administrator: (enter name on Cover)" -> As of: Tuesday, July 14, 2026 · Administrator: (enter name on Cover)
B3: 🔴 CRITICAL — REQUIRES IMMEDIATE ACTION
B4: 🔴 SPED 10-Day Limit EXCEEDED | C4: =COUNTIF('10-Day Compliance'!AA5:AA154,"*EXCEEDED*") -> 0
B5: 🟠 SPED — Day 9 (URGENT) | C5: =COUNTIF('10-Day Compliance'!AA5:AA154,"*URGENT*") -> 0
B6: ⚠ Evidence Items on Legal Hold | C6: =COUNTIF('Evidence Tracker'!S5:S304,"Yes") -> 0
B7: ⏰ Appeal Response Deadlines — Due Within 3 Days | C7: =COUNTIFS('Outcome & Letters'!N5:N154,"Yes",'Outcome & Letters'!Q5:Q154,">="&TODAY(),'Outcome & Letters'!Q5:Q154,"<="&(TODAY()+3)) -> 0
B8: 📋 Integrity Checks Incomplete (before case close) | C8: =COUNTIF('Investigation Tracker'!AD6:AD205,"*INCOMPLETE*") -> 0
B10: 🔍 INVESTIGATION STATUS
B11: Open — Not Yet Started | C11: =COUNTIF('Incident Intake'!X5:X304,"Open") -> 0
B12: In Progress | C12: =COUNTIF('Incident Intake'!X5:X304,"In Progress") -> 0
B13: Finding Reached | C13: =COUNTIF('Incident Intake'!X5:X304,"Finding Reached") -> 0
B14: Consequence Assigned | C14: =COUNTIF('Incident Intake'!X5:X304,"Consequence Assigned") -> 0
B15: Closed This Year | C15: =COUNTIF('Incident Intake'!X5:X304,"Closed") -> 0
B16: On Hold — Legal | C16: =COUNTIF('Incident Intake'!X5:X304,"On Hold — Legal") -> 0
B17: ⚠ Open Cases Stale 5+ Days | C17: =COUNTIFS('Incident Intake'!X5:X304,"Open",'Incident Intake'!Z5:Z304,">="&5) -> 0
B19: 📊 CAMPUS TOTALS — SCHOOL YEAR
B20: Total Incidents Logged | C20: =COUNTA('Incident Intake'!A5:A304) -> 0
B21: Total ISS Placements | C21: =COUNTIF('Incident Intake'!AC5:AC304,"ISS*") -> 0
B22: Total OSS Placements | C22: =COUNTIF('Incident Intake'!AC5:AC304,"OSS*") -> 0
B23: DAEP Placements (all) | C23: =COUNTIF('Incident Intake'!AC5:AC304,"DAEP*") -> 0
B24: Expulsion Referrals | C24: =COUNTIF('Incident Intake'!AC5:AC304,"Expulsion*") -> 0
B25: Law Enforcement Referrals | C25: =COUNTIF('Incident Intake'!S5:S304,"Yes") -> 0
B26: Parent Contacts Logged | C26: =COUNTA('Parent Contact Log'!A5:A254) -> 0
B27: Evidence Items Documented | C27: =COUNTA('Evidence Tracker'!A5:A304) -> 0
B29: ♿ SPED COMPLIANCE DASHBOARD
B30: 🟡 SPED — Day 7-8 (Warning) | C30: =COUNTIF('10-Day Compliance'!AA5:AA154,"*WARNING*") -> 0
B31: 🟠 SPED — Day 9 (Urgent) | C31: =COUNTIF('10-Day Compliance'!AA5:AA154,"*URGENT*") -> 0
B32: 🔴 SPED — Day 10+ (Exceeded) | C32: =COUNTIF('10-Day Compliance'!AA5:AA154,"*EXCEEDED*") -> 0
B33: MDR Required — Not Yet Done | C33: =COUNTIFS('10-Day Compliance'!V5:V154,"Yes",'10-Day Compliance'!W5:W154,"") -> 0
B35: ⚖️ APPEAL & OUTCOME TRACKER
B36: Active Appeals | C36: =COUNTIF('Outcome & Letters'!P5:P154,"Filed*") -> 0
B37: Appeals Resolved — Upheld | C37: =COUNTIF('Outcome & Letters'!T5:T154,"UPHELD*") -> 0
B38: Appeals Resolved — Overturned | C38: =COUNTIF('Outcome & Letters'!T5:T154,"OVERTURNED") -> 0
B39: Outcome Letters NOT Sent | C39: =COUNTIFS('Outcome & Letters'!A5:A154,"<>""",'Outcome & Letters'!J5:J154,"No") -> 0
A41: 🚀 Automate this dashboard in real-time across all campuses · clearpathedgroup.com/waypoint · Clear Path Education Group, LLC

Sheet Investigation Tracker
A1: Investigation Tracker — 5-Stage Workflow from Intake to Closed Case
A2: One row per investigation. Enter Incident ID in col A → student info auto-fills from Intake tab. Work through stages left to right.
A3: ⚙ Integrity Check (col AD): All 5 boxes must be 'Yes' before marking Closed. Red = incomplete. A case that closes early is a liability.
A4: IDENTITY | F4: STAGE 1 — INTAKE | I4: STAGE 2 — INVESTIGATION | N4: STAGE 3 — FINDING | Q4: STAGE 4 — CONSEQUENCE | V4: STAGE 5 — CLOSE | AB4: STATUS | AE4: SPED | AI4: APPEAL / NOTES
A5: Incident ID | B5: ⚙ Date | C5: ⚙ Student ID | D5: ⚙ Student Name | E5: ⚙ Offense | F5: Stage 1: Intake Complete? | G5: Intake Date | H5: Referred By | I5: Stage 2: Witnesses Identified? | J5: Witnesses Interviewed? | K5: Last Interview Date | L5: Student Interviewed? | M5: Student Interview Date | N5: Stage 3: Evidence Reviewed? | O5: Finding | P5: Finding Date | Q5: Stage 4: Consequence Assigned? | R5: Consequence | S5: Consequence Date | T5: Parent Notified of Outcome? | U5: Outcome Notice Date | V5: Stage 5: All Docs Signed? | W5: SPED Coordinator Notified? | X5: Student Given Opportunity to Respond? | Y5: Evidence Documented? | Z5: Rationale Documented? | AA5: Case Closed Date | AB5: ⚙ Investigation Status | AC5: ⚙ Days Open | AD5: ⚙ Integrity Check | AE5: SPED? | AF5: MDR Status | AG5: ARD Notification Date | AH5: FAPE Confirmed? | AI5: Appeal Filed? | AJ5: Appeal Filed Date | AK5: ⚙ Appeal Deadline | AL5: Appeal Status | AM5: Notes
B6: =IFERROR(VLOOKUP(A6,'Incident Intake'!$A:$B,2,FALSE()),"") | C6: =IFERROR(VLOOKUP(A6,'Incident Intake'!$A:$E,5,FALSE()),"") | D6: =IFERROR(VLOOKUP(A6,'Incident Intake'!$A:$G,7,FALSE())&" "&VLOOKUP(A6,'Incident Intake'!$A:$F,6,FALSE()),"") | E6: =IFERROR(VLOOKUP(A6,'Incident Intake'!$A:$J,10,FALSE()),"") | AB6: =IF(A6="","",IF(AB6="Yes","Closed",IF(T6="Yes","Consequence Assigned",IF(O6="Yes","Finding Reached",IF(F6="Yes","In Progress","Open"))))) | AC6: =IF(OR(A6="",AB6="Yes"),"",IF(B6="","",TODAY()-B6)) | AD6: =IF(A6="","",IF(AND(V6="Yes",X6="Yes",Y6="Yes",Z6="Yes",AA6="Yes"),"✅ ALL CHECKS COMPLETE — OK TO CLOSE","⚠ "&(5-COUNTIF(V6:Z6,"Yes"))&" CHECK(S) INCOMPLETE")) | AK6: =IF(AI6="Yes",IF(AJ6="","",AJ6+21),"")
B7: =IFERROR(VLOOKUP(A7,'Incident Intake'!$A:$B,2,FALSE()),"") | C7: =IFERROR(VLOOKUP(A7,'Incident Intake'!$A:$E,5,FALSE()),"") | D7: =IFERROR(VLOOKUP(A7,'Incident Intake'!$A:$G,7,FALSE())&" "&VLOOKUP(A7,'Incident Intake'!$A:$F,6,FALSE()),"") | E7: =IFERROR(VLOOKUP(A7,'Incident Intake'!$A:$J,10,FALSE()),"") | AB7: =IF(A7="","",IF(AB7="Yes","Closed",IF(T7="Yes","Consequence Assigned",IF(O7="Yes","Finding Reached",IF(F7="Yes","In Progress","Open"))))) | AC7: =IF(OR(A7="",AB7="Yes"),"",IF(B7="","",TODAY()-B7)) | AD7: =IF(A7="","",IF(AND(V7="Yes",X7="Yes",Y7="Yes",Z7="Yes",AA7="Yes"),"✅ ALL CHECKS COMPLETE — OK TO CLOSE","⚠ "&(5-COUNTIF(V7:Z7,"Yes"))&" CHECK(S) INCOMPLETE")) | AK7: =IF(AI7="Yes",IF(AJ7="","",AJ7+21),"")
B8: =IFERROR(VLOOKUP(A8,'Incident Intake'!$A:$B,2,FALSE()),"") | C8: =IFERROR(VLOOKUP(A8,'Incident Intake'!$A:$E,5,FALSE()),"") | D8: =IFERROR(VLOOKUP(A8,'Incident Intake'!$A:$G,7,FALSE())&" "&VLOOKUP(A8,'Incident Intake'!$A:$F,6,FALSE()),"") | E8: =IFERROR(VLOOKUP(A8,'Incident Intake'!$A:$J,10,FALSE()),"") | AB8: =IF(A8="","",IF(AB8="Yes","Closed",IF(T8="Yes","Consequence Assigned",IF(O8="Yes","Finding Reached",IF(F8="Yes","In Progress","Open"))))) | AC8: =IF(OR(A8="",AB8="Yes"),"",IF(B8="","",TODAY()-B8)) | AD8: =IF(A8="","",IF(AND(V8="Yes",X8="Yes",Y8="Yes",Z8="Yes",AA8="Yes"),"✅ ALL CHECKS COMPLETE — OK TO CLOSE","⚠ "&(5-COUNTIF(V8:Z8,"Yes"))&" CHECK(S) INCOMPLETE")) | AK8: =IF(AI8="Yes",IF(AJ8="","",AJ8+21),"")
B9: =IFERROR(VLOOKUP(A9,'Incident Intake'!$A:$B,2,FALSE()),"") | C9: =IFERROR(VLOOKUP(A9,'Incident Intake'!$A:$E,5,FALSE()),"") | D9: =IFERROR(VLOOKUP(A9,'Incident Intake'!$A:$G,7,FALSE())&" "&VLOOKUP(A9,'Incident Intake'!$A:$F,6,FALSE()),"") | E9: =IFERROR(VLOOKUP(A9,'Incident Intake'!$A:$J,10,FALSE()),"") | AB9: =IF(A9="","",IF(AB9="Yes","Closed",IF(T9="Yes","Consequence Assigned",IF(O9="Yes","Finding Reached",IF(F9="Yes","In Progress","Open"))))) | AC9: =IF(OR(A9="",AB9="Yes"),"",IF(B9="","",TODAY()-B9)) | AD9: =IF(A9="","",IF(AND(V9="Yes",X9="Yes",Y9="Yes",Z9="Yes",AA9="Yes"),"✅ ALL CHECKS COMPLETE — OK TO CLOSE","⚠ "&(5-COUNTIF(V9:Z9,"Yes"))&" CHECK(S) INCOMPLETE")) | AK9: =IF(AI9="Yes",IF(AJ9="","",AJ9+21),"")
B10: =IFERROR(VLOOKUP(A10,'Incident Intake'!$A:$B,2,FALSE()),"") | C10: =IFERROR(VLOOKUP(A10,'Incident Intake'!$A:$E,5,FALSE()),"") | D10: =IFERROR(VLOOKUP(A10,'Incident Intake'!$A:$G,7,FALSE())&" "&VLOOKUP(A10,'Incident Intake'!$A:$F,6,FALSE()),"") | E10: =IFERROR(VLOOKUP(A10,'Incident Intake'!$A:$J,10,FALSE()),"") | AB10: =IF(A10="","",IF(AB10="Yes","Closed",IF(T10="Yes","Consequence Assigned",IF(O10="Yes","Finding Reached",IF(F10="Yes","In Progress","Open"))))) | AC10: =IF(OR(A10="",AB10="Yes"),"",IF(B10="","",TODAY()-B10)) | AD10: =IF(A10="","",IF(AND(V10="Yes",X10="Yes",Y10="Yes",Z10="Yes",AA10="Yes"),"✅ ALL CHECKS COMPLETE — OK TO CLOSE","⚠ "&(5-COUNTIF(V10:Z10,"Yes"))&" CHECK(S) INCOMPLETE")) | AK10: =IF(AI10="Yes",IF(AJ10="","",AJ10+21),"")
B11: =IFERROR(VLOOKUP(A11,'Incident Intake'!$A:$B,2,FALSE()),"") | C11: =IFERROR(VLOOKUP(A11,'Incident Intake'!$A:$E,5,FALSE()),"") | D11: =IFERROR(VLOOKUP(A11,'Incident Intake'!$A:$G,7,FALSE())&" "&VLOOKUP(A11,'Incident Intake'!$A:$F,6,FALSE()),"") | E11: =IFERROR(VLOOKUP(A11,'Incident Intake'!$A:$J,10,FALSE()),"") | AB11: =IF(A11="","",IF(AB11="Yes","Closed",IF(T11="Yes","Consequence Assigned",IF(O11="Yes","Finding Reached",IF(F11="Yes","In Progress","Open"))))) | AC11: =IF(OR(A11="",AB11="Yes"),"",IF(B11="","",TODAY()-B11)) | AD11: =IF(A11="","",IF(AND(V11="Yes",X11="Yes",Y11="Yes",Z11="Yes",AA11="Yes"),"✅ ALL CHECKS COMPLETE — OK TO CLOSE","⚠ "&(5-COUNTIF(V11:Z11,"Yes"))&" CHECK(S) INCOMPLETE")) | AK11: =IF(AI11="Yes",IF(AJ11="","",AJ11+21),"")
B12: =IFERROR(VLOOKUP(A12,'Incident Intake'!$A:$B,2,FALSE()),"") | C12: =IFERROR(VLOOKUP(A12,'Incident Intake'!$A:$E,5,FALSE()),"") | D12: =IFERROR(VLOOKUP(A12,'Incident Intake'!$A:$G,7,FALSE())&" "&VLOOKUP(A12,'Incident Intake'!$A:$F,6,FALSE()),"") | E12: =IFERROR(VLOOKUP(A12,'Incident Intake'!$A:$J,10,FALSE()),"") | AB12: =IF(A12="","",IF(AB12="Yes","Closed",IF(T12="Yes","Consequence Assigned",IF(O12="Yes","Finding Reached",IF(F12="Yes","In Progress","Open"))))) | AC12: =IF(OR(A12="",AB12="Yes"),"",IF(B12="","",TODAY()-B12)) | AD12: =IF(A12="","",IF(AND(V12="Yes",X12="Yes",Y12="Yes",Z12="Yes",AA12="Yes"),"✅ ALL CHECKS COMPLETE — OK TO CLOSE","⚠ "&(5-COUNTIF(V12:Z12,"Yes"))&" CHECK(S) INCOMPLETE")) | AK12: =IF(AI12="Yes",IF(AJ12="","",AJ12+21),"")
B13: =IFERROR(VLOOKUP(A13,'Incident Intake'!$A:$B,2,FALSE()),"") | C13: =IFERROR(VLOOKUP(A13,'Incident Intake'!$A:$E,5,FALSE()),"") | D13: =IFERROR(VLOOKUP(A13,'Incident Intake'!$A:$G,7,FALSE())&" "&VLOOKUP(A13,'Incident Intake'!$A:$F,6,FALSE()),"") | E13: =IFERROR(VLOOKUP(A13,'Incident Intake'!$A:$J,10,FALSE()),"") | AB13: =IF(A13="","",IF(AB13="Yes","Closed",IF(T13="Yes","Consequence Assigned",IF(O13="Yes","Finding Reached",IF(F13="Yes","In Progress","Open"))))) | AC13: =IF(OR(A13="",AB13="Yes"),"",IF(B13="","",TODAY()-B13)) | AD13: =IF(A13="","",IF(AND(V13="Yes",X13="Yes",Y13="Yes",Z13="Yes",AA13="Yes"),"✅ ALL CHECKS COMPLETE — OK TO CLOSE","⚠ "&(5-COUNTIF(V13:Z13,"Yes"))&" CHECK(S) INCOMPLETE")) | AK13: =IF(AI13="Yes",IF(AJ13="","",AJ13+21),"")
B14: =IFERROR(VLOOKUP(A14,'Incident Intake'!$A:$B,2,FALSE()),"") | C14: =IFERROR(VLOOKUP(A14,'Incident Intake'!$A:$E,5,FALSE()),"") | D14: =IFERROR(VLOOKUP(A14,'Incident Intake'!$A:$G,7,FALSE())&" "&VLOOKUP(A14,'Incident Intake'!$A:$F,6,FALSE()),"") | E14: =IFERROR(VLOOKUP(A14,'Incident Intake'!$A:$J,10,FALSE()),"") | AB14: =IF(A14="","",IF(AB14="Yes","Closed",IF(T14="Yes","Consequence Assigned",IF(O14="Yes","Finding Reached",IF(F14="Yes","In Progress","Open"))))) | AC14: =IF(OR(A14="",AB14="Yes"),"",IF(B14="","",TODAY()-B14)) | AD14: =IF(A14="","",IF(AND(V14="Yes",X14="Yes",Y14="Yes",Z14="Yes",AA14="Yes"),"✅ ALL CHECKS COMPLETE — OK TO CLOSE","⚠ "&(5-COUNTIF(V14:Z14,"Yes"))&" CHECK(S) INCOMPLETE")) | AK14: =IF(AI14="Yes",IF(AJ14="","",AJ14+21),"")
B15: =IFERROR(VLOOKUP(A15,'Incident Intake'!$A:$B,2,FALSE()),"") | C15: =IFERROR(VLOOKUP(A15,'Incident Intake'!$A:$E,5,FALSE()),"") | D15: =IFERROR(VLOOKUP(A15,'Incident Intake'!$A:$G,7,FALSE())&" "&VLOOKUP(A15,'Incident Intake'!$A:$F,6,FALSE()),"") | E15: =IFERROR(VLOOKUP(A15,'Incident Intake'!$A:$J,10,FALSE()),"") | AB15: =IF(A15="","",IF(AB15="Yes","Closed",IF(T15="Yes","Consequence Assigned",IF(O15="Yes","Finding Reached",IF(F15="Yes","In Progress","Open"))))) | AC15: =IF(OR(A15="",AB15="Yes"),"",IF(B15="","",TODAY()-B15)) | AD15: =IF(A15="","",IF(AND(V15="Yes",X15="Yes",Y15="Yes",Z15="Yes",AA15="Yes"),"✅ ALL CHECKS COMPLETE — OK TO CLOSE","⚠ "&(5-COUNTIF(V15:Z15,"Yes"))&" CHECK(S) INCOMPLETE")) | AK15: =IF(AI15="Yes",IF(AJ15="","",AJ15+21),"")
B16: =IFERROR(VLOOKUP(A16,'Incident Intake'!$A:$B,2,FALSE()),"") | C16: =IFERROR(VLOOKUP(A16,'Incident Intake'!$A:$E,5,FALSE()),"") | D16: =IFERROR(VLOOKUP(A16,'Incident Intake'!$A:$G,7,FALSE())&" "&VLOOKUP(A16,'Incident Intake'!$A:$F,6,FALSE()),"") | E16: =IFERROR(VLOOKUP(A16,'Incident Intake'!$A:$J,10,FALSE()),"") | AB16: =IF(A16="","",IF(AB16="Yes","Closed",IF(T16="Yes","Consequence Assigned",IF(O16="Yes","Finding Reached",IF(F16="Yes","In Progress","Open"))))) | AC16: =IF(OR(A16="",AB16="Yes"),"",IF(B16="","",TODAY()-B16)) | AD16: =IF(A16="","",IF(AND(V16="Yes",X16="Yes",Y16="Yes",Z16="Yes",AA16="Yes"),"✅ ALL CHECKS COMPLETE — OK TO CLOSE","⚠ "&(5-COUNTIF(V16:Z16,"Yes"))&" CHECK(S) INCOMPLETE")) | AK16: =IF(AI16="Yes",IF(AJ16="","",AJ16+21),"")
B17: =IFERROR(VLOOKUP(A17,'Incident Intake'!$A:$B,2,FALSE()),"") | C17: =IFERROR(VLOOKUP(A17,'Incident Intake'!$A:$E,5,FALSE()),"") | D17: =IFERROR(VLOOKUP(A17,'Incident Intake'!$A:$G,7,FALSE())&" "&VLOOKUP(A17,'Incident Intake'!$A:$F,6,FALSE()),"") | E17: =IFERROR(VLOOKUP(A17,'Incident Intake'!$A:$J,10,FALSE()),"") | AB17: =IF(A17="","",IF(AB17="Yes","Closed",IF(T17="Yes","Consequence Assigned",IF(O17="Yes","Finding Reached",IF(F17="Yes","In Progress","Open"))))) | AC17: =IF(OR(A17="",AB17="Yes"),"",IF(B17="","",TODAY()-B17)) | AD17: =IF(A17="","",IF(AND(V17="Yes",X17="Yes",Y17="Yes",Z17="Yes",AA17="Yes"),"✅ ALL CHECKS COMPLETE — OK TO CLOSE","⚠ "&(5-COUNTIF(V17:Z17,"Yes"))&" CHECK(S) INCOMPLETE")) | AK17: =IF(AI17="Yes",IF(AJ17="","",AJ17+21),"")
... B205: =IFERROR(VLOOKUP(A205,'Incident Intake'!$A:$B,2,FALSE()),"") | C205: =IFERROR(VLOOKUP(A205,'Incident Intake'!$A:$E,5,FALSE()),"") | D205: =IFERROR(VLOOKUP(A205,'Incident Intake'!$A:$G,7,FALSE())&" "&VLOOKUP(A205,'Incident Intake'!$A:$F,6,FALSE()),"") | E205: =IFERROR(VLOOKUP(A205,'Incident Intake'!$A:$J,10,FALSE()),"") | AB205: =IF(A205="","",IF(AB205="Yes","Closed",IF(T205="Yes","Consequence Assigned",IF(O205="Yes","Finding Reached",IF(F205="Yes","In Progress","Open"))))) | AC205: =IF(OR(A205="",AB205="Yes"),"",IF(B205="","",TODAY()-B205)) | AD205: =IF(A205="","",IF(AND(V205="Yes",X205="Yes",Y205="Yes",Z205="Yes",AA205="Yes"),"✅ ALL CHECKS COMPLETE — OK TO CLOSE","⚠ "&(5-COUNTIF(V205:Z205,"Yes"))&" CHECK(S) INCOMPLETE")) | AK205: =IF(AI205="Yes",IF(AJ205="","",AJ205+21),"")
A206: 🚀 Upgrade to the full platform · clearpathedgroup.com · Clear Path Education Group, LLC

Sheet 10-Day Compliance
A1: 🔴 10-Day SPED Removal Compliance Tracker · IDEA Compliance Required
A2: Track every SPED student's cumulative removal days. Alerts fire at day 7 (warning), day 9 (urgent), day 10+ (MDR required NOW). FAPE must continue after day 10.
A3: ⚠ School days only — not calendar days. Log each removal incident by Incident ID. The ⚙ Total column sums all removal days this school year.
A4: Student ID | B4: Last Name | C4: First Name | D4: Grade | E4: ⚙ Total Removal Days | F4: Incident 1 ID | G4: Incident 1 Date | H4: ⚙ Inc 1 Days | I4: Incident 2 ID | J4: Incident 2 Date | K4: ⚙ Inc 2 Days | L4: Incident 3 ID | M4: Incident 3 Date | N4: ⚙ Inc 3 Days | O4: Incident 4 ID | P4: Incident 4 Date | Q4: ⚙ Inc 4 Days | R4: Incident 5 ID | S4: Incident 5 Date | T4: ⚙ Inc 5 Days | U4: SPED Status | V4: MDR Required? | W4: MDR Date | X4: ARD Coordinator Notified? | Y4: ARD Notification Date | Z4: FAPE Continuing? | AA4: ⚙ Compliance Status | AB4: Notes
E5: =SUM(H5,K5,N5,Q5,T5) -> 0 | H5: =IF(F5="","",IFERROR(VLOOKUP(F5,'Incident Intake'!$A:$AE,31,FALSE())-VLOOKUP(F5,'Incident Intake'!$A:$AD,30,FALSE())+1,1)) | K5: =IF(I5="","",IFERROR(VLOOKUP(I5,'Incident Intake'!$A:$AE,31,FALSE())-VLOOKUP(I5,'Incident Intake'!$A:$AD,30,FALSE())+1,1)) | N5: =IF(L5="","",IFERROR(VLOOKUP(L5,'Incident Intake'!$A:$AE,31,FALSE())-VLOOKUP(L5,'Incident Intake'!$A:$AD,30,FALSE())+1,1)) | Q5: =IF(O5="","",IFERROR(VLOOKUP(O5,'Incident Intake'!$A:$AE,31,FALSE())-VLOOKUP(O5,'Incident Intake'!$A:$AD,30,FALSE())+1,1)) | T5: =IF(R5="","",IFERROR(VLOOKUP(R5,'Incident Intake'!$A:$AE,31,FALSE())-VLOOKUP(R5,'Incident Intake'!$A:$AD,30,FALSE())+1,1)) | AA5: =IF(A5="","",IF(E5>=10,"🔴 EXCEEDED — MDR REQUIRED NOW",IF(E5>=9,"🟠 URGENT — Day "&E5&" — Notify SPED Coord",IF(E5>=7,"🟡 WARNING — Day "&E5&" — Plan MDR",IF(E5>0,"✅ OK — "&E5&" days","✅ No removals")))))
E6: =SUM(H6,K6,N6,Q6,T6) -> 0 | H6: =IF(F6="","",IFERROR(VLOOKUP(F6,'Incident Intake'!$A:$AE,31,FALSE())-VLOOKUP(F6,'Incident Intake'!$A:$AD,30,FALSE())+1,1)) | K6: =IF(I6="","",IFERROR(VLOOKUP(I6,'Incident Intake'!$A:$AE,31,FALSE())-VLOOKUP(I6,'Incident Intake'!$A:$AD,30,FALSE())+1,1)) | N6: =IF(L6="","",IFERROR(VLOOKUP(L6,'Incident Intake'!$A:$AE,31,FALSE())-VLOOKUP(L6,'Incident Intake'!$A:$AD,30,FALSE())+1,1)) | Q6: =IF(O6="","",IFERROR(VLOOKUP(O6,'Incident Intake'!$A:$AE,31,FALSE())-VLOOKUP(O6,'Incident Intake'!$A:$AD,30,FALSE())+1,1)) | T6: =IF(R6="","",IFERROR(VLOOKUP(R6,'Incident Intake'!$A:$AE,31,FALSE())-VLOOKUP(R6,'Incident Intake'!$A:$AD,30,FALSE())+1,1)) | AA6: =IF(A6="","",IF(E6>=10,"🔴 EXCEEDED — MDR REQUIRED NOW",IF(E6>=9,"🟠 URGENT — Day "&E6&" — Notify SPED Coord",IF(E6>=7,"🟡 WARNING — Day "&E6&" — Plan MDR",IF(E6>0,"✅ OK — "&E6&" days","✅ No removals")))))
E7: =SUM(H7,K7,N7,Q7,T7) -> 0 | H7: =IF(F7="","",IFERROR(VLOOKUP(F7,'Incident Intake'!$A:$AE,31,FALSE())-VLOOKUP(F7,'Incident Intake'!$A:$AD,30,FALSE())+1,1)) | K7: =IF(I7="","",IFERROR(VLOOKUP(I7,'Incident Intake'!$A:$AE,31,FALSE())-VLOOKUP(I7,'Incident Intake'!$A:$AD,30,FALSE())+1,1)) | N7: =IF(L7="","",IFERROR(VLOOKUP(L7,'Incident Intake'!$A:$AE,31,FALSE())-VLOOKUP(L7,'Incident Intake'!$A:$AD,30,FALSE())+1,1)) | Q7: =IF(O7="","",IFERROR(VLOOKUP(O7,'Incident Intake'!$A:$AE,31,FALSE())-VLOOKUP(O7,'Incident Intake'!$A:$AD,30,FALSE())+1,1)) | T7: =IF(R7="","",IFERROR(VLOOKUP(R7,'Incident Intake'!$A:$AE,31,FALSE())-VLOOKUP(R7,'Incident Intake'!$A:$AD,30,FALSE())+1,1)) | AA7: =IF(A7="","",IF(E7>=10,"🔴 EXCEEDED — MDR REQUIRED NOW",IF(E7>=9,"🟠 URGENT — Day "&E7&" — Notify SPED Coord",IF(E7>=7,"🟡 WARNING — Day "&E7&" — Plan MDR",IF(E7>0,"✅ OK — "&E7&" days","✅ No removals")))))
E8: =SUM(H8,K8,N8,Q8,T8) -> 0 | H8: =IF(F8="","",IFERROR(VLOOKUP(F8,'Incident Intake'!$A:$AE,31,FALSE())-VLOOKUP(F8,'Incident Intake'!$A:$AD,30,FALSE())+1,1)) | K8: =IF(I8="","",IFERROR(VLOOKUP(I8,'Incident Intake'!$A:$AE,31,FALSE())-VLOOKUP(I8,'Incident Intake'!$A:$AD,30,FALSE())+1,1)) | N8: =IF(L8="","",IFERROR(VLOOKUP(L8,'Incident Intake'!$A:$AE,31,FALSE())-VLOOKUP(L8,'Incident Intake'!$A:$AD,30,FALSE())+1,1)) | Q8: =IF(O8="","",IFERROR(VLOOKUP(O8,'Incident Intake'!$A:$AE,31,FALSE())-VLOOKUP(O8,'Incident Intake'!$A:$AD,30,FALSE())+1,1)) | T8: =IF(R8="","",IFERROR(VLOOKUP(R8,'Incident Intake'!$A:$AE,31,FALSE())-VLOOKUP(R8,'Incident Intake'!$A:$AD,30,FALSE())+1,1)) | AA8: =IF(A8="","",IF(E8>=10,"🔴 EXCEEDED — MDR REQUIRED NOW",IF(E8>=9,"🟠 URGENT — Day "&E8&" — Notify SPED Coord",IF(E8>=7,"🟡 WARNING — Day "&E8&" — Plan MDR",IF(E8>0,"✅ OK — "&E8&" days","✅ No removals")))))
E9: =SUM(H9,K9,N9,Q9,T9) -> 0 | H9: =IF(F9="","",IFERROR(VLOOKUP(F9,'Incident Intake'!$A:$AE,31,FALSE())-VLOOKUP(F9,'Incident Intake'!$A:$AD,30,FALSE())+1,1)) | K9: =IF(I9="","",IFERROR(VLOOKUP(I9,'Incident Intake'!$A:$AE,31,FALSE())-VLOOKUP(I9,'Incident Intake'!$A:$AD,30,FALSE())+1,1)) | N9: =IF(L9="","",IFERROR(VLOOKUP(L9,'Incident Intake'!$A:$AE,31,FALSE())-VLOOKUP(L9,'Incident Intake'!$A:$AD,30,FALSE())+1,1)) | Q9: =IF(O9="","",IFERROR(VLOOKUP(O9,'Incident Intake'!$A:$AE,31,FALSE())-VLOOKUP(O9,'Incident Intake'!$A:$AD,30,FALSE())+1,1)) | T9: =IF(R9="","",IFERROR(VLOOKUP(R9,'Incident Intake'!$A:$AE,31,FALSE())-VLOOKUP(R9,'Incident Intake'!$A:$AD,30,FALSE())+1,1)) | AA9: =IF(A9="","",IF(E9>=10,"🔴 EXCEEDED — MDR REQUIRED NOW",IF(E9>=9,"🟠 URGENT — Day "&E9&" — Notify SPED Coord",IF(E9>=7,"🟡 WARNING — Day "&E9&" — Plan MDR",IF(E9>0,"✅ OK — "&E9&" days","✅ No removals")))))
E10: =SUM(H10,K10,N10,Q10,T10) -> 0 | H10: =IF(F10="","",IFERROR(VLOOKUP(F10,'Incident Intake'!$A:$AE,31,FALSE())-VLOOKUP(F10,'Incident Intake'!$A:$AD,30,FALSE())+1,1)) | K10: =IF(I10="","",IFERROR(VLOOKUP(I10,'Incident Intake'!$A:$AE,31,FALSE())-VLOOKUP(I10,'Incident Intake'!$A:$AD,30,FALSE())+1,1)) | N10: =IF(L10="","",IFERROR(VLOOKUP(L10,'Incident Intake'!$A:$AE,31,FALSE())-VLOOKUP(L10,'Incident Intake'!$A:$AD,30,FALSE())+1,1)) | Q10: =IF(O10="","",IFERROR(VLOOKUP(O10,'Incident Intake'!$A:$AE,31,FALSE())-VLOOKUP(O10,'Incident Intake'!$A:$AD,30,FALSE())+1,1)) | T10: =IF(R10="","",IFERROR(VLOOKUP(R10,'Incident Intake'!$A:$AE,31,FALSE())-VLOOKUP(R10,'Incident Intake'!$A:$AD,30,FALSE())+1,1)) | AA10: =IF(A10="","",IF(E10>=10,"🔴 EXCEEDED — MDR REQUIRED NOW",IF(E10>=9,"🟠 URGENT — Day "&E10&" — Notify SPED Coord",IF(E10>=7,"🟡 WARNING — Day "&E10&" — Plan MDR",IF(E10>0,"✅ OK — "&E10&" days","✅ No removals")))))
E11: =SUM(H11,K11,N11,Q11,T11) -> 0 | H11: =IF(F11="","",IFERROR(VLOOKUP(F11,'Incident Intake'!$A:$AE,31,FALSE())-VLOOKUP(F11,'Incident Intake'!$A:$AD,30,FALSE())+1,1)) | K11: =IF(I11="","",IFERROR(VLOOKUP(I11,'Incident Intake'!$A:$AE,31,FALSE())-VLOOKUP(I11,'Incident Intake'!$A:$AD,30,FALSE())+1,1)) | N11: =IF(L11="","",IFERROR(VLOOKUP(L11,'Incident Intake'!$A:$AE,31,FALSE())-VLOOKUP(L11,'Incident Intake'!$A:$AD,30,FALSE())+1,1)) | Q11: =IF(O11="","",IFERROR(VLOOKUP(O11,'Incident Intake'!$A:$AE,31,FALSE())-VLOOKUP(O11,'Incident Intake'!$A:$AD,30,FALSE())+1,1)) | T11: =IF(R11="","",IFERROR(VLOOKUP(R11,'Incident Intake'!$A:$AE,31,FALSE())-VLOOKUP(R11,'Incident Intake'!$A:$AD,30,FALSE())+1,1)) | AA11: =IF(A11="","",IF(E11>=10,"🔴 EXCEEDED — MDR REQUIRED NOW",IF(E11>=9,"🟠 URGENT — Day "&E11&" — Notify SPED Coord",IF(E11>=7,"🟡 WARNING — Day "&E11&" — Plan MDR",IF(E11>0,"✅ OK — "&E11&" days","✅ No removals")))))
E12: =SUM(H12,K12,N12,Q12,T12) -> 0 | H12: =IF(F12="","",IFERROR(VLOOKUP(F12,'Incident Intake'!$A:$AE,31,FALSE())-VLOOKUP(F12,'Incident Intake'!$A:$AD,30,FALSE())+1,1)) | K12: =IF(I12="","",IFERROR(VLOOKUP(I12,'Incident Intake'!$A:$AE,31,FALSE())-VLOOKUP(I12,'Incident Intake'!$A:$AD,30,FALSE())+1,1)) | N12: =IF(L12="","",IFERROR(VLOOKUP(L12,'Incident Intake'!$A:$AE,31,FALSE())-VLOOKUP(L12,'Incident Intake'!$A:$AD,30,FALSE())+1,1)) | Q12: =IF(O12="","",IFERROR(VLOOKUP(O12,'Incident Intake'!$A:$AE,31,FALSE())-VLOOKUP(O12,'Incident Intake'!$A:$AD,30,FALSE())+1,1)) | T12: =IF(R12="","",IFERROR(VLOOKUP(R12,'Incident Intake'!$A:$AE,31,FALSE())-VLOOKUP(R12,'Incident Intake'!$A:$AD,30,FALSE())+1,1)) | AA12: =IF(A12="","",IF(E12>=10,"🔴 EXCEEDED — MDR REQUIRED NOW",IF(E12>=9,"🟠 URGENT — Day "&E12&" — Notify SPED Coord",IF(E12>=7,"🟡 WARNING — Day "&E12&" — Plan MDR",IF(E12>0,"✅ OK — "&E12&" days","✅ No removals")))))
E13: =SUM(H13,K13,N13,Q13,T13) -> 0 | H13: =IF(F13="","",IFERROR(VLOOKUP(F13,'Incident Intake'!$A:$AE,31,FALSE())-VLOOKUP(F13,'Incident Intake'!$A:$AD,30,FALSE())+1,1)) | K13: =IF(I13="","",IFERROR(VLOOKUP(I13,'Incident Intake'!$A:$AE,31,FALSE())-VLOOKUP(I13,'Incident Intake'!$A:$AD,30,FALSE())+1,1)) | N13: =IF(L13="","",IFERROR(VLOOKUP(L13,'Incident Intake'!$A:$AE,31,FALSE())-VLOOKUP(L13,'Incident Intake'!$A:$AD,30,FALSE())+1,1)) | Q13: =IF(O13="","",IFERROR(VLOOKUP(O13,'Incident Intake'!$A:$AE,31,FALSE())-VLOOKUP(O13,'Incident Intake'!$A:$AD,30,FALSE())+1,1)) | T13: =IF(R13="","",IFERROR(VLOOKUP(R13,'Incident Intake'!$A:$AE,31,FALSE())-VLOOKUP(R13,'Incident Intake'!$A:$AD,30,FALSE())+1,1)) | AA13: =IF(A13="","",IF(E13>=10,"🔴 EXCEEDED — MDR REQUIRED NOW",IF(E13>=9,"🟠 URGENT — Day "&E13&" — Notify SPED Coord",IF(E13>=7,"🟡 WARNING — Day "&E13&" — Plan MDR",IF(E13>0,"✅ OK — "&E13&" days","✅ No removals")))))
E14: =SUM(H14,K14,N14,Q14,T14) -> 0 | H14: =IF(F14="","",IFERROR(VLOOKUP(F14,'Incident Intake'!$A:$AE,31,FALSE())-VLOOKUP(F14,'Incident Intake'!$A:$AD,30,FALSE())+1,1)) | K14: =IF(I14="","",IFERROR(VLOOKUP(I14,'Incident Intake'!$A:$AE,31,FALSE())-VLOOKUP(I14,'Incident Intake'!$A:$AD,30,FALSE())+1,1)) | N14: =IF(L14="","",IFERROR(VLOOKUP(L14,'Incident Intake'!$A:$AE,31,FALSE())-VLOOKUP(L14,'Incident Intake'!$A:$AD,30,FALSE())+1,1)) | Q14: =IF(O14="","",IFERROR(VLOOKUP(O14,'Incident Intake'!$A:$AE,31,FALSE())-VLOOKUP(O14,'Incident Intake'!$A:$AD,30,FALSE())+1,1)) | T14: =IF(R14="","",IFERROR(VLOOKUP(R14,'Incident Intake'!$A:$AE,31,FALSE())-VLOOKUP(R14,'Incident Intake'!$A:$AD,30,FALSE())+1,1)) | AA14: =IF(A14="","",IF(E14>=10,"🔴 EXCEEDED — MDR REQUIRED NOW",IF(E14>=9,"🟠 URGENT — Day "&E14&" — Notify SPED Coord",IF(E14>=7,"🟡 WARNING — Day "&E14&" — Plan MDR",IF(E14>0,"✅ OK — "&E14&" days","✅ No removals")))))
E15: =SUM(H15,K15,N15,Q15,T15) -> 0 | H15: =IF(F15="","",IFERROR(VLOOKUP(F15,'Incident Intake'!$A:$AE,31,FALSE())-VLOOKUP(F15,'Incident Intake'!$A:$AD,30,FALSE())+1,1)) | K15: =IF(I15="","",IFERROR(VLOOKUP(I15,'Incident Intake'!$A:$AE,31,FALSE())-VLOOKUP(I15,'Incident Intake'!$A:$AD,30,FALSE())+1,1)) | N15: =IF(L15="","",IFERROR(VLOOKUP(L15,'Incident Intake'!$A:$AE,31,FALSE())-VLOOKUP(L15,'Incident Intake'!$A:$AD,30,FALSE())+1,1)) | Q15: =IF(O15="","",IFERROR(VLOOKUP(O15,'Incident Intake'!$A:$AE,31,FALSE())-VLOOKUP(O15,'Incident Intake'!$A:$AD,30,FALSE())+1,1)) | T15: =IF(R15="","",IFERROR(VLOOKUP(R15,'Incident Intake'!$A:$AE,31,FALSE())-VLOOKUP(R15,'Incident Intake'!$A:$AD,30,FALSE())+1,1)) | AA15: =IF(A15="","",IF(E15>=10,"🔴 EXCEEDED — MDR REQUIRED NOW",IF(E15>=9,"🟠 URGENT — Day "&E15&" — Notify SPED Coord",IF(E15>=7,"🟡 WARNING — Day "&E15&" — Plan MDR",IF(E15>0,"✅ OK — "&E15&" days","✅ No removals")))))
E16: =SUM(H16,K16,N16,Q16,T16) -> 0 | H16: =IF(F16="","",IFERROR(VLOOKUP(F16,'Incident Intake'!$A:$AE,31,FALSE())-VLOOKUP(F16,'Incident Intake'!$A:$AD,30,FALSE())+1,1)) | K16: =IF(I16="","",IFERROR(VLOOKUP(I16,'Incident Intake'!$A:$AE,31,FALSE())-VLOOKUP(I16,'Incident Intake'!$A:$AD,30,FALSE())+1,1)) | N16: =IF(L16="","",IFERROR(VLOOKUP(L16,'Incident Intake'!$A:$AE,31,FALSE())-VLOOKUP(L16,'Incident Intake'!$A:$AD,30,FALSE())+1,1)) | Q16: =IF(O16="","",IFERROR(VLOOKUP(O16,'Incident Intake'!$A:$AE,31,FALSE())-VLOOKUP(O16,'Incident Intake'!$A:$AD,30,FALSE())+1,1)) | T16: =IF(R16="","",IFERROR(VLOOKUP(R16,'Incident Intake'!$A:$AE,31,FALSE())-VLOOKUP(R16,'Incident Intake'!$A:$AD,30,FALSE())+1,1)) | AA16: =IF(A16="","",IF(E16>=10,"🔴 EXCEEDED — MDR REQUIRED NOW",IF(E16>=9,"🟠 URGENT — Day "&E16&" — Notify SPED Coord",IF(E16>=7,"🟡 WARNING — Day "&E16&" — Plan MDR",IF(E16>0,"✅ OK — "&E16&" days","✅ No removals")))))
... E154: =SUM(H154,K154,N154,Q154,T154) -> 0 | H154: =IF(F154="","",IFERROR(VLOOKUP(F154,'Incident Intake'!$A:$AE,31,FALSE())-VLOOKUP(F154,'Incident Intake'!$A:$AD,30,FALSE())+1,1)) | K154: =IF(I154="","",IFERROR(VLOOKUP(I154,'Incident Intake'!$A:$AE,31,FALSE())-VLOOKUP(I154,'Incident Intake'!$A:$AD,30,FALSE())+1,1)) | N154: =IF(L154="","",IFERROR(VLOOKUP(L154,'Incident Intake'!$A:$AE,31,FALSE())-VLOOKUP(L154,'Incident Intake'!$A:$AD,30,FALSE())+1,1)) | Q154: =IF(O154="","",IFERROR(VLOOKUP(O154,'Incident Intake'!$A:$AE,31,FALSE())-VLOOKUP(O154,'Incident Intake'!$A:$AD,30,FALSE())+1,1)) | T154: =IF(R154="","",IFERROR(VLOOKUP(R154,'Incident Intake'!$A:$AE,31,FALSE())-VLOOKUP(R154,'Incident Intake'!$A:$AD,30,FALSE())+1,1)) | AA154: =IF(A154="","",IF(E154>=10,"🔴 EXCEEDED — MDR REQUIRED NOW",IF(E154>=9,"🟠 URGENT — Day "&E154&" — Notify SPED Coord",IF(E154>=7,"🟡 WARNING — Day "&E154&" — Plan MDR",IF(E154>0,"✅ OK — "&E154&" days","✅ No removals")))))
A155: 🚀 Upgrade to the full platform · clearpathedgroup.com · Clear Path Education Group, LLC

Sheet Evidence Tracker
A1: Evidence Tracker — Chain of Custody Log · Every Piece of Evidence, Every Step
A2: Log every item of evidence: when received, from whom, where stored, who accessed it, when returned. This is your legal protection if challenged.
A3: LEGAL HOLD: If a parent requests records or files a complaint, set col S = 'Yes' immediately. This flags the row and prevents accidental deletion.
A4: Evidence ID | B4: Incident ID | C4: ⚙ Student Name | D4: ⚙ Offense | E4: Date Collected | F4: Time Collected | G4: Collected By | H4: Evidence Type | I4: Description | J4: From Whom Received | K4: Received From Role | L4: Storage Location | M4: Custody Status | N4: Accessed By | O4: Access Date | P4: Access Purpose | Q4: Returned To | R4: Return Date | S4: Legal Hold? | T4: ⚙ Legal Hold Flag | U4: Chain of Custody Complete? | V4: Notes
C5: =IFERROR(VLOOKUP(B5,'Incident Intake'!$A:$G,7,FALSE())&" "&VLOOKUP(B5,'Incident Intake'!$A:$F,6,FALSE()),"") | D5: =IFERROR(VLOOKUP(B5,'Incident Intake'!$A:$J,10,FALSE()),"") | T5: =IF(S5="Yes","🔴 LEGAL HOLD — DO NOT DESTROY","")
C6: =IFERROR(VLOOKUP(B6,'Incident Intake'!$A:$G,7,FALSE())&" "&VLOOKUP(B6,'Incident Intake'!$A:$F,6,FALSE()),"") | D6: =IFERROR(VLOOKUP(B6,'Incident Intake'!$A:$J,10,FALSE()),"") | T6: =IF(S6="Yes","🔴 LEGAL HOLD — DO NOT DESTROY","")
C7: =IFERROR(VLOOKUP(B7,'Incident Intake'!$A:$G,7,FALSE())&" "&VLOOKUP(B7,'Incident Intake'!$A:$F,6,FALSE()),"") | D7: =IFERROR(VLOOKUP(B7,'Incident Intake'!$A:$J,10,FALSE()),"") | T7: =IF(S7="Yes","🔴 LEGAL HOLD — DO NOT DESTROY","")
C8: =IFERROR(VLOOKUP(B8,'Incident Intake'!$A:$G,7,FALSE())&" "&VLOOKUP(B8,'Incident Intake'!$A:$F,6,FALSE()),"") | D8: =IFERROR(VLOOKUP(B8,'Incident Intake'!$A:$J,10,FALSE()),"") | T8: =IF(S8="Yes","🔴 LEGAL HOLD — DO NOT DESTROY","")
C9: =IFERROR(VLOOKUP(B9,'Incident Intake'!$A:$G,7,FALSE())&" "&VLOOKUP(B9,'Incident Intake'!$A:$F,6,FALSE()),"") | D9: =IFERROR(VLOOKUP(B9,'Incident Intake'!$A:$J,10,FALSE()),"") | T9: =IF(S9="Yes","🔴 LEGAL HOLD — DO NOT DESTROY","")
C10: =IFERROR(VLOOKUP(B10,'Incident Intake'!$A:$G,7,FALSE())&" "&VLOOKUP(B10,'Incident Intake'!$A:$F,6,FALSE()),"") | D10: =IFERROR(VLOOKUP(B10,'Incident Intake'!$A:$J,10,FALSE()),"") | T10: =IF(S10="Yes","🔴 LEGAL HOLD — DO NOT DESTROY","")
C11: =IFERROR(VLOOKUP(B11,'Incident Intake'!$A:$G,7,FALSE())&" "&VLOOKUP(B11,'Incident Intake'!$A:$F,6,FALSE()),"") | D11: =IFERROR(VLOOKUP(B11,'Incident Intake'!$A:$J,10,FALSE()),"") | T11: =IF(S11="Yes","🔴 LEGAL HOLD — DO NOT DESTROY","")
C12: =IFERROR(VLOOKUP(B12,'Incident Intake'!$A:$G,7,FALSE())&" "&VLOOKUP(B12,'Incident Intake'!$A:$F,6,FALSE()),"") | D12: =IFERROR(VLOOKUP(B12,'Incident Intake'!$A:$J,10,FALSE()),"") | T12: =IF(S12="Yes","🔴 LEGAL HOLD — DO NOT DESTROY","")
C13: =IFERROR(VLOOKUP(B13,'Incident Intake'!$A:$G,7,FALSE())&" "&VLOOKUP(B13,'Incident Intake'!$A:$F,6,FALSE()),"") | D13: =IFERROR(VLOOKUP(B13,'Incident Intake'!$A:$J,10,FALSE()),"") | T13: =IF(S13="Yes","🔴 LEGAL HOLD — DO NOT DESTROY","")
C14: =IFERROR(VLOOKUP(B14,'Incident Intake'!$A:$G,7,FALSE())&" "&VLOOKUP(B14,'Incident Intake'!$A:$F,6,FALSE()),"") | D14: =IFERROR(VLOOKUP(B14,'Incident Intake'!$A:$J,10,FALSE()),"") | T14: =IF(S14="Yes","🔴 LEGAL HOLD — DO NOT DESTROY","")
C15: =IFERROR(VLOOKUP(B15,'Incident Intake'!$A:$G,7,FALSE())&" "&VLOOKUP(B15,'Incident Intake'!$A:$F,6,FALSE()),"") | D15: =IFERROR(VLOOKUP(B15,'Incident Intake'!$A:$J,10,FALSE()),"") | T15: =IF(S15="Yes","🔴 LEGAL HOLD — DO NOT DESTROY","")
C16: =IFERROR(VLOOKUP(B16,'Incident Intake'!$A:$G,7,FALSE())&" "&VLOOKUP(B16,'Incident Intake'!$A:$F,6,FALSE()),"") | D16: =IFERROR(VLOOKUP(B16,'Incident Intake'!$A:$J,10,FALSE()),"") | T16: =IF(S16="Yes","🔴 LEGAL HOLD — DO NOT DESTROY","")
... C304: =IFERROR(VLOOKUP(B304,'Incident Intake'!$A:$G,7,FALSE())&" "&VLOOKUP(B304,'Incident Intake'!$A:$F,6,FALSE()),"") | D304: =IFERROR(VLOOKUP(B304,'Incident Intake'!$A:$J,10,FALSE()),"") | T304: =IF(S304="Yes","🔴 LEGAL HOLD — DO NOT DESTROY","")
A305: 🚀 Upgrade to the full platform · clearpathedgroup.com · Clear Path Education Group, LLC

Sheet Parent Contact Log
A1: Parent Contact Log · Every Call Documented · Scripts Auto-Populate by Offense
A2: Select an offense in column M → the phone script appears automatically in column L. Log every contact — voicemails count as attempts.
A3: TEC REQUIRED NOTICES: Suspension and DAEP placement require written notice. Document method, date, and confirmation of receipt.
A4: Log ID | B4: Incident ID | C4: Student ID | D4: ⚙ Student Name | E4: Contact Date | F4: Contact Time | G4: Contact Method | H4: Parent / Guardian Name | I4: Relationship | J4: Contact Purpose | K4: ⚙ Required by TEC? | L4: ⚙ Phone Script (select offense in col L) | M4: Script Offense Reference | N4: Summary of Conversation | O4: Commitments Made (by parent) | P4: Commitments Made (by school) | Q4: Follow-Up Required? | R4: Follow-Up Date | S4: Follow-Up Completed? | T4: Admin / Staff Initials | U4: Notes
D5: =IFERROR(VLOOKUP(C5,'Incident Intake'!$E:$G,3,FALSE())&" "&VLOOKUP(C5,'Incident Intake'!$E:$F,2,FALSE()),"") | K5: =IF(J5="","",IF(ISNUMBER(SEARCH("TEC-Required",J5)),"YES — Required","Voluntary")) | L5: =IFERROR(VLOOKUP(M5,Lists!$T:$U,2,FALSE()),"Select an offense in col M to load the phone script →") -> Select an offense in col M to load the phone script →
D6: =IFERROR(VLOOKUP(C6,'Incident Intake'!$E:$G,3,FALSE())&" "&VLOOKUP(C6,'Incident Intake'!$E:$F,2,FALSE()),"") | K6: =IF(J6="","",IF(ISNUMBER(SEARCH("TEC-Required",J6)),"YES — Required","Voluntary")) | L6: =IFERROR(VLOOKUP(M6,Lists!$T:$U,2,FALSE()),"Select an offense in col M to load the phone script →") -> Select an offense in col M to load the phone script →
D7: =IFERROR(VLOOKUP(C7,'Incident Intake'!$E:$G,3,FALSE())&" "&VLOOKUP(C7,'Incident Intake'!$E:$F,2,FALSE()),"") | K7: =IF(J7="","",IF(ISNUMBER(SEARCH("TEC-Required",J7)),"YES — Required","Voluntary")) | L7: =IFERROR(VLOOKUP(M7,Lists!$T:$U,2,FALSE()),"Select an offense in col M to load the phone script →") -> Select an offense in col M to load the phone script →
D8: =IFERROR(VLOOKUP(C8,'Incident Intake'!$E:$G,3,FALSE())&" "&VLOOKUP(C8,'Incident Intake'!$E:$F,2,FALSE()),"") | K8: =IF(J8="","",IF(ISNUMBER(SEARCH("TEC-Required",J8)),"YES — Required","Voluntary")) | L8: =IFERROR(VLOOKUP(M8,Lists!$T:$U,2,FALSE()),"Select an offense in col M to load the phone script →") -> Select an offense in col M to load the phone script →
D9: =IFERROR(VLOOKUP(C9,'Incident Intake'!$E:$G,3,FALSE())&" "&VLOOKUP(C9,'Incident Intake'!$E:$F,2,FALSE()),"") | K9: =IF(J9="","",IF(ISNUMBER(SEARCH("TEC-Required",J9)),"YES — Required","Voluntary")) | L9: =IFERROR(VLOOKUP(M9,Lists!$T:$U,2,FALSE()),"Select an offense in col M to load the phone script →") -> Select an offense in col M to load the phone script →
D10: =IFERROR(VLOOKUP(C10,'Incident Intake'!$E:$G,3,FALSE())&" "&VLOOKUP(C10,'Incident Intake'!$E:$F,2,FALSE()),"") | K10: =IF(J10="","",IF(ISNUMBER(SEARCH("TEC-Required",J10)),"YES — Required","Voluntary")) | L10: =IFERROR(VLOOKUP(M10,Lists!$T:$U,2,FALSE()),"Select an offense in col M to load the phone script →") -> Select an offense in col M to load the phone script →
D11: =IFERROR(VLOOKUP(C11,'Incident Intake'!$E:$G,3,FALSE())&" "&VLOOKUP(C11,'Incident Intake'!$E:$F,2,FALSE()),"") | K11: =IF(J11="","",IF(ISNUMBER(SEARCH("TEC-Required",J11)),"YES — Required","Voluntary")) | L11: =IFERROR(VLOOKUP(M11,Lists!$T:$U,2,FALSE()),"Select an offense in col M to load the phone script →") -> Select an offense in col M to load the phone script →
D12: =IFERROR(VLOOKUP(C12,'Incident Intake'!$E:$G,3,FALSE())&" "&VLOOKUP(C12,'Incident Intake'!$E:$F,2,FALSE()),"") | K12: =IF(J12="","",IF(ISNUMBER(SEARCH("TEC-Required",J12)),"YES — Required","Voluntary")) | L12: =IFERROR(VLOOKUP(M12,Lists!$T:$U,2,FALSE()),"Select an offense in col M to load the phone script →") -> Select an offense in col M to load the phone script →
D13: =IFERROR(VLOOKUP(C13,'Incident Intake'!$E:$G,3,FALSE())&" "&VLOOKUP(C13,'Incident Intake'!$E:$F,2,FALSE()),"") | K13: =IF(J13="","",IF(ISNUMBER(SEARCH("TEC-Required",J13)),"YES — Required","Voluntary")) | L13: =IFERROR(VLOOKUP(M13,Lists!$T:$U,2,FALSE()),"Select an offense in col M to load the phone script →") -> Select an offense in col M to load the phone script →
D14: =IFERROR(VLOOKUP(C14,'Incident Intake'!$E:$G,3,FALSE())&" "&VLOOKUP(C14,'Incident Intake'!$E:$F,2,FALSE()),"") | K14: =IF(J14="","",IF(ISNUMBER(SEARCH("TEC-Required",J14)),"YES — Required","Voluntary")) | L14: =IFERROR(VLOOKUP(M14,Lists!$T:$U,2,FALSE()),"Select an offense in col M to load the phone script →") -> Select an offense in col M to load the phone script →
D15: =IFERROR(VLOOKUP(C15,'Incident Intake'!$E:$G,3,FALSE())&" "&VLOOKUP(C15,'Incident Intake'!$E:$F,2,FALSE()),"") | K15: =IF(J15="","",IF(ISNUMBER(SEARCH("TEC-Required",J15)),"YES — Required","Voluntary")) | L15: =IFERROR(VLOOKUP(M15,Lists!$T:$U,2,FALSE()),"Select an offense in col M to load the phone script →") -> Select an offense in col M to load the phone script →
D16: =IFERROR(VLOOKUP(C16,'Incident Intake'!$E:$G,3,FALSE())&" "&VLOOKUP(C16,'Incident Intake'!$E:$F,2,FALSE()),"") | K16: =IF(J16="","",IF(ISNUMBER(SEARCH("TEC-Required",J16)),"YES — Required","Voluntary")) | L16: =IFERROR(VLOOKUP(M16,Lists!$T:$U,2,FALSE()),"Select an offense in col M to load the phone script →") -> Select an offense in col M to load the phone script →
... D254: =IFERROR(VLOOKUP(C254,'Incident Intake'!$E:$G,3,FALSE())&" "&VLOOKUP(C254,'Incident Intake'!$E:$F,2,FALSE()),"") | K254: =IF(J254="","",IF(ISNUMBER(SEARCH("TEC-Required",J254)),"YES — Required","Voluntary")) | L254: =IFERROR(VLOOKUP(M254,Lists!$T:$U,2,FALSE()),"Select an offense in col M to load the phone script →") -> Select an offense in col M to load the phone script →
A255: 🚀 Upgrade to the full platform · clearpathedgroup.com · Clear Path Education Group, LLC

Sheet Discipline Trends
A1: Discipline Trends — Auto-Built from Incident Intake · No Manual Data Entry
A2: ="Auto-updated: "&TEXT(TODAY(),"MMMM D, YYYY")&" · All data pulls from Incident Intake tab" -> Auto-updated: July 14, 2026 · All data pulls from Incident Intake tab
A3: OVERALL VOLUME
A4: Total Incidents This Year | B4: =COUNTA('Incident Intake'!A5:A304) -> 0
A5: Open Investigations | B5: =COUNTIF('Incident Intake'!X5:X304,"Open") -> 0
A6: In Progress | B6: =COUNTIF('Incident Intake'!X5:X304,"In Progress") -> 0
A7: Closed This Year | B7: =COUNTIF('Incident Intake'!X5:X304,"Closed") -> 0
A8: Cases with Appeals Filed | B8: =COUNTIF('Incident Intake'!AF5:AF304,"Yes") -> 0
A9: Investigations Open 5+ Days | B9: =COUNTIFS('Incident Intake'!Z5:Z304,">="&5,'Incident Intake'!X5:X304,"<>Closed") -> 0
A11: TOP OFFENSE CATEGORIES (from Incident Intake)
A12: Fighting | B12: =COUNTIF('Incident Intake'!$J:$J,"Fighting") -> 0
A13: Assault — Bodily Injury | B13: =COUNTIF('Incident Intake'!$J:$J,"Assault — Bodily Injury") -> 0
A14: Assault — Threat / Fear | B14: =COUNTIF('Incident Intake'!$J:$J,"Assault — Threat / Fear") -> 0
A15: Defiance / Insubordination | B15: =COUNTIF('Incident Intake'!$J:$J,"Defiance / Insubordination") -> 0
A16: Disruption of Class | B16: =COUNTIF('Incident Intake'!$J:$J,"Disruption of Class") -> 0
A17: Bullying / Cyberbullying | B17: =COUNTIF('Incident Intake'!$J:$J,"Bullying / Cyberbullying") -> 0
A18: Controlled Substance — Possession | B18: =COUNTIF('Incident Intake'!$J:$J,"Controlled Substance — Possession") -> 0
A19: Dangerous Weapon | B19: =COUNTIF('Incident Intake'!$J:$J,"Dangerous Weapon") -> 0
A20: Terroristic Threat | B20: =COUNTIF('Incident Intake'!$J:$J,"Terroristic Threat") -> 0
A21: Theft | B21: =COUNTIF('Incident Intake'!$J:$J,"Theft") -> 0
A22: Vandalism / Property Damage | B22: =COUNTIF('Incident Intake'!$J:$J,"Vandalism / Property Damage") -> 0
A23: Harassment | B23: =COUNTIF('Incident Intake'!$J:$J,"Harassment") -> 0
A24: Tobacco / E-Cigarette / Vaping | B24: =COUNTIF('Incident Intake'!$J:$J,"Tobacco / E-Cigarette / Vaping") -> 0
A26: CONSEQUENCE SUMMARY
A27: ISS Placements (all lengths) | B27: =COUNTIF('Incident Intake'!AC5:AC304,"ISS*") -> 0
A28: OSS Placements (all lengths) | B28: =COUNTIF('Incident Intake'!AC5:AC304,"OSS*") -> 0
A29: DAEP Placements — Mandatory | B29: =COUNTIF('Incident Intake'!AC5:AC304,"DAEP — Mandatory") -> 0
A30: DAEP Placements — Discretionary | B30: =COUNTIF('Incident Intake'!AC5:AC304,"DAEP — Discretionary") -> 0
A31: Expulsion Referrals | B31: =COUNTIF('Incident Intake'!AC5:AC304,"Expulsion Referral") -> 0
A32: Law Enforcement Referrals | B32: =COUNTIF('Incident Intake'!S5:S304,"Yes") -> 0
A33: No Action — Unfounded | B33: =COUNTIF('Incident Intake'!AC5:AC304,"No Action — Unfounded") -> 0
A35: SPED & COMPLIANCE FLAGS
A36: SPED Students Involved in Incidents | B36: =COUNTIF('Incident Intake'!U5:U304,"<>No") -> 300
A37: ⚠ SPED — 10-Day Warning or Above | B37: =COUNTIF('10-Day Compliance'!AA5:AA154,"*WARNING*")+COUNTIF('10-Day Compliance'!AA5:AA154,"*URGENT*")+COUNTIF('10-Day Compliance'!AA5:AA154,"*EXCEEDED*") -> 0
A38: 🔴 SPED — 10-Day Limit Exceeded | B38: =COUNTIF('10-Day Compliance'!AA5:AA154,"*EXCEEDED*") -> 0
A39: Incidents with Injury | B39: =COUNTIF('Incident Intake'!P5:P304,"Yes") -> 0
A40: Incidents Involving Law Enforcement | B40: =COUNTIF('Incident Intake'!S5:S304,"Yes") -> 0
A41: Parent Not Notified | B41: =COUNTIF('Incident Intake'!AA5:AA304,"No") -> 0
A43: REPEAT OFFENDER FLAGS
A44: Students with 3+ Incidents (total year) | B44: =SUMPRODUCT((COUNTIF('Incident Intake'!E5:E304,'Incident Intake'!E5:E304)>=3)/COUNTIF('Incident Intake'!E5:E304,'Incident Intake'!E5:E304&"")) -> 0
...

Sheet 📋 Monday Briefing
A1: 📋 MONDAY MORNING BRIEFING — Administrator's Command Toolkit
B2: ="Week of: "&TEXT(TODAY(),"MMMM D, YYYY")&" · Campus: (enter campus name on Cover tab)" -> Week of: July 14, 2026 · Campus: (enter campus name on Cover tab)
B3: 🔴 OPEN INVESTIGATIONS (requiring action today)
B4: Incident ID | C4: Student | D4: Offense | E4: Days Open
B5: =IFERROR(INDEX('Incident Intake'!$A$5:$A$304,MATCH(1,('Incident Intake'!$X$5:$X$304="Open")*('Incident Intake'!$Z$5:$Z$304>=1),0)),"—") -> — | C5: =IF(B5="—","",IFERROR(VLOOKUP(B5,'Incident Intake'!$A:$G,7,FALSE())&" "&VLOOKUP(B5,'Incident Intake'!$A:$F,6,FALSE()),"")) | D5: =IF(B5="—","",IFERROR(VLOOKUP(B5,'Incident Intake'!$A:$J,10,FALSE()),"")) | E5: =IF(B5="—","",IFERROR(VLOOKUP(B5,'Incident Intake'!$A:$Z,26,FALSE()),""))
B6: =IFERROR(INDEX('Incident Intake'!$A$5:$A$304,MATCH(1,('Incident Intake'!$X$5:$X$304="Open")*('Incident Intake'!$Z$5:$Z$304>=2),0)),"—") -> — | C6: =IF(B6="—","",IFERROR(VLOOKUP(B6,'Incident Intake'!$A:$G,7,FALSE())&" "&VLOOKUP(B6,'Incident Intake'!$A:$F,6,FALSE()),"")) | D6: =IF(B6="—","",IFERROR(VLOOKUP(B6,'Incident Intake'!$A:$J,10,FALSE()),"")) | E6: =IF(B6="—","",IFERROR(VLOOKUP(B6,'Incident Intake'!$A:$Z,26,FALSE()),""))
B7: =IFERROR(INDEX('Incident Intake'!$A$5:$A$304,MATCH(1,('Incident Intake'!$X$5:$X$304="Open")*('Incident Intake'!$Z$5:$Z$304>=3),0)),"—") -> — | C7: =IF(B7="—","",IFERROR(VLOOKUP(B7,'Incident Intake'!$A:$G,7,FALSE())&" "&VLOOKUP(B7,'Incident Intake'!$A:$F,6,FALSE()),"")) | D7: =IF(B7="—","",IFERROR(VLOOKUP(B7,'Incident Intake'!$A:$J,10,FALSE()),"")) | E7: =IF(B7="—","",IFERROR(VLOOKUP(B7,'Incident Intake'!$A:$Z,26,FALSE()),""))
B8: =IFERROR(INDEX('Incident Intake'!$A$5:$A$304,MATCH(1,('Incident Intake'!$X$5:$X$304="Open")*('Incident Intake'!$Z$5:$Z$304>=4),0)),"—") -> — | C8: =IF(B8="—","",IFERROR(VLOOKUP(B8,'Incident Intake'!$A:$G,7,FALSE())&" "&VLOOKUP(B8,'Incident Intake'!$A:$F,6,FALSE()),"")) | D8: =IF(B8="—","",IFERROR(VLOOKUP(B8,'Incident Intake'!$A:$J,10,FALSE()),"")) | E8: =IF(B8="—","",IFERROR(VLOOKUP(B8,'Incident Intake'!$A:$Z,26,FALSE()),""))
B9: =IFERROR(INDEX('Incident Intake'!$A$5:$A$304,MATCH(1,('Incident Intake'!$X$5:$X$304="Open")*('Incident Intake'!$Z$5:$Z$304>=5),0)),"—") -> — | C9: =IF(B9="—","",IFERROR(VLOOKUP(B9,'Incident Intake'!$A:$G,7,FALSE())&" "&VLOOKUP(B9,'Incident Intake'!$A:$F,6,FALSE()),"")) | D9: =IF(B9="—","",IFERROR(VLOOKUP(B9,'Incident Intake'!$A:$J,10,FALSE()),"")) | E9: =IF(B9="—","",IFERROR(VLOOKUP(B9,'Incident Intake'!$A:$Z,26,FALSE()),""))
B10: =IFERROR(INDEX('Incident Intake'!$A$5:$A$304,MATCH(1,('Incident Intake'!$X$5:$X$304="Open")*('Incident Intake'!$Z$5:$Z$304>=6),0)),"—") -> — | C10: =IF(B10="—","",IFERROR(VLOOKUP(B10,'Incident Intake'!$A:$G,7,FALSE())&" "&VLOOKUP(B10,'Incident Intake'!$A:$F,6,FALSE()),"")) | D10: =IF(B10="—","",IFERROR(VLOOKUP(B10,'Incident Intake'!$A:$J,10,FALSE()),"")) | E10: =IF(B10="—","",IFERROR(VLOOKUP(B10,'Incident Intake'!$A:$Z,26,FALSE()),""))
B11: =IFERROR(INDEX('Incident Intake'!$A$5:$A$304,MATCH(1,('Incident Intake'!$X$5:$X$304="Open")*('Incident Intake'!$Z$5:$Z$304>=7),0)),"—") -> — | C11: =IF(B11="—","",IFERROR(VLOOKUP(B11,'Incident Intake'!$A:$G,7,FALSE())&" "&VLOOKUP(B11,'Incident Intake'!$A:$F,6,FALSE()),"")) | D11: =IF(B11="—","",IFERROR(VLOOKUP(B11,'Incident Intake'!$A:$J,10,FALSE()),"")) | E11: =IF(B11="—","",IFERROR(VLOOKUP(B11,'Incident Intake'!$A:$Z,26,FALSE()),""))
B12: =IFERROR(INDEX('Incident Intake'!$A$5:$A$304,MATCH(1,('Incident Intake'!$X$5:$X$304="Open")*('Incident Intake'!$Z$5:$Z$304>=8),0)),"—") -> — | C12: =IF(B12="—","",IFERROR(VLOOKUP(B12,'Incident Intake'!$A:$G,7,FALSE())&" "&VLOOKUP(B12,'Incident Intake'!$A:$F,6,FALSE()),"")) | D12: =IF(B12="—","",IFERROR(VLOOKUP(B12,'Incident Intake'!$A:$J,10,FALSE()),"")) | E12: =IF(B12="—","",IFERROR(VLOOKUP(B12,'Incident Intake'!$A:$Z,26,FALSE()),""))
B14: 🟡 SPED 10-DAY COMPLIANCE ALERTS
B15: Student ID | C15: Name | D15: Days Used | E15: Status
B16: =IFERROR(INDEX('10-Day Compliance'!$A$5:$A$154,MATCH(1,('10-Day Compliance'!$E$5:$E$154>=7)*ROW('10-Day Compliance'!$E$5:$E$154)/ROW('10-Day Compliance'!$E$5:$E$154)>=1,0)),"—") -> — | C16: =IF(B16="—","",IFERROR(VLOOKUP(B16,'10-Day Compliance'!$A:$C,3,FALSE())&" "&VLOOKUP(B16,'10-Day Compliance'!$A:$B,2,FALSE()),"")) | D16: =IF(B16="—","",IFERROR(VLOOKUP(B16,'10-Day Compliance'!$A:$E,5,FALSE()),"")) | E16: =IF(B16="—","",IFERROR(VLOOKUP(B16,'10-Day Compliance'!$A:$AA,27,FALSE()),""))
B17: =IFERROR(INDEX('10-Day Compliance'!$A$5:$A$154,MATCH(1,('10-Day Compliance'!$E$5:$E$154>=7)*ROW('10-Day Compliance'!$E$5:$E$154)/ROW('10-Day Compliance'!$E$5:$E$154)>=2,0)),"—") -> — | C17: =IF(B17="—","",IFERROR(VLOOKUP(B17,'10-Day Compliance'!$A:$C,3,FALSE())&" "&VLOOKUP(B17,'10-Day Compliance'!$A:$B,2,FALSE()),"")) | D17: =IF(B17="—","",IFERROR(VLOOKUP(B17,'10-Day Compliance'!$A:$E,5,FALSE()),"")) | E17: =IF(B17="—","",IFERROR(VLOOKUP(B17,'10-Day Compliance'!$A:$AA,27,FALSE()),""))
B18: =IFERROR(INDEX('10-Day Compliance'!$A$5:$A$154,MATCH(1,('10-Day Compliance'!$E$5:$E$154>=7)*ROW('10-Day Compliance'!$E$5:$E$154)/ROW('10-Day Compliance'!$E$5:$E$154)>=3,0)),"—") -> — | C18: =IF(B18="—","",IFERROR(VLOOKUP(B18,'10-Day Compliance'!$A:$C,3,FALSE())&" "&VLOOKUP(B18,'10-Day Compliance'!$A:$B,2,FALSE()),"")) | D18: =IF(B18="—","",IFERROR(VLOOKUP(B18,'10-Day Compliance'!$A:$E,5,FALSE()),"")) | E18: =IF(B18="—","",IFERROR(VLOOKUP(B18,'10-Day Compliance'!$A:$AA,27,FALSE()),""))
B19: =IFERROR(INDEX('10-Day Compliance'!$A$5:$A$154,MATCH(1,('10-Day Compliance'!$E$5:$E$154>=7)*ROW('10-Day Compliance'!$E$5:$E$154)/ROW('10-Day Compliance'!$E$5:$E$154)>=4,0)),"—") -> — | C19: =IF(B19="—","",IFERROR(VLOOKUP(B19,'10-Day Compliance'!$A:$C,3,FALSE())&" "&VLOOKUP(B19,'10-Day Compliance'!$A:$B,2,FALSE()),"")) | D19: =IF(B19="—","",IFERROR(VLOOKUP(B19,'10-Day Compliance'!$A:$E,5,FALSE()),"")) | E19: =IF(B19="—","",IFERROR(VLOOKUP(B19,'10-Day Compliance'!$A:$AA,27,FALSE()),""))
B20: =IFERROR(INDEX('10-Day Compliance'!$A$5:$A$154,MATCH(1,('10-Day Compliance'!$E$5:$E$154>=7)*ROW('10-Day Compliance'!$E$5:$E$154)/ROW('10-Day Compliance'!$E$5:$E$154)>=5,0)),"—") -> — | C20: =IF(B20="—","",IFERROR(VLOOKUP(B20,'10-Day Compliance'!$A:$C,3,FALSE())&" "&VLOOKUP(B20,'10-Day Compliance'!$A:$B,2,FALSE()),"")) | D20: =IF(B20="—","",IFERROR(VLOOKUP(B20,'10-Day Compliance'!$A:$E,5,FALSE()),"")) | E20: =IF(B20="—","",IFERROR(VLOOKUP(B20,'10-Day Compliance'!$A:$AA,27,FALSE()),""))
B21: =IFERROR(INDEX('10-Day Compliance'!$A$5:$A$154,MATCH(1,('10-Day Compliance'!$E$5:$E$154>=7)*ROW('10-Day Compliance'!$E$5:$E$154)/ROW('10-Day Compliance'!$E$5:$E$154)>=6,0)),"—") -> — | C21: =IF(B21="—","",IFERROR(VLOOKUP(B21,'10-Day Compliance'!$A:$C,3,FALSE())&" "&VLOOKUP(B21,'10-Day Compliance'!$A:$B,2,FALSE()),"")) | D21: =IF(B21="—","",IFERROR(VLOOKUP(B21,'10-Day Compliance'!$A:$E,5,FALSE()),"")) | E21: =IF(B21="—","",IFERROR(VLOOKUP(B21,'10-Day Compliance'!$A:$AA,27,FALSE()),""))
B23: 📞 PARENT FOLLOW-UPS DUE THIS WEEK
B24: Student | C24: Incident | D24: Follow-Up Date | E24: Admin
B25: =IFERROR(INDEX('Parent Contact Log'!$D$5:$D$254,MATCH(1,('Parent Contact Log'!$Q$5:$Q$254="Yes")*('Parent Contact Log'!$S$5:$S$254<>"Yes")*('Parent Contact Log'!$R$5:$R$254<=TODAY()+7),0)),"—") -> — | C25: =IF(B25="—","",IFERROR(INDEX('Parent Contact Log'!$B$5:$B$254,MATCH(B25,'Parent Contact Log'!$D$5:$D$254,0)),"")) | D25: =IF(B25="—","",IFERROR(INDEX('Parent Contact Log'!$R$5:$R$254,MATCH(B25,'Parent Contact Log'!$D$5:$D$254,0)),"")) | E25: =IF(B25="—","",IFERROR(INDEX('Parent Contact Log'!$T$5:$T$254,MATCH(B25,'Parent Contact Log'!$D$5:$D$254,0)),""))
B26: =IFERROR(INDEX('Parent Contact Log'!$D$5:$D$254,MATCH(1,('Parent Contact Log'!$Q$5:$Q$254="Yes")*('Parent Contact Log'!$S$5:$S$254<>"Yes")*('Parent Contact Log'!$R$5:$R$254<=TODAY()+7),0)),"—") -> — | C26: =IF(B26="—","",IFERROR(INDEX('Parent Contact Log'!$B$5:$B$254,MATCH(B26,'Parent Contact Log'!$D$5:$D$254,0)),"")) | D26: =IF(B26="—","",IFERROR(INDEX('Parent Contact Log'!$R$5:$R$254,MATCH(B26,'Parent Contact Log'!$D$5:$D$254,0)),"")) | E26: =IF(B26="—","",IFERROR(INDEX('Parent Contact Log'!$T$5:$T$254,MATCH(B26,'Parent Contact Log'!$D$5:$D$254,0)),""))
B27: =IFERROR(INDEX('Parent Contact Log'!$D$5:$D$254,MATCH(1,('Parent Contact Log'!$Q$5:$Q$254="Yes")*('Parent Contact Log'!$S$5:$S$254<>"Yes")*('Parent Contact Log'!$R$5:$R$254<=TODAY()+7),0)),"—") -> — | C27: =IF(B27="—","",IFERROR(INDEX('Parent Contact Log'!$B$5:$B$254,MATCH(B27,'Parent Contact Log'!$D$5:$D$254,0)),"")) | D27: =IF(B27="—","",IFERROR(INDEX('Parent Contact Log'!$R$5:$R$254,MATCH(B27,'Parent Contact Log'!$D$5:$D$254,0)),"")) | E27: =IF(B27="—","",IFERROR(INDEX('Parent Contact Log'!$T$5:$T$254,MATCH(B27,'Parent Contact Log'!$D$5:$D$254,0)),""))
B28: =IFERROR(INDEX('Parent Contact Log'!$D$5:$D$254,MATCH(1,('Parent Contact Log'!$Q$5:$Q$254="Yes")*('Parent Contact Log'!$S$5:$S$254<>"Yes")*('Parent Contact Log'!$R$5:$R$254<=TODAY()+7),0)),"—") -> — | C28: =IF(B28="—","",IFERROR(INDEX('Parent Contact Log'!$B$5:$B$254,MATCH(B28,'Parent Contact Log'!$D$5:$D$254,0)),"")) | D28: =IF(B28="—","",IFERROR(INDEX('Parent Contact Log'!$R$5:$R$254,MATCH(B28,'Parent Contact Log'!$D$5:$D$254,0)),"")) | E28: =IF(B28="—","",IFERROR(INDEX('Parent Contact Log'!$T$5:$T$254,MATCH(B28,'Parent Contact Log'!$D$5:$D$254,0)),""))
B29: =IFERROR(INDEX('Parent Contact Log'!$D$5:$D$254,MATCH(1,('Parent Contact Log'!$Q$5:$Q$254="Yes")*('Parent Contact Log'!$S$5:$S$254<>"Yes")*('Parent Contact Log'!$R$5:$R$254<=TODAY()+7),0)),"—") -> — | C29: =IF(B29="—","",IFERROR(INDEX('Parent Contact Log'!$B$5:$B$254,MATCH(B29,'Parent Contact Log'!$D$5:$D$254,0)),"")) | D29: =IF(B29="—","",IFERROR(INDEX('Parent Contact Log'!$R$5:$R$254,MATCH(B29,'Parent Contact Log'!$D$5:$D$254,0)),"")) | E29: =IF(B29="—","",IFERROR(INDEX('Parent Contact Log'!$T$5:$T$254,MATCH(B29,'Parent Contact Log'!$D$5:$D$254,0)),""))
