Workbook

Sheet Cover
A1: DAEP Student Tracker — Texas Edition
A2: Clear Path Education Group, LLC
A3: Built for Texas campus administrators and DAEP coordinators.
A4: Track students, placements, compliance deadlines, and discipline incidents — all in one place. No training required.
A6: ─── FILL IN YOUR DISTRICT INFORMATION ───────────────────────
A7: District Name:
A8: Campus Name:
A9: School Year: | C9: 2025-26
A10: DAEP Coordinator:
A11: Date Updated:
A13: ─── HOW TO USE THIS TRACKER ──────────────────────────────────
A14: 1. ROSTER tab — Add every DAEP-assigned student first. This tab feeds all other tabs.
A15: 2. INCIDENT LOG tab — Log each discipline incident. Reference the Student ID from the Roster.
A16: 3. DAEP PLACEMENTS tab — Record the formal placement. Auto-countdown begins immediately.
A17: 4. COMPLIANCE CHECKLIST tab — Track required SPED/504 actions and deadlines.
A18: 5. DASHBOARD tab — Auto-updates from all other tabs. No data entry needed here.
A19: 6. REFERENCE tab — Texas Education Code citations, glossary, and compliance timelines.
A20: 7. Color guide: Yellow = approaching deadline. Red = overdue. Green = complete.
A21: 8. Gray cells = auto-calculated. Do NOT type in them — they contain formulas.
A22: 9. This file works in Google Sheets AND Microsoft Excel.
... A32: Verify all TEC citations with your district legal counsel before relying on them for placement decisions.

Sheet Roster
A1: ROSTER — Active DAEP Students
A2: Student ID | B2: Last Name | C2: First Name | D2: Grade Level | E2: Campus of Origin | F2: DAEP Campus | G2: Enrollment Date | H2: Exit Date | I2: Status | J2: SPED Eligible? | K2: 504 Eligible? | L2: Primary Disability (SPED) | M2: IEP Annual Review Due | N2: Days in DAEP ⚙ | O2: Placement Length (days) | P2: Days Remaining ⚙ | Q2: Notes / Flags | R2: Incident Count ⚙
A3: STU-001 | B3: Ramirez | C3: Carlos | D3: 8th Grade | E3: Jefferson Middle | F3: Crossroads DAEP Center | G3: 46042 | I3: Active | J3: Yes | K3: No | L3: Emotional Disturbance | M3: 46127 | N3: =IF(A3="","",IF(H3="",TODAY()-G3,H3-G3)) -> 175 | O3: 45 | P3: =IF(A3="","",IF(O3="","",MAX(0,O3-N3))) -> 0 | Q3: MDR held 1/16 — not a manifestation | R3: =IF(A3="","",COUNTIF('Incident Log'!D:D,A3)) -> 1
A4: STU-002 | B4: Johnson | C4: Destiny | D4: 10th Grade | E4: Lincoln High | F4: Crossroads DAEP Center | G4: 46062 | I4: Active | J4: No | K4: No | N4: =IF(A4="","",IF(H4="",TODAY()-G4,H4-G4)) -> 155 | O4: 60 | P4: =IF(A4="","",IF(O4="","",MAX(0,O4-N4))) -> 0 | R4: =IF(A4="","",COUNTIF('Incident Log'!D:D,A4)) -> 1
A5: STU-003 | B5: Williams | C5: Marcus | D5: 7th Grade | E5: Jefferson Middle | F5: Crossroads DAEP Center | G5: 45978 | H5: 46038 | I5: Exited | J5: Yes | K5: No | L5: Specific Learning Disability | M5: 46076 | N5: =IF(A5="","",IF(H5="",TODAY()-G5,H5-G5)) -> 60 | O5: 30 | P5: =IF(A5="","",IF(O5="","",MAX(0,O5-N5))) -> 0 | Q5: Completed placement | R5: =IF(A5="","",COUNTIF('Incident Log'!D:D,A5)) -> 1
A6: STU-004 | B6: Nguyen | C6: Amy | D6: 9th Grade | E6: Lincoln High | F6: Crossroads DAEP Center | G6: 46083 | I6: Active | J6: No | K6: Yes | N6: =IF(A6="","",IF(H6="",TODAY()-G6,H6-G6)) -> 134 | O6: 30 | P6: =IF(A6="","",IF(O6="","",MAX(0,O6-N6))) -> 0 | Q6: 504 plan — ADHD | R6: =IF(A6="","",COUNTIF('Incident Log'!D:D,A6)) -> 1
A7: STU-005 | B7: Brooks | C7: Jamal | D7: 11th Grade | E7: Lincoln High | F7: Crossroads DAEP Center | G7: 46104 | I7: Active | J7: No | K7: No | N7: =IF(A7="","",IF(H7="",TODAY()-G7,H7-G7)) -> 113 | O7: 45 | P7: =IF(A7="","",IF(O7="","",MAX(0,O7-N7))) -> 0 | R7: =IF(A7="","",COUNTIF('Incident Log'!D:D,A7)) -> 1
N8: =IF(A8="","",IF(H8="",TODAY()-G8,H8-G8)) | P8: =IF(A8="","",IF(O8="","",MAX(0,O8-N8))) | R8: =IF(A8="","",COUNTIF('Incident Log'!D:D,A8))
N9: =IF(A9="","",IF(H9="",TODAY()-G9,H9-G9)) | P9: =IF(A9="","",IF(O9="","",MAX(0,O9-N9))) | R9: =IF(A9="","",COUNTIF('Incident Log'!D:D,A9))
N10: =IF(A10="","",IF(H10="",TODAY()-G10,H10-G10)) | P10: =IF(A10="","",IF(O10="","",MAX(0,O10-N10))) | R10: =IF(A10="","",COUNTIF('Incident Log'!D:D,A10))
N11: =IF(A11="","",IF(H11="",TODAY()-G11,H11-G11)) | P11: =IF(A11="","",IF(O11="","",MAX(0,O11-N11))) | R11: =IF(A11="","",COUNTIF('Incident Log'!D:D,A11))
N12: =IF(A12="","",IF(H12="",TODAY()-G12,H12-G12)) | P12: =IF(A12="","",IF(O12="","",MAX(0,O12-N12))) | R12: =IF(A12="","",COUNTIF('Incident Log'!D:D,A12))
N13: =IF(A13="","",IF(H13="",TODAY()-G13,H13-G13)) | P13: =IF(A13="","",IF(O13="","",MAX(0,O13-N13))) | R13: =IF(A13="","",COUNTIF('Incident Log'!D:D,A13))
N14: =IF(A14="","",IF(H14="",TODAY()-G14,H14-G14)) | P14: =IF(A14="","",IF(O14="","",MAX(0,O14-N14))) | R14: =IF(A14="","",COUNTIF('Incident Log'!D:D,A14))
N15: =IF(A15="","",IF(H15="",TODAY()-G15,H15-G15)) | P15: =IF(A15="","",IF(O15="","",MAX(0,O15-N15))) | R15: =IF(A15="","",COUNTIF('Incident Log'!D:D,A15))
N16: =IF(A16="","",IF(H16="",TODAY()-G16,H16-G16)) | P16: =IF(A16="","",IF(O16="","",MAX(0,O16-N16))) | R16: =IF(A16="","",COUNTIF('Incident Log'!D:D,A16))
N17: =IF(A17="","",IF(H17="",TODAY()-G17,H17-G17)) | P17: =IF(A17="","",IF(O17="","",MAX(0,O17-N17))) | R17: =IF(A17="","",COUNTIF('Incident Log'!D:D,A17))
N18: =IF(A18="","",IF(H18="",TODAY()-G18,H18-G18)) | P18: =IF(A18="","",IF(O18="","",MAX(0,O18-N18))) | R18: =IF(A18="","",COUNTIF('Incident Log'!D:D,A18))
N19: =IF(A19="","",IF(H19="",TODAY()-G19,H19-G19)) | P19: =IF(A19="","",IF(O19="","",MAX(0,O19-N19))) | R19: =IF(A19="","",COUNTIF('Incident Log'!D:D,A19))
... N102: =IF(A102="","",IF(H102="",TODAY()-G102,H102-G102)) | P102: =IF(A102="","",IF(O102="","",MAX(0,O102-N102))) | R102: =IF(A102="","",COUNTIF('Incident Log'!D:D,A102))

Sheet Incident Log
A1: INCIDENT LOG — One Row Per Incident
A2: Incident ID | B2: Incident Date | C2: Reporting Campus | D2: Student ID | E2: Last Name ⚙ | F2: First Name ⚙ | G2: Grade ⚙ | H2: Offense Category | I2: TEC Reference | J2: Offense Description | K2: Mandatory Removal? | L2: Weapon Involved? | M2: Drug/Alcohol Involved? | N2: Reported By (Role) | O2: Administrator Reviewing | P2: Parent/Guardian Notified? | Q2: Notification Date | R2: Referred to DAEP? | S2: Notes
A3: INC-001 | B3: 46038 | C3: Jefferson Middle | D3: STU-001 | E3: =IF(D3="","",VLOOKUP(D3,Roster!$A:$C,2,FALSE)) -> Ramirez | F3: =IF(D3="","",VLOOKUP(D3,Roster!$A:$C,3,FALSE)) -> Carlos | G3: =IF(D3="","",VLOOKUP(D3,Roster!$A:$D,4,FALSE)) -> 8th Grade | H3: Fighting | I3: TEC §37.006 — Mandatory DAEP Removal | J3: Fight in cafeteria resulting in injury | K3: Yes | L3: No | M3: No | N3: Teacher | O3: Vice Principal | P3: Yes | Q3: 46038 | R3: Yes | S3: Parent notified same day by phone. Student suspended pending placement.
A4: INC-002 | B4: 46057 | C4: Lincoln High | D4: STU-002 | E4: =IF(D4="","",VLOOKUP(D4,Roster!$A:$C,2,FALSE)) -> Johnson | F4: =IF(D4="","",VLOOKUP(D4,Roster!$A:$C,3,FALSE)) -> Destiny | G4: =IF(D4="","",VLOOKUP(D4,Roster!$A:$D,4,FALSE)) -> 10th Grade | H4: Drugs/Alcohol | I4: TEC §37.006 — Mandatory DAEP Removal | J4: Possession of vape pen containing THC | K4: Yes | L4: No | M4: Yes | N4: Teacher | O4: Principal | P4: Yes | Q4: 46057 | R4: Yes
A5: INC-003 | B5: 45973 | C5: Jefferson Middle | D5: STU-003 | E5: =IF(D5="","",VLOOKUP(D5,Roster!$A:$C,2,FALSE)) -> Williams | F5: =IF(D5="","",VLOOKUP(D5,Roster!$A:$C,3,FALSE)) -> Marcus | G5: =IF(D5="","",VLOOKUP(D5,Roster!$A:$D,4,FALSE)) -> 7th Grade | H5: Fighting | I5: TEC §37.006 — Mandatory DAEP Removal | J5: Altercation in gym locker room | K5: Yes | L5: No | M5: No | N5: Coach | O5: Vice Principal | P5: Yes | Q5: 45974 | R5: Yes | S5: MDR completed prior to placement.
A6: INC-004 | B6: 46080 | C6: Lincoln High | D6: STU-004 | E6: =IF(D6="","",VLOOKUP(D6,Roster!$A:$C,2,FALSE)) -> Nguyen | F6: =IF(D6="","",VLOOKUP(D6,Roster!$A:$C,3,FALSE)) -> Amy | G6: =IF(D6="","",VLOOKUP(D6,Roster!$A:$D,4,FALSE)) -> 9th Grade | H6: Drugs/Alcohol | I6: TEC §37.006 — Mandatory DAEP Removal | J6: Alcohol possession at school event | K6: Yes | L6: No | M6: Yes | N6: Administrator | O6: Principal | P6: Yes | Q6: 46080 | R6: Yes
A7: INC-005 | B7: 46100 | C7: Lincoln High | D7: STU-005 | E7: =IF(D7="","",VLOOKUP(D7,Roster!$A:$C,2,FALSE)) -> Brooks | F7: =IF(D7="","",VLOOKUP(D7,Roster!$A:$C,3,FALSE)) -> Jamal | G7: =IF(D7="","",VLOOKUP(D7,Roster!$A:$D,4,FALSE)) -> 11th Grade | H7: Harassment/Bullying | I7: TEC §37.006 — Mandatory DAEP Removal | J7: Repeated harassment after prior intervention | K7: No | L7: No | M7: No | N7: Counselor | O7: Vice Principal | P7: Yes | Q7: 46101 | R7: Yes
E8: =IF(D8="","",VLOOKUP(D8,Roster!$A:$C,2,FALSE)) | F8: =IF(D8="","",VLOOKUP(D8,Roster!$A:$C,3,FALSE)) | G8: =IF(D8="","",VLOOKUP(D8,Roster!$A:$D,4,FALSE))
E9: =IF(D9="","",VLOOKUP(D9,Roster!$A:$C,2,FALSE)) | F9: =IF(D9="","",VLOOKUP(D9,Roster!$A:$C,3,FALSE)) | G9: =IF(D9="","",VLOOKUP(D9,Roster!$A:$D,4,FALSE))
E10: =IF(D10="","",VLOOKUP(D10,Roster!$A:$C,2,FALSE)) | F10: =IF(D10="","",VLOOKUP(D10,Roster!$A:$C,3,FALSE)) | G10: =IF(D10="","",VLOOKUP(D10,Roster!$A:$D,4,FALSE))
E11: =IF(D11="","",VLOOKUP(D11,Roster!$A:$C,2,FALSE)) | F11: =IF(D11="","",VLOOKUP(D11,Roster!$A:$C,3,FALSE)) | G11: =IF(D11="","",VLOOKUP(D11,Roster!$A:$D,4,FALSE))
E12: =IF(D12="","",VLOOKUP(D12,Roster!$A:$C,2,FALSE)) | F12: =IF(D12="","",VLOOKUP(D12,Roster!$A:$C,3,FALSE)) | G12: =IF(D12="","",VLOOKUP(D12,Roster!$A:$D,4,FALSE))
E13: =IF(D13="","",VLOOKUP(D13,Roster!$A:$C,2,FALSE)) | F13: =IF(D13="","",VLOOKUP(D13,Roster!$A:$C,3,FALSE)) | G13: =IF(D13="","",VLOOKUP(D13,Roster!$A:$D,4,FALSE))
E14: =IF(D14="","",VLOOKUP(D14,Roster!$A:$C,2,FALSE)) | F14: =IF(D14="","",VLOOKUP(D14,Roster!$A:$C,3,FALSE)) | G14: =IF(D14="","",VLOOKUP(D14,Roster!$A:$D,4,FALSE))
E15: =IF(D15="","",VLOOKUP(D15,Roster!$A:$C,2,FALSE)) | F15: =IF(D15="","",VLOOKUP(D15,Roster!$A:$C,3,FALSE)) | G15: =IF(D15="","",VLOOKUP(D15,Roster!$A:$D,4,FALSE))
E16: =IF(D16="","",VLOOKUP(D16,Roster!$A:$C,2,FALSE)) | F16: =IF(D16="","",VLOOKUP(D16,Roster!$A:$C,3,FALSE)) | G16: =IF(D16="","",VLOOKUP(D16,Roster!$A:$D,4,FALSE))
E17: =IF(D17="","",VLOOKUP(D17,Roster!$A:$C,2,FALSE)) | F17: =IF(D17="","",VLOOKUP(D17,Roster!$A:$C,3,FALSE)) | G17: =IF(D17="","",VLOOKUP(D17,Roster!$A:$D,4,FALSE))
E18: =IF(D18="","",VLOOKUP(D18,Roster!$A:$C,2,FALSE)) | F18: =IF(D18="","",VLOOKUP(D18,Roster!$A:$C,3,FALSE)) | G18: =IF(D18="","",VLOOKUP(D18,Roster!$A:$D,4,FALSE))
E19: =IF(D19="","",VLOOKUP(D19,Roster!$A:$C,2,FALSE)) | F19: =IF(D19="","",VLOOKUP(D19,Roster!$A:$C,3,FALSE)) | G19: =IF(D19="","",VLOOKUP(D19,Roster!$A:$D,4,FALSE))
... E202: =IF(D202="","",VLOOKUP(D202,Roster!$A:$C,2,FALSE)) | F202: =IF(D202="","",VLOOKUP(D202,Roster!$A:$C,3,FALSE)) | G202: =IF(D202="","",VLOOKUP(D202,Roster!$A:$D,4,FALSE))

Sheet DAEP Placements
A1: DAEP PLACEMENTS — One Row Per Formal Placement | ⚠ Days shown are CALENDAR days. Texas law counts SCHOOL days. Adjust authorized days to account for weekends/holidays.
A2: Placement ID | B2: Student ID | C2: Last Name ⚙ | D2: First Name ⚙ | E2: Incident ID | F2: Placement Start Date | G2: Authorized Days | H2: End Date (approx) ⚙ | I2: Days Elapsed ⚙ | J2: Days Remaining ⚙ | K2: Extended? | L2: Extension Days Added | M2: Adjusted Total Days ⚙ | N2: Adjusted End Date ⚙ | O2: Actual Exit Date | P2: Exit Reason | Q2: Return Campus | R2: SPED? ⚙ | S2: 504? ⚙ | T2: Manifestation Det. Required? ⚙ | U2: Compliance Status | V2: Notes | W2: ⚙ Board Index (do not edit)
A3: PLC-001 | B3: STU-001 | C3: =IF(B3="","",VLOOKUP(B3,Roster!$A:$C,2,FALSE)) -> Ramirez | D3: =IF(B3="","",VLOOKUP(B3,Roster!$A:$C,3,FALSE)) -> Carlos | E3: INC-001 | F3: 46042 | G3: 45 | H3: =IF(F3="","",F3+G3) -> 46087 | I3: =IF(F3="","",IF(O3<>"",O3-F3,TODAY()-F3)) -> 175 | J3: =IF(F3="","",MAX(0,IF(K3="Yes",M3,G3)-I3)) -> 0 | K3: No | M3: =IF(K3="Yes",G3+L3,G3) -> 45 | N3: =IF(F3="","",F3+M3) -> 46087 | Q3: Jefferson Middle | R3: =IF(B3="","",VLOOKUP(B3,Roster!$A:$K,10,FALSE)) -> Yes | S3: =IF(B3="","",VLOOKUP(B3,Roster!$A:$K,11,FALSE)) -> No | T3: =IF(B3="","",IF(OR(R3="Yes",S3="Yes"),"Yes — MDR Required","No")) -> Yes — MDR Required | U3: Compliant | V3: MDR held 1/16 — not a manifestation. | W3: =IF(OR(B3="",O3<>""),"",COUNTIFS(B$3:B3,"<>",O$3:O3,"")) -> 1
A4: PLC-002 | B4: STU-002 | C4: =IF(B4="","",VLOOKUP(B4,Roster!$A:$C,2,FALSE)) -> Johnson | D4: =IF(B4="","",VLOOKUP(B4,Roster!$A:$C,3,FALSE)) -> Destiny | E4: INC-002 | F4: 46062 | G4: 60 | H4: =IF(F4="","",F4+G4) -> 46122 | I4: =IF(F4="","",IF(O4<>"",O4-F4,TODAY()-F4)) -> 155 | J4: =IF(F4="","",MAX(0,IF(K4="Yes",M4,G4)-I4)) -> 0 | K4: No | M4: =IF(K4="Yes",G4+L4,G4) -> 60 | N4: =IF(F4="","",F4+M4) -> 46122 | Q4: Lincoln High | R4: =IF(B4="","",VLOOKUP(B4,Roster!$A:$K,10,FALSE)) -> No | S4: =IF(B4="","",VLOOKUP(B4,Roster!$A:$K,11,FALSE)) -> No | T4: =IF(B4="","",IF(OR(R4="Yes",S4="Yes"),"Yes — MDR Required","No")) -> No | U4: Compliant | W4: =IF(OR(B4="",O4<>""),"",COUNTIFS(B$3:B4,"<>",O$3:O4,"")) -> 2
A5: PLC-003 | B5: STU-003 | C5: =IF(B5="","",VLOOKUP(B5,Roster!$A:$C,2,FALSE)) -> Williams | D5: =IF(B5="","",VLOOKUP(B5,Roster!$A:$C,3,FALSE)) -> Marcus | E5: INC-003 | F5: 45978 | G5: 30 | H5: =IF(F5="","",F5+G5) -> 46008 | I5: =IF(F5="","",IF(O5<>"",O5-F5,TODAY()-F5)) -> 60 | J5: =IF(F5="","",MAX(0,IF(K5="Yes",M5,G5)-I5)) -> 0 | K5: No | M5: =IF(K5="Yes",G5+L5,G5) -> 30 | N5: =IF(F5="","",F5+M5) -> 46008 | O5: 46038 | P5: Completed Placement | Q5: Jefferson Middle | R5: =IF(B5="","",VLOOKUP(B5,Roster!$A:$K,10,FALSE)) -> Yes | S5: =IF(B5="","",VLOOKUP(B5,Roster!$A:$K,11,FALSE)) -> No | T5: =IF(B5="","",IF(OR(R5="Yes",S5="Yes"),"Yes — MDR Required","No")) -> Yes — MDR Required | U5: Compliant | W5: =IF(OR(B5="",O5<>""),"",COUNTIFS(B$3:B5,"<>",O$3:O5,""))
A6: PLC-004 | B6: STU-004 | C6: =IF(B6="","",VLOOKUP(B6,Roster!$A:$C,2,FALSE)) -> Nguyen | D6: =IF(B6="","",VLOOKUP(B6,Roster!$A:$C,3,FALSE)) -> Amy | E6: INC-004 | F6: 46083 | G6: 30 | H6: =IF(F6="","",F6+G6) -> 46113 | I6: =IF(F6="","",IF(O6<>"",O6-F6,TODAY()-F6)) -> 134 | J6: =IF(F6="","",MAX(0,IF(K6="Yes",M6,G6)-I6)) -> 0 | K6: No | M6: =IF(K6="Yes",G6+L6,G6) -> 30 | N6: =IF(F6="","",F6+M6) -> 46113 | Q6: Lincoln High | R6: =IF(B6="","",VLOOKUP(B6,Roster!$A:$K,10,FALSE)) -> No | S6: =IF(B6="","",VLOOKUP(B6,Roster!$A:$K,11,FALSE)) -> Yes | T6: =IF(B6="","",IF(OR(R6="Yes",S6="Yes"),"Yes — MDR Required","No")) -> Yes — MDR Required | U6: Compliant | W6: =IF(OR(B6="",O6<>""),"",COUNTIFS(B$3:B6,"<>",O$3:O6,"")) -> 3
C7: =IF(B7="","",VLOOKUP(B7,Roster!$A:$C,2,FALSE)) | D7: =IF(B7="","",VLOOKUP(B7,Roster!$A:$C,3,FALSE)) | H7: =IF(F7="","",F7+G7) | I7: =IF(F7="","",IF(O7<>"",O7-F7,TODAY()-F7)) | J7: =IF(F7="","",MAX(0,IF(K7="Yes",M7,G7)-I7)) | M7: =IF(K7="Yes",G7+L7,G7) -> 0 | N7: =IF(F7="","",F7+M7) | R7: =IF(B7="","",VLOOKUP(B7,Roster!$A:$K,10,FALSE)) | S7: =IF(B7="","",VLOOKUP(B7,Roster!$A:$K,11,FALSE)) | T7: =IF(B7="","",IF(OR(R7="Yes",S7="Yes"),"Yes — MDR Required","No")) | W7: =IF(OR(B7="",O7<>""),"",COUNTIFS(B$3:B7,"<>",O$3:O7,""))
C8: =IF(B8="","",VLOOKUP(B8,Roster!$A:$C,2,FALSE)) | D8: =IF(B8="","",VLOOKUP(B8,Roster!$A:$C,3,FALSE)) | H8: =IF(F8="","",F8+G8) | I8: =IF(F8="","",IF(O8<>"",O8-F8,TODAY()-F8)) | J8: =IF(F8="","",MAX(0,IF(K8="Yes",M8,G8)-I8)) | M8: =IF(K8="Yes",G8+L8,G8) -> 0 | N8: =IF(F8="","",F8+M8) | R8: =IF(B8="","",VLOOKUP(B8,Roster!$A:$K,10,FALSE)) | S8: =IF(B8="","",VLOOKUP(B8,Roster!$A:$K,11,FALSE)) | T8: =IF(B8="","",IF(OR(R8="Yes",S8="Yes"),"Yes — MDR Required","No")) | W8: =IF(OR(B8="",O8<>""),"",COUNTIFS(B$3:B8,"<>",O$3:O8,""))
C9: =IF(B9="","",VLOOKUP(B9,Roster!$A:$C,2,FALSE)) | D9: =IF(B9="","",VLOOKUP(B9,Roster!$A:$C,3,FALSE)) | H9: =IF(F9="","",F9+G9) | I9: =IF(F9="","",IF(O9<>"",O9-F9,TODAY()-F9)) | J9: =IF(F9="","",MAX(0,IF(K9="Yes",M9,G9)-I9)) | M9: =IF(K9="Yes",G9+L9,G9) -> 0 | N9: =IF(F9="","",F9+M9) | R9: =IF(B9="","",VLOOKUP(B9,Roster!$A:$K,10,FALSE)) | S9: =IF(B9="","",VLOOKUP(B9,Roster!$A:$K,11,FALSE)) | T9: =IF(B9="","",IF(OR(R9="Yes",S9="Yes"),"Yes — MDR Required","No")) | W9: =IF(OR(B9="",O9<>""),"",COUNTIFS(B$3:B9,"<>",O$3:O9,""))
C10: =IF(B10="","",VLOOKUP(B10,Roster!$A:$C,2,FALSE)) | D10: =IF(B10="","",VLOOKUP(B10,Roster!$A:$C,3,FALSE)) | H10: =IF(F10="","",F10+G10) | I10: =IF(F10="","",IF(O10<>"",O10-F10,TODAY()-F10)) | J10: =IF(F10="","",MAX(0,IF(K10="Yes",M10,G10)-I10)) | M10: =IF(K10="Yes",G10+L10,G10) -> 0 | N10: =IF(F10="","",F10+M10) | R10: =IF(B10="","",VLOOKUP(B10,Roster!$A:$K,10,FALSE)) | S10: =IF(B10="","",VLOOKUP(B10,Roster!$A:$K,11,FALSE)) | T10: =IF(B10="","",IF(OR(R10="Yes",S10="Yes"),"Yes — MDR Required","No")) | W10: =IF(OR(B10="",O10<>""),"",COUNTIFS(B$3:B10,"<>",O$3:O10,""))
C11: =IF(B11="","",VLOOKUP(B11,Roster!$A:$C,2,FALSE)) | D11: =IF(B11="","",VLOOKUP(B11,Roster!$A:$C,3,FALSE)) | H11: =IF(F11="","",F11+G11) | I11: =IF(F11="","",IF(O11<>"",O11-F11,TODAY()-F11)) | J11: =IF(F11="","",MAX(0,IF(K11="Yes",M11,G11)-I11)) | M11: =IF(K11="Yes",G11+L11,G11) -> 0 | N11: =IF(F11="","",F11+M11) | R11: =IF(B11="","",VLOOKUP(B11,Roster!$A:$K,10,FALSE)) | S11: =IF(B11="","",VLOOKUP(B11,Roster!$A:$K,11,FALSE)) | T11: =IF(B11="","",IF(OR(R11="Yes",S11="Yes"),"Yes — MDR Required","No")) | W11: =IF(OR(B11="",O11<>""),"",COUNTIFS(B$3:B11,"<>",O$3:O11,""))
C12: =IF(B12="","",VLOOKUP(B12,Roster!$A:$C,2,FALSE)) | D12: =IF(B12="","",VLOOKUP(B12,Roster!$A:$C,3,FALSE)) | H12: =IF(F12="","",F12+G12) | I12: =IF(F12="","",IF(O12<>"",O12-F12,TODAY()-F12)) | J12: =IF(F12="","",MAX(0,IF(K12="Yes",M12,G12)-I12)) | M12: =IF(K12="Yes",G12+L12,G12) -> 0 | N12: =IF(F12="","",F12+M12) | R12: =IF(B12="","",VLOOKUP(B12,Roster!$A:$K,10,FALSE)) | S12: =IF(B12="","",VLOOKUP(B12,Roster!$A:$K,11,FALSE)) | T12: =IF(B12="","",IF(OR(R12="Yes",S12="Yes"),"Yes — MDR Required","No")) | W12: =IF(OR(B12="",O12<>""),"",COUNTIFS(B$3:B12,"<>",O$3:O12,""))
C13: =IF(B13="","",VLOOKUP(B13,Roster!$A:$C,2,FALSE)) | D13: =IF(B13="","",VLOOKUP(B13,Roster!$A:$C,3,FALSE)) | H13: =IF(F13="","",F13+G13) | I13: =IF(F13="","",IF(O13<>"",O13-F13,TODAY()-F13)) | J13: =IF(F13="","",MAX(0,IF(K13="Yes",M13,G13)-I13)) | M13: =IF(K13="Yes",G13+L13,G13) -> 0 | N13: =IF(F13="","",F13+M13) | R13: =IF(B13="","",VLOOKUP(B13,Roster!$A:$K,10,FALSE)) | S13: =IF(B13="","",VLOOKUP(B13,Roster!$A:$K,11,FALSE)) | T13: =IF(B13="","",IF(OR(R13="Yes",S13="Yes"),"Yes — MDR Required","No")) | W13: =IF(OR(B13="",O13<>""),"",COUNTIFS(B$3:B13,"<>",O$3:O13,""))
C14: =IF(B14="","",VLOOKUP(B14,Roster!$A:$C,2,FALSE)) | D14: =IF(B14="","",VLOOKUP(B14,Roster!$A:$C,3,FALSE)) | H14: =IF(F14="","",F14+G14) | I14: =IF(F14="","",IF(O14<>"",O14-F14,TODAY()-F14)) | J14: =IF(F14="","",MAX(0,IF(K14="Yes",M14,G14)-I14)) | M14: =IF(K14="Yes",G14+L14,G14) -> 0 | N14: =IF(F14="","",F14+M14) | R14: =IF(B14="","",VLOOKUP(B14,Roster!$A:$K,10,FALSE)) | S14: =IF(B14="","",VLOOKUP(B14,Roster!$A:$K,11,FALSE)) | T14: =IF(B14="","",IF(OR(R14="Yes",S14="Yes"),"Yes — MDR Required","No")) | W14: =IF(OR(B14="",O14<>""),"",COUNTIFS(B$3:B14,"<>",O$3:O14,""))
C15: =IF(B15="","",VLOOKUP(B15,Roster!$A:$C,2,FALSE)) | D15: =IF(B15="","",VLOOKUP(B15,Roster!$A:$C,3,FALSE)) | H15: =IF(F15="","",F15+G15) | I15: =IF(F15="","",IF(O15<>"",O15-F15,TODAY()-F15)) | J15: =IF(F15="","",MAX(0,IF(K15="Yes",M15,G15)-I15)) | M15: =IF(K15="Yes",G15+L15,G15) -> 0 | N15: =IF(F15="","",F15+M15) | R15: =IF(B15="","",VLOOKUP(B15,Roster!$A:$K,10,FALSE)) | S15: =IF(B15="","",VLOOKUP(B15,Roster!$A:$K,11,FALSE)) | T15: =IF(B15="","",IF(OR(R15="Yes",S15="Yes"),"Yes — MDR Required","No")) | W15: =IF(OR(B15="",O15<>""),"",COUNTIFS(B$3:B15,"<>",O$3:O15,""))
C16: =IF(B16="","",VLOOKUP(B16,Roster!$A:$C,2,FALSE)) | D16: =IF(B16="","",VLOOKUP(B16,Roster!$A:$C,3,FALSE)) | H16: =IF(F16="","",F16+G16) | I16: =IF(F16="","",IF(O16<>"",O16-F16,TODAY()-F16)) | J16: =IF(F16="","",MAX(0,IF(K16="Yes",M16,G16)-I16)) | M16: =IF(K16="Yes",G16+L16,G16) -> 0 | N16: =IF(F16="","",F16+M16) | R16: =IF(B16="","",VLOOKUP(B16,Roster!$A:$K,10,FALSE)) | S16: =IF(B16="","",VLOOKUP(B16,Roster!$A:$K,11,FALSE)) | T16: =IF(B16="","",IF(OR(R16="Yes",S16="Yes"),"Yes — MDR Required","No")) | W16: =IF(OR(B16="",O16<>""),"",COUNTIFS(B$3:B16,"<>",O$3:O16,""))
C17: =IF(B17="","",VLOOKUP(B17,Roster!$A:$C,2,FALSE)) | D17: =IF(B17="","",VLOOKUP(B17,Roster!$A:$C,3,FALSE)) | H17: =IF(F17="","",F17+G17) | I17: =IF(F17="","",IF(O17<>"",O17-F17,TODAY()-F17)) | J17: =IF(F17="","",MAX(0,IF(K17="Yes",M17,G17)-I17)) | M17: =IF(K17="Yes",G17+L17,G17) -> 0 | N17: =IF(F17="","",F17+M17) | R17: =IF(B17="","",VLOOKUP(B17,Roster!$A:$K,10,FALSE)) | S17: =IF(B17="","",VLOOKUP(B17,Roster!$A:$K,11,FALSE)) | T17: =IF(B17="","",IF(OR(R17="Yes",S17="Yes"),"Yes — MDR Required","No")) | W17: =IF(OR(B17="",O17<>""),"",COUNTIFS(B$3:B17,"<>",O$3:O17,""))
C18: =IF(B18="","",VLOOKUP(B18,Roster!$A:$C,2,FALSE)) | D18: =IF(B18="","",VLOOKUP(B18,Roster!$A:$C,3,FALSE)) | H18: =IF(F18="","",F18+G18) | I18: =IF(F18="","",IF(O18<>"",O18-F18,TODAY()-F18)) | J18: =IF(F18="","",MAX(0,IF(K18="Yes",M18,G18)-I18)) | M18: =IF(K18="Yes",G18+L18,G18) -> 0 | N18: =IF(F18="","",F18+M18) | R18: =IF(B18="","",VLOOKUP(B18,Roster!$A:$K,10,FALSE)) | S18: =IF(B18="","",VLOOKUP(B18,Roster!$A:$K,11,FALSE)) | T18: =IF(B18="","",IF(OR(R18="Yes",S18="Yes"),"Yes — MDR Required","No")) | W18: =IF(OR(B18="",O18<>""),"",COUNTIFS(B$3:B18,"<>",O$3:O18,""))
... C102: =IF(B102="","",VLOOKUP(B102,Roster!$A:$C,2,FALSE)) | D102: =IF(B102="","",VLOOKUP(B102,Roster!$A:$C,3,FALSE)) | H102: =IF(F102="","",F102+G102) | I102: =IF(F102="","",IF(O102<>"",O102-F102,TODAY()-F102)) | J102: =IF(F102="","",MAX(0,IF(K102="Yes",M102,G102)-I102)) | M102: =IF(K102="Yes",G102+L102,G102) -> 0 | N102: =IF(F102="","",F102+M102) | R102: =IF(B102="","",VLOOKUP(B102,Roster!$A:$K,10,FALSE)) | S102: =IF(B102="","",VLOOKUP(B102,Roster!$A:$K,11,FALSE)) | T102: =IF(B102="","",IF(OR(R102="Yes",S102="Yes"),"Yes — MDR Required","No")) | W102: =IF(OR(B102="",O102<>""),"",COUNTIFS(B$3:B102,"<>",O$3:O102,""))

Sheet Compliance Checklist
A1: COMPLIANCE CHECKLIST — SPED & 504 Required Actions During DAEP Placement
A2: ⚠ LEGAL NOTICE: Deadline dates shown are CALENDAR-day approximations. Texas law counts SCHOOL days for MDR and related timelines. Always verify with your district's SPED director and legal counsel. This tracker does not constitute legal advice.
A3: Checklist ID | B3: Student ID | C3: Last Name ⚙ | D3: First Name ⚙ | E3: Placement ID | F3: SPED or 504 | G3: Compliance Action Required | H3: TEC / Legal Reference | I3: Placement Start Date | J3: Deadline (school days) | K3: Deadline Date ⚙ | L3: Days Until Deadline ⚙ | M3: Status | N3: Completion Date | O3: Completed By | P3: Meeting Held? | Q3: Meeting Date | R3: Notes / Documentation Location | S3: ⚙ Board Index (do not edit)
A4: CC-001 | B4: STU-001 | C4: =IF(B4="","",VLOOKUP(B4,Roster!$A:$C,2,FALSE)) -> Ramirez | D4: =IF(B4="","",VLOOKUP(B4,Roster!$A:$C,3,FALSE)) -> Carlos | E4: PLC-001 | F4: Yes | G4: Manifestation Determination Review (MDR) | H4: 34 CFR §300.530(e) / TEC §37.004 | I4: 46042 | J4: 10 | K4: =IF(OR(I4="",J4=""),"",I4+ROUND(J4*7/5,0)) -> 46056 | L4: =IF(K4="","",IF(M4="Complete","N/A — Completed",K4-TODAY())) -> N/A — Completed | M4: Complete | N4: 46038 | O4: SPED Coordinator | P4: Yes | Q4: 46038 | R4: Not a manifestation — placement proceeds. | S4: =IF(AND(B4<>"",ISNUMBER(L4),L4>=-5,L4<=10,M4<>"Complete",M4<>"N/A"),COUNTIFS(B$4:B4,"<>",L$4:L4,">=-5",L$4:L4,"<=10",M$4:M4,"<>Complete",M$4:M4,"<>N/A"),"")
A5: CC-002 | B5: STU-003 | C5: =IF(B5="","",VLOOKUP(B5,Roster!$A:$C,2,FALSE)) -> Williams | D5: =IF(B5="","",VLOOKUP(B5,Roster!$A:$C,3,FALSE)) -> Marcus | E5: PLC-003 | F5: Yes | G5: Annual IEP Review (Due During Placement) | H5: IDEA — 34 CFR §300.324 | I5: 45978 | J5: 45 | K5: =IF(OR(I5="",J5=""),"",I5+ROUND(J5*7/5,0)) -> 46041 | L5: =IF(K5="","",IF(M5="Complete","N/A — Completed",K5-TODAY())) -> N/A — Completed | M5: Complete | N5: 46009 | O5: ARD Committee | P5: Yes | Q5: 46009 | S5: =IF(AND(B5<>"",ISNUMBER(L5),L5>=-5,L5<=10,M5<>"Complete",M5<>"N/A"),COUNTIFS(B$4:B5,"<>",L$4:L5,">=-5",L$4:L5,"<=10",M$4:M5,"<>Complete",M$4:M5,"<>N/A"),"")
A6: CC-003 | B6: STU-004 | C6: =IF(B6="","",VLOOKUP(B6,Roster!$A:$C,2,FALSE)) -> Nguyen | D6: =IF(B6="","",VLOOKUP(B6,Roster!$A:$C,3,FALSE)) -> Amy | E6: PLC-004 | F6: N/A | G6: 504 Plan Review | H6: Section 504 — 34 CFR §104.35 | I6: 46083 | J6: 15 | K6: =IF(OR(I6="",J6=""),"",I6+ROUND(J6*7/5,0)) -> 46104 | L6: =IF(K6="","",IF(M6="Complete","N/A — Completed",K6-TODAY())) -> -113 | M6: In Progress | O6: 504 Coordinator | P6: No | R6: Meeting scheduled. | S6: =IF(AND(B6<>"",ISNUMBER(L6),L6>=-5,L6<=10,M6<>"Complete",M6<>"N/A"),COUNTIFS(B$4:B6,"<>",L$4:L6,">=-5",L$4:L6,"<=10",M$4:M6,"<>Complete",M$4:M6,"<>N/A"),"")
C7: =IF(B7="","",VLOOKUP(B7,Roster!$A:$C,2,FALSE)) | D7: =IF(B7="","",VLOOKUP(B7,Roster!$A:$C,3,FALSE)) | K7: =IF(OR(I7="",J7=""),"",I7+ROUND(J7*7/5,0)) | L7: =IF(K7="","",IF(M7="Complete","N/A — Completed",K7-TODAY())) | S7: =IF(AND(B7<>"",ISNUMBER(L7),L7>=-5,L7<=10,M7<>"Complete",M7<>"N/A"),COUNTIFS(B$4:B7,"<>",L$4:L7,">=-5",L$4:L7,"<=10",M$4:M7,"<>Complete",M$4:M7,"<>N/A"),"")
C8: =IF(B8="","",VLOOKUP(B8,Roster!$A:$C,2,FALSE)) | D8: =IF(B8="","",VLOOKUP(B8,Roster!$A:$C,3,FALSE)) | K8: =IF(OR(I8="",J8=""),"",I8+ROUND(J8*7/5,0)) | L8: =IF(K8="","",IF(M8="Complete","N/A — Completed",K8-TODAY())) | S8: =IF(AND(B8<>"",ISNUMBER(L8),L8>=-5,L8<=10,M8<>"Complete",M8<>"N/A"),COUNTIFS(B$4:B8,"<>",L$4:L8,">=-5",L$4:L8,"<=10",M$4:M8,"<>Complete",M$4:M8,"<>N/A"),"")
C9: =IF(B9="","",VLOOKUP(B9,Roster!$A:$C,2,FALSE)) | D9: =IF(B9="","",VLOOKUP(B9,Roster!$A:$C,3,FALSE)) | K9: =IF(OR(I9="",J9=""),"",I9+ROUND(J9*7/5,0)) | L9: =IF(K9="","",IF(M9="Complete","N/A — Completed",K9-TODAY())) | S9: =IF(AND(B9<>"",ISNUMBER(L9),L9>=-5,L9<=10,M9<>"Complete",M9<>"N/A"),COUNTIFS(B$4:B9,"<>",L$4:L9,">=-5",L$4:L9,"<=10",M$4:M9,"<>Complete",M$4:M9,"<>N/A"),"")
C10: =IF(B10="","",VLOOKUP(B10,Roster!$A:$C,2,FALSE)) | D10: =IF(B10="","",VLOOKUP(B10,Roster!$A:$C,3,FALSE)) | K10: =IF(OR(I10="",J10=""),"",I10+ROUND(J10*7/5,0)) | L10: =IF(K10="","",IF(M10="Complete","N/A — Completed",K10-TODAY())) | S10: =IF(AND(B10<>"",ISNUMBER(L10),L10>=-5,L10<=10,M10<>"Complete",M10<>"N/A"),COUNTIFS(B$4:B10,"<>",L$4:L10,">=-5",L$4:L10,"<=10",M$4:M10,"<>Complete",M$4:M10,"<>N/A"),"")
C11: =IF(B11="","",VLOOKUP(B11,Roster!$A:$C,2,FALSE)) | D11: =IF(B11="","",VLOOKUP(B11,Roster!$A:$C,3,FALSE)) | K11: =IF(OR(I11="",J11=""),"",I11+ROUND(J11*7/5,0)) | L11: =IF(K11="","",IF(M11="Complete","N/A — Completed",K11-TODAY())) | S11: =IF(AND(B11<>"",ISNUMBER(L11),L11>=-5,L11<=10,M11<>"Complete",M11<>"N/A"),COUNTIFS(B$4:B11,"<>",L$4:L11,">=-5",L$4:L11,"<=10",M$4:M11,"<>Complete",M$4:M11,"<>N/A"),"")
C12: =IF(B12="","",VLOOKUP(B12,Roster!$A:$C,2,FALSE)) | D12: =IF(B12="","",VLOOKUP(B12,Roster!$A:$C,3,FALSE)) | K12: =IF(OR(I12="",J12=""),"",I12+ROUND(J12*7/5,0)) | L12: =IF(K12="","",IF(M12="Complete","N/A — Completed",K12-TODAY())) | S12: =IF(AND(B12<>"",ISNUMBER(L12),L12>=-5,L12<=10,M12<>"Complete",M12<>"N/A"),COUNTIFS(B$4:B12,"<>",L$4:L12,">=-5",L$4:L12,"<=10",M$4:M12,"<>Complete",M$4:M12,"<>N/A"),"")
C13: =IF(B13="","",VLOOKUP(B13,Roster!$A:$C,2,FALSE)) | D13: =IF(B13="","",VLOOKUP(B13,Roster!$A:$C,3,FALSE)) | K13: =IF(OR(I13="",J13=""),"",I13+ROUND(J13*7/5,0)) | L13: =IF(K13="","",IF(M13="Complete","N/A — Completed",K13-TODAY())) | S13: =IF(AND(B13<>"",ISNUMBER(L13),L13>=-5,L13<=10,M13<>"Complete",M13<>"N/A"),COUNTIFS(B$4:B13,"<>",L$4:L13,">=-5",L$4:L13,"<=10",M$4:M13,"<>Complete",M$4:M13,"<>N/A"),"")
C14: =IF(B14="","",VLOOKUP(B14,Roster!$A:$C,2,FALSE)) | D14: =IF(B14="","",VLOOKUP(B14,Roster!$A:$C,3,FALSE)) | K14: =IF(OR(I14="",J14=""),"",I14+ROUND(J14*7/5,0)) | L14: =IF(K14="","",IF(M14="Complete","N/A — Completed",K14-TODAY())) | S14: =IF(AND(B14<>"",ISNUMBER(L14),L14>=-5,L14<=10,M14<>"Complete",M14<>"N/A"),COUNTIFS(B$4:B14,"<>",L$4:L14,">=-5",L$4:L14,"<=10",M$4:M14,"<>Complete",M$4:M14,"<>N/A"),"")
C15: =IF(B15="","",VLOOKUP(B15,Roster!$A:$C,2,FALSE)) | D15: =IF(B15="","",VLOOKUP(B15,Roster!$A:$C,3,FALSE)) | K15: =IF(OR(I15="",J15=""),"",I15+ROUND(J15*7/5,0)) | L15: =IF(K15="","",IF(M15="Complete","N/A — Completed",K15-TODAY())) | S15: =IF(AND(B15<>"",ISNUMBER(L15),L15>=-5,L15<=10,M15<>"Complete",M15<>"N/A"),COUNTIFS(B$4:B15,"<>",L$4:L15,">=-5",L$4:L15,"<=10",M$4:M15,"<>Complete",M$4:M15,"<>N/A"),"")
C16: =IF(B16="","",VLOOKUP(B16,Roster!$A:$C,2,FALSE)) | D16: =IF(B16="","",VLOOKUP(B16,Roster!$A:$C,3,FALSE)) | K16: =IF(OR(I16="",J16=""),"",I16+ROUND(J16*7/5,0)) | L16: =IF(K16="","",IF(M16="Complete","N/A — Completed",K16-TODAY())) | S16: =IF(AND(B16<>"",ISNUMBER(L16),L16>=-5,L16<=10,M16<>"Complete",M16<>"N/A"),COUNTIFS(B$4:B16,"<>",L$4:L16,">=-5",L$4:L16,"<=10",M$4:M16,"<>Complete",M$4:M16,"<>N/A"),"")
C17: =IF(B17="","",VLOOKUP(B17,Roster!$A:$C,2,FALSE)) | D17: =IF(B17="","",VLOOKUP(B17,Roster!$A:$C,3,FALSE)) | K17: =IF(OR(I17="",J17=""),"",I17+ROUND(J17*7/5,0)) | L17: =IF(K17="","",IF(M17="Complete","N/A — Completed",K17-TODAY())) | S17: =IF(AND(B17<>"",ISNUMBER(L17),L17>=-5,L17<=10,M17<>"Complete",M17<>"N/A"),COUNTIFS(B$4:B17,"<>",L$4:L17,">=-5",L$4:L17,"<=10",M$4:M17,"<>Complete",M$4:M17,"<>N/A"),"")
C18: =IF(B18="","",VLOOKUP(B18,Roster!$A:$C,2,FALSE)) | D18: =IF(B18="","",VLOOKUP(B18,Roster!$A:$C,3,FALSE)) | K18: =IF(OR(I18="",J18=""),"",I18+ROUND(J18*7/5,0)) | L18: =IF(K18="","",IF(M18="Complete","N/A — Completed",K18-TODAY())) | S18: =IF(AND(B18<>"",ISNUMBER(L18),L18>=-5,L18<=10,M18<>"Complete",M18<>"N/A"),COUNTIFS(B$4:B18,"<>",L$4:L18,">=-5",L$4:L18,"<=10",M$4:M18,"<>Complete",M$4:M18,"<>N/A"),"")
... C153: =IF(B153="","",VLOOKUP(B153,Roster!$A:$C,2,FALSE)) | D153: =IF(B153="","",VLOOKUP(B153,Roster!$A:$C,3,FALSE)) | K153: =IF(OR(I153="",J153=""),"",I153+ROUND(J153*7/5,0)) | L153: =IF(K153="","",IF(M153="Complete","N/A — Completed",K153-TODAY())) | S153: =IF(AND(B153<>"",ISNUMBER(L153),L153>=-5,L153<=10,M153<>"Complete",M153<>"N/A"),COUNTIFS(B$4:B153,"<>",L$4:L153,">=-5",L$4:L153,"<=10",M$4:M153,"<>Complete",M$4:M153,"<>N/A"),"")

Sheet Dashboard
A1: DASHBOARD — Auto-Summary (No Data Entry Needed Here)
A2: ="Dashboard reflects data as of: "&TEXT(TODAY(),"MM/DD/YYYY") -> Dashboard reflects data as of: 07/14/2026
A4: KEY METRICS — CURRENT SNAPSHOT
A5: Active Placements | B5: =COUNTIF(Roster!I$3:I$102,"Active") -> 4
A6: Active SPED Students | B6: =COUNTIFS(Roster!J$3:J$102,"Yes",Roster!I$3:I$102,"Active") -> 1
A7: Active 504 Students | B7: =COUNTIFS(Roster!K$3:K$102,"Yes",Roster!I$3:I$102,"Active") -> 1
A8: Placements Expiring ≤5 Days | B8: =COUNTIFS('DAEP Placements'!J$3:J$102,">0",'DAEP Placements'!J$3:J$102,"<=5",'DAEP Placements'!O$3:O$102,"") -> 0
A9: ⚠ Overdue Placements | B9: =COUNTIFS('DAEP Placements'!J$3:J$102,"<=0",'DAEP Placements'!O$3:O$102,"",'DAEP Placements'!B$3:B$102,"<>") -> 3
A10: Compliance Items Open | B10: =COUNTIFS('Compliance Checklist'!M$4:M$153,"<>Complete",'Compliance Checklist'!M$4:M$153,"<>N/A",'Compliance Checklist'!B$4:B$153,"<>") -> 1
A11: Total Incidents (YTD) | B11: =COUNTA('Incident Log'!A$3:A$202) -> 5
A12: Extended Placements | B12: =COUNTIF('DAEP Placements'!K$3:K$102,"Yes") -> 0
A14: COMPLIANCE DEADLINES — NEXT 30 DAYS
A15: Student Last Name | B15: Student First Name | C15: Placement ID | D15: Action Required | E15: Deadline Date | F15: Days Until Deadline | G15: Status
A16: [GOOGLE SHEETS] Paste this formula in cell A below to auto-populate:
A17: =IFERROR(FILTER('Compliance Checklist'!C4:R500,ISNUMBER('Compliance Checklist'!L4:L500),'Compliance Checklist'!L4:L500<=30,'Compliance Checklist'!L4:L500>=-5,'Compliance Checklist'!M4:M500<>"Complete",'Compliance Checklist'!M4:M500<>"N/A"),"No items due in next 30 days")
A18: For Excel: Open the Compliance Checklist tab → Sort by column L (Days Until Deadline) ascending → manually review top rows.
A20: ROSTER STATUS BREAKDOWN
A21: Active | B21: =COUNTIF(Roster!I$3:I$102,"Active") -> 4
A22: Exited | B22: =COUNTIF(Roster!I$3:I$102,"Exited") -> 1
A23: Extended | B23: =COUNTIF(Roster!I$3:I$102,"Extended") -> 0
A24: Pending Placement | B24: =COUNTIF(Roster!I$3:I$102,"Pending Placement") -> 0
A25: Returned Early | B25: =COUNTIF(Roster!I$3:I$102,"Returned Early") -> 0
A26: TOTAL (all statuses) | B26: =COUNTA(Roster!A$3:A$102) -> 5
A28: INCIDENTS BY OFFENSE CATEGORY (YTD)
A29: Fighting | B29: =COUNTIF('Incident Log'!H$3:H$202,"Fighting") -> 2
A30: Drugs/Alcohol | B30: =COUNTIF('Incident Log'!H$3:H$202,"Drugs/Alcohol") -> 2
A31: Weapons | B31: =COUNTIF('Incident Log'!H$3:H$202,"Weapons") -> 0
A32: Harassment/Bullying | B32: =COUNTIF('Incident Log'!H$3:H$202,"Harassment/Bullying") -> 1
A33: Truancy | B33: =COUNTIF('Incident Log'!H$3:H$202,"Truancy") -> 0
A34: Defiance/Insubordination | B34: =COUNTIF('Incident Log'!H$3:H$202,"Defiance/Insubordination") -> 0
A35: Theft | B35: =COUNTIF('Incident Log'!H$3:H$202,"Theft") -> 0
A36: Vandalism | B36: =COUNTIF('Incident Log'!H$3:H$202,"Vandalism") -> 0
A37: Sexual Offense | B37: =COUNTIF('Incident Log'!H$3:H$202,"Sexual Offense") -> 0
A38: Gang-Related Activity | B38: =COUNTIF('Incident Log'!H$3:H$202,"Gang-Related Activity") -> 0
A39: Other | B39: =COUNTIF('Incident Log'!H$3:H$202,"Other") -> 0
A40: TOTAL | B40: =COUNTA('Incident Log'!A$3:A$202) -> 5
A42: ACTIVE STUDENTS BY GRADE
A43: Pre-K | B43: =COUNTIFS(Roster!D$3:D$102,"Pre-K",Roster!I$3:I$102,"Active") -> 0 | C43: =REPT("|",B43)
A44: Kindergarten | B44: =COUNTIFS(Roster!D$3:D$102,"Kindergarten",Roster!I$3:I$102,"Active") -> 0 | C44: =REPT("|",B44)
A45: 1st Grade | B45: =COUNTIFS(Roster!D$3:D$102,"1st Grade",Roster!I$3:I$102,"Active") -> 0 | C45: =REPT("|",B45)
...

Sheet 📋 Status Board
A1: 📋 WEEKLY DAEP STATUS BOARD
A2: ="As of: "&TEXT(TODAY(),"MMMM D, YYYY") -> As of: July 14, 2026
A3: Print this tab for your Monday morning principal briefing. All data auto-updates from your other tabs.
A5: 🔴 ACTIVE DAEP PLACEMENTS
A6: Student ID | B6: Student Name | C6: Grade | D6: Placement Days | E6: Start Date | F6: Planned End | G6: Days Remaining | H6: SPED?
A7: =IFERROR(INDEX('DAEP Placements'!B$3:B$102,MATCH(1,'DAEP Placements'!W$3:W$102,0)),"") -> STU-001 | B7: =IF(A7="","",VLOOKUP(A7,Roster!$A:$C,2,FALSE)&", "&VLOOKUP(A7,Roster!$A:$C,3,FALSE)) -> Ramirez, Carlos | C7: =IF(A7="","",VLOOKUP(A7,Roster!$A:$D,4,FALSE)) -> 8th Grade | D7: =IF(A7="","",INDEX('DAEP Placements'!G$3:G$102,MATCH(A7,'DAEP Placements'!B$3:B$102,0))) -> 45 | E7: =IF(A7="","",INDEX('DAEP Placements'!F$3:F$102,MATCH(A7,'DAEP Placements'!B$3:B$102,0))) -> 46042 | F7: =IF(A7="","",INDEX('DAEP Placements'!H$3:H$102,MATCH(A7,'DAEP Placements'!B$3:B$102,0))) -> 46087 | G7: =IF(A7="","",INDEX('DAEP Placements'!J$3:J$102,MATCH(A7,'DAEP Placements'!B$3:B$102,0))) -> 0 | H7: =IF(A7="","",VLOOKUP(A7,Roster!$A:$K,10,FALSE)) -> Yes
A8: =IFERROR(INDEX('DAEP Placements'!B$3:B$102,MATCH(2,'DAEP Placements'!W$3:W$102,0)),"") -> STU-002 | B8: =IF(A8="","",VLOOKUP(A8,Roster!$A:$C,2,FALSE)&", "&VLOOKUP(A8,Roster!$A:$C,3,FALSE)) -> Johnson, Destiny | C8: =IF(A8="","",VLOOKUP(A8,Roster!$A:$D,4,FALSE)) -> 10th Grade | D8: =IF(A8="","",INDEX('DAEP Placements'!G$3:G$102,MATCH(A8,'DAEP Placements'!B$3:B$102,0))) -> 60 | E8: =IF(A8="","",INDEX('DAEP Placements'!F$3:F$102,MATCH(A8,'DAEP Placements'!B$3:B$102,0))) -> 46062 | F8: =IF(A8="","",INDEX('DAEP Placements'!H$3:H$102,MATCH(A8,'DAEP Placements'!B$3:B$102,0))) -> 46122 | G8: =IF(A8="","",INDEX('DAEP Placements'!J$3:J$102,MATCH(A8,'DAEP Placements'!B$3:B$102,0))) -> 0 | H8: =IF(A8="","",VLOOKUP(A8,Roster!$A:$K,10,FALSE)) -> No
A9: =IFERROR(INDEX('DAEP Placements'!B$3:B$102,MATCH(3,'DAEP Placements'!W$3:W$102,0)),"") -> STU-004 | B9: =IF(A9="","",VLOOKUP(A9,Roster!$A:$C,2,FALSE)&", "&VLOOKUP(A9,Roster!$A:$C,3,FALSE)) -> Nguyen, Amy | C9: =IF(A9="","",VLOOKUP(A9,Roster!$A:$D,4,FALSE)) -> 9th Grade | D9: =IF(A9="","",INDEX('DAEP Placements'!G$3:G$102,MATCH(A9,'DAEP Placements'!B$3:B$102,0))) -> 30 | E9: =IF(A9="","",INDEX('DAEP Placements'!F$3:F$102,MATCH(A9,'DAEP Placements'!B$3:B$102,0))) -> 46083 | F9: =IF(A9="","",INDEX('DAEP Placements'!H$3:H$102,MATCH(A9,'DAEP Placements'!B$3:B$102,0))) -> 46113 | G9: =IF(A9="","",INDEX('DAEP Placements'!J$3:J$102,MATCH(A9,'DAEP Placements'!B$3:B$102,0))) -> 0 | H9: =IF(A9="","",VLOOKUP(A9,Roster!$A:$K,10,FALSE)) -> No
A10: =IFERROR(INDEX('DAEP Placements'!B$3:B$102,MATCH(4,'DAEP Placements'!W$3:W$102,0)),"") | B10: =IF(A10="","",VLOOKUP(A10,Roster!$A:$C,2,FALSE)&", "&VLOOKUP(A10,Roster!$A:$C,3,FALSE)) | C10: =IF(A10="","",VLOOKUP(A10,Roster!$A:$D,4,FALSE)) | D10: =IF(A10="","",INDEX('DAEP Placements'!G$3:G$102,MATCH(A10,'DAEP Placements'!B$3:B$102,0))) | E10: =IF(A10="","",INDEX('DAEP Placements'!F$3:F$102,MATCH(A10,'DAEP Placements'!B$3:B$102,0))) | F10: =IF(A10="","",INDEX('DAEP Placements'!H$3:H$102,MATCH(A10,'DAEP Placements'!B$3:B$102,0))) | G10: =IF(A10="","",INDEX('DAEP Placements'!J$3:J$102,MATCH(A10,'DAEP Placements'!B$3:B$102,0))) | H10: =IF(A10="","",VLOOKUP(A10,Roster!$A:$K,10,FALSE))
A11: =IFERROR(INDEX('DAEP Placements'!B$3:B$102,MATCH(5,'DAEP Placements'!W$3:W$102,0)),"") | B11: =IF(A11="","",VLOOKUP(A11,Roster!$A:$C,2,FALSE)&", "&VLOOKUP(A11,Roster!$A:$C,3,FALSE)) | C11: =IF(A11="","",VLOOKUP(A11,Roster!$A:$D,4,FALSE)) | D11: =IF(A11="","",INDEX('DAEP Placements'!G$3:G$102,MATCH(A11,'DAEP Placements'!B$3:B$102,0))) | E11: =IF(A11="","",INDEX('DAEP Placements'!F$3:F$102,MATCH(A11,'DAEP Placements'!B$3:B$102,0))) | F11: =IF(A11="","",INDEX('DAEP Placements'!H$3:H$102,MATCH(A11,'DAEP Placements'!B$3:B$102,0))) | G11: =IF(A11="","",INDEX('DAEP Placements'!J$3:J$102,MATCH(A11,'DAEP Placements'!B$3:B$102,0))) | H11: =IF(A11="","",VLOOKUP(A11,Roster!$A:$K,10,FALSE))
A12: =IFERROR(INDEX('DAEP Placements'!B$3:B$102,MATCH(6,'DAEP Placements'!W$3:W$102,0)),"") | B12: =IF(A12="","",VLOOKUP(A12,Roster!$A:$C,2,FALSE)&", "&VLOOKUP(A12,Roster!$A:$C,3,FALSE)) | C12: =IF(A12="","",VLOOKUP(A12,Roster!$A:$D,4,FALSE)) | D12: =IF(A12="","",INDEX('DAEP Placements'!G$3:G$102,MATCH(A12,'DAEP Placements'!B$3:B$102,0))) | E12: =IF(A12="","",INDEX('DAEP Placements'!F$3:F$102,MATCH(A12,'DAEP Placements'!B$3:B$102,0))) | F12: =IF(A12="","",INDEX('DAEP Placements'!H$3:H$102,MATCH(A12,'DAEP Placements'!B$3:B$102,0))) | G12: =IF(A12="","",INDEX('DAEP Placements'!J$3:J$102,MATCH(A12,'DAEP Placements'!B$3:B$102,0))) | H12: =IF(A12="","",VLOOKUP(A12,Roster!$A:$K,10,FALSE))
A13: =IFERROR(INDEX('DAEP Placements'!B$3:B$102,MATCH(7,'DAEP Placements'!W$3:W$102,0)),"") | B13: =IF(A13="","",VLOOKUP(A13,Roster!$A:$C,2,FALSE)&", "&VLOOKUP(A13,Roster!$A:$C,3,FALSE)) | C13: =IF(A13="","",VLOOKUP(A13,Roster!$A:$D,4,FALSE)) | D13: =IF(A13="","",INDEX('DAEP Placements'!G$3:G$102,MATCH(A13,'DAEP Placements'!B$3:B$102,0))) | E13: =IF(A13="","",INDEX('DAEP Placements'!F$3:F$102,MATCH(A13,'DAEP Placements'!B$3:B$102,0))) | F13: =IF(A13="","",INDEX('DAEP Placements'!H$3:H$102,MATCH(A13,'DAEP Placements'!B$3:B$102,0))) | G13: =IF(A13="","",INDEX('DAEP Placements'!J$3:J$102,MATCH(A13,'DAEP Placements'!B$3:B$102,0))) | H13: =IF(A13="","",VLOOKUP(A13,Roster!$A:$K,10,FALSE))
A14: =IFERROR(INDEX('DAEP Placements'!B$3:B$102,MATCH(8,'DAEP Placements'!W$3:W$102,0)),"") | B14: =IF(A14="","",VLOOKUP(A14,Roster!$A:$C,2,FALSE)&", "&VLOOKUP(A14,Roster!$A:$C,3,FALSE)) | C14: =IF(A14="","",VLOOKUP(A14,Roster!$A:$D,4,FALSE)) | D14: =IF(A14="","",INDEX('DAEP Placements'!G$3:G$102,MATCH(A14,'DAEP Placements'!B$3:B$102,0))) | E14: =IF(A14="","",INDEX('DAEP Placements'!F$3:F$102,MATCH(A14,'DAEP Placements'!B$3:B$102,0))) | F14: =IF(A14="","",INDEX('DAEP Placements'!H$3:H$102,MATCH(A14,'DAEP Placements'!B$3:B$102,0))) | G14: =IF(A14="","",INDEX('DAEP Placements'!J$3:J$102,MATCH(A14,'DAEP Placements'!B$3:B$102,0))) | H14: =IF(A14="","",VLOOKUP(A14,Roster!$A:$K,10,FALSE))
A15: =IFERROR(INDEX('DAEP Placements'!B$3:B$102,MATCH(9,'DAEP Placements'!W$3:W$102,0)),"") | B15: =IF(A15="","",VLOOKUP(A15,Roster!$A:$C,2,FALSE)&", "&VLOOKUP(A15,Roster!$A:$C,3,FALSE)) | C15: =IF(A15="","",VLOOKUP(A15,Roster!$A:$D,4,FALSE)) | D15: =IF(A15="","",INDEX('DAEP Placements'!G$3:G$102,MATCH(A15,'DAEP Placements'!B$3:B$102,0))) | E15: =IF(A15="","",INDEX('DAEP Placements'!F$3:F$102,MATCH(A15,'DAEP Placements'!B$3:B$102,0))) | F15: =IF(A15="","",INDEX('DAEP Placements'!H$3:H$102,MATCH(A15,'DAEP Placements'!B$3:B$102,0))) | G15: =IF(A15="","",INDEX('DAEP Placements'!J$3:J$102,MATCH(A15,'DAEP Placements'!B$3:B$102,0))) | H15: =IF(A15="","",VLOOKUP(A15,Roster!$A:$K,10,FALSE))
A16: =IFERROR(INDEX('DAEP Placements'!B$3:B$102,MATCH(10,'DAEP Placements'!W$3:W$102,0)),"") | B16: =IF(A16="","",VLOOKUP(A16,Roster!$A:$C,2,FALSE)&", "&VLOOKUP(A16,Roster!$A:$C,3,FALSE)) | C16: =IF(A16="","",VLOOKUP(A16,Roster!$A:$D,4,FALSE)) | D16: =IF(A16="","",INDEX('DAEP Placements'!G$3:G$102,MATCH(A16,'DAEP Placements'!B$3:B$102,0))) | E16: =IF(A16="","",INDEX('DAEP Placements'!F$3:F$102,MATCH(A16,'DAEP Placements'!B$3:B$102,0))) | F16: =IF(A16="","",INDEX('DAEP Placements'!H$3:H$102,MATCH(A16,'DAEP Placements'!B$3:B$102,0))) | G16: =IF(A16="","",INDEX('DAEP Placements'!J$3:J$102,MATCH(A16,'DAEP Placements'!B$3:B$102,0))) | H16: =IF(A16="","",VLOOKUP(A16,Roster!$A:$K,10,FALSE))
A17: =IFERROR(INDEX('DAEP Placements'!B$3:B$102,MATCH(11,'DAEP Placements'!W$3:W$102,0)),"") | B17: =IF(A17="","",VLOOKUP(A17,Roster!$A:$C,2,FALSE)&", "&VLOOKUP(A17,Roster!$A:$C,3,FALSE)) | C17: =IF(A17="","",VLOOKUP(A17,Roster!$A:$D,4,FALSE)) | D17: =IF(A17="","",INDEX('DAEP Placements'!G$3:G$102,MATCH(A17,'DAEP Placements'!B$3:B$102,0))) | E17: =IF(A17="","",INDEX('DAEP Placements'!F$3:F$102,MATCH(A17,'DAEP Placements'!B$3:B$102,0))) | F17: =IF(A17="","",INDEX('DAEP Placements'!H$3:H$102,MATCH(A17,'DAEP Placements'!B$3:B$102,0))) | G17: =IF(A17="","",INDEX('DAEP Placements'!J$3:J$102,MATCH(A17,'DAEP Placements'!B$3:B$102,0))) | H17: =IF(A17="","",VLOOKUP(A17,Roster!$A:$K,10,FALSE))
A18: =IFERROR(INDEX('DAEP Placements'!B$3:B$102,MATCH(12,'DAEP Placements'!W$3:W$102,0)),"") | B18: =IF(A18="","",VLOOKUP(A18,Roster!$A:$C,2,FALSE)&", "&VLOOKUP(A18,Roster!$A:$C,3,FALSE)) | C18: =IF(A18="","",VLOOKUP(A18,Roster!$A:$D,4,FALSE)) | D18: =IF(A18="","",INDEX('DAEP Placements'!G$3:G$102,MATCH(A18,'DAEP Placements'!B$3:B$102,0))) | E18: =IF(A18="","",INDEX('DAEP Placements'!F$3:F$102,MATCH(A18,'DAEP Placements'!B$3:B$102,0))) | F18: =IF(A18="","",INDEX('DAEP Placements'!H$3:H$102,MATCH(A18,'DAEP Placements'!B$3:B$102,0))) | G18: =IF(A18="","",INDEX('DAEP Placements'!J$3:J$102,MATCH(A18,'DAEP Placements'!B$3:B$102,0))) | H18: =IF(A18="","",VLOOKUP(A18,Roster!$A:$K,10,FALSE))
A19: =IFERROR(INDEX('DAEP Placements'!B$3:B$102,MATCH(13,'DAEP Placements'!W$3:W$102,0)),"") | B19: =IF(A19="","",VLOOKUP(A19,Roster!$A:$C,2,FALSE)&", "&VLOOKUP(A19,Roster!$A:$C,3,FALSE)) | C19: =IF(A19="","",VLOOKUP(A19,Roster!$A:$D,4,FALSE)) | D19: =IF(A19="","",INDEX('DAEP Placements'!G$3:G$102,MATCH(A19,'DAEP Placements'!B$3:B$102,0))) | E19: =IF(A19="","",INDEX('DAEP Placements'!F$3:F$102,MATCH(A19,'DAEP Placements'!B$3:B$102,0))) | F19: =IF(A19="","",INDEX('DAEP Placements'!H$3:H$102,MATCH(A19,'DAEP Placements'!B$3:B$102,0))) | G19: =IF(A19="","",INDEX('DAEP Placements'!J$3:J$102,MATCH(A19,'DAEP Placements'!B$3:B$102,0))) | H19: =IF(A19="","",VLOOKUP(A19,Roster!$A:$K,10,FALSE))
A20: =IFERROR(INDEX('DAEP Placements'!B$3:B$102,MATCH(14,'DAEP Placements'!W$3:W$102,0)),"") | B20: =IF(A20="","",VLOOKUP(A20,Roster!$A:$C,2,FALSE)&", "&VLOOKUP(A20,Roster!$A:$C,3,FALSE)) | C20: =IF(A20="","",VLOOKUP(A20,Roster!$A:$D,4,FALSE)) | D20: =IF(A20="","",INDEX('DAEP Placements'!G$3:G$102,MATCH(A20,'DAEP Placements'!B$3:B$102,0))) | E20: =IF(A20="","",INDEX('DAEP Placements'!F$3:F$102,MATCH(A20,'DAEP Placements'!B$3:B$102,0))) | F20: =IF(A20="","",INDEX('DAEP Placements'!H$3:H$102,MATCH(A20,'DAEP Placements'!B$3:B$102,0))) | G20: =IF(A20="","",INDEX('DAEP Placements'!J$3:J$102,MATCH(A20,'DAEP Placements'!B$3:B$102,0))) | H20: =IF(A20="","",VLOOKUP(A20,Roster!$A:$K,10,FALSE))
A21: =IFERROR(INDEX('DAEP Placements'!B$3:B$102,MATCH(15,'DAEP Placements'!W$3:W$102,0)),"") | B21: =IF(A21="","",VLOOKUP(A21,Roster!$A:$C,2,FALSE)&", "&VLOOKUP(A21,Roster!$A:$C,3,FALSE)) | C21: =IF(A21="","",VLOOKUP(A21,Roster!$A:$D,4,FALSE)) | D21: =IF(A21="","",INDEX('DAEP Placements'!G$3:G$102,MATCH(A21,'DAEP Placements'!B$3:B$102,0))) | E21: =IF(A21="","",INDEX('DAEP Placements'!F$3:F$102,MATCH(A21,'DAEP Placements'!B$3:B$102,0))) | F21: =IF(A21="","",INDEX('DAEP Placements'!H$3:H$102,MATCH(A21,'DAEP Placements'!B$3:B$102,0))) | G21: =IF(A21="","",INDEX('DAEP Placements'!J$3:J$102,MATCH(A21,'DAEP Placements'!B$3:B$102,0))) | H21: =IF(A21="","",VLOOKUP(A21,Roster!$A:$K,10,FALSE))
A22: =IFERROR(INDEX('DAEP Placements'!B$3:B$102,MATCH(16,'DAEP Placements'!W$3:W$102,0)),"") | B22: =IF(A22="","",VLOOKUP(A22,Roster!$A:$C,2,FALSE)&", "&VLOOKUP(A22,Roster!$A:$C,3,FALSE)) | C22: =IF(A22="","",VLOOKUP(A22,Roster!$A:$D,4,FALSE)) | D22: =IF(A22="","",INDEX('DAEP Placements'!G$3:G$102,MATCH(A22,'DAEP Placements'!B$3:B$102,0))) | E22: =IF(A22="","",INDEX('DAEP Placements'!F$3:F$102,MATCH(A22,'DAEP Placements'!B$3:B$102,0))) | F22: =IF(A22="","",INDEX('DAEP Placements'!H$3:H$102,MATCH(A22,'DAEP Placements'!B$3:B$102,0))) | G22: =IF(A22="","",INDEX('DAEP Placements'!J$3:J$102,MATCH(A22,'DAEP Placements'!B$3:B$102,0))) | H22: =IF(A22="","",VLOOKUP(A22,Roster!$A:$K,10,FALSE))
A23: =IFERROR(INDEX('DAEP Placements'!B$3:B$102,MATCH(17,'DAEP Placements'!W$3:W$102,0)),"") | B23: =IF(A23="","",VLOOKUP(A23,Roster!$A:$C,2,FALSE)&", "&VLOOKUP(A23,Roster!$A:$C,3,FALSE)) | C23: =IF(A23="","",VLOOKUP(A23,Roster!$A:$D,4,FALSE)) | D23: =IF(A23="","",INDEX('DAEP Placements'!G$3:G$102,MATCH(A23,'DAEP Placements'!B$3:B$102,0))) | E23: =IF(A23="","",INDEX('DAEP Placements'!F$3:F$102,MATCH(A23,'DAEP Placements'!B$3:B$102,0))) | F23: =IF(A23="","",INDEX('DAEP Placements'!H$3:H$102,MATCH(A23,'DAEP Placements'!B$3:B$102,0))) | G23: =IF(A23="","",INDEX('DAEP Placements'!J$3:J$102,MATCH(A23,'DAEP Placements'!B$3:B$102,0))) | H23: =IF(A23="","",VLOOKUP(A23,Roster!$A:$K,10,FALSE))
A24: =IFERROR(INDEX('DAEP Placements'!B$3:B$102,MATCH(18,'DAEP Placements'!W$3:W$102,0)),"") | B24: =IF(A24="","",VLOOKUP(A24,Roster!$A:$C,2,FALSE)&", "&VLOOKUP(A24,Roster!$A:$C,3,FALSE)) | C24: =IF(A24="","",VLOOKUP(A24,Roster!$A:$D,4,FALSE)) | D24: =IF(A24="","",INDEX('DAEP Placements'!G$3:G$102,MATCH(A24,'DAEP Placements'!B$3:B$102,0))) | E24: =IF(A24="","",INDEX('DAEP Placements'!F$3:F$102,MATCH(A24,'DAEP Placements'!B$3:B$102,0))) | F24: =IF(A24="","",INDEX('DAEP Placements'!H$3:H$102,MATCH(A24,'DAEP Placements'!B$3:B$102,0))) | G24: =IF(A24="","",INDEX('DAEP Placements'!J$3:J$102,MATCH(A24,'DAEP Placements'!B$3:B$102,0))) | H24: =IF(A24="","",VLOOKUP(A24,Roster!$A:$K,10,FALSE))
A25: =IFERROR(INDEX('DAEP Placements'!B$3:B$102,MATCH(19,'DAEP Placements'!W$3:W$102,0)),"") | B25: =IF(A25="","",VLOOKUP(A25,Roster!$A:$C,2,FALSE)&", "&VLOOKUP(A25,Roster!$A:$C,3,FALSE)) | C25: =IF(A25="","",VLOOKUP(A25,Roster!$A:$D,4,FALSE)) | D25: =IF(A25="","",INDEX('DAEP Placements'!G$3:G$102,MATCH(A25,'DAEP Placements'!B$3:B$102,0))) | E25: =IF(A25="","",INDEX('DAEP Placements'!F$3:F$102,MATCH(A25,'DAEP Placements'!B$3:B$102,0))) | F25: =IF(A25="","",INDEX('DAEP Placements'!H$3:H$102,MATCH(A25,'DAEP Placements'!B$3:B$102,0))) | G25: =IF(A25="","",INDEX('DAEP Placements'!J$3:J$102,MATCH(A25,'DAEP Placements'!B$3:B$102,0))) | H25: =IF(A25="","",VLOOKUP(A25,Roster!$A:$K,10,FALSE))
A26: =IFERROR(INDEX('DAEP Placements'!B$3:B$102,MATCH(20,'DAEP Placements'!W$3:W$102,0)),"") | B26: =IF(A26="","",VLOOKUP(A26,Roster!$A:$C,2,FALSE)&", "&VLOOKUP(A26,Roster!$A:$C,3,FALSE)) | C26: =IF(A26="","",VLOOKUP(A26,Roster!$A:$D,4,FALSE)) | D26: =IF(A26="","",INDEX('DAEP Placements'!G$3:G$102,MATCH(A26,'DAEP Placements'!B$3:B$102,0))) | E26: =IF(A26="","",INDEX('DAEP Placements'!F$3:F$102,MATCH(A26,'DAEP Placements'!B$3:B$102,0))) | F26: =IF(A26="","",INDEX('DAEP Placements'!H$3:H$102,MATCH(A26,'DAEP Placements'!B$3:B$102,0))) | G26: =IF(A26="","",INDEX('DAEP Placements'!J$3:J$102,MATCH(A26,'DAEP Placements'!B$3:B$102,0))) | H26: =IF(A26="","",VLOOKUP(A26,Roster!$A:$K,10,FALSE))
A28: ⚠ COMPLIANCE ITEMS DUE WITHIN 10 DAYS
A29: Student ID | B29: Student Name | C29: Action Required | D29: Deadline Date | E29: Days Remaining | F29: Status
A30: =IFERROR(INDEX('Compliance Checklist'!B$4:B$153,MATCH(1,'Compliance Checklist'!S$4:S$153,0)),"") | B30: =IF(A30="","",VLOOKUP(A30,Roster!$A:$C,2,FALSE)&", "&VLOOKUP(A30,Roster!$A:$C,3,FALSE)) | C30: =IF(A30="","",INDEX('Compliance Checklist'!G$4:G$153,MATCH(A30,'Compliance Checklist'!B$4:B$153,0))) | D30: =IF(A30="","",INDEX('Compliance Checklist'!K$4:K$153,MATCH(A30,'Compliance Checklist'!B$4:B$153,0))) | E30: =IF(A30="","",INDEX('Compliance Checklist'!L$4:L$153,MATCH(A30,'Compliance Checklist'!B$4:B$153,0))) | F30: =IF(A30="","",INDEX('Compliance Checklist'!M$4:M$153,MATCH(A30,'Compliance Checklist'!B$4:B$153,0)))
A31: =IFERROR(INDEX('Compliance Checklist'!B$4:B$153,MATCH(2,'Compliance Checklist'!S$4:S$153,0)),"") | B31: =IF(A31="","",VLOOKUP(A31,Roster!$A:$C,2,FALSE)&", "&VLOOKUP(A31,Roster!$A:$C,3,FALSE)) | C31: =IF(A31="","",INDEX('Compliance Checklist'!G$4:G$153,MATCH(A31,'Compliance Checklist'!B$4:B$153,0))) | D31: =IF(A31="","",INDEX('Compliance Checklist'!K$4:K$153,MATCH(A31,'Compliance Checklist'!B$4:B$153,0))) | E31: =IF(A31="","",INDEX('Compliance Checklist'!L$4:L$153,MATCH(A31,'Compliance Checklist'!B$4:B$153,0))) | F31: =IF(A31="","",INDEX('Compliance Checklist'!M$4:M$153,MATCH(A31,'Compliance Checklist'!B$4:B$153,0)))
A32: =IFERROR(INDEX('Compliance Checklist'!B$4:B$153,MATCH(3,'Compliance Checklist'!S$4:S$153,0)),"") | B32: =IF(A32="","",VLOOKUP(A32,Roster!$A:$C,2,FALSE)&", "&VLOOKUP(A32,Roster!$A:$C,3,FALSE)) | C32: =IF(A32="","",INDEX('Compliance Checklist'!G$4:G$153,MATCH(A32,'Compliance Checklist'!B$4:B$153,0))) | D32: =IF(A32="","",INDEX('Compliance Checklist'!K$4:K$153,MATCH(A32,'Compliance Checklist'!B$4:B$153,0))) | E32: =IF(A32="","",INDEX('Compliance Checklist'!L$4:L$153,MATCH(A32,'Compliance Checklist'!B$4:B$153,0))) | F32: =IF(A32="","",INDEX('Compliance Checklist'!M$4:M$153,MATCH(A32,'Compliance Checklist'!B$4:B$153,0)))
A33: =IFERROR(INDEX('Compliance Checklist'!B$4:B$153,MATCH(4,'Compliance Checklist'!S$4:S$153,0)),"") | B33: =IF(A33="","",VLOOKUP(A33,Roster!$A:$C,2,FALSE)&", "&VLOOKUP(A33,Roster!$A:$C,3,FALSE)) | C33: =IF(A33="","",INDEX('Compliance Checklist'!G$4:G$153,MATCH(A33,'Compliance Checklist'!B$4:B$153,0))) | D33: =IF(A33="","",INDEX('Compliance Checklist'!K$4:K$153,MATCH(A33,'Compliance Checklist'!B$4:B$153,0))) | E33: =IF(A33="","",INDEX('Compliance Checklist'!L$4:L$153,MATCH(A33,'Compliance Checklist'!B$4:B$153,0))) | F33: =IF(A33="","",INDEX('Compliance Checklist'!M$4:M$153,MATCH(A33,'Compliance Checklist'!B$4:B$153,0)))
A34: =IFERROR(INDEX('Compliance Checklist'!B$4:B$153,MATCH(5,'Compliance Checklist'!S$4:S$153,0)),"") | B34: =IF(A34="","",VLOOKUP(A34,Roster!$A:$C,2,FALSE)&", "&VLOOKUP(A34,Roster!$A:$C,3,FALSE)) | C34: =IF(A34="","",INDEX('Compliance Checklist'!G$4:G$153,MATCH(A34,'Compliance Checklist'!B$4:B$153,0))) | D34: =IF(A34="","",INDEX('Compliance Checklist'!K$4:K$153,MATCH(A34,'Compliance Checklist'!B$4:B$153,0))) | E34: =IF(A34="","",INDEX('Compliance Checklist'!L$4:L$153,MATCH(A34,'Compliance Checklist'!B$4:B$153,0))) | F34: =IF(A34="","",INDEX('Compliance Checklist'!M$4:M$153,MATCH(A34,'Compliance Checklist'!B$4:B$153,0)))
A35: =IFERROR(INDEX('Compliance Checklist'!B$4:B$153,MATCH(6,'Compliance Checklist'!S$4:S$153,0)),"") | B35: =IF(A35="","",VLOOKUP(A35,Roster!$A:$C,2,FALSE)&", "&VLOOKUP(A35,Roster!$A:$C,3,FALSE)) | C35: =IF(A35="","",INDEX('Compliance Checklist'!G$4:G$153,MATCH(A35,'Compliance Checklist'!B$4:B$153,0))) | D35: =IF(A35="","",INDEX('Compliance Checklist'!K$4:K$153,MATCH(A35,'Compliance Checklist'!B$4:B$153,0))) | E35: =IF(A35="","",INDEX('Compliance Checklist'!L$4:L$153,MATCH(A35,'Compliance Checklist'!B$4:B$153,0))) | F35: =IF(A35="","",INDEX('Compliance Checklist'!M$4:M$153,MATCH(A35,'Compliance Checklist'!B$4:B$153,0)))
A36: =IFERROR(INDEX('Compliance Checklist'!B$4:B$153,MATCH(7,'Compliance Checklist'!S$4:S$153,0)),"") | B36: =IF(A36="","",VLOOKUP(A36,Roster!$A:$C,2,FALSE)&", "&VLOOKUP(A36,Roster!$A:$C,3,FALSE)) | C36: =IF(A36="","",INDEX('Compliance Checklist'!G$4:G$153,MATCH(A36,'Compliance Checklist'!B$4:B$153,0))) | D36: =IF(A36="","",INDEX('Compliance Checklist'!K$4:K$153,MATCH(A36,'Compliance Checklist'!B$4:B$153,0))) | E36: =IF(A36="","",INDEX('Compliance Checklist'!L$4:L$153,MATCH(A36,'Compliance Checklist'!B$4:B$153,0))) | F36: =IF(A36="","",INDEX('Compliance Checklist'!M$4:M$153,MATCH(A36,'Compliance Checklist'!B$4:B$153,0)))
A37: =IFERROR(INDEX('Compliance Checklist'!B$4:B$153,MATCH(8,'Compliance Checklist'!S$4:S$153,0)),"") | B37: =IF(A37="","",VLOOKUP(A37,Roster!$A:$C,2,FALSE)&", "&VLOOKUP(A37,Roster!$A:$C,3,FALSE)) | C37: =IF(A37="","",INDEX('Compliance Checklist'!G$4:G$153,MATCH(A37,'Compliance Checklist'!B$4:B$153,0))) | D37: =IF(A37="","",INDEX('Compliance Checklist'!K$4:K$153,MATCH(A37,'Compliance Checklist'!B$4:B$153,0))) | E37: =IF(A37="","",INDEX('Compliance Checklist'!L$4:L$153,MATCH(A37,'Compliance Checklist'!B$4:B$153,0))) | F37: =IF(A37="","",INDEX('Compliance Checklist'!M$4:M$153,MATCH(A37,'Compliance Checklist'!B$4:B$153,0)))
A38: =IFERROR(INDEX('Compliance Checklist'!B$4:B$153,MATCH(9,'Compliance Checklist'!S$4:S$153,0)),"") | B38: =IF(A38="","",VLOOKUP(A38,Roster!$A:$C,2,FALSE)&", "&VLOOKUP(A38,Roster!$A:$C,3,FALSE)) | C38: =IF(A38="","",INDEX('Compliance Checklist'!G$4:G$153,MATCH(A38,'Compliance Checklist'!B$4:B$153,0))) | D38: =IF(A38="","",INDEX('Compliance Checklist'!K$4:K$153,MATCH(A38,'Compliance Checklist'!B$4:B$153,0))) | E38: =IF(A38="","",INDEX('Compliance Checklist'!L$4:L$153,MATCH(A38,'Compliance Checklist'!B$4:B$153,0))) | F38: =IF(A38="","",INDEX('Compliance Checklist'!M$4:M$153,MATCH(A38,'Compliance Checklist'!B$4:B$153,0)))
A39: =IFERROR(INDEX('Compliance Checklist'!B$4:B$153,MATCH(10,'Compliance Checklist'!S$4:S$153,0)),"") | B39: =IF(A39="","",VLOOKUP(A39,Roster!$A:$C,2,FALSE)&", "&VLOOKUP(A39,Roster!$A:$C,3,FALSE)) | C39: =IF(A39="","",INDEX('Compliance Checklist'!G$4:G$153,MATCH(A39,'Compliance Checklist'!B$4:B$153,0))) | D39: =IF(A39="","",INDEX('Compliance Checklist'!K$4:K$153,MATCH(A39,'Compliance Checklist'!B$4:B$153,0))) | E39: =IF(A39="","",INDEX('Compliance Checklist'!L$4:L$153,MATCH(A39,'Compliance Checklist'!B$4:B$153,0))) | F39: =IF(A39="","",INDEX('Compliance Checklist'!M$4:M$153,MATCH(A39,'Compliance Checklist'!B$4:B$153,0)))
A41: 📊 SNAPSHOT COUNTS
A42: Active Placements | B42: =COUNTIFS('DAEP Placements'!O$3:O$102,"",'DAEP Placements'!B$3:B$102,"<>") -> 3
A43: Expiring ≤ 5 Days | B43: =COUNTIFS('DAEP Placements'!J$3:J$102,">0",'DAEP Placements'!J$3:J$102,"<=5",'DAEP Placements'!O$3:O$102,"") -> 0
...

Sheet Reference
A1: REFERENCE — Texas DAEP Legal Framework & Definitions
A2: Clear Path Education Group, LLC | For organizational use only — not legal advice
A4: TEXAS EDUCATION CODE CHAPTER 37 — DAEP FRAMEWORK
A5: TEC Section | B5: Title | C5: Summary
A6: §37.001 | B6: Student Code of Conduct | C6: Districts must adopt a SCOC specifying conditions for DAEP and expulsion.
A7: §37.002 | B7: Removal by Teacher | C7: Teachers may remove a student for documented conduct that violates the SCOC.
A8: §37.004 | B8: Placement of Students with Disabilities | C8: SPED-specific rules; manifestation determination requirement applies.
A9: §37.005 | B9: Suspension | C9: Short-term removal (max 3 days in-school or out-of-school suspension).
A10: §37.006 | B10: Removal to DAEP — Mandatory | C10: Lists conduct requiring mandatory DAEP placement.
A11: §37.007 | B11: Expulsion from School — Mandatory | C11: Lists conduct requiring mandatory expulsion consideration.
A12: §37.008 | B12: DAEP Standards | C12: Required academic and behavioral components of a DAEP program.
A13: §37.009 | B13: Conference / Due Process | C13: Required conference before DAEP placement; parent notification required.
A14: §37.010 | B14: JJAEP | C14: Juvenile Justice Alternative Education Program standards and referral process.
A15: §37.011 | B15: Juvenile Justice Programs | C15: Coordination between school district and juvenile justice agencies.
A16: §37.013 | B16: Parental Notification | C16: Required notifications to parents/guardians during the disciplinary process.
... A18: §37.020 | B18: PEIMS Reporting | C18: Data reporting requirements for disciplinary actions to the state.
A20: MANDATORY vs. DISCRETIONARY DAEP REMOVAL
B21: MANDATORY DAEP (TEC §37.006) — Administrator has NO discretion; placement is required
B22: • Conduct punishable as a felony (on or off campus, school-related)
B23: • Assault causing bodily injury to a school employee
B24: • Controlled substance — delivery, sale, or possession (type-dependent)
B25: • Terroristic threat against a school official or student
B26: • Use or exhibition of a firearm (off campus, school-related)
B27: • Title 5 Penal Code felony committed off campus
B28: • Conduct on school property involving a registered sex offender
B30: DISCRETIONARY DAEP (TEC §37.006(a)) — Administrator MAY place; not required
B31: • Persistent misbehavior or repeated disruption
B32: • Bullying that encourages student to transfer out of district
B33: • Criminal mischief (Class B or higher)
... B37: • Any conduct designated by the district's Student Code of Conduct
A39: SPED & 504 COMPLIANCE REQUIREMENTS DURING DAEP PLACEMENT
A40: Requirement | B40: Trigger | C40: Deadline | D40: Legal Authority
A41: Manifestation Determination Review (MDR) | B41: Any DAEP placement of a SPED student | C41: Within 10 SCHOOL DAYS of placement decision | D41: 34 CFR §300.530; TEC §37.004
A42: FBA — Functional Behavioral Assessment | B42: Conduct determined to be manifestation; or no current FBA on file | C42: Must be initiated; completed during/after placement | D42: 34 CFR §300.530(d)(1)(ii)
A43: BIP — Behavior Intervention Plan | B43: Following FBA completion; conduct is manifestation of disability | C43: Developed based on FBA; before return to regular campus | D43: 34 CFR §300.530(d)(1)(ii)
A44: IEP Services Continuation | B44: All active IEP students placed in DAEP | C44: Services must continue during entire placement | D44: 34 CFR §300.530(d)(1)(i)
A45: Section 504 Meeting | B45: Any 504-eligible student facing DAEP placement | C45: Before or concurrent with placement | D45: 34 CFR §104.36
A46: Prior Written Notice (SPED) | B46: Before changing placement of any SPED student | C46: Before implementation of placement | D46: 34 CFR §300.503
A47: Parental Notification | B47: All DAEP placements | C47: As soon as practicable; before or day of placement | D47: TEC §37.009; §37.013
A48: Return-to-Campus ARD | B48: SPED student returning from DAEP | C48: Before student returns to home campus | D48: TEC §37.004 + local ARD policy
...

Sheet ↑ Upgrade to Waypoint
A1: ↑ UPGRADE TO WAYPOINT — Full DAEP Management Platform
A2: Clear Path Education Group, LLC
A4: You've outgrown the spreadsheet. That's a good thing.
A5: Waypoint does everything this tracker does — automatically, securely, and in compliance with Texas law.
A6: No formulas. No manual updates. No missed deadlines.
A8: WHAT WAYPOINT DOES THAT THIS TRACKER CANNOT
A9: Feature | B9: This Tracker | C9: Waypoint
A10: Student DAEP roster | B10: Manual entry per campus | C10: Automatic from student import or Laserfiche sync
A11: Placement countdown | B11: Calendar-day approximation | C11: School-day accurate with holiday calendar built in
A12: SPED compliance alerts | B12: Color-coded rows (manual) | C12: Automated alerts pushed to responsible staff
A13: Parent notification tracking | B13: Checkbox / notes field | C13: Logged with timestamp, method, and staff name
A14: PEIMS reporting | B14: Manual export / none | C14: One-click PEIMS-ready export
A15: Laserfiche integration | B15: Not available | C15: Direct sync — incidents import automatically, no re-entry
A16: Multi-campus visibility | B16: One file per campus | C16: District-wide dashboard across all campuses, real-time
A17: Role-based access control | B17: File sharing (no restrictions) | C17: Individual logins with role-based permissions
