Workbook

Sheet Cover
A1: ISS Engagement & Intervention Tracker — Texas Edition
A2: Clear Path Education Group, LLC · clearpathedgroup.com
A3: Built for Texas campus administrators, counselors, and behavior coordinators.
A4: ISS works when it changes behavior — not just removes students from class. This tracker makes every day of ISS count by logging interventions, measuring engagement, and requiring a structured re-entry process before students return.
A6: ▸ DISTRICT & CAMPUS INFORMATION
B7: District Name
B8: Campus Name
B9: Department / Team
B10: Coordinator
B11: School Year | C11: 2025–2026
B12: Prepared By
A14: ▸ HOW TO USE THIS TRACKER
B15: 1. Student Roster | C15: Add every student placed in ISS. Root cause, risk tier, SPED flags, and cumulative stats calculate automatically.
B16: 2. ISS Placements | C16: One row per placement. Offense tier, assigned days, intervention track, and 10-day SPED flag all tracked here.
B17: 3. Daily Activity Log | C17: Log every intervention session daily. Engagement level, completion, staff observations. This is the heart of the tracker.
B18: 4. Re-Entry Checklist | C18: 8 required steps before a student returns to class. All steps must be complete before the student leaves ISS.
B19: 5. Intervention Library | C19: Reference table: offense tier + root cause → recommended intervention track. No guesswork for staff.
B20: 6. Outcome Tracker | C20: Before/after incident counts per student. See which interventions actually reduce recidivism over time.
B21: 7. Dashboard | C21: Campus-wide summary. Active placements, re-entry readiness, intervention completion rates, recidivism flags.
B22: 8. 🔄 Re-Entry Board | C22: Print this tab every Monday. Shows all students returning within 7 days and their re-entry checklist status.
A24: ⚠ FOR ORGANIZATIONAL USE ONLY — Not legal advice. Consult district counsel for all placement and consequence decisions.
A26: 🚀 Ready to scale? Visit clearpathedgroup.com to upgrade to the full platform

Sheet Student Roster
A1: ISS Student Roster — Texas Edition
A2: ⚙ Auto-calculated fields are shaded gray and locked. Enter data in white cells only.
A3: Student ID | B3: Last Name | C3: First Name | D3: Grade | E3: Campus | F3: Counselor Assigned | G3: Primary Root Cause | H3: Secondary Root Cause | I3: SPED? | J3: 504? | K3: SPED Code | L3: ELL? | M3: At-Risk? | N3: ⚙ Total ISS Placements | O3: ⚙ Total ISS Days | P3: ⚙ Active Placement? | Q3: ⚙ Incidents This Year | R3: ⚙ Last Placement Date | S3: ⚙ Re-Entry Complete? | T3: Risk Tier | U3: Notes
N4: =COUNTIF('ISS Placements'!B:B,A4) -> 0 | O4: =SUMIF('ISS Placements'!B$4:B$203,A4,'ISS Placements'!L$4:L$203) -> 0 | P4: =IF(COUNTIFS('ISS Placements'!B:B,A4,'ISS Placements'!O:O,"")>0,"YES","No") -> No | Q4: =COUNTIF('ISS Placements'!B:B,A4) -> 0 | R4: =IF(COUNTIF('ISS Placements'!B:B,A4)>0,_xludf.MAXIFS('ISS Placements'!J:J,'ISS Placements'!B:B,A4),"") | S4: =IF(A4="","",IF(COUNTIFS('Re-Entry Checklist'!C:C,A4,'Re-Entry Checklist'!Y:Y,"✅ READY")>0,"Yes","No"))
N5: =COUNTIF('ISS Placements'!B:B,A5) -> 0 | O5: =SUMIF('ISS Placements'!B$4:B$203,A5,'ISS Placements'!L$4:L$203) -> 0 | P5: =IF(COUNTIFS('ISS Placements'!B:B,A5,'ISS Placements'!O:O,"")>0,"YES","No") -> No | Q5: =COUNTIF('ISS Placements'!B:B,A5) -> 0 | R5: =IF(COUNTIF('ISS Placements'!B:B,A5)>0,_xludf.MAXIFS('ISS Placements'!J:J,'ISS Placements'!B:B,A5),"") | S5: =IF(A5="","",IF(COUNTIFS('Re-Entry Checklist'!C:C,A5,'Re-Entry Checklist'!Y:Y,"✅ READY")>0,"Yes","No"))
N6: =COUNTIF('ISS Placements'!B:B,A6) -> 0 | O6: =SUMIF('ISS Placements'!B$4:B$203,A6,'ISS Placements'!L$4:L$203) -> 0 | P6: =IF(COUNTIFS('ISS Placements'!B:B,A6,'ISS Placements'!O:O,"")>0,"YES","No") -> No | Q6: =COUNTIF('ISS Placements'!B:B,A6) -> 0 | R6: =IF(COUNTIF('ISS Placements'!B:B,A6)>0,_xludf.MAXIFS('ISS Placements'!J:J,'ISS Placements'!B:B,A6),"") | S6: =IF(A6="","",IF(COUNTIFS('Re-Entry Checklist'!C:C,A6,'Re-Entry Checklist'!Y:Y,"✅ READY")>0,"Yes","No"))
N7: =COUNTIF('ISS Placements'!B:B,A7) -> 0 | O7: =SUMIF('ISS Placements'!B$4:B$203,A7,'ISS Placements'!L$4:L$203) -> 0 | P7: =IF(COUNTIFS('ISS Placements'!B:B,A7,'ISS Placements'!O:O,"")>0,"YES","No") -> No | Q7: =COUNTIF('ISS Placements'!B:B,A7) -> 0 | R7: =IF(COUNTIF('ISS Placements'!B:B,A7)>0,_xludf.MAXIFS('ISS Placements'!J:J,'ISS Placements'!B:B,A7),"") | S7: =IF(A7="","",IF(COUNTIFS('Re-Entry Checklist'!C:C,A7,'Re-Entry Checklist'!Y:Y,"✅ READY")>0,"Yes","No"))
N8: =COUNTIF('ISS Placements'!B:B,A8) -> 0 | O8: =SUMIF('ISS Placements'!B$4:B$203,A8,'ISS Placements'!L$4:L$203) -> 0 | P8: =IF(COUNTIFS('ISS Placements'!B:B,A8,'ISS Placements'!O:O,"")>0,"YES","No") -> No | Q8: =COUNTIF('ISS Placements'!B:B,A8) -> 0 | R8: =IF(COUNTIF('ISS Placements'!B:B,A8)>0,_xludf.MAXIFS('ISS Placements'!J:J,'ISS Placements'!B:B,A8),"") | S8: =IF(A8="","",IF(COUNTIFS('Re-Entry Checklist'!C:C,A8,'Re-Entry Checklist'!Y:Y,"✅ READY")>0,"Yes","No"))
N9: =COUNTIF('ISS Placements'!B:B,A9) -> 0 | O9: =SUMIF('ISS Placements'!B$4:B$203,A9,'ISS Placements'!L$4:L$203) -> 0 | P9: =IF(COUNTIFS('ISS Placements'!B:B,A9,'ISS Placements'!O:O,"")>0,"YES","No") -> No | Q9: =COUNTIF('ISS Placements'!B:B,A9) -> 0 | R9: =IF(COUNTIF('ISS Placements'!B:B,A9)>0,_xludf.MAXIFS('ISS Placements'!J:J,'ISS Placements'!B:B,A9),"") | S9: =IF(A9="","",IF(COUNTIFS('Re-Entry Checklist'!C:C,A9,'Re-Entry Checklist'!Y:Y,"✅ READY")>0,"Yes","No"))
N10: =COUNTIF('ISS Placements'!B:B,A10) -> 0 | O10: =SUMIF('ISS Placements'!B$4:B$203,A10,'ISS Placements'!L$4:L$203) -> 0 | P10: =IF(COUNTIFS('ISS Placements'!B:B,A10,'ISS Placements'!O:O,"")>0,"YES","No") -> No | Q10: =COUNTIF('ISS Placements'!B:B,A10) -> 0 | R10: =IF(COUNTIF('ISS Placements'!B:B,A10)>0,_xludf.MAXIFS('ISS Placements'!J:J,'ISS Placements'!B:B,A10),"") | S10: =IF(A10="","",IF(COUNTIFS('Re-Entry Checklist'!C:C,A10,'Re-Entry Checklist'!Y:Y,"✅ READY")>0,"Yes","No"))
N11: =COUNTIF('ISS Placements'!B:B,A11) -> 0 | O11: =SUMIF('ISS Placements'!B$4:B$203,A11,'ISS Placements'!L$4:L$203) -> 0 | P11: =IF(COUNTIFS('ISS Placements'!B:B,A11,'ISS Placements'!O:O,"")>0,"YES","No") -> No | Q11: =COUNTIF('ISS Placements'!B:B,A11) -> 0 | R11: =IF(COUNTIF('ISS Placements'!B:B,A11)>0,_xludf.MAXIFS('ISS Placements'!J:J,'ISS Placements'!B:B,A11),"") | S11: =IF(A11="","",IF(COUNTIFS('Re-Entry Checklist'!C:C,A11,'Re-Entry Checklist'!Y:Y,"✅ READY")>0,"Yes","No"))
N12: =COUNTIF('ISS Placements'!B:B,A12) -> 0 | O12: =SUMIF('ISS Placements'!B$4:B$203,A12,'ISS Placements'!L$4:L$203) -> 0 | P12: =IF(COUNTIFS('ISS Placements'!B:B,A12,'ISS Placements'!O:O,"")>0,"YES","No") -> No | Q12: =COUNTIF('ISS Placements'!B:B,A12) -> 0 | R12: =IF(COUNTIF('ISS Placements'!B:B,A12)>0,_xludf.MAXIFS('ISS Placements'!J:J,'ISS Placements'!B:B,A12),"") | S12: =IF(A12="","",IF(COUNTIFS('Re-Entry Checklist'!C:C,A12,'Re-Entry Checklist'!Y:Y,"✅ READY")>0,"Yes","No"))
N13: =COUNTIF('ISS Placements'!B:B,A13) -> 0 | O13: =SUMIF('ISS Placements'!B$4:B$203,A13,'ISS Placements'!L$4:L$203) -> 0 | P13: =IF(COUNTIFS('ISS Placements'!B:B,A13,'ISS Placements'!O:O,"")>0,"YES","No") -> No | Q13: =COUNTIF('ISS Placements'!B:B,A13) -> 0 | R13: =IF(COUNTIF('ISS Placements'!B:B,A13)>0,_xludf.MAXIFS('ISS Placements'!J:J,'ISS Placements'!B:B,A13),"") | S13: =IF(A13="","",IF(COUNTIFS('Re-Entry Checklist'!C:C,A13,'Re-Entry Checklist'!Y:Y,"✅ READY")>0,"Yes","No"))
N14: =COUNTIF('ISS Placements'!B:B,A14) -> 0 | O14: =SUMIF('ISS Placements'!B$4:B$203,A14,'ISS Placements'!L$4:L$203) -> 0 | P14: =IF(COUNTIFS('ISS Placements'!B:B,A14,'ISS Placements'!O:O,"")>0,"YES","No") -> No | Q14: =COUNTIF('ISS Placements'!B:B,A14) -> 0 | R14: =IF(COUNTIF('ISS Placements'!B:B,A14)>0,_xludf.MAXIFS('ISS Placements'!J:J,'ISS Placements'!B:B,A14),"") | S14: =IF(A14="","",IF(COUNTIFS('Re-Entry Checklist'!C:C,A14,'Re-Entry Checklist'!Y:Y,"✅ READY")>0,"Yes","No"))
N15: =COUNTIF('ISS Placements'!B:B,A15) -> 0 | O15: =SUMIF('ISS Placements'!B$4:B$203,A15,'ISS Placements'!L$4:L$203) -> 0 | P15: =IF(COUNTIFS('ISS Placements'!B:B,A15,'ISS Placements'!O:O,"")>0,"YES","No") -> No | Q15: =COUNTIF('ISS Placements'!B:B,A15) -> 0 | R15: =IF(COUNTIF('ISS Placements'!B:B,A15)>0,_xludf.MAXIFS('ISS Placements'!J:J,'ISS Placements'!B:B,A15),"") | S15: =IF(A15="","",IF(COUNTIFS('Re-Entry Checklist'!C:C,A15,'Re-Entry Checklist'!Y:Y,"✅ READY")>0,"Yes","No"))
... N103: =COUNTIF('ISS Placements'!B:B,A103) -> 0 | O103: =SUMIF('ISS Placements'!B$4:B$203,A103,'ISS Placements'!L$4:L$203) -> 0 | P103: =IF(COUNTIFS('ISS Placements'!B:B,A103,'ISS Placements'!O:O,"")>0,"YES","No") -> No | Q103: =COUNTIF('ISS Placements'!B:B,A103) -> 0 | R103: =IF(COUNTIF('ISS Placements'!B:B,A103)>0,_xludf.MAXIFS('ISS Placements'!J:J,'ISS Placements'!B:B,A103),"") | S103: =IF(A103="","",IF(COUNTIFS('Re-Entry Checklist'!C:C,A103,'Re-Entry Checklist'!Y:Y,"✅ READY")>0,"Yes","No"))
A104: 🚀 Upgrade to the full platform · clearpathedgroup.com · Clear Path Education Group, LLC

Sheet ISS Placements
A1: ISS Placements — Texas Edition
A2: ⚠ Texas law counts SCHOOL days for suspension limits. Assigned days here are CALENDAR days — adjust accordingly.
A3: Placement ID | B3: Student ID | C3: ⚙ Last Name | D3: ⚙ First Name | E3: ⚙ Grade | F3: Campus | G3: Offense Description | H3: TEC Reference | I3: Offense Tier | J3: Placement Start | K3: Assigned Days | L3: ⚙ Days in ISS | M3: ⚙ Days Remaining | N3: ⚙ Projected End | O3: Actual End Date | P3: Exit Reason | Q3: Intervention Track | R3: SPED? | S3: ⚙ 10-Day SPED Flag | T3: Re-Entry Complete? | U3: Compliance Status | V3: Notes | W3: ⚙ Board Index (do not edit)
C4: =IF(B4="","",VLOOKUP(B4,'Student Roster'!A:C,2,FALSE)) | D4: =IF(B4="","",VLOOKUP(B4,'Student Roster'!A:C,3,FALSE)) | E4: =IF(B4="","",VLOOKUP(B4,'Student Roster'!A:D,4,FALSE)) | L4: =IF(J4="","",IF(O4="",TODAY()-J4,O4-J4)) | M4: =IF(J4="","",MAX(0,K4-L4)) | N4: =IF(J4="","",J4+K4) | S4: =IF(AND(R4="Yes",L4>=8),"⚠ APPROACHING 10-DAY","OK") -> OK | U4: =IF(J4="","",IF(AND(T4="Yes",L4<=K4),"Complete",IF(L4>K4,"⚠ OVERDUE","In Progress"))) | W4: =IF(AND(B4<>"",N4<>"",O4="",N4>=TODAY(),N4<=TODAY()+7),COUNTIFS(B$4:B4,"<>",N$4:N4,">="&TODAY(),N$4:N4,"<="&TODAY()+7,O$4:O4,""),"")
C5: =IF(B5="","",VLOOKUP(B5,'Student Roster'!A:C,2,FALSE)) | D5: =IF(B5="","",VLOOKUP(B5,'Student Roster'!A:C,3,FALSE)) | E5: =IF(B5="","",VLOOKUP(B5,'Student Roster'!A:D,4,FALSE)) | L5: =IF(J5="","",IF(O5="",TODAY()-J5,O5-J5)) | M5: =IF(J5="","",MAX(0,K5-L5)) | N5: =IF(J5="","",J5+K5) | S5: =IF(AND(R5="Yes",L5>=8),"⚠ APPROACHING 10-DAY","OK") -> OK | U5: =IF(J5="","",IF(AND(T5="Yes",L5<=K5),"Complete",IF(L5>K5,"⚠ OVERDUE","In Progress"))) | W5: =IF(AND(B5<>"",N5<>"",O5="",N5>=TODAY(),N5<=TODAY()+7),COUNTIFS(B$4:B5,"<>",N$4:N5,">="&TODAY(),N$4:N5,"<="&TODAY()+7,O$4:O5,""),"")
C6: =IF(B6="","",VLOOKUP(B6,'Student Roster'!A:C,2,FALSE)) | D6: =IF(B6="","",VLOOKUP(B6,'Student Roster'!A:C,3,FALSE)) | E6: =IF(B6="","",VLOOKUP(B6,'Student Roster'!A:D,4,FALSE)) | L6: =IF(J6="","",IF(O6="",TODAY()-J6,O6-J6)) | M6: =IF(J6="","",MAX(0,K6-L6)) | N6: =IF(J6="","",J6+K6) | S6: =IF(AND(R6="Yes",L6>=8),"⚠ APPROACHING 10-DAY","OK") -> OK | U6: =IF(J6="","",IF(AND(T6="Yes",L6<=K6),"Complete",IF(L6>K6,"⚠ OVERDUE","In Progress"))) | W6: =IF(AND(B6<>"",N6<>"",O6="",N6>=TODAY(),N6<=TODAY()+7),COUNTIFS(B$4:B6,"<>",N$4:N6,">="&TODAY(),N$4:N6,"<="&TODAY()+7,O$4:O6,""),"")
C7: =IF(B7="","",VLOOKUP(B7,'Student Roster'!A:C,2,FALSE)) | D7: =IF(B7="","",VLOOKUP(B7,'Student Roster'!A:C,3,FALSE)) | E7: =IF(B7="","",VLOOKUP(B7,'Student Roster'!A:D,4,FALSE)) | L7: =IF(J7="","",IF(O7="",TODAY()-J7,O7-J7)) | M7: =IF(J7="","",MAX(0,K7-L7)) | N7: =IF(J7="","",J7+K7) | S7: =IF(AND(R7="Yes",L7>=8),"⚠ APPROACHING 10-DAY","OK") -> OK | U7: =IF(J7="","",IF(AND(T7="Yes",L7<=K7),"Complete",IF(L7>K7,"⚠ OVERDUE","In Progress"))) | W7: =IF(AND(B7<>"",N7<>"",O7="",N7>=TODAY(),N7<=TODAY()+7),COUNTIFS(B$4:B7,"<>",N$4:N7,">="&TODAY(),N$4:N7,"<="&TODAY()+7,O$4:O7,""),"")
C8: =IF(B8="","",VLOOKUP(B8,'Student Roster'!A:C,2,FALSE)) | D8: =IF(B8="","",VLOOKUP(B8,'Student Roster'!A:C,3,FALSE)) | E8: =IF(B8="","",VLOOKUP(B8,'Student Roster'!A:D,4,FALSE)) | L8: =IF(J8="","",IF(O8="",TODAY()-J8,O8-J8)) | M8: =IF(J8="","",MAX(0,K8-L8)) | N8: =IF(J8="","",J8+K8) | S8: =IF(AND(R8="Yes",L8>=8),"⚠ APPROACHING 10-DAY","OK") -> OK | U8: =IF(J8="","",IF(AND(T8="Yes",L8<=K8),"Complete",IF(L8>K8,"⚠ OVERDUE","In Progress"))) | W8: =IF(AND(B8<>"",N8<>"",O8="",N8>=TODAY(),N8<=TODAY()+7),COUNTIFS(B$4:B8,"<>",N$4:N8,">="&TODAY(),N$4:N8,"<="&TODAY()+7,O$4:O8,""),"")
C9: =IF(B9="","",VLOOKUP(B9,'Student Roster'!A:C,2,FALSE)) | D9: =IF(B9="","",VLOOKUP(B9,'Student Roster'!A:C,3,FALSE)) | E9: =IF(B9="","",VLOOKUP(B9,'Student Roster'!A:D,4,FALSE)) | L9: =IF(J9="","",IF(O9="",TODAY()-J9,O9-J9)) | M9: =IF(J9="","",MAX(0,K9-L9)) | N9: =IF(J9="","",J9+K9) | S9: =IF(AND(R9="Yes",L9>=8),"⚠ APPROACHING 10-DAY","OK") -> OK | U9: =IF(J9="","",IF(AND(T9="Yes",L9<=K9),"Complete",IF(L9>K9,"⚠ OVERDUE","In Progress"))) | W9: =IF(AND(B9<>"",N9<>"",O9="",N9>=TODAY(),N9<=TODAY()+7),COUNTIFS(B$4:B9,"<>",N$4:N9,">="&TODAY(),N$4:N9,"<="&TODAY()+7,O$4:O9,""),"")
C10: =IF(B10="","",VLOOKUP(B10,'Student Roster'!A:C,2,FALSE)) | D10: =IF(B10="","",VLOOKUP(B10,'Student Roster'!A:C,3,FALSE)) | E10: =IF(B10="","",VLOOKUP(B10,'Student Roster'!A:D,4,FALSE)) | L10: =IF(J10="","",IF(O10="",TODAY()-J10,O10-J10)) | M10: =IF(J10="","",MAX(0,K10-L10)) | N10: =IF(J10="","",J10+K10) | S10: =IF(AND(R10="Yes",L10>=8),"⚠ APPROACHING 10-DAY","OK") -> OK | U10: =IF(J10="","",IF(AND(T10="Yes",L10<=K10),"Complete",IF(L10>K10,"⚠ OVERDUE","In Progress"))) | W10: =IF(AND(B10<>"",N10<>"",O10="",N10>=TODAY(),N10<=TODAY()+7),COUNTIFS(B$4:B10,"<>",N$4:N10,">="&TODAY(),N$4:N10,"<="&TODAY()+7,O$4:O10,""),"")
C11: =IF(B11="","",VLOOKUP(B11,'Student Roster'!A:C,2,FALSE)) | D11: =IF(B11="","",VLOOKUP(B11,'Student Roster'!A:C,3,FALSE)) | E11: =IF(B11="","",VLOOKUP(B11,'Student Roster'!A:D,4,FALSE)) | L11: =IF(J11="","",IF(O11="",TODAY()-J11,O11-J11)) | M11: =IF(J11="","",MAX(0,K11-L11)) | N11: =IF(J11="","",J11+K11) | S11: =IF(AND(R11="Yes",L11>=8),"⚠ APPROACHING 10-DAY","OK") -> OK | U11: =IF(J11="","",IF(AND(T11="Yes",L11<=K11),"Complete",IF(L11>K11,"⚠ OVERDUE","In Progress"))) | W11: =IF(AND(B11<>"",N11<>"",O11="",N11>=TODAY(),N11<=TODAY()+7),COUNTIFS(B$4:B11,"<>",N$4:N11,">="&TODAY(),N$4:N11,"<="&TODAY()+7,O$4:O11,""),"")
C12: =IF(B12="","",VLOOKUP(B12,'Student Roster'!A:C,2,FALSE)) | D12: =IF(B12="","",VLOOKUP(B12,'Student Roster'!A:C,3,FALSE)) | E12: =IF(B12="","",VLOOKUP(B12,'Student Roster'!A:D,4,FALSE)) | L12: =IF(J12="","",IF(O12="",TODAY()-J12,O12-J12)) | M12: =IF(J12="","",MAX(0,K12-L12)) | N12: =IF(J12="","",J12+K12) | S12: =IF(AND(R12="Yes",L12>=8),"⚠ APPROACHING 10-DAY","OK") -> OK | U12: =IF(J12="","",IF(AND(T12="Yes",L12<=K12),"Complete",IF(L12>K12,"⚠ OVERDUE","In Progress"))) | W12: =IF(AND(B12<>"",N12<>"",O12="",N12>=TODAY(),N12<=TODAY()+7),COUNTIFS(B$4:B12,"<>",N$4:N12,">="&TODAY(),N$4:N12,"<="&TODAY()+7,O$4:O12,""),"")
C13: =IF(B13="","",VLOOKUP(B13,'Student Roster'!A:C,2,FALSE)) | D13: =IF(B13="","",VLOOKUP(B13,'Student Roster'!A:C,3,FALSE)) | E13: =IF(B13="","",VLOOKUP(B13,'Student Roster'!A:D,4,FALSE)) | L13: =IF(J13="","",IF(O13="",TODAY()-J13,O13-J13)) | M13: =IF(J13="","",MAX(0,K13-L13)) | N13: =IF(J13="","",J13+K13) | S13: =IF(AND(R13="Yes",L13>=8),"⚠ APPROACHING 10-DAY","OK") -> OK | U13: =IF(J13="","",IF(AND(T13="Yes",L13<=K13),"Complete",IF(L13>K13,"⚠ OVERDUE","In Progress"))) | W13: =IF(AND(B13<>"",N13<>"",O13="",N13>=TODAY(),N13<=TODAY()+7),COUNTIFS(B$4:B13,"<>",N$4:N13,">="&TODAY(),N$4:N13,"<="&TODAY()+7,O$4:O13,""),"")
C14: =IF(B14="","",VLOOKUP(B14,'Student Roster'!A:C,2,FALSE)) | D14: =IF(B14="","",VLOOKUP(B14,'Student Roster'!A:C,3,FALSE)) | E14: =IF(B14="","",VLOOKUP(B14,'Student Roster'!A:D,4,FALSE)) | L14: =IF(J14="","",IF(O14="",TODAY()-J14,O14-J14)) | M14: =IF(J14="","",MAX(0,K14-L14)) | N14: =IF(J14="","",J14+K14) | S14: =IF(AND(R14="Yes",L14>=8),"⚠ APPROACHING 10-DAY","OK") -> OK | U14: =IF(J14="","",IF(AND(T14="Yes",L14<=K14),"Complete",IF(L14>K14,"⚠ OVERDUE","In Progress"))) | W14: =IF(AND(B14<>"",N14<>"",O14="",N14>=TODAY(),N14<=TODAY()+7),COUNTIFS(B$4:B14,"<>",N$4:N14,">="&TODAY(),N$4:N14,"<="&TODAY()+7,O$4:O14,""),"")
C15: =IF(B15="","",VLOOKUP(B15,'Student Roster'!A:C,2,FALSE)) | D15: =IF(B15="","",VLOOKUP(B15,'Student Roster'!A:C,3,FALSE)) | E15: =IF(B15="","",VLOOKUP(B15,'Student Roster'!A:D,4,FALSE)) | L15: =IF(J15="","",IF(O15="",TODAY()-J15,O15-J15)) | M15: =IF(J15="","",MAX(0,K15-L15)) | N15: =IF(J15="","",J15+K15) | S15: =IF(AND(R15="Yes",L15>=8),"⚠ APPROACHING 10-DAY","OK") -> OK | U15: =IF(J15="","",IF(AND(T15="Yes",L15<=K15),"Complete",IF(L15>K15,"⚠ OVERDUE","In Progress"))) | W15: =IF(AND(B15<>"",N15<>"",O15="",N15>=TODAY(),N15<=TODAY()+7),COUNTIFS(B$4:B15,"<>",N$4:N15,">="&TODAY(),N$4:N15,"<="&TODAY()+7,O$4:O15,""),"")
... C203: =IF(B203="","",VLOOKUP(B203,'Student Roster'!A:C,2,FALSE)) | D203: =IF(B203="","",VLOOKUP(B203,'Student Roster'!A:C,3,FALSE)) | E203: =IF(B203="","",VLOOKUP(B203,'Student Roster'!A:D,4,FALSE)) | L203: =IF(J203="","",IF(O203="",TODAY()-J203,O203-J203)) | M203: =IF(J203="","",MAX(0,K203-L203)) | N203: =IF(J203="","",J203+K203) | S203: =IF(AND(R203="Yes",L203>=8),"⚠ APPROACHING 10-DAY","OK") -> OK | U203: =IF(J203="","",IF(AND(T203="Yes",L203<=K203),"Complete",IF(L203>K203,"⚠ OVERDUE","In Progress"))) | W203: =IF(AND(B203<>"",N203<>"",O203="",N203>=TODAY(),N203<=TODAY()+7),COUNTIFS(B$4:B203,"<>",N$4:N203,">="&TODAY(),N$4:N203,"<="&TODAY()+7,O$4:O203,""),"")
A204: 🚀 Upgrade to the full platform · clearpathedgroup.com · Clear Path Education Group, LLC

Sheet Daily Activity Log
A1: Daily Activity Log — ISS Intervention Tracker
A2: Log EVERY intervention session. This data drives the Outcome Tracker — the more you log, the more you can measure.
A3: Log ID | B3: Placement ID | C3: Student ID | D3: ⚙ Last Name | E3: ⚙ First Name | F3: Log Date | G3: Day # of Placement | H3: Intervention Type | I3: Intervention Name | J3: Duration (mins) | K3: Completion Status | L3: Staff Member | M3: Student Engagement | N3: Behavior During Session | O3: Key Observation / Notes | P3: Follow-Up Needed? | Q3: Follow-Up Notes
D4: =IF(C4="","",VLOOKUP(C4,'Student Roster'!A:C,2,FALSE)) | E4: =IF(C4="","",VLOOKUP(C4,'Student Roster'!A:C,3,FALSE))
D5: =IF(C5="","",VLOOKUP(C5,'Student Roster'!A:C,2,FALSE)) | E5: =IF(C5="","",VLOOKUP(C5,'Student Roster'!A:C,3,FALSE))
D6: =IF(C6="","",VLOOKUP(C6,'Student Roster'!A:C,2,FALSE)) | E6: =IF(C6="","",VLOOKUP(C6,'Student Roster'!A:C,3,FALSE))
D7: =IF(C7="","",VLOOKUP(C7,'Student Roster'!A:C,2,FALSE)) | E7: =IF(C7="","",VLOOKUP(C7,'Student Roster'!A:C,3,FALSE))
D8: =IF(C8="","",VLOOKUP(C8,'Student Roster'!A:C,2,FALSE)) | E8: =IF(C8="","",VLOOKUP(C8,'Student Roster'!A:C,3,FALSE))
D9: =IF(C9="","",VLOOKUP(C9,'Student Roster'!A:C,2,FALSE)) | E9: =IF(C9="","",VLOOKUP(C9,'Student Roster'!A:C,3,FALSE))
D10: =IF(C10="","",VLOOKUP(C10,'Student Roster'!A:C,2,FALSE)) | E10: =IF(C10="","",VLOOKUP(C10,'Student Roster'!A:C,3,FALSE))
D11: =IF(C11="","",VLOOKUP(C11,'Student Roster'!A:C,2,FALSE)) | E11: =IF(C11="","",VLOOKUP(C11,'Student Roster'!A:C,3,FALSE))
D12: =IF(C12="","",VLOOKUP(C12,'Student Roster'!A:C,2,FALSE)) | E12: =IF(C12="","",VLOOKUP(C12,'Student Roster'!A:C,3,FALSE))
D13: =IF(C13="","",VLOOKUP(C13,'Student Roster'!A:C,2,FALSE)) | E13: =IF(C13="","",VLOOKUP(C13,'Student Roster'!A:C,3,FALSE))
D14: =IF(C14="","",VLOOKUP(C14,'Student Roster'!A:C,2,FALSE)) | E14: =IF(C14="","",VLOOKUP(C14,'Student Roster'!A:C,3,FALSE))
D15: =IF(C15="","",VLOOKUP(C15,'Student Roster'!A:C,2,FALSE)) | E15: =IF(C15="","",VLOOKUP(C15,'Student Roster'!A:C,3,FALSE))
... D503: =IF(C503="","",VLOOKUP(C503,'Student Roster'!A:C,2,FALSE)) | E503: =IF(C503="","",VLOOKUP(C503,'Student Roster'!A:C,3,FALSE))
A504: 🚀 Upgrade to the full platform · clearpathedgroup.com · Clear Path Education Group, LLC

Sheet Re-Entry Checklist
A1: Re-Entry Checklist — ISS Intervention Tracker
A2: ALL 8 steps must be complete before a student returns to class. ⚙ 'Ready to Return?' auto-calculates when all steps are marked Yes.
A3: Checklist ID | B3: Placement ID | C3: Student ID | D3: ⚙ Last Name | E3: ⚙ First Name | F3: ⚙ Return Date | G3: Step 1: Written Reflection? | H3: Step 1 Date | I3: Step 2: Restorative Conversation? | J3: Step 2 Date | K3: Step 3: Parent Summary Sent? | L3: Step 3 Date | M3: Step 4: Counselor Sign-Off? | N3: Step 4 Date | O3: Step 5: Behavior Plan Updated? | P3: Step 5 Date | Q3: Step 6: Teacher Notified? | R3: Step 6 Date | S3: Step 7: Academic Plan in Place? | T3: Step 7 Date | U3: Step 8: CBC Final Approval? | V3: Step 8 Date | W3: ⚙ Steps Complete | X3: ⚙ Steps Remaining | Y3: ⚙ Ready to Return? | Z3: Re-Entry Notes
D4: =IF(C4="","",VLOOKUP(C4,'Student Roster'!A:C,2,FALSE)) | E4: =IF(C4="","",VLOOKUP(C4,'Student Roster'!A:C,3,FALSE)) | F4: =IF(B4="","",VLOOKUP(B4,'ISS Placements'!A:N,14,FALSE)) | W4: =COUNTIF(G4:V4,"Yes") -> 0 | X4: =8-W4 -> 8 | Y4: =IF(C4="","",IF(W4>=8,"✅ READY","❌ NOT READY"))
D5: =IF(C5="","",VLOOKUP(C5,'Student Roster'!A:C,2,FALSE)) | E5: =IF(C5="","",VLOOKUP(C5,'Student Roster'!A:C,3,FALSE)) | F5: =IF(B5="","",VLOOKUP(B5,'ISS Placements'!A:N,14,FALSE)) | W5: =COUNTIF(G5:V5,"Yes") -> 0 | X5: =8-W5 -> 8 | Y5: =IF(C5="","",IF(W5>=8,"✅ READY","❌ NOT READY"))
D6: =IF(C6="","",VLOOKUP(C6,'Student Roster'!A:C,2,FALSE)) | E6: =IF(C6="","",VLOOKUP(C6,'Student Roster'!A:C,3,FALSE)) | F6: =IF(B6="","",VLOOKUP(B6,'ISS Placements'!A:N,14,FALSE)) | W6: =COUNTIF(G6:V6,"Yes") -> 0 | X6: =8-W6 -> 8 | Y6: =IF(C6="","",IF(W6>=8,"✅ READY","❌ NOT READY"))
D7: =IF(C7="","",VLOOKUP(C7,'Student Roster'!A:C,2,FALSE)) | E7: =IF(C7="","",VLOOKUP(C7,'Student Roster'!A:C,3,FALSE)) | F7: =IF(B7="","",VLOOKUP(B7,'ISS Placements'!A:N,14,FALSE)) | W7: =COUNTIF(G7:V7,"Yes") -> 0 | X7: =8-W7 -> 8 | Y7: =IF(C7="","",IF(W7>=8,"✅ READY","❌ NOT READY"))
D8: =IF(C8="","",VLOOKUP(C8,'Student Roster'!A:C,2,FALSE)) | E8: =IF(C8="","",VLOOKUP(C8,'Student Roster'!A:C,3,FALSE)) | F8: =IF(B8="","",VLOOKUP(B8,'ISS Placements'!A:N,14,FALSE)) | W8: =COUNTIF(G8:V8,"Yes") -> 0 | X8: =8-W8 -> 8 | Y8: =IF(C8="","",IF(W8>=8,"✅ READY","❌ NOT READY"))
D9: =IF(C9="","",VLOOKUP(C9,'Student Roster'!A:C,2,FALSE)) | E9: =IF(C9="","",VLOOKUP(C9,'Student Roster'!A:C,3,FALSE)) | F9: =IF(B9="","",VLOOKUP(B9,'ISS Placements'!A:N,14,FALSE)) | W9: =COUNTIF(G9:V9,"Yes") -> 0 | X9: =8-W9 -> 8 | Y9: =IF(C9="","",IF(W9>=8,"✅ READY","❌ NOT READY"))
D10: =IF(C10="","",VLOOKUP(C10,'Student Roster'!A:C,2,FALSE)) | E10: =IF(C10="","",VLOOKUP(C10,'Student Roster'!A:C,3,FALSE)) | F10: =IF(B10="","",VLOOKUP(B10,'ISS Placements'!A:N,14,FALSE)) | W10: =COUNTIF(G10:V10,"Yes") -> 0 | X10: =8-W10 -> 8 | Y10: =IF(C10="","",IF(W10>=8,"✅ READY","❌ NOT READY"))
D11: =IF(C11="","",VLOOKUP(C11,'Student Roster'!A:C,2,FALSE)) | E11: =IF(C11="","",VLOOKUP(C11,'Student Roster'!A:C,3,FALSE)) | F11: =IF(B11="","",VLOOKUP(B11,'ISS Placements'!A:N,14,FALSE)) | W11: =COUNTIF(G11:V11,"Yes") -> 0 | X11: =8-W11 -> 8 | Y11: =IF(C11="","",IF(W11>=8,"✅ READY","❌ NOT READY"))
D12: =IF(C12="","",VLOOKUP(C12,'Student Roster'!A:C,2,FALSE)) | E12: =IF(C12="","",VLOOKUP(C12,'Student Roster'!A:C,3,FALSE)) | F12: =IF(B12="","",VLOOKUP(B12,'ISS Placements'!A:N,14,FALSE)) | W12: =COUNTIF(G12:V12,"Yes") -> 0 | X12: =8-W12 -> 8 | Y12: =IF(C12="","",IF(W12>=8,"✅ READY","❌ NOT READY"))
D13: =IF(C13="","",VLOOKUP(C13,'Student Roster'!A:C,2,FALSE)) | E13: =IF(C13="","",VLOOKUP(C13,'Student Roster'!A:C,3,FALSE)) | F13: =IF(B13="","",VLOOKUP(B13,'ISS Placements'!A:N,14,FALSE)) | W13: =COUNTIF(G13:V13,"Yes") -> 0 | X13: =8-W13 -> 8 | Y13: =IF(C13="","",IF(W13>=8,"✅ READY","❌ NOT READY"))
D14: =IF(C14="","",VLOOKUP(C14,'Student Roster'!A:C,2,FALSE)) | E14: =IF(C14="","",VLOOKUP(C14,'Student Roster'!A:C,3,FALSE)) | F14: =IF(B14="","",VLOOKUP(B14,'ISS Placements'!A:N,14,FALSE)) | W14: =COUNTIF(G14:V14,"Yes") -> 0 | X14: =8-W14 -> 8 | Y14: =IF(C14="","",IF(W14>=8,"✅ READY","❌ NOT READY"))
D15: =IF(C15="","",VLOOKUP(C15,'Student Roster'!A:C,2,FALSE)) | E15: =IF(C15="","",VLOOKUP(C15,'Student Roster'!A:C,3,FALSE)) | F15: =IF(B15="","",VLOOKUP(B15,'ISS Placements'!A:N,14,FALSE)) | W15: =COUNTIF(G15:V15,"Yes") -> 0 | X15: =8-W15 -> 8 | Y15: =IF(C15="","",IF(W15>=8,"✅ READY","❌ NOT READY"))
... D153: =IF(C153="","",VLOOKUP(C153,'Student Roster'!A:C,2,FALSE)) | E153: =IF(C153="","",VLOOKUP(C153,'Student Roster'!A:C,3,FALSE)) | F153: =IF(B153="","",VLOOKUP(B153,'ISS Placements'!A:N,14,FALSE)) | W153: =COUNTIF(G153:V153,"Yes") -> 0 | X153: =8-W153 -> 8 | Y153: =IF(C153="","",IF(W153>=8,"✅ READY","❌ NOT READY"))
A154: 🚀 Upgrade to the full platform · clearpathedgroup.com · Clear Path Education Group, LLC

Sheet Intervention Library
A1: Intervention Library — Tier-Matched Tracks by Root Cause & Offense Tier
A2: Use this table to match the right intervention to the right student. Assign the track in the ISS Placements tab.
A3: Track | B3: Track Name | C3: Best For (Root Cause) | D3: Best For (Offense Tier) | E3: Duration | F3: Facilitator | G3: Description | H3: Research Basis
A4: Track A | B4: Reflection & Journaling | C4: Emotional Dysregulation, Impulsivity / ADHD, Trauma Response | D4: Tier 1 — Minor, Tier 2 — Moderate | E4: 30–45 min/day | F4: Counselor or ISS Monitor | G4: Student completes structured daily journal with prompts: What happened? How did I feel? Who was affected? What would I do differently? What support do I need? Prompts escalate in depth over multi-day placements. | H4: Expressive writing shown to reduce cortisol and improve self-regulation (Pennebaker & Beall, 1986; Smyth, 1998).
A5: Track B | B5: Restorative Practices | C5: Peer Conflict, Bullying (Perpetrator), Bullying (Victim) | D5: Tier 2 — Moderate, Tier 3 — Serious | E5: 45–60 min total + conference | F5: Counselor + CBC | G5: Day 1: Student writes their account of the incident. Day 2: Student completes empathy mapping (how did the other person feel?). Day 3: Prepare for a facilitated restorative conversation. Day 4+: Conference with affected party. Written repair agreement produced. | H5: Restorative justice reduces repeat offenses by 44% vs. suspension alone (Smith et al., 2019; IIRP Research).
A6: Track C | B6: Social-Emotional Learning (SEL) | C6: Impulsivity / ADHD, Emotional Dysregulation, Academic Frustration | D6: Tier 1 — Minor, Tier 2 — Moderate | E6: 30–45 min/day | F6: ISS Monitor (scripted modules) | G6: CASEL-aligned modules: Zones of Regulation (emotional awareness), Growth Mindset (effort vs. fixed), and self-management skills. Modules are self-paced with reflection questions. No special training required. | H6: CASEL meta-analysis: SEL programs improve academics 11% and reduce behavior incidents 25% (Durlak et al., 2011).
A7: Track D | B7: Conflict Resolution Skills | C7: Peer Conflict, Bullying (Perpetrator) | D7: Tier 2 — Moderate, Tier 3 — Serious | E7: 45 min/day | F7: Counselor | G7: Structured conflict resolution curriculum: identifying triggers, de-escalation language, active listening, negotiation. Student role-plays scenarios. Culminates in a written conflict resolution plan for common trigger situations. | H7: Conflict resolution training reduces aggressive behavior by 38% in middle school settings (Johnson & Johnson, 2009).
A8: Track E | B8: Academic Support + Mentoring | C8: Academic Frustration, Family Crisis | D8: Tier 1 — Minor, Tier 2 — Moderate | E8: 60 min/day + daily teacher check-in | F8: Subject teachers + mentor | G8: Student receives academic catch-up assignments from each teacher. Mentor (admin, counselor, or teacher) meets for 15 min daily: goals for today, one positive observation, one area to strengthen. Prevents academic disengagement from widening during placement. | H8: Mentoring during ISS prevents academic gaps that drive future disengagement (Balfanz et al., 2014).
A9: Track F | B9: Behavioral Skills Building | C9: Impulsivity / ADHD, Emotional Dysregulation, Substance-Related | D9: Tier 2 — Moderate, Tier 3 — Serious, Tier 4 — Severe | E9: 45–60 min/day | F9: Counselor (SPED-trained preferred) | G9: Structured skill-building: identifying personal behavior triggers, building a personal de-escalation toolkit, drafting a behavior contract with measurable goals. For SPED students: coordinates with existing BIP. Produces updated behavior plan on final day. | H9: Explicit behavioral skills instruction is core to PBIS Tier 2/3 framework (Sugai & Horner, 2002).
A10: Track G | B10: Family Engagement | C10: Family Crisis, Trauma Response, Gang-Related | D10: Tier 2 — Moderate, Tier 3 — Serious, Tier 4 — Severe | E10: Parent meeting + daily check-in | F10: CBC + Counselor | G10: Parent/guardian conference on Day 1 to build shared plan. Daily 5-min phone/text update to family. Student writes a letter to parent describing what they are learning and what will change. Family receives written re-entry plan before student returns. | H10: Family involvement is the single strongest predictor of behavior improvement in school settings (Epstein, 2011).
A11: Track H | B11: Crisis Support (Counselor-Led) | C11: Trauma Response, Family Crisis, Substance-Related, Bullying (Victim) | D11: Tier 3 — Serious, Tier 4 — Severe | E11: Variable — counselor-directed | F11: Licensed Counselor only | G11: Counselor-led individual sessions. Student may not be ready for group or structured activities. Focus on stabilization, safety planning, and basic coping skills. Coordinates with SPED team, social worker, or outside supports as needed. Document all sessions. This track may require referral to DAEP or outside agency. | H11: Trauma-informed care approaches in schools improve attendance, behavior, and academic outcomes (Cole et al., 2005).
A12: 🚀 Upgrade to the full platform · clearpathedgroup.com · Clear Path Education Group, LLC

Sheet Student Activity Plans
A1: Student Activity Plans — What Students DO in ISS by Offense Type
A2: Assign activities from this reference when logging a placement. Each offense has a default activity track with specific daily tasks for the student.
A3: 📋 PRINT OR SHARE: Give the student their Day 1 activity on their first morning in ISS. Do not wait.
B4: Offense / Placement Reason | C4: Recommended Track | D4: Day 1 — Student Activity | E4: Day 2 — Student Activity | F4: Day 3 — Student Activity | G4: Day 4+ / Extended — Student Activity | H4: Re-Entry Requirement (before return)
B5: ▸ Fighting / Physical Altercation
B6: Recommended: Track B — Restorative Practices
D7: DAY 1 | E7: DAY 2 | F7: DAY 3 | G7: DAY 4+ / EXTENDED | H7: RE-ENTRY REQUIREMENT
C8: ↑ Track B — Restorative Practices | D8: Write a full account of what happened: What did YOU do? What could you have done differently at each step? (Minimum 1 page — be honest, not just what sounds good.) | E8: Empathy mapping: Draw the other person's perspective. What were they feeling at each point in the conflict? What do you think they need from you now? | F8: Conflict response planning: List your top 3 personal conflict triggers. For each trigger, write 2 strategies you can use INSTEAD of fighting. Practice saying them out loud. | G8: Prepare for restorative conversation: Write what you want to say to the other person. What will you acknowledge? What will you commit to? Practice with ISS monitor. | H8: Restorative conversation with affected party (counselor-facilitated). Signed repair agreement on file before return to class.
B10: ▸ Defiance / Insubordination
B11: Recommended: Track F — Behavioral Skills Building
D12: DAY 1 | E12: DAY 2 | F12: DAY 3 | G12: DAY 4+ / EXTENDED | H12: RE-ENTRY REQUIREMENT
C13: ↑ Track F — Behavioral Skills Building | D13: Reflection journal: Describe the specific moment you made the choice to defy the adult. What were you feeling? What did you WANT to happen? What actually happened? | E13: Authority relationships worksheet: List 5 adults at school. For each, write: (1) What do they need from me? (2) What do I need from them? (3) What gets in the way? | F13: Behavior contract drafting: Write your own behavior contract. Choose 3 specific, realistic goals. Use 'I WILL' statements — not 'I will try.' Share draft with counselor for feedback. | G13: Practice scenarios: ISS monitor gives you 3 situations where you might get frustrated. You write out and say aloud your positive response to each. Log what felt hard. | H13: Signed behavior contract with 3 goals. One adult (mentor or counselor) assigned for daily 5-minute check-in for 30 days after return.
B15: ▸ Disruption of Class
B16: Recommended: Track C — Social-Emotional Learning
D17: DAY 1 | E17: DAY 2 | F17: DAY 3 | G17: DAY 4+ / EXTENDED | H17: RE-ENTRY REQUIREMENT
C18: ↑ Track C — Social-Emotional Learning | D18: Reflection journal: What specifically did you do that was disruptive? What was happening in your body right before? Draw or describe your emotions at that moment. | E18: Zones of Regulation module: Complete the assigned SEL worksheet on identifying your zone and choosing your response. Identify which zone you were in during the incident. | F18: Impact analysis: Write a letter to the class (you do not have to deliver it). Describe how your behavior affected the class's ability to learn. What would you want them to know? | G18: Goal-setting: Write 3 specific goals for how you will manage your energy and attention in the classroom. For each, identify one adult who will help you stay on track. | H18: Written goals shared with homeroom teacher before return. Teacher confirms re-entry conversation has occurred.
B20: ▸ Bullying / Cyberbullying
B21: Recommended: Track B — Restorative Practices + Track C — SEL
D22: DAY 1 | E22: DAY 2 | F22: DAY 3 | G22: DAY 4+ / EXTENDED | H22: RE-ENTRY REQUIREMENT
C23: ↑ Track B — Restorative Practices + Track C — SEL | D23: Accountability writing: Describe every specific act of bullying you participated in. Be exact and honest. This is not shared publicly — it is for you to face what you did. | E23: Empathy deep-dive: Research the effects of bullying on targets (use provided articles or teacher-supplied reading). Write: What did the other person experience? What do I now understand that I didn't before? | F23: Power and belonging worksheet: Why did you bully? What were you getting from it? What need were you meeting? What other ways can you meet that need without harming someone? | G23: Repair plan: Write 3 specific things you will do to make things right. These must be actions, not just apologies. Share with counselor for review. | H23: Mediated conversation or written apology delivered. Counselor sign-off. No retaliation agreement signed by student.
B25: ▸ Controlled Substance — Possession
B26: Recommended: Track H — Crisis Support + Substance Education
D27: DAY 1 | E27: DAY 2 | F27: DAY 3 | G27: DAY 4+ / EXTENDED | H27: RE-ENTRY REQUIREMENT
C28: ↑ Track H — Crisis Support + Substance Education | D28: Honest reflection (confidential with counselor): What was happening in your life that led to this? What need were you trying to meet? No judgment — this is about understanding. | E28: Substance education: Complete assigned reading or module on how the substance affects brain development in teenagers. Write 3 things that surprised you. | F28: Risk and consequence mapping: Draw your personal web of consequences from this incident — for you, your family, your future. What is at stake? | G28: Support planning: What support do you need to make sure this doesn't happen again? Who are your safe people? What will you do when you feel pressure? | H28: Parent conference with student present. Student presents their support plan. Counselor referral completed.
B30: ▸ Theft / Vandalism
B31: Recommended: Track B — Restorative Practices + Community Service
D32: DAY 1 | E32: DAY 2 | F32: DAY 3 | G32: DAY 4+ / EXTENDED | H32: RE-ENTRY REQUIREMENT
C33: ↑ Track B — Restorative Practices + Community Service | D33: Accountability writing: Describe exactly what you did. What was your reason in the moment? What were you telling yourself to justify it? | E33: Impact analysis: Who was affected by what you did? List every person (victim, staff who had to respond, classmates who witnessed it). Write what each person experienced. | F33: Restitution planning: What can you do to make this right? Write a realistic plan — it may include repair, replacement, apology, or service. Present to CBC. | G33: Community service: Perform assigned campus service (connected to the harm where possible). Write daily reflection: What did I do? What did I contribute? How does this change how I see this school? | H33: Signed restitution agreement completed. Service log on file. Written apology delivered if victim agreed.
B35: ▸ Harassment / Sexual Harassment
B36: Recommended: Track B — Restorative + Track F — Behavioral Skills
D37: DAY 1 | E37: DAY 2 | F37: DAY 3 | G37: DAY 4+ / EXTENDED | H37: RE-ENTRY REQUIREMENT
C38: ↑ Track B — Restorative + Track F — Behavioral Skills | D38: Accountability writing (reviewed by counselor): Describe what you did. Label it accurately. This is non-negotiable — calling it 'just joking' is not acceptable. | E38: Boundary and consent education: Complete assigned reading or video module. Write: What is consent? What is harassment? Where is the line and how do I know? | F38: Impact reflection: Write from the perspective of the person you harassed. What did they experience? What do they now feel when they see you? What did you take from them? | G38: Behavior commitment: Write 5 specific ways you will show respect to people at school. These are observable — things others can see you doing. | H38: Title IX coordinator sign-off. Behavior commitment shared with counselor and CBC. Separate-class plan in place if needed.
B40: ▸ Assault — Threat / Fear of Injury
B41: Recommended: Track H — Crisis Support + Threat Assessment
D42: DAY 1 | E42: DAY 2 | F42: DAY 3 | G42: DAY 4+ / EXTENDED | H42: RE-ENTRY REQUIREMENT
C43: ↑ Track H — Crisis Support + Threat Assessment | D43: Threat Assessment conversation with counselor (Day 1 priority — before any written activity). Safety confirmed. Counselor determines if student is ready for self-directed work. | E43: If cleared: Write what happened from your perspective. What triggered you? What were you experiencing in your body? What was your goal? | F43: De-escalation skills: Learn and practice 3 personal de-escalation strategies (breathing, walking away, requesting a break). Write when you will use each. | G43: Safety planning: Write a personal safety plan — the adults you will go to, the signals that you're escalating, the steps you will take before you get to that point. | H43: Safety plan signed and shared with counselor, CBC, and parent. One trusted adult confirmed as ongoing contact.
B45: ▸ Repeated Misconduct (same violation)
B46: Recommended: Track G — Family Engagement + Track F — Behavioral Skills
D47: DAY 1 | E47: DAY 2 | F47: DAY 3 | G47: DAY 4+ / EXTENDED | H47: RE-ENTRY REQUIREMENT
C48: ↑ Track G — Family Engagement + Track F — Behavioral Skills | D48: Pattern analysis: List every incident of this type this year. For each: What was happening that day? What triggered it? What was the same across incidents? | E48: Why has it not changed? Write honestly: What has been tried before? Why didn't it work? What do you need that hasn't been provided? What have you not tried? | F48: Goal setting with stakes: Write 3 goals that are different from anything you've tried before. For each, name the specific adult who will hold you accountable and how. | G48: Family letter: Write to your parent/guardian. Tell them what you understand about your pattern, what you are committing to change, and what you need from them. | H48: Family conference with student's letter shared. New behavior plan co-created with family, student, and counselor. Outside referral completed if appropriate.
...

Sheet Outcome Tracker
A1: Outcome Tracker — ISS Intervention Effectiveness
A2: Fill in incidents before/after each placement. Over time this shows which interventions actually reduce repeat incidents.
A3: Student ID | B3: ⚙ Last Name | C3: ⚙ First Name | D3: ⚙ Grade | E3: Intervention Track Used | F3: Placement Start | G3: Placement End | H3: Incidents 30 Days BEFORE | I3: Incidents 30 Days AFTER | J3: ⚙ Incident Change | K3: ⚙ Reduction % | L3: ⚙ Effective? | M3: Recidivism w/in 30 Days? | N3: Recidivism w/in 90 Days? | O3: Notes
B4: =IF(A4="","",VLOOKUP(A4,'Student Roster'!A:C,2,FALSE)) | C4: =IF(A4="","",VLOOKUP(A4,'Student Roster'!A:C,3,FALSE)) | D4: =IF(A4="","",VLOOKUP(A4,'Student Roster'!A:D,4,FALSE)) | J4: =IF(OR(H4="",I4=""),"",I4-H4) | K4: =IF(H4=0,"",ROUND((H4-I4)/H4*100,0)&"%") | L4: =IF(J4="","",IF(J4<0,"✅ Effective",IF(J4=0,"↔ No Change","❌ Not Effective")))
B5: =IF(A5="","",VLOOKUP(A5,'Student Roster'!A:C,2,FALSE)) | C5: =IF(A5="","",VLOOKUP(A5,'Student Roster'!A:C,3,FALSE)) | D5: =IF(A5="","",VLOOKUP(A5,'Student Roster'!A:D,4,FALSE)) | J5: =IF(OR(H5="",I5=""),"",I5-H5) | K5: =IF(H5=0,"",ROUND((H5-I5)/H5*100,0)&"%") | L5: =IF(J5="","",IF(J5<0,"✅ Effective",IF(J5=0,"↔ No Change","❌ Not Effective")))
B6: =IF(A6="","",VLOOKUP(A6,'Student Roster'!A:C,2,FALSE)) | C6: =IF(A6="","",VLOOKUP(A6,'Student Roster'!A:C,3,FALSE)) | D6: =IF(A6="","",VLOOKUP(A6,'Student Roster'!A:D,4,FALSE)) | J6: =IF(OR(H6="",I6=""),"",I6-H6) | K6: =IF(H6=0,"",ROUND((H6-I6)/H6*100,0)&"%") | L6: =IF(J6="","",IF(J6<0,"✅ Effective",IF(J6=0,"↔ No Change","❌ Not Effective")))
B7: =IF(A7="","",VLOOKUP(A7,'Student Roster'!A:C,2,FALSE)) | C7: =IF(A7="","",VLOOKUP(A7,'Student Roster'!A:C,3,FALSE)) | D7: =IF(A7="","",VLOOKUP(A7,'Student Roster'!A:D,4,FALSE)) | J7: =IF(OR(H7="",I7=""),"",I7-H7) | K7: =IF(H7=0,"",ROUND((H7-I7)/H7*100,0)&"%") | L7: =IF(J7="","",IF(J7<0,"✅ Effective",IF(J7=0,"↔ No Change","❌ Not Effective")))
B8: =IF(A8="","",VLOOKUP(A8,'Student Roster'!A:C,2,FALSE)) | C8: =IF(A8="","",VLOOKUP(A8,'Student Roster'!A:C,3,FALSE)) | D8: =IF(A8="","",VLOOKUP(A8,'Student Roster'!A:D,4,FALSE)) | J8: =IF(OR(H8="",I8=""),"",I8-H8) | K8: =IF(H8=0,"",ROUND((H8-I8)/H8*100,0)&"%") | L8: =IF(J8="","",IF(J8<0,"✅ Effective",IF(J8=0,"↔ No Change","❌ Not Effective")))
B9: =IF(A9="","",VLOOKUP(A9,'Student Roster'!A:C,2,FALSE)) | C9: =IF(A9="","",VLOOKUP(A9,'Student Roster'!A:C,3,FALSE)) | D9: =IF(A9="","",VLOOKUP(A9,'Student Roster'!A:D,4,FALSE)) | J9: =IF(OR(H9="",I9=""),"",I9-H9) | K9: =IF(H9=0,"",ROUND((H9-I9)/H9*100,0)&"%") | L9: =IF(J9="","",IF(J9<0,"✅ Effective",IF(J9=0,"↔ No Change","❌ Not Effective")))
B10: =IF(A10="","",VLOOKUP(A10,'Student Roster'!A:C,2,FALSE)) | C10: =IF(A10="","",VLOOKUP(A10,'Student Roster'!A:C,3,FALSE)) | D10: =IF(A10="","",VLOOKUP(A10,'Student Roster'!A:D,4,FALSE)) | J10: =IF(OR(H10="",I10=""),"",I10-H10) | K10: =IF(H10=0,"",ROUND((H10-I10)/H10*100,0)&"%") | L10: =IF(J10="","",IF(J10<0,"✅ Effective",IF(J10=0,"↔ No Change","❌ Not Effective")))
B11: =IF(A11="","",VLOOKUP(A11,'Student Roster'!A:C,2,FALSE)) | C11: =IF(A11="","",VLOOKUP(A11,'Student Roster'!A:C,3,FALSE)) | D11: =IF(A11="","",VLOOKUP(A11,'Student Roster'!A:D,4,FALSE)) | J11: =IF(OR(H11="",I11=""),"",I11-H11) | K11: =IF(H11=0,"",ROUND((H11-I11)/H11*100,0)&"%") | L11: =IF(J11="","",IF(J11<0,"✅ Effective",IF(J11=0,"↔ No Change","❌ Not Effective")))
B12: =IF(A12="","",VLOOKUP(A12,'Student Roster'!A:C,2,FALSE)) | C12: =IF(A12="","",VLOOKUP(A12,'Student Roster'!A:C,3,FALSE)) | D12: =IF(A12="","",VLOOKUP(A12,'Student Roster'!A:D,4,FALSE)) | J12: =IF(OR(H12="",I12=""),"",I12-H12) | K12: =IF(H12=0,"",ROUND((H12-I12)/H12*100,0)&"%") | L12: =IF(J12="","",IF(J12<0,"✅ Effective",IF(J12=0,"↔ No Change","❌ Not Effective")))
B13: =IF(A13="","",VLOOKUP(A13,'Student Roster'!A:C,2,FALSE)) | C13: =IF(A13="","",VLOOKUP(A13,'Student Roster'!A:C,3,FALSE)) | D13: =IF(A13="","",VLOOKUP(A13,'Student Roster'!A:D,4,FALSE)) | J13: =IF(OR(H13="",I13=""),"",I13-H13) | K13: =IF(H13=0,"",ROUND((H13-I13)/H13*100,0)&"%") | L13: =IF(J13="","",IF(J13<0,"✅ Effective",IF(J13=0,"↔ No Change","❌ Not Effective")))
B14: =IF(A14="","",VLOOKUP(A14,'Student Roster'!A:C,2,FALSE)) | C14: =IF(A14="","",VLOOKUP(A14,'Student Roster'!A:C,3,FALSE)) | D14: =IF(A14="","",VLOOKUP(A14,'Student Roster'!A:D,4,FALSE)) | J14: =IF(OR(H14="",I14=""),"",I14-H14) | K14: =IF(H14=0,"",ROUND((H14-I14)/H14*100,0)&"%") | L14: =IF(J14="","",IF(J14<0,"✅ Effective",IF(J14=0,"↔ No Change","❌ Not Effective")))
B15: =IF(A15="","",VLOOKUP(A15,'Student Roster'!A:C,2,FALSE)) | C15: =IF(A15="","",VLOOKUP(A15,'Student Roster'!A:C,3,FALSE)) | D15: =IF(A15="","",VLOOKUP(A15,'Student Roster'!A:D,4,FALSE)) | J15: =IF(OR(H15="",I15=""),"",I15-H15) | K15: =IF(H15=0,"",ROUND((H15-I15)/H15*100,0)&"%") | L15: =IF(J15="","",IF(J15<0,"✅ Effective",IF(J15=0,"↔ No Change","❌ Not Effective")))
... B153: =IF(A153="","",VLOOKUP(A153,'Student Roster'!A:C,2,FALSE)) | C153: =IF(A153="","",VLOOKUP(A153,'Student Roster'!A:C,3,FALSE)) | D153: =IF(A153="","",VLOOKUP(A153,'Student Roster'!A:D,4,FALSE)) | J153: =IF(OR(H153="",I153=""),"",I153-H153) | K153: =IF(H153=0,"",ROUND((H153-I153)/H153*100,0)&"%") | L153: =IF(J153="","",IF(J153<0,"✅ Effective",IF(J153=0,"↔ No Change","❌ Not Effective")))
A154: 🚀 Upgrade to the full platform · clearpathedgroup.com · Clear Path Education Group, LLC

Sheet Dashboard
A1: ISS Intervention Tracker — Campus Dashboard
A2: ="Dashboard refreshed: "&TEXT(TODAY(),"MMMM D, YYYY") -> Dashboard refreshed: July 14, 2026
A3: PLACEMENT OVERVIEW
A4: Students on Roster | B4: =COUNTA('Student Roster'!A4:A103) -> 0
A5: Active ISS Placements | B5: =COUNTIF('Student Roster'!P4:P103,"YES") -> 0
A6: Total Placements This Year | B6: =COUNTA('ISS Placements'!A4:A203) -> 0
A7: Students with 3+ Placements | B7: =COUNTIF('Student Roster'!N4:N103,">="&3) -> 0
A9: RE-ENTRY STATUS
A10: Re-Entry Ready (all 8 steps) | B10: =COUNTIF('Re-Entry Checklist'!Y4:Y153,"✅ READY") -> 0
A11: Re-Entry Incomplete — Overdue | B11: =COUNTIFS('Re-Entry Checklist'!Y4:Y153,"❌ NOT READY",'Re-Entry Checklist'!C4:C153,"<>") -> 0
A12: Re-Entry Due Within 2 Days | B12: =COUNTIFS('ISS Placements'!N4:N203,">="&TODAY(),'ISS Placements'!N4:N203,"<="&TODAY()+2,'ISS Placements'!O4:O203,"") -> 0
A14: INTERVENTION DATA
A15: Activity Sessions Logged | B15: =COUNTA('Daily Activity Log'!A4:A503) -> 0
A16: Sessions Completed | B16: =COUNTIF('Daily Activity Log'!K4:K503,"Complete") -> 0
A17: Sessions Refused | B17: =COUNTIF('Daily Activity Log'!K4:K503,"Refused") -> 0
A18: Follow-Ups Needed | B18: =COUNTIF('Daily Activity Log'!P4:P503,"Yes") -> 0
A20: SPED & COMPLIANCE
A21: SPED Students in ISS | B21: =COUNTIF('Student Roster'!I4:I103,"Yes") -> 0
A22: ⚠ Approaching 10-Day Limit | B22: =COUNTIF('ISS Placements'!S4:S203,"⚠*") -> 0
A23: Tier 3 Risk Students | B23: =COUNTIF('Student Roster'!T4:T103,"Tier 3*") -> 0
A25: OUTCOME SUMMARY
A26: Interventions Tracked | B26: =COUNTA('Outcome Tracker'!A4:A153) -> 0
A27: Effective (Incidents Reduced) | B27: =COUNTIF('Outcome Tracker'!L4:L153,"✅*") -> 0
A28: Not Effective | B28: =COUNTIF('Outcome Tracker'!L4:L153,"❌*") -> 0
A29: Recidivism Within 30 Days | B29: =COUNTIF('Outcome Tracker'!M4:M153,"Yes") -> 0
A31: 🚀 Ready to automate this? Visit clearpathedgroup.com/navigator · Clear Path Education Group, LLC

Sheet 🔄 Re-Entry Board
A1: 🔄 WEEKLY RE-ENTRY BOARD — Students Returning Within 7 Days
A2: ="Print this tab every Monday. Week of: "&TEXT(TODAY(),"MMMM D, YYYY") -> Print this tab every Monday. Week of: July 14, 2026
A3: STUDENTS RETURNING WITHIN 7 DAYS
A4: Student ID | B4: Last Name | C4: First Name | D4: Return Date | E4: Days Until Return | F4: Steps Complete | G4: Ready?
A5: =IFERROR(INDEX('ISS Placements'!B$4:B$203,MATCH(1,'ISS Placements'!W$4:W$203,0)),"") | B5: =IF(A5="","",VLOOKUP(A5,'Student Roster'!A:C,2,FALSE)) | C5: =IF(A5="","",VLOOKUP(A5,'Student Roster'!A:C,3,FALSE)) | D5: =IF(A5="","",INDEX('ISS Placements'!N$4:N$203,MATCH(A5,'ISS Placements'!B$4:B$203,0))) | E5: =IF(D5="","",D5-TODAY()) | F5: =IF(A5="","",IFERROR(INDEX('Re-Entry Checklist'!W$4:W$153,MATCH(A5,'Re-Entry Checklist'!C$4:C$153,0)),0)) | G5: =IF(A5="","",IF(F5>=8,"✅ READY","❌ NOT READY"))
A6: =IFERROR(INDEX('ISS Placements'!B$4:B$203,MATCH(2,'ISS Placements'!W$4:W$203,0)),"") | B6: =IF(A6="","",VLOOKUP(A6,'Student Roster'!A:C,2,FALSE)) | C6: =IF(A6="","",VLOOKUP(A6,'Student Roster'!A:C,3,FALSE)) | D6: =IF(A6="","",INDEX('ISS Placements'!N$4:N$203,MATCH(A6,'ISS Placements'!B$4:B$203,0))) | E6: =IF(D6="","",D6-TODAY()) | F6: =IF(A6="","",IFERROR(INDEX('Re-Entry Checklist'!W$4:W$153,MATCH(A6,'Re-Entry Checklist'!C$4:C$153,0)),0)) | G6: =IF(A6="","",IF(F6>=8,"✅ READY","❌ NOT READY"))
A7: =IFERROR(INDEX('ISS Placements'!B$4:B$203,MATCH(3,'ISS Placements'!W$4:W$203,0)),"") | B7: =IF(A7="","",VLOOKUP(A7,'Student Roster'!A:C,2,FALSE)) | C7: =IF(A7="","",VLOOKUP(A7,'Student Roster'!A:C,3,FALSE)) | D7: =IF(A7="","",INDEX('ISS Placements'!N$4:N$203,MATCH(A7,'ISS Placements'!B$4:B$203,0))) | E7: =IF(D7="","",D7-TODAY()) | F7: =IF(A7="","",IFERROR(INDEX('Re-Entry Checklist'!W$4:W$153,MATCH(A7,'Re-Entry Checklist'!C$4:C$153,0)),0)) | G7: =IF(A7="","",IF(F7>=8,"✅ READY","❌ NOT READY"))
A8: =IFERROR(INDEX('ISS Placements'!B$4:B$203,MATCH(4,'ISS Placements'!W$4:W$203,0)),"") | B8: =IF(A8="","",VLOOKUP(A8,'Student Roster'!A:C,2,FALSE)) | C8: =IF(A8="","",VLOOKUP(A8,'Student Roster'!A:C,3,FALSE)) | D8: =IF(A8="","",INDEX('ISS Placements'!N$4:N$203,MATCH(A8,'ISS Placements'!B$4:B$203,0))) | E8: =IF(D8="","",D8-TODAY()) | F8: =IF(A8="","",IFERROR(INDEX('Re-Entry Checklist'!W$4:W$153,MATCH(A8,'Re-Entry Checklist'!C$4:C$153,0)),0)) | G8: =IF(A8="","",IF(F8>=8,"✅ READY","❌ NOT READY"))
A9: =IFERROR(INDEX('ISS Placements'!B$4:B$203,MATCH(5,'ISS Placements'!W$4:W$203,0)),"") | B9: =IF(A9="","",VLOOKUP(A9,'Student Roster'!A:C,2,FALSE)) | C9: =IF(A9="","",VLOOKUP(A9,'Student Roster'!A:C,3,FALSE)) | D9: =IF(A9="","",INDEX('ISS Placements'!N$4:N$203,MATCH(A9,'ISS Placements'!B$4:B$203,0))) | E9: =IF(D9="","",D9-TODAY()) | F9: =IF(A9="","",IFERROR(INDEX('Re-Entry Checklist'!W$4:W$153,MATCH(A9,'Re-Entry Checklist'!C$4:C$153,0)),0)) | G9: =IF(A9="","",IF(F9>=8,"✅ READY","❌ NOT READY"))
A10: =IFERROR(INDEX('ISS Placements'!B$4:B$203,MATCH(6,'ISS Placements'!W$4:W$203,0)),"") | B10: =IF(A10="","",VLOOKUP(A10,'Student Roster'!A:C,2,FALSE)) | C10: =IF(A10="","",VLOOKUP(A10,'Student Roster'!A:C,3,FALSE)) | D10: =IF(A10="","",INDEX('ISS Placements'!N$4:N$203,MATCH(A10,'ISS Placements'!B$4:B$203,0))) | E10: =IF(D10="","",D10-TODAY()) | F10: =IF(A10="","",IFERROR(INDEX('Re-Entry Checklist'!W$4:W$153,MATCH(A10,'Re-Entry Checklist'!C$4:C$153,0)),0)) | G10: =IF(A10="","",IF(F10>=8,"✅ READY","❌ NOT READY"))
A11: =IFERROR(INDEX('ISS Placements'!B$4:B$203,MATCH(7,'ISS Placements'!W$4:W$203,0)),"") | B11: =IF(A11="","",VLOOKUP(A11,'Student Roster'!A:C,2,FALSE)) | C11: =IF(A11="","",VLOOKUP(A11,'Student Roster'!A:C,3,FALSE)) | D11: =IF(A11="","",INDEX('ISS Placements'!N$4:N$203,MATCH(A11,'ISS Placements'!B$4:B$203,0))) | E11: =IF(D11="","",D11-TODAY()) | F11: =IF(A11="","",IFERROR(INDEX('Re-Entry Checklist'!W$4:W$153,MATCH(A11,'Re-Entry Checklist'!C$4:C$153,0)),0)) | G11: =IF(A11="","",IF(F11>=8,"✅ READY","❌ NOT READY"))
A12: =IFERROR(INDEX('ISS Placements'!B$4:B$203,MATCH(8,'ISS Placements'!W$4:W$203,0)),"") | B12: =IF(A12="","",VLOOKUP(A12,'Student Roster'!A:C,2,FALSE)) | C12: =IF(A12="","",VLOOKUP(A12,'Student Roster'!A:C,3,FALSE)) | D12: =IF(A12="","",INDEX('ISS Placements'!N$4:N$203,MATCH(A12,'ISS Placements'!B$4:B$203,0))) | E12: =IF(D12="","",D12-TODAY()) | F12: =IF(A12="","",IFERROR(INDEX('Re-Entry Checklist'!W$4:W$153,MATCH(A12,'Re-Entry Checklist'!C$4:C$153,0)),0)) | G12: =IF(A12="","",IF(F12>=8,"✅ READY","❌ NOT READY"))
A13: =IFERROR(INDEX('ISS Placements'!B$4:B$203,MATCH(9,'ISS Placements'!W$4:W$203,0)),"") | B13: =IF(A13="","",VLOOKUP(A13,'Student Roster'!A:C,2,FALSE)) | C13: =IF(A13="","",VLOOKUP(A13,'Student Roster'!A:C,3,FALSE)) | D13: =IF(A13="","",INDEX('ISS Placements'!N$4:N$203,MATCH(A13,'ISS Placements'!B$4:B$203,0))) | E13: =IF(D13="","",D13-TODAY()) | F13: =IF(A13="","",IFERROR(INDEX('Re-Entry Checklist'!W$4:W$153,MATCH(A13,'Re-Entry Checklist'!C$4:C$153,0)),0)) | G13: =IF(A13="","",IF(F13>=8,"✅ READY","❌ NOT READY"))
A14: =IFERROR(INDEX('ISS Placements'!B$4:B$203,MATCH(10,'ISS Placements'!W$4:W$203,0)),"") | B14: =IF(A14="","",VLOOKUP(A14,'Student Roster'!A:C,2,FALSE)) | C14: =IF(A14="","",VLOOKUP(A14,'Student Roster'!A:C,3,FALSE)) | D14: =IF(A14="","",INDEX('ISS Placements'!N$4:N$203,MATCH(A14,'ISS Placements'!B$4:B$203,0))) | E14: =IF(D14="","",D14-TODAY()) | F14: =IF(A14="","",IFERROR(INDEX('Re-Entry Checklist'!W$4:W$153,MATCH(A14,'Re-Entry Checklist'!C$4:C$153,0)),0)) | G14: =IF(A14="","",IF(F14>=8,"✅ READY","❌ NOT READY"))
A15: =IFERROR(INDEX('ISS Placements'!B$4:B$203,MATCH(11,'ISS Placements'!W$4:W$203,0)),"") | B15: =IF(A15="","",VLOOKUP(A15,'Student Roster'!A:C,2,FALSE)) | C15: =IF(A15="","",VLOOKUP(A15,'Student Roster'!A:C,3,FALSE)) | D15: =IF(A15="","",INDEX('ISS Placements'!N$4:N$203,MATCH(A15,'ISS Placements'!B$4:B$203,0))) | E15: =IF(D15="","",D15-TODAY()) | F15: =IF(A15="","",IFERROR(INDEX('Re-Entry Checklist'!W$4:W$153,MATCH(A15,'Re-Entry Checklist'!C$4:C$153,0)),0)) | G15: =IF(A15="","",IF(F15>=8,"✅ READY","❌ NOT READY"))
A16: =IFERROR(INDEX('ISS Placements'!B$4:B$203,MATCH(12,'ISS Placements'!W$4:W$203,0)),"") | B16: =IF(A16="","",VLOOKUP(A16,'Student Roster'!A:C,2,FALSE)) | C16: =IF(A16="","",VLOOKUP(A16,'Student Roster'!A:C,3,FALSE)) | D16: =IF(A16="","",INDEX('ISS Placements'!N$4:N$203,MATCH(A16,'ISS Placements'!B$4:B$203,0))) | E16: =IF(D16="","",D16-TODAY()) | F16: =IF(A16="","",IFERROR(INDEX('Re-Entry Checklist'!W$4:W$153,MATCH(A16,'Re-Entry Checklist'!C$4:C$153,0)),0)) | G16: =IF(A16="","",IF(F16>=8,"✅ READY","❌ NOT READY"))
A17: =IFERROR(INDEX('ISS Placements'!B$4:B$203,MATCH(13,'ISS Placements'!W$4:W$203,0)),"") | B17: =IF(A17="","",VLOOKUP(A17,'Student Roster'!A:C,2,FALSE)) | C17: =IF(A17="","",VLOOKUP(A17,'Student Roster'!A:C,3,FALSE)) | D17: =IF(A17="","",INDEX('ISS Placements'!N$4:N$203,MATCH(A17,'ISS Placements'!B$4:B$203,0))) | E17: =IF(D17="","",D17-TODAY()) | F17: =IF(A17="","",IFERROR(INDEX('Re-Entry Checklist'!W$4:W$153,MATCH(A17,'Re-Entry Checklist'!C$4:C$153,0)),0)) | G17: =IF(A17="","",IF(F17>=8,"✅ READY","❌ NOT READY"))
A18: =IFERROR(INDEX('ISS Placements'!B$4:B$203,MATCH(14,'ISS Placements'!W$4:W$203,0)),"") | B18: =IF(A18="","",VLOOKUP(A18,'Student Roster'!A:C,2,FALSE)) | C18: =IF(A18="","",VLOOKUP(A18,'Student Roster'!A:C,3,FALSE)) | D18: =IF(A18="","",INDEX('ISS Placements'!N$4:N$203,MATCH(A18,'ISS Placements'!B$4:B$203,0))) | E18: =IF(D18="","",D18-TODAY()) | F18: =IF(A18="","",IFERROR(INDEX('Re-Entry Checklist'!W$4:W$153,MATCH(A18,'Re-Entry Checklist'!C$4:C$153,0)),0)) | G18: =IF(A18="","",IF(F18>=8,"✅ READY","❌ NOT READY"))
A19: =IFERROR(INDEX('ISS Placements'!B$4:B$203,MATCH(15,'ISS Placements'!W$4:W$203,0)),"") | B19: =IF(A19="","",VLOOKUP(A19,'Student Roster'!A:C,2,FALSE)) | C19: =IF(A19="","",VLOOKUP(A19,'Student Roster'!A:C,3,FALSE)) | D19: =IF(A19="","",INDEX('ISS Placements'!N$4:N$203,MATCH(A19,'ISS Placements'!B$4:B$203,0))) | E19: =IF(D19="","",D19-TODAY()) | F19: =IF(A19="","",IFERROR(INDEX('Re-Entry Checklist'!W$4:W$153,MATCH(A19,'Re-Entry Checklist'!C$4:C$153,0)),0)) | G19: =IF(A19="","",IF(F19>=8,"✅ READY","❌ NOT READY"))
A20: =IFERROR(INDEX('ISS Placements'!B$4:B$203,MATCH(16,'ISS Placements'!W$4:W$203,0)),"") | B20: =IF(A20="","",VLOOKUP(A20,'Student Roster'!A:C,2,FALSE)) | C20: =IF(A20="","",VLOOKUP(A20,'Student Roster'!A:C,3,FALSE)) | D20: =IF(A20="","",INDEX('ISS Placements'!N$4:N$203,MATCH(A20,'ISS Placements'!B$4:B$203,0))) | E20: =IF(D20="","",D20-TODAY()) | F20: =IF(A20="","",IFERROR(INDEX('Re-Entry Checklist'!W$4:W$153,MATCH(A20,'Re-Entry Checklist'!C$4:C$153,0)),0)) | G20: =IF(A20="","",IF(F20>=8,"✅ READY","❌ NOT READY"))
A21: =IFERROR(INDEX('ISS Placements'!B$4:B$203,MATCH(17,'ISS Placements'!W$4:W$203,0)),"") | B21: =IF(A21="","",VLOOKUP(A21,'Student Roster'!A:C,2,FALSE)) | C21: =IF(A21="","",VLOOKUP(A21,'Student Roster'!A:C,3,FALSE)) | D21: =IF(A21="","",INDEX('ISS Placements'!N$4:N$203,MATCH(A21,'ISS Placements'!B$4:B$203,0))) | E21: =IF(D21="","",D21-TODAY()) | F21: =IF(A21="","",IFERROR(INDEX('Re-Entry Checklist'!W$4:W$153,MATCH(A21,'Re-Entry Checklist'!C$4:C$153,0)),0)) | G21: =IF(A21="","",IF(F21>=8,"✅ READY","❌ NOT READY"))
A22: =IFERROR(INDEX('ISS Placements'!B$4:B$203,MATCH(18,'ISS Placements'!W$4:W$203,0)),"") | B22: =IF(A22="","",VLOOKUP(A22,'Student Roster'!A:C,2,FALSE)) | C22: =IF(A22="","",VLOOKUP(A22,'Student Roster'!A:C,3,FALSE)) | D22: =IF(A22="","",INDEX('ISS Placements'!N$4:N$203,MATCH(A22,'ISS Placements'!B$4:B$203,0))) | E22: =IF(D22="","",D22-TODAY()) | F22: =IF(A22="","",IFERROR(INDEX('Re-Entry Checklist'!W$4:W$153,MATCH(A22,'Re-Entry Checklist'!C$4:C$153,0)),0)) | G22: =IF(A22="","",IF(F22>=8,"✅ READY","❌ NOT READY"))
A23: =IFERROR(INDEX('ISS Placements'!B$4:B$203,MATCH(19,'ISS Placements'!W$4:W$203,0)),"") | B23: =IF(A23="","",VLOOKUP(A23,'Student Roster'!A:C,2,FALSE)) | C23: =IF(A23="","",VLOOKUP(A23,'Student Roster'!A:C,3,FALSE)) | D23: =IF(A23="","",INDEX('ISS Placements'!N$4:N$203,MATCH(A23,'ISS Placements'!B$4:B$203,0))) | E23: =IF(D23="","",D23-TODAY()) | F23: =IF(A23="","",IFERROR(INDEX('Re-Entry Checklist'!W$4:W$153,MATCH(A23,'Re-Entry Checklist'!C$4:C$153,0)),0)) | G23: =IF(A23="","",IF(F23>=8,"✅ READY","❌ NOT READY"))
A24: =IFERROR(INDEX('ISS Placements'!B$4:B$203,MATCH(20,'ISS Placements'!W$4:W$203,0)),"") | B24: =IF(A24="","",VLOOKUP(A24,'Student Roster'!A:C,2,FALSE)) | C24: =IF(A24="","",VLOOKUP(A24,'Student Roster'!A:C,3,FALSE)) | D24: =IF(A24="","",INDEX('ISS Placements'!N$4:N$203,MATCH(A24,'ISS Placements'!B$4:B$203,0))) | E24: =IF(D24="","",D24-TODAY()) | F24: =IF(A24="","",IFERROR(INDEX('Re-Entry Checklist'!W$4:W$153,MATCH(A24,'Re-Entry Checklist'!C$4:C$153,0)),0)) | G24: =IF(A24="","",IF(F24>=8,"✅ READY","❌ NOT READY"))
A25: =IFERROR(INDEX('ISS Placements'!B$4:B$203,MATCH(21,'ISS Placements'!W$4:W$203,0)),"") | B25: =IF(A25="","",VLOOKUP(A25,'Student Roster'!A:C,2,FALSE)) | C25: =IF(A25="","",VLOOKUP(A25,'Student Roster'!A:C,3,FALSE)) | D25: =IF(A25="","",INDEX('ISS Placements'!N$4:N$203,MATCH(A25,'ISS Placements'!B$4:B$203,0))) | E25: =IF(D25="","",D25-TODAY()) | F25: =IF(A25="","",IFERROR(INDEX('Re-Entry Checklist'!W$4:W$153,MATCH(A25,'Re-Entry Checklist'!C$4:C$153,0)),0)) | G25: =IF(A25="","",IF(F25>=8,"✅ READY","❌ NOT READY"))
A26: =IFERROR(INDEX('ISS Placements'!B$4:B$203,MATCH(22,'ISS Placements'!W$4:W$203,0)),"") | B26: =IF(A26="","",VLOOKUP(A26,'Student Roster'!A:C,2,FALSE)) | C26: =IF(A26="","",VLOOKUP(A26,'Student Roster'!A:C,3,FALSE)) | D26: =IF(A26="","",INDEX('ISS Placements'!N$4:N$203,MATCH(A26,'ISS Placements'!B$4:B$203,0))) | E26: =IF(D26="","",D26-TODAY()) | F26: =IF(A26="","",IFERROR(INDEX('Re-Entry Checklist'!W$4:W$153,MATCH(A26,'Re-Entry Checklist'!C$4:C$153,0)),0)) | G26: =IF(A26="","",IF(F26>=8,"✅ READY","❌ NOT READY"))
A27: =IFERROR(INDEX('ISS Placements'!B$4:B$203,MATCH(23,'ISS Placements'!W$4:W$203,0)),"") | B27: =IF(A27="","",VLOOKUP(A27,'Student Roster'!A:C,2,FALSE)) | C27: =IF(A27="","",VLOOKUP(A27,'Student Roster'!A:C,3,FALSE)) | D27: =IF(A27="","",INDEX('ISS Placements'!N$4:N$203,MATCH(A27,'ISS Placements'!B$4:B$203,0))) | E27: =IF(D27="","",D27-TODAY()) | F27: =IF(A27="","",IFERROR(INDEX('Re-Entry Checklist'!W$4:W$153,MATCH(A27,'Re-Entry Checklist'!C$4:C$153,0)),0)) | G27: =IF(A27="","",IF(F27>=8,"✅ READY","❌ NOT READY"))
A28: =IFERROR(INDEX('ISS Placements'!B$4:B$203,MATCH(24,'ISS Placements'!W$4:W$203,0)),"") | B28: =IF(A28="","",VLOOKUP(A28,'Student Roster'!A:C,2,FALSE)) | C28: =IF(A28="","",VLOOKUP(A28,'Student Roster'!A:C,3,FALSE)) | D28: =IF(A28="","",INDEX('ISS Placements'!N$4:N$203,MATCH(A28,'ISS Placements'!B$4:B$203,0))) | E28: =IF(D28="","",D28-TODAY()) | F28: =IF(A28="","",IFERROR(INDEX('Re-Entry Checklist'!W$4:W$153,MATCH(A28,'Re-Entry Checklist'!C$4:C$153,0)),0)) | G28: =IF(A28="","",IF(F28>=8,"✅ READY","❌ NOT READY"))
