Workbook

Sheet Cover
A1: Meridian — Special Education Compliance Tracker
A2: IEP · 504 · Dyslexia/HB 3928 · CAP Findings · SPPI-13 Secondary Transition
A3: Clear Path Education Group, LLC | Built for Texas SPED coordinators and special education directors.
A4: Track compliance deadlines, IEP annual reviews, HB 3928 obligations, and TEA corrective action — all in one file.
A6: ─── FILL IN YOUR DISTRICT INFORMATION ─────────────────────────────
A7: District Name:
A8: School Year: | C8: 2025-26
A9: SPED Director:
A10: 504 Coordinator:
A11: Date Updated:
A13: ─── HOW TO USE THIS TRACKER ──────────────────────────────────────────
A14: 1. SPED STUDENT ROSTER — Add every SPED and 504-eligible student. This tab feeds all other tabs.
A15: 2. IEP TRACKER — One row per student with an active IEP. Tracks annual review dates and ARD status.
A16: 3. 504 PLAN TRACKER — One row per student with a 504 plan. Tracks review dates, dyslexia flags, and HB 3928.
A17: 4. DYSLEXIA / HB 3928 — Tracks students with dyslexia identification and required review status.
A18: 5. CAP FINDINGS TRACKER — Log TEA Corrective Action Plan findings, tasks, and deadlines.
A19: 6. SPPI-13 SECONDARY TRANSITION — Tracks grades 10–12 SPED students against SPPI-13 compliance requirements.
A20: 7. DASHBOARD — Auto-summary. No data entry needed here.
A21: 8. REFERENCE — IDEA compliance timelines, SPPI indicators, HB 3928 requirements, glossary.
... A34: © 2025 Clear Path Education Group, LLC | clearpathedgroup.com | For organizational use only — not legal advice.

Sheet SPED Student Roster
A1: SPED STUDENT ROSTER — Students with IEPs, 504 Plans, or Dyslexia Identification
A2: Student ID | B2: Last Name | C2: First Name | D2: Grade | E2: Campus | F2: SPED Status | G2: Primary Disability | H2: 504 Plan? | I2: Dyslexia Identified? | J2: HB 3928 Review Status | K2: Waypoint Student ID (if linked) | L2: IEP Count ⚙ | M2: 504 Count ⚙ | N2: Notes
A3: MER-001 | B3: Alvarez | C3: Elena | D3: 11th Grade | E3: Lincoln High | F3: Eligible — Active IEP | G3: Learning Disability (LD) | H3: No | I3: Yes | J3: Review Complete | L3: =IF(A3="","",COUNTIF('IEP Tracker'!B:B,A3)) -> 1 | M3: =IF(A3="","",COUNTIF('504 Plan Tracker'!B:B,A3)) -> 0 | N3: Dyslexia — Barton program. Annual IEP review upcoming.
A4: MER-002 | B4: Brown | C4: Jaylen | D4: 8th Grade | E4: Roosevelt Middle | F4: Eligible — Active IEP | G4: Emotional Disturbance (ED) | H4: No | I4: No | J4: Not Applicable | L4: =IF(A4="","",COUNTIF('IEP Tracker'!B:B,A4)) -> 1 | M4: =IF(A4="","",COUNTIF('504 Plan Tracker'!B:B,A4)) -> 0 | N4: Behavior plan active.
A5: MER-003 | B5: Kim | C5: Sarah | D5: 6th Grade | E5: Jefferson Middle | F5: 504 Only | G5: None | H5: Yes | I5: Yes | J5: Pending Review | L5: =IF(A5="","",COUNTIF('IEP Tracker'!B:B,A5)) -> 0 | M5: =IF(A5="","",COUNTIF('504 Plan Tracker'!B:B,A5)) -> 1 | N5: 504 Only — dyslexia identified 9/21.
A6: MER-004 | B6: Washington | C6: Darius | D6: 12th Grade | E6: Lincoln High | F6: Eligible — Active IEP | G6: Intellectual Disability (ID) | H6: No | I6: No | J6: Not Applicable | L6: =IF(A6="","",COUNTIF('IEP Tracker'!B:B,A6)) -> 1 | M6: =IF(A6="","",COUNTIF('504 Plan Tracker'!B:B,A6)) -> 0 | N6: SPPI-13 secondary transition planning.
A7: MER-005 | B7: Nguyen | C7: Mai | D7: 9th Grade | E7: Lincoln High | F7: Eligible — Active IEP | G7: Other Health Impairment (OHI) | H7: Yes | I7: Yes | J7: Pending Review | L7: =IF(A7="","",COUNTIF('IEP Tracker'!B:B,A7)) -> 1 | M7: =IF(A7="","",COUNTIF('504 Plan Tracker'!B:B,A7)) -> 1 | N7: ADHD — both IEP and 504 supports.
L8: =IF(A8="","",COUNTIF('IEP Tracker'!B:B,A8)) | M8: =IF(A8="","",COUNTIF('504 Plan Tracker'!B:B,A8)) | N8: =COUNTIF('IEP Tracker'!B:B,A8) -> 0
L9: =IF(A9="","",COUNTIF('IEP Tracker'!B:B,A9)) | M9: =IF(A9="","",COUNTIF('504 Plan Tracker'!B:B,A9)) | N9: =COUNTIF('IEP Tracker'!B:B,A9) -> 0
L10: =IF(A10="","",COUNTIF('IEP Tracker'!B:B,A10)) | M10: =IF(A10="","",COUNTIF('504 Plan Tracker'!B:B,A10)) | N10: =COUNTIF('IEP Tracker'!B:B,A10) -> 0
L11: =IF(A11="","",COUNTIF('IEP Tracker'!B:B,A11)) | M11: =IF(A11="","",COUNTIF('504 Plan Tracker'!B:B,A11)) | N11: =COUNTIF('IEP Tracker'!B:B,A11) -> 0
L12: =IF(A12="","",COUNTIF('IEP Tracker'!B:B,A12)) | M12: =IF(A12="","",COUNTIF('504 Plan Tracker'!B:B,A12)) | N12: =COUNTIF('IEP Tracker'!B:B,A12) -> 0
L13: =IF(A13="","",COUNTIF('IEP Tracker'!B:B,A13)) | M13: =IF(A13="","",COUNTIF('504 Plan Tracker'!B:B,A13)) | N13: =COUNTIF('IEP Tracker'!B:B,A13) -> 0
L14: =IF(A14="","",COUNTIF('IEP Tracker'!B:B,A14)) | M14: =IF(A14="","",COUNTIF('504 Plan Tracker'!B:B,A14)) | N14: =COUNTIF('IEP Tracker'!B:B,A14) -> 0
L15: =IF(A15="","",COUNTIF('IEP Tracker'!B:B,A15)) | M15: =IF(A15="","",COUNTIF('504 Plan Tracker'!B:B,A15)) | N15: =COUNTIF('IEP Tracker'!B:B,A15) -> 0
L16: =IF(A16="","",COUNTIF('IEP Tracker'!B:B,A16)) | M16: =IF(A16="","",COUNTIF('504 Plan Tracker'!B:B,A16)) | N16: =COUNTIF('IEP Tracker'!B:B,A16) -> 0
L17: =IF(A17="","",COUNTIF('IEP Tracker'!B:B,A17)) | M17: =IF(A17="","",COUNTIF('504 Plan Tracker'!B:B,A17)) | N17: =COUNTIF('IEP Tracker'!B:B,A17) -> 0
L18: =IF(A18="","",COUNTIF('IEP Tracker'!B:B,A18)) | M18: =IF(A18="","",COUNTIF('504 Plan Tracker'!B:B,A18)) | N18: =COUNTIF('IEP Tracker'!B:B,A18) -> 0
L19: =IF(A19="","",COUNTIF('IEP Tracker'!B:B,A19)) | M19: =IF(A19="","",COUNTIF('504 Plan Tracker'!B:B,A19)) | N19: =COUNTIF('IEP Tracker'!B:B,A19) -> 0
... L201: =IF(A201="","",COUNTIF('IEP Tracker'!B:B,A201)) | M201: =IF(A201="","",COUNTIF('504 Plan Tracker'!B:B,A201)) | N201: =COUNTIF('IEP Tracker'!B:B,A201) -> 0

Sheet IEP Tracker
A1: IEP TRACKER — One Row Per Active IEP
A2: ⚠ Annual review must be held within 12 months of the previous review date. ARD meeting notice required 5 calendar days in advance (19 TAC §89.1050).
A3: IEP ID | B3: Student ID | C3: Last Name ⚙ | D3: First Name ⚙ | E3: Grade ⚙ | F3: Campus ⚙ | G3: IEP Status | H3: Case Manager | I3: Last Annual Review Date | J3: Annual Review Due Date | K3: Days Until Review ⚙ | L3: Annual Review Held? | M3: Date Review Held | N3: ARD Meeting Scheduled? | O3: ARD Meeting Date | P3: Next Re-Evaluation Due | Q3: SPED Status ⚙ | R3: Notes
A4: IEP-001 | B4: MER-001 | C4: =IF(B4="","",IFERROR(VLOOKUP(B4,'SPED Student Roster'!$A:$B,2,FALSE),"")) -> Alvarez | D4: =IF(B4="","",IFERROR(VLOOKUP(B4,'SPED Student Roster'!$A:$C,3,FALSE),"")) -> Elena | E4: =IF(B4="","",IFERROR(VLOOKUP(B4,'SPED Student Roster'!$A:$D,4,FALSE),"")) -> 11th Grade | F4: =IF(B4="","",IFERROR(VLOOKUP(B4,'SPED Student Roster'!$A:$E,5,FALSE),"")) -> Lincoln High | G4: Annual Review Due | H4: Ms. Garcia | I4: 45732 | J4: 46097 | K4: =IF(OR(B4="",J4=""),"",J4-TODAY()) -> -120 | L4: No | N4: Yes | O4: 46092 | P4: 46828 | Q4: =IF(B4="","",IFERROR(VLOOKUP(B4,'SPED Student Roster'!$A:$F,6,FALSE),"")) -> Eligible — Active IEP | R4: Annual review due 3/15 — ARD scheduled.
A5: IEP-002 | B5: MER-002 | C5: =IF(B5="","",IFERROR(VLOOKUP(B5,'SPED Student Roster'!$A:$B,2,FALSE),"")) -> Brown | D5: =IF(B5="","",IFERROR(VLOOKUP(B5,'SPED Student Roster'!$A:$C,3,FALSE),"")) -> Jaylen | E5: =IF(B5="","",IFERROR(VLOOKUP(B5,'SPED Student Roster'!$A:$D,4,FALSE),"")) -> 8th Grade | F5: =IF(B5="","",IFERROR(VLOOKUP(B5,'SPED Student Roster'!$A:$E,5,FALSE),"")) -> Roosevelt Middle | G5: Active | H5: Mr. Thompson | I5: 45921 | J5: 46286 | K5: =IF(OR(B5="",J5=""),"",J5-TODAY()) -> 69 | L5: No | N5: No | P5: 47017 | Q5: =IF(B5="","",IFERROR(VLOOKUP(B5,'SPED Student Roster'!$A:$F,6,FALSE),"")) -> Eligible — Active IEP | R5: BIP review concurrent with ARD. Next annual Sept 2026.
A6: IEP-003 | B6: MER-004 | C6: =IF(B6="","",IFERROR(VLOOKUP(B6,'SPED Student Roster'!$A:$B,2,FALSE),"")) -> Washington | D6: =IF(B6="","",IFERROR(VLOOKUP(B6,'SPED Student Roster'!$A:$C,3,FALSE),"")) -> Darius | E6: =IF(B6="","",IFERROR(VLOOKUP(B6,'SPED Student Roster'!$A:$D,4,FALSE),"")) -> 12th Grade | F6: =IF(B6="","",IFERROR(VLOOKUP(B6,'SPED Student Roster'!$A:$E,5,FALSE),"")) -> Lincoln High | G6: Active | H6: Ms. Rivera | I6: 45779 | J6: 46144 | K6: =IF(OR(B6="",J6=""),"",J6-TODAY()) -> -73 | L6: No | N6: No | P6: 46875 | Q6: =IF(B6="","",IFERROR(VLOOKUP(B6,'SPED Student Roster'!$A:$F,6,FALSE),"")) -> Eligible — Active IEP | R6: Transition plan: post-secondary vocational training. Graduation May 2026.
A7: IEP-004 | B7: MER-005 | C7: =IF(B7="","",IFERROR(VLOOKUP(B7,'SPED Student Roster'!$A:$B,2,FALSE),"")) -> Nguyen | D7: =IF(B7="","",IFERROR(VLOOKUP(B7,'SPED Student Roster'!$A:$C,3,FALSE),"")) -> Mai | E7: =IF(B7="","",IFERROR(VLOOKUP(B7,'SPED Student Roster'!$A:$D,4,FALSE),"")) -> 9th Grade | F7: =IF(B7="","",IFERROR(VLOOKUP(B7,'SPED Student Roster'!$A:$E,5,FALSE),"")) -> Lincoln High | G7: Annual Review Due | H7: Ms. Garcia | I7: 45718 | J7: 46083 | K7: =IF(OR(B7="",J7=""),"",J7-TODAY()) -> -134 | L7: No | N7: Yes | O7: 46082 | P7: 46814 | Q7: =IF(B7="","",IFERROR(VLOOKUP(B7,'SPED Student Roster'!$A:$F,6,FALSE),"")) -> Eligible — Active IEP | R7: Annual review overdue. ARD rescheduled for 2/28.
C8: =IF(B8="","",IFERROR(VLOOKUP(B8,'SPED Student Roster'!$A:$B,2,FALSE),"")) | D8: =IF(B8="","",IFERROR(VLOOKUP(B8,'SPED Student Roster'!$A:$C,3,FALSE),"")) | E8: =IF(B8="","",IFERROR(VLOOKUP(B8,'SPED Student Roster'!$A:$D,4,FALSE),"")) | F8: =IF(B8="","",IFERROR(VLOOKUP(B8,'SPED Student Roster'!$A:$E,5,FALSE),"")) | K8: =IF(OR(B8="",J8=""),"",J8-TODAY()) | Q8: =IF(B8="","",IFERROR(VLOOKUP(B8,'SPED Student Roster'!$A:$F,6,FALSE),""))
C9: =IF(B9="","",IFERROR(VLOOKUP(B9,'SPED Student Roster'!$A:$B,2,FALSE),"")) | D9: =IF(B9="","",IFERROR(VLOOKUP(B9,'SPED Student Roster'!$A:$C,3,FALSE),"")) | E9: =IF(B9="","",IFERROR(VLOOKUP(B9,'SPED Student Roster'!$A:$D,4,FALSE),"")) | F9: =IF(B9="","",IFERROR(VLOOKUP(B9,'SPED Student Roster'!$A:$E,5,FALSE),"")) | K9: =IF(OR(B9="",J9=""),"",J9-TODAY()) | Q9: =IF(B9="","",IFERROR(VLOOKUP(B9,'SPED Student Roster'!$A:$F,6,FALSE),""))
C10: =IF(B10="","",IFERROR(VLOOKUP(B10,'SPED Student Roster'!$A:$B,2,FALSE),"")) | D10: =IF(B10="","",IFERROR(VLOOKUP(B10,'SPED Student Roster'!$A:$C,3,FALSE),"")) | E10: =IF(B10="","",IFERROR(VLOOKUP(B10,'SPED Student Roster'!$A:$D,4,FALSE),"")) | F10: =IF(B10="","",IFERROR(VLOOKUP(B10,'SPED Student Roster'!$A:$E,5,FALSE),"")) | K10: =IF(OR(B10="",J10=""),"",J10-TODAY()) | Q10: =IF(B10="","",IFERROR(VLOOKUP(B10,'SPED Student Roster'!$A:$F,6,FALSE),""))
C11: =IF(B11="","",IFERROR(VLOOKUP(B11,'SPED Student Roster'!$A:$B,2,FALSE),"")) | D11: =IF(B11="","",IFERROR(VLOOKUP(B11,'SPED Student Roster'!$A:$C,3,FALSE),"")) | E11: =IF(B11="","",IFERROR(VLOOKUP(B11,'SPED Student Roster'!$A:$D,4,FALSE),"")) | F11: =IF(B11="","",IFERROR(VLOOKUP(B11,'SPED Student Roster'!$A:$E,5,FALSE),"")) | K11: =IF(OR(B11="",J11=""),"",J11-TODAY()) | Q11: =IF(B11="","",IFERROR(VLOOKUP(B11,'SPED Student Roster'!$A:$F,6,FALSE),""))
C12: =IF(B12="","",IFERROR(VLOOKUP(B12,'SPED Student Roster'!$A:$B,2,FALSE),"")) | D12: =IF(B12="","",IFERROR(VLOOKUP(B12,'SPED Student Roster'!$A:$C,3,FALSE),"")) | E12: =IF(B12="","",IFERROR(VLOOKUP(B12,'SPED Student Roster'!$A:$D,4,FALSE),"")) | F12: =IF(B12="","",IFERROR(VLOOKUP(B12,'SPED Student Roster'!$A:$E,5,FALSE),"")) | K12: =IF(OR(B12="",J12=""),"",J12-TODAY()) | Q12: =IF(B12="","",IFERROR(VLOOKUP(B12,'SPED Student Roster'!$A:$F,6,FALSE),""))
C13: =IF(B13="","",IFERROR(VLOOKUP(B13,'SPED Student Roster'!$A:$B,2,FALSE),"")) | D13: =IF(B13="","",IFERROR(VLOOKUP(B13,'SPED Student Roster'!$A:$C,3,FALSE),"")) | E13: =IF(B13="","",IFERROR(VLOOKUP(B13,'SPED Student Roster'!$A:$D,4,FALSE),"")) | F13: =IF(B13="","",IFERROR(VLOOKUP(B13,'SPED Student Roster'!$A:$E,5,FALSE),"")) | K13: =IF(OR(B13="",J13=""),"",J13-TODAY()) | Q13: =IF(B13="","",IFERROR(VLOOKUP(B13,'SPED Student Roster'!$A:$F,6,FALSE),""))
C14: =IF(B14="","",IFERROR(VLOOKUP(B14,'SPED Student Roster'!$A:$B,2,FALSE),"")) | D14: =IF(B14="","",IFERROR(VLOOKUP(B14,'SPED Student Roster'!$A:$C,3,FALSE),"")) | E14: =IF(B14="","",IFERROR(VLOOKUP(B14,'SPED Student Roster'!$A:$D,4,FALSE),"")) | F14: =IF(B14="","",IFERROR(VLOOKUP(B14,'SPED Student Roster'!$A:$E,5,FALSE),"")) | K14: =IF(OR(B14="",J14=""),"",J14-TODAY()) | Q14: =IF(B14="","",IFERROR(VLOOKUP(B14,'SPED Student Roster'!$A:$F,6,FALSE),""))
C15: =IF(B15="","",IFERROR(VLOOKUP(B15,'SPED Student Roster'!$A:$B,2,FALSE),"")) | D15: =IF(B15="","",IFERROR(VLOOKUP(B15,'SPED Student Roster'!$A:$C,3,FALSE),"")) | E15: =IF(B15="","",IFERROR(VLOOKUP(B15,'SPED Student Roster'!$A:$D,4,FALSE),"")) | F15: =IF(B15="","",IFERROR(VLOOKUP(B15,'SPED Student Roster'!$A:$E,5,FALSE),"")) | K15: =IF(OR(B15="",J15=""),"",J15-TODAY()) | Q15: =IF(B15="","",IFERROR(VLOOKUP(B15,'SPED Student Roster'!$A:$F,6,FALSE),""))
C16: =IF(B16="","",IFERROR(VLOOKUP(B16,'SPED Student Roster'!$A:$B,2,FALSE),"")) | D16: =IF(B16="","",IFERROR(VLOOKUP(B16,'SPED Student Roster'!$A:$C,3,FALSE),"")) | E16: =IF(B16="","",IFERROR(VLOOKUP(B16,'SPED Student Roster'!$A:$D,4,FALSE),"")) | F16: =IF(B16="","",IFERROR(VLOOKUP(B16,'SPED Student Roster'!$A:$E,5,FALSE),"")) | K16: =IF(OR(B16="",J16=""),"",J16-TODAY()) | Q16: =IF(B16="","",IFERROR(VLOOKUP(B16,'SPED Student Roster'!$A:$F,6,FALSE),""))
C17: =IF(B17="","",IFERROR(VLOOKUP(B17,'SPED Student Roster'!$A:$B,2,FALSE),"")) | D17: =IF(B17="","",IFERROR(VLOOKUP(B17,'SPED Student Roster'!$A:$C,3,FALSE),"")) | E17: =IF(B17="","",IFERROR(VLOOKUP(B17,'SPED Student Roster'!$A:$D,4,FALSE),"")) | F17: =IF(B17="","",IFERROR(VLOOKUP(B17,'SPED Student Roster'!$A:$E,5,FALSE),"")) | K17: =IF(OR(B17="",J17=""),"",J17-TODAY()) | Q17: =IF(B17="","",IFERROR(VLOOKUP(B17,'SPED Student Roster'!$A:$F,6,FALSE),""))
C18: =IF(B18="","",IFERROR(VLOOKUP(B18,'SPED Student Roster'!$A:$B,2,FALSE),"")) | D18: =IF(B18="","",IFERROR(VLOOKUP(B18,'SPED Student Roster'!$A:$C,3,FALSE),"")) | E18: =IF(B18="","",IFERROR(VLOOKUP(B18,'SPED Student Roster'!$A:$D,4,FALSE),"")) | F18: =IF(B18="","",IFERROR(VLOOKUP(B18,'SPED Student Roster'!$A:$E,5,FALSE),"")) | K18: =IF(OR(B18="",J18=""),"",J18-TODAY()) | Q18: =IF(B18="","",IFERROR(VLOOKUP(B18,'SPED Student Roster'!$A:$F,6,FALSE),""))
C19: =IF(B19="","",IFERROR(VLOOKUP(B19,'SPED Student Roster'!$A:$B,2,FALSE),"")) | D19: =IF(B19="","",IFERROR(VLOOKUP(B19,'SPED Student Roster'!$A:$C,3,FALSE),"")) | E19: =IF(B19="","",IFERROR(VLOOKUP(B19,'SPED Student Roster'!$A:$D,4,FALSE),"")) | F19: =IF(B19="","",IFERROR(VLOOKUP(B19,'SPED Student Roster'!$A:$E,5,FALSE),"")) | K19: =IF(OR(B19="",J19=""),"",J19-TODAY()) | Q19: =IF(B19="","",IFERROR(VLOOKUP(B19,'SPED Student Roster'!$A:$F,6,FALSE),""))
... C201: =IF(B201="","",IFERROR(VLOOKUP(B201,'SPED Student Roster'!$A:$B,2,FALSE),"")) | D201: =IF(B201="","",IFERROR(VLOOKUP(B201,'SPED Student Roster'!$A:$C,3,FALSE),"")) | E201: =IF(B201="","",IFERROR(VLOOKUP(B201,'SPED Student Roster'!$A:$D,4,FALSE),"")) | F201: =IF(B201="","",IFERROR(VLOOKUP(B201,'SPED Student Roster'!$A:$E,5,FALSE),"")) | K201: =IF(OR(B201="",J201=""),"",J201-TODAY()) | Q201: =IF(B201="","",IFERROR(VLOOKUP(B201,'SPED Student Roster'!$A:$F,6,FALSE),""))

Sheet 504 Plan Tracker
A1: 504 PLAN TRACKER — One Row Per Active 504 Plan
A2: ⚠ Section 504 plans require annual review (34 CFR §104.36). Dyslexia plans must comply with HB 3928 and include MDT composition verification.
A3: 504 ID | B3: Student ID | C3: Last Name ⚙ | D3: First Name ⚙ | E3: Grade ⚙ | F3: Campus ⚙ | G3: 504 Status | H3: Case Manager | I3: Last Annual Review Date | J3: Annual Review Due Date | K3: Days Until Review ⚙ | L3: Review Held? | M3: Date Review Held | N3: Is Dyslexia Plan? | O3: HB 3928 Reviewed? | P3: MDT Composition Verified? | Q3: Progress Report Required? | R3: Notes
A4: 504-001 | B4: MER-003 | C4: =IF(B4="","",IFERROR(VLOOKUP(B4,'SPED Student Roster'!$A:$B,2,FALSE),"")) -> Kim | D4: =IF(B4="","",IFERROR(VLOOKUP(B4,'SPED Student Roster'!$A:$C,3,FALSE),"")) -> Sarah | E4: =IF(B4="","",IFERROR(VLOOKUP(B4,'SPED Student Roster'!$A:$D,4,FALSE),"")) -> 6th Grade | F4: =IF(B4="","",IFERROR(VLOOKUP(B4,'SPED Student Roster'!$A:$E,5,FALSE),"")) -> Jefferson Middle | G4: Annual Review Due | H4: Mr. Kim | I4: 45704 | J4: 46069 | K4: =IF(OR(B4="",J4=""),"",J4-TODAY()) -> -148 | L4: No | N4: Yes | O4: Yes | P4: Yes | Q4: Yes | R4: Dyslexia 504 — HB 3928 compliant. Annual review overdue.
A5: 504-002 | B5: MER-005 | C5: =IF(B5="","",IFERROR(VLOOKUP(B5,'SPED Student Roster'!$A:$B,2,FALSE),"")) -> Nguyen | D5: =IF(B5="","",IFERROR(VLOOKUP(B5,'SPED Student Roster'!$A:$C,3,FALSE),"")) -> Mai | E5: =IF(B5="","",IFERROR(VLOOKUP(B5,'SPED Student Roster'!$A:$D,4,FALSE),"")) -> 9th Grade | F5: =IF(B5="","",IFERROR(VLOOKUP(B5,'SPED Student Roster'!$A:$E,5,FALSE),"")) -> Lincoln High | G5: Active | H5: Ms. Garcia | I5: 45758 | J5: 46123 | K5: =IF(OR(B5="",J5=""),"",J5-TODAY()) -> -94 | L5: No | N5: No | O5: No | P5: No | Q5: No | R5: Standard 504 for ADHD/OHI. Annual review April 2026.
C6: =IF(B6="","",IFERROR(VLOOKUP(B6,'SPED Student Roster'!$A:$B,2,FALSE),"")) | D6: =IF(B6="","",IFERROR(VLOOKUP(B6,'SPED Student Roster'!$A:$C,3,FALSE),"")) | E6: =IF(B6="","",IFERROR(VLOOKUP(B6,'SPED Student Roster'!$A:$D,4,FALSE),"")) | F6: =IF(B6="","",IFERROR(VLOOKUP(B6,'SPED Student Roster'!$A:$E,5,FALSE),"")) | K6: =IF(OR(B6="",J6=""),"",J6-TODAY())
C7: =IF(B7="","",IFERROR(VLOOKUP(B7,'SPED Student Roster'!$A:$B,2,FALSE),"")) | D7: =IF(B7="","",IFERROR(VLOOKUP(B7,'SPED Student Roster'!$A:$C,3,FALSE),"")) | E7: =IF(B7="","",IFERROR(VLOOKUP(B7,'SPED Student Roster'!$A:$D,4,FALSE),"")) | F7: =IF(B7="","",IFERROR(VLOOKUP(B7,'SPED Student Roster'!$A:$E,5,FALSE),"")) | K7: =IF(OR(B7="",J7=""),"",J7-TODAY())
C8: =IF(B8="","",IFERROR(VLOOKUP(B8,'SPED Student Roster'!$A:$B,2,FALSE),"")) | D8: =IF(B8="","",IFERROR(VLOOKUP(B8,'SPED Student Roster'!$A:$C,3,FALSE),"")) | E8: =IF(B8="","",IFERROR(VLOOKUP(B8,'SPED Student Roster'!$A:$D,4,FALSE),"")) | F8: =IF(B8="","",IFERROR(VLOOKUP(B8,'SPED Student Roster'!$A:$E,5,FALSE),"")) | K8: =IF(OR(B8="",J8=""),"",J8-TODAY())
C9: =IF(B9="","",IFERROR(VLOOKUP(B9,'SPED Student Roster'!$A:$B,2,FALSE),"")) | D9: =IF(B9="","",IFERROR(VLOOKUP(B9,'SPED Student Roster'!$A:$C,3,FALSE),"")) | E9: =IF(B9="","",IFERROR(VLOOKUP(B9,'SPED Student Roster'!$A:$D,4,FALSE),"")) | F9: =IF(B9="","",IFERROR(VLOOKUP(B9,'SPED Student Roster'!$A:$E,5,FALSE),"")) | K9: =IF(OR(B9="",J9=""),"",J9-TODAY())
C10: =IF(B10="","",IFERROR(VLOOKUP(B10,'SPED Student Roster'!$A:$B,2,FALSE),"")) | D10: =IF(B10="","",IFERROR(VLOOKUP(B10,'SPED Student Roster'!$A:$C,3,FALSE),"")) | E10: =IF(B10="","",IFERROR(VLOOKUP(B10,'SPED Student Roster'!$A:$D,4,FALSE),"")) | F10: =IF(B10="","",IFERROR(VLOOKUP(B10,'SPED Student Roster'!$A:$E,5,FALSE),"")) | K10: =IF(OR(B10="",J10=""),"",J10-TODAY())
C11: =IF(B11="","",IFERROR(VLOOKUP(B11,'SPED Student Roster'!$A:$B,2,FALSE),"")) | D11: =IF(B11="","",IFERROR(VLOOKUP(B11,'SPED Student Roster'!$A:$C,3,FALSE),"")) | E11: =IF(B11="","",IFERROR(VLOOKUP(B11,'SPED Student Roster'!$A:$D,4,FALSE),"")) | F11: =IF(B11="","",IFERROR(VLOOKUP(B11,'SPED Student Roster'!$A:$E,5,FALSE),"")) | K11: =IF(OR(B11="",J11=""),"",J11-TODAY())
C12: =IF(B12="","",IFERROR(VLOOKUP(B12,'SPED Student Roster'!$A:$B,2,FALSE),"")) | D12: =IF(B12="","",IFERROR(VLOOKUP(B12,'SPED Student Roster'!$A:$C,3,FALSE),"")) | E12: =IF(B12="","",IFERROR(VLOOKUP(B12,'SPED Student Roster'!$A:$D,4,FALSE),"")) | F12: =IF(B12="","",IFERROR(VLOOKUP(B12,'SPED Student Roster'!$A:$E,5,FALSE),"")) | K12: =IF(OR(B12="",J12=""),"",J12-TODAY())
C13: =IF(B13="","",IFERROR(VLOOKUP(B13,'SPED Student Roster'!$A:$B,2,FALSE),"")) | D13: =IF(B13="","",IFERROR(VLOOKUP(B13,'SPED Student Roster'!$A:$C,3,FALSE),"")) | E13: =IF(B13="","",IFERROR(VLOOKUP(B13,'SPED Student Roster'!$A:$D,4,FALSE),"")) | F13: =IF(B13="","",IFERROR(VLOOKUP(B13,'SPED Student Roster'!$A:$E,5,FALSE),"")) | K13: =IF(OR(B13="",J13=""),"",J13-TODAY())
C14: =IF(B14="","",IFERROR(VLOOKUP(B14,'SPED Student Roster'!$A:$B,2,FALSE),"")) | D14: =IF(B14="","",IFERROR(VLOOKUP(B14,'SPED Student Roster'!$A:$C,3,FALSE),"")) | E14: =IF(B14="","",IFERROR(VLOOKUP(B14,'SPED Student Roster'!$A:$D,4,FALSE),"")) | F14: =IF(B14="","",IFERROR(VLOOKUP(B14,'SPED Student Roster'!$A:$E,5,FALSE),"")) | K14: =IF(OR(B14="",J14=""),"",J14-TODAY())
C15: =IF(B15="","",IFERROR(VLOOKUP(B15,'SPED Student Roster'!$A:$B,2,FALSE),"")) | D15: =IF(B15="","",IFERROR(VLOOKUP(B15,'SPED Student Roster'!$A:$C,3,FALSE),"")) | E15: =IF(B15="","",IFERROR(VLOOKUP(B15,'SPED Student Roster'!$A:$D,4,FALSE),"")) | F15: =IF(B15="","",IFERROR(VLOOKUP(B15,'SPED Student Roster'!$A:$E,5,FALSE),"")) | K15: =IF(OR(B15="",J15=""),"",J15-TODAY())
C16: =IF(B16="","",IFERROR(VLOOKUP(B16,'SPED Student Roster'!$A:$B,2,FALSE),"")) | D16: =IF(B16="","",IFERROR(VLOOKUP(B16,'SPED Student Roster'!$A:$C,3,FALSE),"")) | E16: =IF(B16="","",IFERROR(VLOOKUP(B16,'SPED Student Roster'!$A:$D,4,FALSE),"")) | F16: =IF(B16="","",IFERROR(VLOOKUP(B16,'SPED Student Roster'!$A:$E,5,FALSE),"")) | K16: =IF(OR(B16="",J16=""),"",J16-TODAY())
C17: =IF(B17="","",IFERROR(VLOOKUP(B17,'SPED Student Roster'!$A:$B,2,FALSE),"")) | D17: =IF(B17="","",IFERROR(VLOOKUP(B17,'SPED Student Roster'!$A:$C,3,FALSE),"")) | E17: =IF(B17="","",IFERROR(VLOOKUP(B17,'SPED Student Roster'!$A:$D,4,FALSE),"")) | F17: =IF(B17="","",IFERROR(VLOOKUP(B17,'SPED Student Roster'!$A:$E,5,FALSE),"")) | K17: =IF(OR(B17="",J17=""),"",J17-TODAY())
... C201: =IF(B201="","",IFERROR(VLOOKUP(B201,'SPED Student Roster'!$A:$B,2,FALSE),"")) | D201: =IF(B201="","",IFERROR(VLOOKUP(B201,'SPED Student Roster'!$A:$C,3,FALSE),"")) | E201: =IF(B201="","",IFERROR(VLOOKUP(B201,'SPED Student Roster'!$A:$D,4,FALSE),"")) | F201: =IF(B201="","",IFERROR(VLOOKUP(B201,'SPED Student Roster'!$A:$E,5,FALSE),"")) | K201: =IF(OR(B201="",J201=""),"",J201-TODAY())

Sheet Dyslexia-HB 3928
A1: DYSLEXIA & HB 3928 TRACKER — Students with Dyslexia Identification
A2: Texas HB 3928 (2021) requires annual review of all students identified with dyslexia, MDT composition verification, and structured literacy instruction. This tracker monitors required annual actions.
A3: Student ID | B3: Last Name ⚙ | C3: First Name ⚙ | D3: Grade ⚙ | E3: Campus ⚙ | F3: Dyslexia Identification Date | G3: Dyslexia Program / Intervention | H3: HB 3928 Annual Review Status | I3: 504 Plan Linked? | J3: 504 Plan ID | K3: MDT Composition Verified? | L3: Progress Report Required? | M3: Progress Report Due Date | N3: Progress Report Status | O3: Structured Literacy Instruction Confirmed? | P3: Notes
A4: MER-001 | B4: =IF(A4="","",IFERROR(VLOOKUP(A4,'SPED Student Roster'!$A:$B,2,FALSE),"")) -> Alvarez | C4: =IF(A4="","",IFERROR(VLOOKUP(A4,'SPED Student Roster'!$A:$C,3,FALSE),"")) -> Elena | D4: =IF(A4="","",IFERROR(VLOOKUP(A4,'SPED Student Roster'!$A:$D,4,FALSE),"")) -> 11th Grade | E4: =IF(A4="","",IFERROR(VLOOKUP(A4,'SPED Student Roster'!$A:$E,5,FALSE),"")) -> Lincoln High | F4: 44059 | G4: Barton Reading and Spelling | H4: Review Complete | I4: No | K4: Yes | L4: Yes | M4: 46113 | N4: In Progress | O4: Yes | P4: Annual HB 3928 review completed. Progress report due 3/31.
A5: MER-003 | B5: =IF(A5="","",IFERROR(VLOOKUP(A5,'SPED Student Roster'!$A:$B,2,FALSE),"")) -> Kim | C5: =IF(A5="","",IFERROR(VLOOKUP(A5,'SPED Student Roster'!$A:$C,3,FALSE),"")) -> Sarah | D5: =IF(A5="","",IFERROR(VLOOKUP(A5,'SPED Student Roster'!$A:$D,4,FALSE),"")) -> 6th Grade | E5: =IF(A5="","",IFERROR(VLOOKUP(A5,'SPED Student Roster'!$A:$E,5,FALSE),"")) -> Jefferson Middle | F5: 44450 | G5: Wilson Reading System | H5: Pending Review | I5: Yes | J5: 504-001 | K5: Yes | L5: Yes | M5: 46082 | N5: Not Started | O5: Yes | P5: Annual HB 3928 review not yet completed — URGENT.
B6: =IF(A6="","",IFERROR(VLOOKUP(A6,'SPED Student Roster'!$A:$B,2,FALSE),"")) | C6: =IF(A6="","",IFERROR(VLOOKUP(A6,'SPED Student Roster'!$A:$C,3,FALSE),"")) | D6: =IF(A6="","",IFERROR(VLOOKUP(A6,'SPED Student Roster'!$A:$D,4,FALSE),"")) | E6: =IF(A6="","",IFERROR(VLOOKUP(A6,'SPED Student Roster'!$A:$E,5,FALSE),""))
B7: =IF(A7="","",IFERROR(VLOOKUP(A7,'SPED Student Roster'!$A:$B,2,FALSE),"")) | C7: =IF(A7="","",IFERROR(VLOOKUP(A7,'SPED Student Roster'!$A:$C,3,FALSE),"")) | D7: =IF(A7="","",IFERROR(VLOOKUP(A7,'SPED Student Roster'!$A:$D,4,FALSE),"")) | E7: =IF(A7="","",IFERROR(VLOOKUP(A7,'SPED Student Roster'!$A:$E,5,FALSE),""))
B8: =IF(A8="","",IFERROR(VLOOKUP(A8,'SPED Student Roster'!$A:$B,2,FALSE),"")) | C8: =IF(A8="","",IFERROR(VLOOKUP(A8,'SPED Student Roster'!$A:$C,3,FALSE),"")) | D8: =IF(A8="","",IFERROR(VLOOKUP(A8,'SPED Student Roster'!$A:$D,4,FALSE),"")) | E8: =IF(A8="","",IFERROR(VLOOKUP(A8,'SPED Student Roster'!$A:$E,5,FALSE),""))
B9: =IF(A9="","",IFERROR(VLOOKUP(A9,'SPED Student Roster'!$A:$B,2,FALSE),"")) | C9: =IF(A9="","",IFERROR(VLOOKUP(A9,'SPED Student Roster'!$A:$C,3,FALSE),"")) | D9: =IF(A9="","",IFERROR(VLOOKUP(A9,'SPED Student Roster'!$A:$D,4,FALSE),"")) | E9: =IF(A9="","",IFERROR(VLOOKUP(A9,'SPED Student Roster'!$A:$E,5,FALSE),""))
B10: =IF(A10="","",IFERROR(VLOOKUP(A10,'SPED Student Roster'!$A:$B,2,FALSE),"")) | C10: =IF(A10="","",IFERROR(VLOOKUP(A10,'SPED Student Roster'!$A:$C,3,FALSE),"")) | D10: =IF(A10="","",IFERROR(VLOOKUP(A10,'SPED Student Roster'!$A:$D,4,FALSE),"")) | E10: =IF(A10="","",IFERROR(VLOOKUP(A10,'SPED Student Roster'!$A:$E,5,FALSE),""))
B11: =IF(A11="","",IFERROR(VLOOKUP(A11,'SPED Student Roster'!$A:$B,2,FALSE),"")) | C11: =IF(A11="","",IFERROR(VLOOKUP(A11,'SPED Student Roster'!$A:$C,3,FALSE),"")) | D11: =IF(A11="","",IFERROR(VLOOKUP(A11,'SPED Student Roster'!$A:$D,4,FALSE),"")) | E11: =IF(A11="","",IFERROR(VLOOKUP(A11,'SPED Student Roster'!$A:$E,5,FALSE),""))
B12: =IF(A12="","",IFERROR(VLOOKUP(A12,'SPED Student Roster'!$A:$B,2,FALSE),"")) | C12: =IF(A12="","",IFERROR(VLOOKUP(A12,'SPED Student Roster'!$A:$C,3,FALSE),"")) | D12: =IF(A12="","",IFERROR(VLOOKUP(A12,'SPED Student Roster'!$A:$D,4,FALSE),"")) | E12: =IF(A12="","",IFERROR(VLOOKUP(A12,'SPED Student Roster'!$A:$E,5,FALSE),""))
B13: =IF(A13="","",IFERROR(VLOOKUP(A13,'SPED Student Roster'!$A:$B,2,FALSE),"")) | C13: =IF(A13="","",IFERROR(VLOOKUP(A13,'SPED Student Roster'!$A:$C,3,FALSE),"")) | D13: =IF(A13="","",IFERROR(VLOOKUP(A13,'SPED Student Roster'!$A:$D,4,FALSE),"")) | E13: =IF(A13="","",IFERROR(VLOOKUP(A13,'SPED Student Roster'!$A:$E,5,FALSE),""))
B14: =IF(A14="","",IFERROR(VLOOKUP(A14,'SPED Student Roster'!$A:$B,2,FALSE),"")) | C14: =IF(A14="","",IFERROR(VLOOKUP(A14,'SPED Student Roster'!$A:$C,3,FALSE),"")) | D14: =IF(A14="","",IFERROR(VLOOKUP(A14,'SPED Student Roster'!$A:$D,4,FALSE),"")) | E14: =IF(A14="","",IFERROR(VLOOKUP(A14,'SPED Student Roster'!$A:$E,5,FALSE),""))
B15: =IF(A15="","",IFERROR(VLOOKUP(A15,'SPED Student Roster'!$A:$B,2,FALSE),"")) | C15: =IF(A15="","",IFERROR(VLOOKUP(A15,'SPED Student Roster'!$A:$C,3,FALSE),"")) | D15: =IF(A15="","",IFERROR(VLOOKUP(A15,'SPED Student Roster'!$A:$D,4,FALSE),"")) | E15: =IF(A15="","",IFERROR(VLOOKUP(A15,'SPED Student Roster'!$A:$E,5,FALSE),""))
B16: =IF(A16="","",IFERROR(VLOOKUP(A16,'SPED Student Roster'!$A:$B,2,FALSE),"")) | C16: =IF(A16="","",IFERROR(VLOOKUP(A16,'SPED Student Roster'!$A:$C,3,FALSE),"")) | D16: =IF(A16="","",IFERROR(VLOOKUP(A16,'SPED Student Roster'!$A:$D,4,FALSE),"")) | E16: =IF(A16="","",IFERROR(VLOOKUP(A16,'SPED Student Roster'!$A:$E,5,FALSE),""))
B17: =IF(A17="","",IFERROR(VLOOKUP(A17,'SPED Student Roster'!$A:$B,2,FALSE),"")) | C17: =IF(A17="","",IFERROR(VLOOKUP(A17,'SPED Student Roster'!$A:$C,3,FALSE),"")) | D17: =IF(A17="","",IFERROR(VLOOKUP(A17,'SPED Student Roster'!$A:$D,4,FALSE),"")) | E17: =IF(A17="","",IFERROR(VLOOKUP(A17,'SPED Student Roster'!$A:$E,5,FALSE),""))
... B151: =IF(A151="","",IFERROR(VLOOKUP(A151,'SPED Student Roster'!$A:$B,2,FALSE),"")) | C151: =IF(A151="","",IFERROR(VLOOKUP(A151,'SPED Student Roster'!$A:$C,3,FALSE),"")) | D151: =IF(A151="","",IFERROR(VLOOKUP(A151,'SPED Student Roster'!$A:$D,4,FALSE),"")) | E151: =IF(A151="","",IFERROR(VLOOKUP(A151,'SPED Student Roster'!$A:$E,5,FALSE),""))

Sheet CAP Findings
A1: CAP FINDINGS TRACKER — TEA Corrective Action Plan Findings and Tasks
A2: Log each finding from a TEA monitoring visit or complaint investigation. Track systemic and child-specific correction deadlines separately. Each finding may have multiple tasks — use the CAP TASKS section below.
A3: SECTION A: FINDINGS
A4: Finding ID | B4: Campus (if specific) | C4: Finding Number (TEA) | D4: Description | E4: Legal Citation | F4: Issued Date | G4: Systemic Correction Due | H4: Child-Specific Correction Due | I4: Days Until Systemic Due ⚙ | J4: Days Until Child Due ⚙ | K4: Status | L4: Date Closed | M4: TEA Response Required? | N4: Notes
A5: CAP-001 | B5: Districtwide | C5: TEA-2025-114 | D5: Annual IEP reviews not held within 12 months for 3 students | E5: 34 CFR §300.324(b) | F5: 45962 | G5: 46054 | H5: 46006 | I5: =IF(OR(A5="",G5=""),"",IF(K5="Closed","Done",G5-TODAY())) -> -163 | J5: =IF(OR(A5="",H5=""),"",IF(K5="Closed","Done",H5-TODAY())) -> -211 | K5: In Progress | M5: Yes | N5: Evidence collection underway.
I6: =IF(OR(A6="",G6=""),"",IF(K6="Closed","Done",G6-TODAY())) | J6: =IF(OR(A6="",H6=""),"",IF(K6="Closed","Done",H6-TODAY()))
I7: =IF(OR(A7="",G7=""),"",IF(K7="Closed","Done",G7-TODAY())) | J7: =IF(OR(A7="",H7=""),"",IF(K7="Closed","Done",H7-TODAY()))
I8: =IF(OR(A8="",G8=""),"",IF(K8="Closed","Done",G8-TODAY())) | J8: =IF(OR(A8="",H8=""),"",IF(K8="Closed","Done",H8-TODAY()))
I9: =IF(OR(A9="",G9=""),"",IF(K9="Closed","Done",G9-TODAY())) | J9: =IF(OR(A9="",H9=""),"",IF(K9="Closed","Done",H9-TODAY()))
I10: =IF(OR(A10="",G10=""),"",IF(K10="Closed","Done",G10-TODAY())) | J10: =IF(OR(A10="",H10=""),"",IF(K10="Closed","Done",H10-TODAY()))
I11: =IF(OR(A11="",G11=""),"",IF(K11="Closed","Done",G11-TODAY())) | J11: =IF(OR(A11="",H11=""),"",IF(K11="Closed","Done",H11-TODAY()))
I12: =IF(OR(A12="",G12=""),"",IF(K12="Closed","Done",G12-TODAY())) | J12: =IF(OR(A12="",H12=""),"",IF(K12="Closed","Done",H12-TODAY()))
I13: =IF(OR(A13="",G13=""),"",IF(K13="Closed","Done",G13-TODAY())) | J13: =IF(OR(A13="",H13=""),"",IF(K13="Closed","Done",H13-TODAY()))
I14: =IF(OR(A14="",G14=""),"",IF(K14="Closed","Done",G14-TODAY())) | J14: =IF(OR(A14="",H14=""),"",IF(K14="Closed","Done",H14-TODAY()))
I15: =IF(OR(A15="",G15=""),"",IF(K15="Closed","Done",G15-TODAY())) | J15: =IF(OR(A15="",H15=""),"",IF(K15="Closed","Done",H15-TODAY()))
I16: =IF(OR(A16="",G16=""),"",IF(K16="Closed","Done",G16-TODAY())) | J16: =IF(OR(A16="",H16=""),"",IF(K16="Closed","Done",H16-TODAY()))
I17: =IF(OR(A17="",G17=""),"",IF(K17="Closed","Done",G17-TODAY())) | J17: =IF(OR(A17="",H17=""),"",IF(K17="Closed","Done",H17-TODAY()))
... I54: =IF(OR(A54="",G54=""),"",IF(K54="Closed","Done",G54-TODAY())) | J54: =IF(OR(A54="",H54=""),"",IF(K54="Closed","Done",H54-TODAY()))
A55: SECTION B: TASKS (one row per task; link to Finding ID in column A above)
A56: Task ID | B56: Finding ID (cross-ref) | C56: Task Description | D56: Assigned To | E56: Due Date | F56: Days Until Due ⚙ | G56: Status | H56: Completion Date | I56: Evidence / Documentation | J56: Notes
A57: TASK-001 | B57: CAP-001 | C57: Convene ARD meeting for each identified student | D57: SPED Director | E57: 46006 | F57: =IF(OR(A57="",E57=""),"",IF(G57="Closed","Done",E57-TODAY())) -> -211 | G57: In Progress | I57: ARD schedules + signed minutes
F58: =IF(OR(A58="",E58=""),"",IF(G58="Closed","Done",E58-TODAY()))
F59: =IF(OR(A59="",E59=""),"",IF(G59="Closed","Done",E59-TODAY()))
F60: =IF(OR(A60="",E60=""),"",IF(G60="Closed","Done",E60-TODAY()))
F61: =IF(OR(A61="",E61=""),"",IF(G61="Closed","Done",E61-TODAY()))
F62: =IF(OR(A62="",E62=""),"",IF(G62="Closed","Done",E62-TODAY()))
F63: =IF(OR(A63="",E63=""),"",IF(G63="Closed","Done",E63-TODAY()))
F64: =IF(OR(A64="",E64=""),"",IF(G64="Closed","Done",E64-TODAY()))
F65: =IF(OR(A65="",E65=""),"",IF(G65="Closed","Done",E65-TODAY()))
F66: =IF(OR(A66="",E66=""),"",IF(G66="Closed","Done",E66-TODAY()))
F67: =IF(OR(A67="",E67=""),"",IF(G67="Closed","Done",E67-TODAY()))
F68: =IF(OR(A68="",E68=""),"",IF(G68="Closed","Done",E68-TODAY()))
F69: =IF(OR(A69="",E69=""),"",IF(G69="Closed","Done",E69-TODAY()))
... F156: =IF(OR(A156="",E156=""),"",IF(G156="Closed","Done",E156-TODAY()))

Sheet SPPI-13 Transition
A1: SPPI-13 — SECONDARY TRANSITION COMPLIANCE TRACKER
A2: SPPI-13 requires that 100% of SPED students age 16+ (or younger if appropriate) have appropriate measurable postsecondary goals, transition services, and coordinated activities in their IEP. (IDEA 20 U.S.C. §1414(d)(1)(A)(VIII))
A3: This tracker covers all 5 core SPPI-13 compliance elements. Each column is a required component. ALL five must be "Yes" for a student to be counted as compliant.
A4: Student ID | B4: Last Name ⚙ | C4: First Name ⚙ | D4: Grade ⚙ | E4: Campus ⚙ | F4: School Year | G4: 1. Postsecondary Goals in IEP? | H4: Goals Date | I4: 2. Transition Assessments Completed? | J4: Assessment Date | K4: Assessment Types Used | L4: 3. Transition Services in IEP? | M4: Services Date | N4: 4. Student Participated in Planning? | O4: Participation Date | P4: 5. Outside Agency Invited? | Q4: Agency Name | R4: Agency Invitation Date | S4: SPPI-13 Compliant? ⚙ | T4: Notes
A5: MER-004 | B5: =IF(A5="","",IFERROR(VLOOKUP(A5,'SPED Student Roster'!$A:$B,2,FALSE),"")) -> Washington | C5: =IF(A5="","",IFERROR(VLOOKUP(A5,'SPED Student Roster'!$A:$C,3,FALSE),"")) -> Darius | D5: =IF(A5="","",IFERROR(VLOOKUP(A5,'SPED Student Roster'!$A:$D,4,FALSE),"")) -> 12th Grade | E5: =IF(A5="","",IFERROR(VLOOKUP(A5,'SPED Student Roster'!$A:$E,5,FALSE),"")) -> Lincoln High | F5: 2025–2026 | G5: Yes | H5: 45930 | I5: Yes | J5: 45915 | K5: Interest inventory; situational assessment | L5: Yes | M5: 45930 | N5: Yes | O5: 45930 | P5: Yes | Q5: Texas Workforce Solutions — VR | R5: 45910 | S5: =IF(A5="","",IF(AND(G5="Yes",I5="Yes",L5="Yes",N5="Yes",P5="Yes"),"Compliant","Non-Compliant")) -> Compliant | T5: Compliant — all 5 elements documented.
A6: MER-005 | B6: =IF(A6="","",IFERROR(VLOOKUP(A6,'SPED Student Roster'!$A:$B,2,FALSE),"")) -> Nguyen | C6: =IF(A6="","",IFERROR(VLOOKUP(A6,'SPED Student Roster'!$A:$C,3,FALSE),"")) -> Mai | D6: =IF(A6="","",IFERROR(VLOOKUP(A6,'SPED Student Roster'!$A:$D,4,FALSE),"")) -> 9th Grade | E6: =IF(A6="","",IFERROR(VLOOKUP(A6,'SPED Student Roster'!$A:$E,5,FALSE),"")) -> Lincoln High | F6: 2025–2026 | G6: Yes | H6: 45950 | I6: Yes | J6: 45942 | K6: Transition interview | L6: No | N6: Yes | O6: 45950 | P6: No | S6: =IF(A6="","",IF(AND(G6="Yes",I6="Yes",L6="Yes",N6="Yes",P6="Yes"),"Compliant","Non-Compliant")) -> Non-Compliant | T6: Services not yet documented — follow up at spring ARD.
B7: =IF(A7="","",IFERROR(VLOOKUP(A7,'SPED Student Roster'!$A:$B,2,FALSE),"")) | C7: =IF(A7="","",IFERROR(VLOOKUP(A7,'SPED Student Roster'!$A:$C,3,FALSE),"")) | D7: =IF(A7="","",IFERROR(VLOOKUP(A7,'SPED Student Roster'!$A:$D,4,FALSE),"")) | E7: =IF(A7="","",IFERROR(VLOOKUP(A7,'SPED Student Roster'!$A:$E,5,FALSE),"")) | S7: =IF(A7="","",IF(AND(G7="Yes",I7="Yes",L7="Yes",N7="Yes",P7="Yes"),"Compliant","Non-Compliant"))
B8: =IF(A8="","",IFERROR(VLOOKUP(A8,'SPED Student Roster'!$A:$B,2,FALSE),"")) | C8: =IF(A8="","",IFERROR(VLOOKUP(A8,'SPED Student Roster'!$A:$C,3,FALSE),"")) | D8: =IF(A8="","",IFERROR(VLOOKUP(A8,'SPED Student Roster'!$A:$D,4,FALSE),"")) | E8: =IF(A8="","",IFERROR(VLOOKUP(A8,'SPED Student Roster'!$A:$E,5,FALSE),"")) | S8: =IF(A8="","",IF(AND(G8="Yes",I8="Yes",L8="Yes",N8="Yes",P8="Yes"),"Compliant","Non-Compliant"))
B9: =IF(A9="","",IFERROR(VLOOKUP(A9,'SPED Student Roster'!$A:$B,2,FALSE),"")) | C9: =IF(A9="","",IFERROR(VLOOKUP(A9,'SPED Student Roster'!$A:$C,3,FALSE),"")) | D9: =IF(A9="","",IFERROR(VLOOKUP(A9,'SPED Student Roster'!$A:$D,4,FALSE),"")) | E9: =IF(A9="","",IFERROR(VLOOKUP(A9,'SPED Student Roster'!$A:$E,5,FALSE),"")) | S9: =IF(A9="","",IF(AND(G9="Yes",I9="Yes",L9="Yes",N9="Yes",P9="Yes"),"Compliant","Non-Compliant"))
B10: =IF(A10="","",IFERROR(VLOOKUP(A10,'SPED Student Roster'!$A:$B,2,FALSE),"")) | C10: =IF(A10="","",IFERROR(VLOOKUP(A10,'SPED Student Roster'!$A:$C,3,FALSE),"")) | D10: =IF(A10="","",IFERROR(VLOOKUP(A10,'SPED Student Roster'!$A:$D,4,FALSE),"")) | E10: =IF(A10="","",IFERROR(VLOOKUP(A10,'SPED Student Roster'!$A:$E,5,FALSE),"")) | S10: =IF(A10="","",IF(AND(G10="Yes",I10="Yes",L10="Yes",N10="Yes",P10="Yes"),"Compliant","Non-Compliant"))
B11: =IF(A11="","",IFERROR(VLOOKUP(A11,'SPED Student Roster'!$A:$B,2,FALSE),"")) | C11: =IF(A11="","",IFERROR(VLOOKUP(A11,'SPED Student Roster'!$A:$C,3,FALSE),"")) | D11: =IF(A11="","",IFERROR(VLOOKUP(A11,'SPED Student Roster'!$A:$D,4,FALSE),"")) | E11: =IF(A11="","",IFERROR(VLOOKUP(A11,'SPED Student Roster'!$A:$E,5,FALSE),"")) | S11: =IF(A11="","",IF(AND(G11="Yes",I11="Yes",L11="Yes",N11="Yes",P11="Yes"),"Compliant","Non-Compliant"))
B12: =IF(A12="","",IFERROR(VLOOKUP(A12,'SPED Student Roster'!$A:$B,2,FALSE),"")) | C12: =IF(A12="","",IFERROR(VLOOKUP(A12,'SPED Student Roster'!$A:$C,3,FALSE),"")) | D12: =IF(A12="","",IFERROR(VLOOKUP(A12,'SPED Student Roster'!$A:$D,4,FALSE),"")) | E12: =IF(A12="","",IFERROR(VLOOKUP(A12,'SPED Student Roster'!$A:$E,5,FALSE),"")) | S12: =IF(A12="","",IF(AND(G12="Yes",I12="Yes",L12="Yes",N12="Yes",P12="Yes"),"Compliant","Non-Compliant"))
B13: =IF(A13="","",IFERROR(VLOOKUP(A13,'SPED Student Roster'!$A:$B,2,FALSE),"")) | C13: =IF(A13="","",IFERROR(VLOOKUP(A13,'SPED Student Roster'!$A:$C,3,FALSE),"")) | D13: =IF(A13="","",IFERROR(VLOOKUP(A13,'SPED Student Roster'!$A:$D,4,FALSE),"")) | E13: =IF(A13="","",IFERROR(VLOOKUP(A13,'SPED Student Roster'!$A:$E,5,FALSE),"")) | S13: =IF(A13="","",IF(AND(G13="Yes",I13="Yes",L13="Yes",N13="Yes",P13="Yes"),"Compliant","Non-Compliant"))
B14: =IF(A14="","",IFERROR(VLOOKUP(A14,'SPED Student Roster'!$A:$B,2,FALSE),"")) | C14: =IF(A14="","",IFERROR(VLOOKUP(A14,'SPED Student Roster'!$A:$C,3,FALSE),"")) | D14: =IF(A14="","",IFERROR(VLOOKUP(A14,'SPED Student Roster'!$A:$D,4,FALSE),"")) | E14: =IF(A14="","",IFERROR(VLOOKUP(A14,'SPED Student Roster'!$A:$E,5,FALSE),"")) | S14: =IF(A14="","",IF(AND(G14="Yes",I14="Yes",L14="Yes",N14="Yes",P14="Yes"),"Compliant","Non-Compliant"))
B15: =IF(A15="","",IFERROR(VLOOKUP(A15,'SPED Student Roster'!$A:$B,2,FALSE),"")) | C15: =IF(A15="","",IFERROR(VLOOKUP(A15,'SPED Student Roster'!$A:$C,3,FALSE),"")) | D15: =IF(A15="","",IFERROR(VLOOKUP(A15,'SPED Student Roster'!$A:$D,4,FALSE),"")) | E15: =IF(A15="","",IFERROR(VLOOKUP(A15,'SPED Student Roster'!$A:$E,5,FALSE),"")) | S15: =IF(A15="","",IF(AND(G15="Yes",I15="Yes",L15="Yes",N15="Yes",P15="Yes"),"Compliant","Non-Compliant"))
B16: =IF(A16="","",IFERROR(VLOOKUP(A16,'SPED Student Roster'!$A:$B,2,FALSE),"")) | C16: =IF(A16="","",IFERROR(VLOOKUP(A16,'SPED Student Roster'!$A:$C,3,FALSE),"")) | D16: =IF(A16="","",IFERROR(VLOOKUP(A16,'SPED Student Roster'!$A:$D,4,FALSE),"")) | E16: =IF(A16="","",IFERROR(VLOOKUP(A16,'SPED Student Roster'!$A:$E,5,FALSE),"")) | S16: =IF(A16="","",IF(AND(G16="Yes",I16="Yes",L16="Yes",N16="Yes",P16="Yes"),"Compliant","Non-Compliant"))
B17: =IF(A17="","",IFERROR(VLOOKUP(A17,'SPED Student Roster'!$A:$B,2,FALSE),"")) | C17: =IF(A17="","",IFERROR(VLOOKUP(A17,'SPED Student Roster'!$A:$C,3,FALSE),"")) | D17: =IF(A17="","",IFERROR(VLOOKUP(A17,'SPED Student Roster'!$A:$D,4,FALSE),"")) | E17: =IF(A17="","",IFERROR(VLOOKUP(A17,'SPED Student Roster'!$A:$E,5,FALSE),"")) | S17: =IF(A17="","",IF(AND(G17="Yes",I17="Yes",L17="Yes",N17="Yes",P17="Yes"),"Compliant","Non-Compliant"))
B18: =IF(A18="","",IFERROR(VLOOKUP(A18,'SPED Student Roster'!$A:$B,2,FALSE),"")) | C18: =IF(A18="","",IFERROR(VLOOKUP(A18,'SPED Student Roster'!$A:$C,3,FALSE),"")) | D18: =IF(A18="","",IFERROR(VLOOKUP(A18,'SPED Student Roster'!$A:$D,4,FALSE),"")) | E18: =IF(A18="","",IFERROR(VLOOKUP(A18,'SPED Student Roster'!$A:$E,5,FALSE),"")) | S18: =IF(A18="","",IF(AND(G18="Yes",I18="Yes",L18="Yes",N18="Yes",P18="Yes"),"Compliant","Non-Compliant"))
... B101: =IF(A101="","",IFERROR(VLOOKUP(A101,'SPED Student Roster'!$A:$B,2,FALSE),"")) | C101: =IF(A101="","",IFERROR(VLOOKUP(A101,'SPED Student Roster'!$A:$C,3,FALSE),"")) | D101: =IF(A101="","",IFERROR(VLOOKUP(A101,'SPED Student Roster'!$A:$D,4,FALSE),"")) | E101: =IF(A101="","",IFERROR(VLOOKUP(A101,'SPED Student Roster'!$A:$E,5,FALSE),"")) | S101: =IF(A101="","",IF(AND(G101="Yes",I101="Yes",L101="Yes",N101="Yes",P101="Yes"),"Compliant","Non-Compliant"))

Sheet Dashboard
A1: DASHBOARD — SPED Compliance Summary (No Data Entry Needed)
A2: ="Reflects data as of: "&TEXT(TODAY(),"MM/DD/YYYY") -> Reflects data as of: 07/14/2026
A4: KEY METRICS
A5: Total SPED Students | B5: =MAX(0,COUNTA('SPED Student Roster'!B:B)-2) -> 4
A6: Students with Active IEPs | B6: =COUNTIF('IEP Tracker'!G:G,"Active") -> 2
A7: IEP Annual Reviews Due (30d) | B7: =COUNTIFS('IEP Tracker'!K:K,"<="&30,'IEP Tracker'!L:L,"<>Yes") -> 3
A8: IEP Annual Reviews Overdue | B8: =COUNTIFS('IEP Tracker'!J:J,"<"&TODAY(),'IEP Tracker'!L:L,"<>Yes") -> 3
A9: Active 504 Plans | B9: =COUNTIF('504 Plan Tracker'!G:G,"Active") -> 1
A10: 504 Reviews Due (30d) | B10: =COUNTIFS('504 Plan Tracker'!K:K,"<="&30,'504 Plan Tracker'!L:L,"<>Yes") -> 2
A11: 504 Reviews Overdue | B11: =COUNTIFS('504 Plan Tracker'!J:J,"<"&TODAY(),'504 Plan Tracker'!L:L,"<>Yes") -> 2
A12: Students with Dyslexia | B12: =MAX(0,COUNTA('Dyslexia-HB 3928'!A:A)-3) -> 2
A13: HB 3928 Reviews Pending | B13: =COUNTIF('Dyslexia-HB 3928'!H:H,"Pending Review") -> 1
A14: Open CAP Findings | B14: =COUNTIF('CAP Findings'!K:K,"Open")+COUNTIF('CAP Findings'!K:K,"In Progress") -> 1
A15: CAP Tasks Overdue | B15: =COUNTIFS('CAP Findings'!G:G,"<"&TODAY(),'CAP Findings'!H:H,"") -> 0
A16: SPPI-13 Compliant Students | B16: =COUNTIF('SPPI-13 Transition'!S:S,"✅ COMPLIANT") -> 0
A17: SPPI-13 Non-Compliant Students | B17: =COUNTIF('SPPI-13 Transition'!S:S,"❌ NOT COMPLIANT") -> 0
A19: SPED STUDENTS BY STATUS
A20: Eligible — Active IEP | B20: =COUNTIF('SPED Student Roster'!F:F,"Eligible — Active IEP") -> 4
A21: Referred — Evaluation Pending | B21: =COUNTIF('SPED Student Roster'!F:F,"Referred — Evaluation Pending") -> 0
A22: Exited SPED | B22: =COUNTIF('SPED Student Roster'!F:F,"Exited SPED") -> 0
A23: Not Eligible | B23: =COUNTIF('SPED Student Roster'!F:F,"Not Eligible") -> 0
A24: 504 Only | B24: =COUNTIF('SPED Student Roster'!F:F,"504 Only") -> 1
A25: Dyslexia Only | B25: =COUNTIF('SPED Student Roster'!F:F,"Dyslexia Only") -> 0
A27: IEP ANNUAL REVIEW COUNTDOWN
A28: [GOOGLE SHEETS] Dynamic filter — paste in A below:
A29: =IFERROR(FILTER('IEP Tracker'!C4:R500,ISNUMBER(VALUE('IEP Tracker'!K4:K500)),'IEP Tracker'!L4:L500<>"Yes"),"No pending reviews")
A30: For Excel: Go to IEP Tracker tab → Sort by column K (Days Until Review) ascending.
A32: © 2025 Clear Path Education Group, LLC | clearpathedgroup.com | Upgrade to Meridian for automated compliance tracking.

Sheet 📋 Compliance Health Board
A1: 📋 WEEKLY SPED COMPLIANCE HEALTH BOARD
A2: ="As of: "&TEXT(TODAY(),"MMMM D, YYYY") -> As of: July 14, 2026
A3: Print this tab for your weekly SPED compliance review. All data auto-updates from your other tabs.
A5: 🔴 IEP ANNUAL REVIEWS DUE WITHIN 30 DAYS
A6: IEP ID | B6: Student ID | C6: Last Name | D6: Grade | E6: Campus | F6: Review Due Date | G6: Days Remaining | H6: Case Manager
A7: =IF('IEP Tracker'!B4="","",IF(AND('IEP Tracker'!L4<>"Yes",'IEP Tracker'!J4-TODAY()<=30),'IEP Tracker'!A4,"")) -> IEP-001 | B7: =IF('IEP Tracker'!B4="","",IF(AND('IEP Tracker'!L4<>"Yes",'IEP Tracker'!J4-TODAY()<=30),'IEP Tracker'!B4,"")) -> MER-001 | C7: =IF('IEP Tracker'!B4="","",IF(AND('IEP Tracker'!L4<>"Yes",'IEP Tracker'!J4-TODAY()<=30),'IEP Tracker'!C4,"")) -> Alvarez | D7: =IF('IEP Tracker'!B4="","",IF(AND('IEP Tracker'!L4<>"Yes",'IEP Tracker'!J4-TODAY()<=30),'IEP Tracker'!D4,"")) -> Elena | E7: =IF('IEP Tracker'!B4="","",IF(AND('IEP Tracker'!L4<>"Yes",'IEP Tracker'!J4-TODAY()<=30),'IEP Tracker'!E4,"")) -> 11th Grade | F7: =IF('IEP Tracker'!B4="","",IF(AND('IEP Tracker'!L4<>"Yes",'IEP Tracker'!J4-TODAY()<=30),'IEP Tracker'!J4,"")) -> 46097 | G7: =IF('IEP Tracker'!B4="","",IF(AND('IEP Tracker'!L4<>"Yes",'IEP Tracker'!J4-TODAY()<=30),'IEP Tracker'!K4,"")) -> -120 | H7: =IF('IEP Tracker'!B4="","",IF(AND('IEP Tracker'!L4<>"Yes",'IEP Tracker'!J4-TODAY()<=30),'IEP Tracker'!H4,"")) -> Ms. Garcia
A8: =IF('IEP Tracker'!B5="","",IF(AND('IEP Tracker'!L5<>"Yes",'IEP Tracker'!J5-TODAY()<=30),'IEP Tracker'!A5,"")) | B8: =IF('IEP Tracker'!B5="","",IF(AND('IEP Tracker'!L5<>"Yes",'IEP Tracker'!J5-TODAY()<=30),'IEP Tracker'!B5,"")) | C8: =IF('IEP Tracker'!B5="","",IF(AND('IEP Tracker'!L5<>"Yes",'IEP Tracker'!J5-TODAY()<=30),'IEP Tracker'!C5,"")) | D8: =IF('IEP Tracker'!B5="","",IF(AND('IEP Tracker'!L5<>"Yes",'IEP Tracker'!J5-TODAY()<=30),'IEP Tracker'!D5,"")) | E8: =IF('IEP Tracker'!B5="","",IF(AND('IEP Tracker'!L5<>"Yes",'IEP Tracker'!J5-TODAY()<=30),'IEP Tracker'!E5,"")) | F8: =IF('IEP Tracker'!B5="","",IF(AND('IEP Tracker'!L5<>"Yes",'IEP Tracker'!J5-TODAY()<=30),'IEP Tracker'!J5,"")) | G8: =IF('IEP Tracker'!B5="","",IF(AND('IEP Tracker'!L5<>"Yes",'IEP Tracker'!J5-TODAY()<=30),'IEP Tracker'!K5,"")) | H8: =IF('IEP Tracker'!B5="","",IF(AND('IEP Tracker'!L5<>"Yes",'IEP Tracker'!J5-TODAY()<=30),'IEP Tracker'!H5,""))
A9: =IF('IEP Tracker'!B6="","",IF(AND('IEP Tracker'!L6<>"Yes",'IEP Tracker'!J6-TODAY()<=30),'IEP Tracker'!A6,"")) -> IEP-003 | B9: =IF('IEP Tracker'!B6="","",IF(AND('IEP Tracker'!L6<>"Yes",'IEP Tracker'!J6-TODAY()<=30),'IEP Tracker'!B6,"")) -> MER-004 | C9: =IF('IEP Tracker'!B6="","",IF(AND('IEP Tracker'!L6<>"Yes",'IEP Tracker'!J6-TODAY()<=30),'IEP Tracker'!C6,"")) -> Washington | D9: =IF('IEP Tracker'!B6="","",IF(AND('IEP Tracker'!L6<>"Yes",'IEP Tracker'!J6-TODAY()<=30),'IEP Tracker'!D6,"")) -> Darius | E9: =IF('IEP Tracker'!B6="","",IF(AND('IEP Tracker'!L6<>"Yes",'IEP Tracker'!J6-TODAY()<=30),'IEP Tracker'!E6,"")) -> 12th Grade | F9: =IF('IEP Tracker'!B6="","",IF(AND('IEP Tracker'!L6<>"Yes",'IEP Tracker'!J6-TODAY()<=30),'IEP Tracker'!J6,"")) -> 46144 | G9: =IF('IEP Tracker'!B6="","",IF(AND('IEP Tracker'!L6<>"Yes",'IEP Tracker'!J6-TODAY()<=30),'IEP Tracker'!K6,"")) -> -73 | H9: =IF('IEP Tracker'!B6="","",IF(AND('IEP Tracker'!L6<>"Yes",'IEP Tracker'!J6-TODAY()<=30),'IEP Tracker'!H6,"")) -> Ms. Rivera
A10: =IF('IEP Tracker'!B7="","",IF(AND('IEP Tracker'!L7<>"Yes",'IEP Tracker'!J7-TODAY()<=30),'IEP Tracker'!A7,"")) -> IEP-004 | B10: =IF('IEP Tracker'!B7="","",IF(AND('IEP Tracker'!L7<>"Yes",'IEP Tracker'!J7-TODAY()<=30),'IEP Tracker'!B7,"")) -> MER-005 | C10: =IF('IEP Tracker'!B7="","",IF(AND('IEP Tracker'!L7<>"Yes",'IEP Tracker'!J7-TODAY()<=30),'IEP Tracker'!C7,"")) -> Nguyen | D10: =IF('IEP Tracker'!B7="","",IF(AND('IEP Tracker'!L7<>"Yes",'IEP Tracker'!J7-TODAY()<=30),'IEP Tracker'!D7,"")) -> Mai | E10: =IF('IEP Tracker'!B7="","",IF(AND('IEP Tracker'!L7<>"Yes",'IEP Tracker'!J7-TODAY()<=30),'IEP Tracker'!E7,"")) -> 9th Grade | F10: =IF('IEP Tracker'!B7="","",IF(AND('IEP Tracker'!L7<>"Yes",'IEP Tracker'!J7-TODAY()<=30),'IEP Tracker'!J7,"")) -> 46083 | G10: =IF('IEP Tracker'!B7="","",IF(AND('IEP Tracker'!L7<>"Yes",'IEP Tracker'!J7-TODAY()<=30),'IEP Tracker'!K7,"")) -> -134 | H10: =IF('IEP Tracker'!B7="","",IF(AND('IEP Tracker'!L7<>"Yes",'IEP Tracker'!J7-TODAY()<=30),'IEP Tracker'!H7,"")) -> Ms. Garcia
A11: =IF('IEP Tracker'!B8="","",IF(AND('IEP Tracker'!L8<>"Yes",'IEP Tracker'!J8-TODAY()<=30),'IEP Tracker'!A8,"")) | B11: =IF('IEP Tracker'!B8="","",IF(AND('IEP Tracker'!L8<>"Yes",'IEP Tracker'!J8-TODAY()<=30),'IEP Tracker'!B8,"")) | C11: =IF('IEP Tracker'!B8="","",IF(AND('IEP Tracker'!L8<>"Yes",'IEP Tracker'!J8-TODAY()<=30),'IEP Tracker'!C8,"")) | D11: =IF('IEP Tracker'!B8="","",IF(AND('IEP Tracker'!L8<>"Yes",'IEP Tracker'!J8-TODAY()<=30),'IEP Tracker'!D8,"")) | E11: =IF('IEP Tracker'!B8="","",IF(AND('IEP Tracker'!L8<>"Yes",'IEP Tracker'!J8-TODAY()<=30),'IEP Tracker'!E8,"")) | F11: =IF('IEP Tracker'!B8="","",IF(AND('IEP Tracker'!L8<>"Yes",'IEP Tracker'!J8-TODAY()<=30),'IEP Tracker'!J8,"")) | G11: =IF('IEP Tracker'!B8="","",IF(AND('IEP Tracker'!L8<>"Yes",'IEP Tracker'!J8-TODAY()<=30),'IEP Tracker'!K8,"")) | H11: =IF('IEP Tracker'!B8="","",IF(AND('IEP Tracker'!L8<>"Yes",'IEP Tracker'!J8-TODAY()<=30),'IEP Tracker'!H8,""))
A12: =IF('IEP Tracker'!B9="","",IF(AND('IEP Tracker'!L9<>"Yes",'IEP Tracker'!J9-TODAY()<=30),'IEP Tracker'!A9,"")) | B12: =IF('IEP Tracker'!B9="","",IF(AND('IEP Tracker'!L9<>"Yes",'IEP Tracker'!J9-TODAY()<=30),'IEP Tracker'!B9,"")) | C12: =IF('IEP Tracker'!B9="","",IF(AND('IEP Tracker'!L9<>"Yes",'IEP Tracker'!J9-TODAY()<=30),'IEP Tracker'!C9,"")) | D12: =IF('IEP Tracker'!B9="","",IF(AND('IEP Tracker'!L9<>"Yes",'IEP Tracker'!J9-TODAY()<=30),'IEP Tracker'!D9,"")) | E12: =IF('IEP Tracker'!B9="","",IF(AND('IEP Tracker'!L9<>"Yes",'IEP Tracker'!J9-TODAY()<=30),'IEP Tracker'!E9,"")) | F12: =IF('IEP Tracker'!B9="","",IF(AND('IEP Tracker'!L9<>"Yes",'IEP Tracker'!J9-TODAY()<=30),'IEP Tracker'!J9,"")) | G12: =IF('IEP Tracker'!B9="","",IF(AND('IEP Tracker'!L9<>"Yes",'IEP Tracker'!J9-TODAY()<=30),'IEP Tracker'!K9,"")) | H12: =IF('IEP Tracker'!B9="","",IF(AND('IEP Tracker'!L9<>"Yes",'IEP Tracker'!J9-TODAY()<=30),'IEP Tracker'!H9,""))
A13: =IF('IEP Tracker'!B10="","",IF(AND('IEP Tracker'!L10<>"Yes",'IEP Tracker'!J10-TODAY()<=30),'IEP Tracker'!A10,"")) | B13: =IF('IEP Tracker'!B10="","",IF(AND('IEP Tracker'!L10<>"Yes",'IEP Tracker'!J10-TODAY()<=30),'IEP Tracker'!B10,"")) | C13: =IF('IEP Tracker'!B10="","",IF(AND('IEP Tracker'!L10<>"Yes",'IEP Tracker'!J10-TODAY()<=30),'IEP Tracker'!C10,"")) | D13: =IF('IEP Tracker'!B10="","",IF(AND('IEP Tracker'!L10<>"Yes",'IEP Tracker'!J10-TODAY()<=30),'IEP Tracker'!D10,"")) | E13: =IF('IEP Tracker'!B10="","",IF(AND('IEP Tracker'!L10<>"Yes",'IEP Tracker'!J10-TODAY()<=30),'IEP Tracker'!E10,"")) | F13: =IF('IEP Tracker'!B10="","",IF(AND('IEP Tracker'!L10<>"Yes",'IEP Tracker'!J10-TODAY()<=30),'IEP Tracker'!J10,"")) | G13: =IF('IEP Tracker'!B10="","",IF(AND('IEP Tracker'!L10<>"Yes",'IEP Tracker'!J10-TODAY()<=30),'IEP Tracker'!K10,"")) | H13: =IF('IEP Tracker'!B10="","",IF(AND('IEP Tracker'!L10<>"Yes",'IEP Tracker'!J10-TODAY()<=30),'IEP Tracker'!H10,""))
A14: =IF('IEP Tracker'!B11="","",IF(AND('IEP Tracker'!L11<>"Yes",'IEP Tracker'!J11-TODAY()<=30),'IEP Tracker'!A11,"")) | B14: =IF('IEP Tracker'!B11="","",IF(AND('IEP Tracker'!L11<>"Yes",'IEP Tracker'!J11-TODAY()<=30),'IEP Tracker'!B11,"")) | C14: =IF('IEP Tracker'!B11="","",IF(AND('IEP Tracker'!L11<>"Yes",'IEP Tracker'!J11-TODAY()<=30),'IEP Tracker'!C11,"")) | D14: =IF('IEP Tracker'!B11="","",IF(AND('IEP Tracker'!L11<>"Yes",'IEP Tracker'!J11-TODAY()<=30),'IEP Tracker'!D11,"")) | E14: =IF('IEP Tracker'!B11="","",IF(AND('IEP Tracker'!L11<>"Yes",'IEP Tracker'!J11-TODAY()<=30),'IEP Tracker'!E11,"")) | F14: =IF('IEP Tracker'!B11="","",IF(AND('IEP Tracker'!L11<>"Yes",'IEP Tracker'!J11-TODAY()<=30),'IEP Tracker'!J11,"")) | G14: =IF('IEP Tracker'!B11="","",IF(AND('IEP Tracker'!L11<>"Yes",'IEP Tracker'!J11-TODAY()<=30),'IEP Tracker'!K11,"")) | H14: =IF('IEP Tracker'!B11="","",IF(AND('IEP Tracker'!L11<>"Yes",'IEP Tracker'!J11-TODAY()<=30),'IEP Tracker'!H11,""))
A15: =IF('IEP Tracker'!B12="","",IF(AND('IEP Tracker'!L12<>"Yes",'IEP Tracker'!J12-TODAY()<=30),'IEP Tracker'!A12,"")) | B15: =IF('IEP Tracker'!B12="","",IF(AND('IEP Tracker'!L12<>"Yes",'IEP Tracker'!J12-TODAY()<=30),'IEP Tracker'!B12,"")) | C15: =IF('IEP Tracker'!B12="","",IF(AND('IEP Tracker'!L12<>"Yes",'IEP Tracker'!J12-TODAY()<=30),'IEP Tracker'!C12,"")) | D15: =IF('IEP Tracker'!B12="","",IF(AND('IEP Tracker'!L12<>"Yes",'IEP Tracker'!J12-TODAY()<=30),'IEP Tracker'!D12,"")) | E15: =IF('IEP Tracker'!B12="","",IF(AND('IEP Tracker'!L12<>"Yes",'IEP Tracker'!J12-TODAY()<=30),'IEP Tracker'!E12,"")) | F15: =IF('IEP Tracker'!B12="","",IF(AND('IEP Tracker'!L12<>"Yes",'IEP Tracker'!J12-TODAY()<=30),'IEP Tracker'!J12,"")) | G15: =IF('IEP Tracker'!B12="","",IF(AND('IEP Tracker'!L12<>"Yes",'IEP Tracker'!J12-TODAY()<=30),'IEP Tracker'!K12,"")) | H15: =IF('IEP Tracker'!B12="","",IF(AND('IEP Tracker'!L12<>"Yes",'IEP Tracker'!J12-TODAY()<=30),'IEP Tracker'!H12,""))
A16: =IF('IEP Tracker'!B13="","",IF(AND('IEP Tracker'!L13<>"Yes",'IEP Tracker'!J13-TODAY()<=30),'IEP Tracker'!A13,"")) | B16: =IF('IEP Tracker'!B13="","",IF(AND('IEP Tracker'!L13<>"Yes",'IEP Tracker'!J13-TODAY()<=30),'IEP Tracker'!B13,"")) | C16: =IF('IEP Tracker'!B13="","",IF(AND('IEP Tracker'!L13<>"Yes",'IEP Tracker'!J13-TODAY()<=30),'IEP Tracker'!C13,"")) | D16: =IF('IEP Tracker'!B13="","",IF(AND('IEP Tracker'!L13<>"Yes",'IEP Tracker'!J13-TODAY()<=30),'IEP Tracker'!D13,"")) | E16: =IF('IEP Tracker'!B13="","",IF(AND('IEP Tracker'!L13<>"Yes",'IEP Tracker'!J13-TODAY()<=30),'IEP Tracker'!E13,"")) | F16: =IF('IEP Tracker'!B13="","",IF(AND('IEP Tracker'!L13<>"Yes",'IEP Tracker'!J13-TODAY()<=30),'IEP Tracker'!J13,"")) | G16: =IF('IEP Tracker'!B13="","",IF(AND('IEP Tracker'!L13<>"Yes",'IEP Tracker'!J13-TODAY()<=30),'IEP Tracker'!K13,"")) | H16: =IF('IEP Tracker'!B13="","",IF(AND('IEP Tracker'!L13<>"Yes",'IEP Tracker'!J13-TODAY()<=30),'IEP Tracker'!H13,""))
A17: =IF('IEP Tracker'!B14="","",IF(AND('IEP Tracker'!L14<>"Yes",'IEP Tracker'!J14-TODAY()<=30),'IEP Tracker'!A14,"")) | B17: =IF('IEP Tracker'!B14="","",IF(AND('IEP Tracker'!L14<>"Yes",'IEP Tracker'!J14-TODAY()<=30),'IEP Tracker'!B14,"")) | C17: =IF('IEP Tracker'!B14="","",IF(AND('IEP Tracker'!L14<>"Yes",'IEP Tracker'!J14-TODAY()<=30),'IEP Tracker'!C14,"")) | D17: =IF('IEP Tracker'!B14="","",IF(AND('IEP Tracker'!L14<>"Yes",'IEP Tracker'!J14-TODAY()<=30),'IEP Tracker'!D14,"")) | E17: =IF('IEP Tracker'!B14="","",IF(AND('IEP Tracker'!L14<>"Yes",'IEP Tracker'!J14-TODAY()<=30),'IEP Tracker'!E14,"")) | F17: =IF('IEP Tracker'!B14="","",IF(AND('IEP Tracker'!L14<>"Yes",'IEP Tracker'!J14-TODAY()<=30),'IEP Tracker'!J14,"")) | G17: =IF('IEP Tracker'!B14="","",IF(AND('IEP Tracker'!L14<>"Yes",'IEP Tracker'!J14-TODAY()<=30),'IEP Tracker'!K14,"")) | H17: =IF('IEP Tracker'!B14="","",IF(AND('IEP Tracker'!L14<>"Yes",'IEP Tracker'!J14-TODAY()<=30),'IEP Tracker'!H14,""))
A18: =IF('IEP Tracker'!B15="","",IF(AND('IEP Tracker'!L15<>"Yes",'IEP Tracker'!J15-TODAY()<=30),'IEP Tracker'!A15,"")) | B18: =IF('IEP Tracker'!B15="","",IF(AND('IEP Tracker'!L15<>"Yes",'IEP Tracker'!J15-TODAY()<=30),'IEP Tracker'!B15,"")) | C18: =IF('IEP Tracker'!B15="","",IF(AND('IEP Tracker'!L15<>"Yes",'IEP Tracker'!J15-TODAY()<=30),'IEP Tracker'!C15,"")) | D18: =IF('IEP Tracker'!B15="","",IF(AND('IEP Tracker'!L15<>"Yes",'IEP Tracker'!J15-TODAY()<=30),'IEP Tracker'!D15,"")) | E18: =IF('IEP Tracker'!B15="","",IF(AND('IEP Tracker'!L15<>"Yes",'IEP Tracker'!J15-TODAY()<=30),'IEP Tracker'!E15,"")) | F18: =IF('IEP Tracker'!B15="","",IF(AND('IEP Tracker'!L15<>"Yes",'IEP Tracker'!J15-TODAY()<=30),'IEP Tracker'!J15,"")) | G18: =IF('IEP Tracker'!B15="","",IF(AND('IEP Tracker'!L15<>"Yes",'IEP Tracker'!J15-TODAY()<=30),'IEP Tracker'!K15,"")) | H18: =IF('IEP Tracker'!B15="","",IF(AND('IEP Tracker'!L15<>"Yes",'IEP Tracker'!J15-TODAY()<=30),'IEP Tracker'!H15,""))
... A21: =IF('IEP Tracker'!B18="","",IF(AND('IEP Tracker'!L18<>"Yes",'IEP Tracker'!J18-TODAY()<=30),'IEP Tracker'!A18,"")) | B21: =IF('IEP Tracker'!B18="","",IF(AND('IEP Tracker'!L18<>"Yes",'IEP Tracker'!J18-TODAY()<=30),'IEP Tracker'!B18,"")) | C21: =IF('IEP Tracker'!B18="","",IF(AND('IEP Tracker'!L18<>"Yes",'IEP Tracker'!J18-TODAY()<=30),'IEP Tracker'!C18,"")) | D21: =IF('IEP Tracker'!B18="","",IF(AND('IEP Tracker'!L18<>"Yes",'IEP Tracker'!J18-TODAY()<=30),'IEP Tracker'!D18,"")) | E21: =IF('IEP Tracker'!B18="","",IF(AND('IEP Tracker'!L18<>"Yes",'IEP Tracker'!J18-TODAY()<=30),'IEP Tracker'!E18,"")) | F21: =IF('IEP Tracker'!B18="","",IF(AND('IEP Tracker'!L18<>"Yes",'IEP Tracker'!J18-TODAY()<=30),'IEP Tracker'!J18,"")) | G21: =IF('IEP Tracker'!B18="","",IF(AND('IEP Tracker'!L18<>"Yes",'IEP Tracker'!J18-TODAY()<=30),'IEP Tracker'!K18,"")) | H21: =IF('IEP Tracker'!B18="","",IF(AND('IEP Tracker'!L18<>"Yes",'IEP Tracker'!J18-TODAY()<=30),'IEP Tracker'!H18,""))
A23: ⚠ 504 PLAN REVIEWS DUE WITHIN 30 DAYS
A24: 504 ID | B24: Student ID | C24: Last Name | D24: Grade | E24: Campus | F24: Review Due Date | G24: Days Remaining | H24: Case Manager
A25: =IF('504 Plan Tracker'!B4="","",IF(AND('504 Plan Tracker'!L4<>"Yes",'504 Plan Tracker'!J4-TODAY()<=30),'504 Plan Tracker'!A4,"")) -> 504-001 | B25: =IF('504 Plan Tracker'!B4="","",IF(AND('504 Plan Tracker'!L4<>"Yes",'504 Plan Tracker'!J4-TODAY()<=30),'504 Plan Tracker'!B4,"")) -> MER-003 | C25: =IF('504 Plan Tracker'!B4="","",IF(AND('504 Plan Tracker'!L4<>"Yes",'504 Plan Tracker'!J4-TODAY()<=30),'504 Plan Tracker'!C4,"")) -> Kim | D25: =IF('504 Plan Tracker'!B4="","",IF(AND('504 Plan Tracker'!L4<>"Yes",'504 Plan Tracker'!J4-TODAY()<=30),'504 Plan Tracker'!D4,"")) -> Sarah | E25: =IF('504 Plan Tracker'!B4="","",IF(AND('504 Plan Tracker'!L4<>"Yes",'504 Plan Tracker'!J4-TODAY()<=30),'504 Plan Tracker'!E4,"")) -> 6th Grade | F25: =IF('504 Plan Tracker'!B4="","",IF(AND('504 Plan Tracker'!L4<>"Yes",'504 Plan Tracker'!J4-TODAY()<=30),'504 Plan Tracker'!F4,"")) -> Jefferson Middle | G25: =IF('504 Plan Tracker'!B4="","",IF(AND('504 Plan Tracker'!L4<>"Yes",'504 Plan Tracker'!J4-TODAY()<=30),'504 Plan Tracker'!K4,"")) -> -148 | H25: =IF('504 Plan Tracker'!B4="","",IF(AND('504 Plan Tracker'!L4<>"Yes",'504 Plan Tracker'!J4-TODAY()<=30),'504 Plan Tracker'!H4,"")) -> Mr. Kim
A26: =IF('504 Plan Tracker'!B5="","",IF(AND('504 Plan Tracker'!L5<>"Yes",'504 Plan Tracker'!J5-TODAY()<=30),'504 Plan Tracker'!A5,"")) -> 504-002 | B26: =IF('504 Plan Tracker'!B5="","",IF(AND('504 Plan Tracker'!L5<>"Yes",'504 Plan Tracker'!J5-TODAY()<=30),'504 Plan Tracker'!B5,"")) -> MER-005 | C26: =IF('504 Plan Tracker'!B5="","",IF(AND('504 Plan Tracker'!L5<>"Yes",'504 Plan Tracker'!J5-TODAY()<=30),'504 Plan Tracker'!C5,"")) -> Nguyen | D26: =IF('504 Plan Tracker'!B5="","",IF(AND('504 Plan Tracker'!L5<>"Yes",'504 Plan Tracker'!J5-TODAY()<=30),'504 Plan Tracker'!D5,"")) -> Mai | E26: =IF('504 Plan Tracker'!B5="","",IF(AND('504 Plan Tracker'!L5<>"Yes",'504 Plan Tracker'!J5-TODAY()<=30),'504 Plan Tracker'!E5,"")) -> 9th Grade | F26: =IF('504 Plan Tracker'!B5="","",IF(AND('504 Plan Tracker'!L5<>"Yes",'504 Plan Tracker'!J5-TODAY()<=30),'504 Plan Tracker'!F5,"")) -> Lincoln High | G26: =IF('504 Plan Tracker'!B5="","",IF(AND('504 Plan Tracker'!L5<>"Yes",'504 Plan Tracker'!J5-TODAY()<=30),'504 Plan Tracker'!K5,"")) -> -94 | H26: =IF('504 Plan Tracker'!B5="","",IF(AND('504 Plan Tracker'!L5<>"Yes",'504 Plan Tracker'!J5-TODAY()<=30),'504 Plan Tracker'!H5,"")) -> Ms. Garcia
A27: =IF('504 Plan Tracker'!B6="","",IF(AND('504 Plan Tracker'!L6<>"Yes",'504 Plan Tracker'!J6-TODAY()<=30),'504 Plan Tracker'!A6,"")) | B27: =IF('504 Plan Tracker'!B6="","",IF(AND('504 Plan Tracker'!L6<>"Yes",'504 Plan Tracker'!J6-TODAY()<=30),'504 Plan Tracker'!B6,"")) | C27: =IF('504 Plan Tracker'!B6="","",IF(AND('504 Plan Tracker'!L6<>"Yes",'504 Plan Tracker'!J6-TODAY()<=30),'504 Plan Tracker'!C6,"")) | D27: =IF('504 Plan Tracker'!B6="","",IF(AND('504 Plan Tracker'!L6<>"Yes",'504 Plan Tracker'!J6-TODAY()<=30),'504 Plan Tracker'!D6,"")) | E27: =IF('504 Plan Tracker'!B6="","",IF(AND('504 Plan Tracker'!L6<>"Yes",'504 Plan Tracker'!J6-TODAY()<=30),'504 Plan Tracker'!E6,"")) | F27: =IF('504 Plan Tracker'!B6="","",IF(AND('504 Plan Tracker'!L6<>"Yes",'504 Plan Tracker'!J6-TODAY()<=30),'504 Plan Tracker'!F6,"")) | G27: =IF('504 Plan Tracker'!B6="","",IF(AND('504 Plan Tracker'!L6<>"Yes",'504 Plan Tracker'!J6-TODAY()<=30),'504 Plan Tracker'!K6,"")) | H27: =IF('504 Plan Tracker'!B6="","",IF(AND('504 Plan Tracker'!L6<>"Yes",'504 Plan Tracker'!J6-TODAY()<=30),'504 Plan Tracker'!H6,""))
