Workbook

Sheet Cover
A1: Navigator — Student Behavior & Intervention Tracker
A2: RTI / MTSS / ISS / OSS Edition | Clear Path Education Group, LLC
A3: Built for Texas campus behavior coordinators, counselors, and assistant principals.
A4: Track referrals, suspensions, student supports, and intervention effectiveness — all in one place.
A6: ─── FILL IN YOUR CAMPUS INFORMATION ─────────────────────────────
A7: District Name:
A8: Campus Name:
A9: School Year: | C9: 2025-26
A10: Behavior Coordinator / Counselor:
A11: Date Updated:
A13: ─── HOW TO USE THIS TRACKER ──────────────────────────────────────
A14: 1. STUDENT ROSTER — Add every student you are tracking. This tab feeds all other tabs.
A15: 2. REFERRAL LOG — Log each behavioral referral. One row per referral. Reference the Student ID.
A16: 3. ISS / OSS PLACEMENTS — Record each suspension. Auto-calculates days elapsed.
A17: 4. STUDENT SUPPORTS — Log every intervention assigned. Track effectiveness when completed.
A18: 5. RISK SCORE CALCULATOR — Manually score students using the weighted algorithm from Navigator.
A19: 6. DASHBOARD — Auto-summary. No data entry needed here.
A20: 7. REFERENCE — RTI/MTSS framework, skill gap definitions, intervention menu.
A21: 8. Yellow = approaching threshold. Red = escalation flag. Green = resolved/on-track.
A22: 9. Gray cells = auto-calculated formulas — do NOT type in them.
... A31: © 2025 Clear Path Education Group, LLC | clearpathedgroup.com | For organizational use only — not legal advice.

Sheet Roster
A1: STUDENT ROSTER — Students Under Behavior Monitoring
A2: Student ID | B2: Last Name | C2: First Name | D2: Grade | E2: Campus | F2: SPED Eligible? | G2: 504 Eligible? | H2: Status | I2: Referral Count ⚙ | J2: ISS Count ⚙ | K2: OSS Count ⚙ | L2: Active Supports ⚙ | M2: Risk Level | N2: Notes
A3: NAV-001 | B3: Torres | C3: Miguel | D3: 9th Grade | E3: Lincoln High | F3: No | G3: No | H3: Active | I3: =COUNTIF('Referral Log'!D$3:D$201,A3) -> 3 | J3: =COUNTIFS('ISS-OSS Placements'!B$3:B$201,A3,'ISS-OSS Placements'!F$3:F$201,"*ISS*") -> 0 | K3: =COUNTIFS('ISS-OSS Placements'!B$3:B$201,A3,'ISS-OSS Placements'!F$3:F$201,"*OSS*") -> 3 | L3: =COUNTIFS('Student Supports'!B$3:B$201,A3,'Student Supports'!K$3:K$201,"Active") -> 0 | M3: High | N3: 3 OSS in 90 days — DAEP escalation review underway.
A4: NAV-002 | B4: Chen | C4: Amy | D4: 7th Grade | E4: Roosevelt Middle | F4: No | G4: No | H4: Active | I4: =COUNTIF('Referral Log'!D$3:D$201,A4) -> 2 | J4: =COUNTIFS('ISS-OSS Placements'!B$3:B$201,A4,'ISS-OSS Placements'!F$3:F$201,"*ISS*") -> 1 | K4: =COUNTIFS('ISS-OSS Placements'!B$3:B$201,A4,'ISS-OSS Placements'!F$3:F$201,"*OSS*") -> 0 | L4: =COUNTIFS('Student Supports'!B$3:B$201,A4,'Student Supports'!K$3:K$201,"Active") -> 1 | M4: Medium | N4: CICO support active — trending down.
A5: NAV-003 | B5: Jackson | C5: DeShawn | D5: 10th Grade | E5: Lincoln High | F5: Yes | G5: No | H5: Active | I5: =COUNTIF('Referral Log'!D$3:D$201,A5) -> 1 | J5: =COUNTIFS('ISS-OSS Placements'!B$3:B$201,A5,'ISS-OSS Placements'!F$3:F$201,"*ISS*") -> 0 | K5: =COUNTIFS('ISS-OSS Placements'!B$3:B$201,A5,'ISS-OSS Placements'!F$3:F$201,"*OSS*") -> 0 | L5: =COUNTIFS('Student Supports'!B$3:B$201,A5,'Student Supports'!K$3:K$201,"Active") -> 0 | M5: Medium | N5: BIP in place; SPED coordinator monitoring.
A6: NAV-004 | B6: Martinez | C6: Sofia | D6: 6th Grade | E6: Jefferson Middle | F6: No | G6: Yes | H6: Active | I6: =COUNTIF('Referral Log'!D$3:D$201,A6) -> 1 | J6: =COUNTIFS('ISS-OSS Placements'!B$3:B$201,A6,'ISS-OSS Placements'!F$3:F$201,"*ISS*") -> 0 | K6: =COUNTIFS('ISS-OSS Placements'!B$3:B$201,A6,'ISS-OSS Placements'!F$3:F$201,"*OSS*") -> 0 | L6: =COUNTIFS('Student Supports'!B$3:B$201,A6,'Student Supports'!K$3:K$201,"Active") -> 0 | M6: Low | N6: First referral 3/2 — monitoring.
A7: NAV-005 | B7: Patel | C7: Raj | D7: 8th Grade | E7: Roosevelt Middle | F7: Yes | G7: No | H7: Active | I7: =COUNTIF('Referral Log'!D$3:D$201,A7) -> 0 | J7: =COUNTIFS('ISS-OSS Placements'!B$3:B$201,A7,'ISS-OSS Placements'!F$3:F$201,"*ISS*") -> 0 | K7: =COUNTIFS('ISS-OSS Placements'!B$3:B$201,A7,'ISS-OSS Placements'!F$3:F$201,"*OSS*") -> 0 | L7: =COUNTIFS('Student Supports'!B$3:B$201,A7,'Student Supports'!K$3:K$201,"Active") -> 1 | M7: Low | N7: Behavior contract active.
I8: =COUNTIF('Referral Log'!D$3:D$201,A8) -> 0 | J8: =COUNTIFS('ISS-OSS Placements'!B$3:B$201,A8,'ISS-OSS Placements'!F$3:F$201,"*ISS*") -> 0 | K8: =COUNTIFS('ISS-OSS Placements'!B$3:B$201,A8,'ISS-OSS Placements'!F$3:F$201,"*OSS*") -> 0 | L8: =COUNTIFS('Student Supports'!B$3:B$201,A8,'Student Supports'!K$3:K$201,"Active") -> 0
I9: =COUNTIF('Referral Log'!D$3:D$201,A9) -> 0 | J9: =COUNTIFS('ISS-OSS Placements'!B$3:B$201,A9,'ISS-OSS Placements'!F$3:F$201,"*ISS*") -> 0 | K9: =COUNTIFS('ISS-OSS Placements'!B$3:B$201,A9,'ISS-OSS Placements'!F$3:F$201,"*OSS*") -> 0 | L9: =COUNTIFS('Student Supports'!B$3:B$201,A9,'Student Supports'!K$3:K$201,"Active") -> 0
I10: =COUNTIF('Referral Log'!D$3:D$201,A10) -> 0 | J10: =COUNTIFS('ISS-OSS Placements'!B$3:B$201,A10,'ISS-OSS Placements'!F$3:F$201,"*ISS*") -> 0 | K10: =COUNTIFS('ISS-OSS Placements'!B$3:B$201,A10,'ISS-OSS Placements'!F$3:F$201,"*OSS*") -> 0 | L10: =COUNTIFS('Student Supports'!B$3:B$201,A10,'Student Supports'!K$3:K$201,"Active") -> 0
I11: =COUNTIF('Referral Log'!D$3:D$201,A11) -> 0 | J11: =COUNTIFS('ISS-OSS Placements'!B$3:B$201,A11,'ISS-OSS Placements'!F$3:F$201,"*ISS*") -> 0 | K11: =COUNTIFS('ISS-OSS Placements'!B$3:B$201,A11,'ISS-OSS Placements'!F$3:F$201,"*OSS*") -> 0 | L11: =COUNTIFS('Student Supports'!B$3:B$201,A11,'Student Supports'!K$3:K$201,"Active") -> 0
I12: =COUNTIF('Referral Log'!D$3:D$201,A12) -> 0 | J12: =COUNTIFS('ISS-OSS Placements'!B$3:B$201,A12,'ISS-OSS Placements'!F$3:F$201,"*ISS*") -> 0 | K12: =COUNTIFS('ISS-OSS Placements'!B$3:B$201,A12,'ISS-OSS Placements'!F$3:F$201,"*OSS*") -> 0 | L12: =COUNTIFS('Student Supports'!B$3:B$201,A12,'Student Supports'!K$3:K$201,"Active") -> 0
I13: =COUNTIF('Referral Log'!D$3:D$201,A13) -> 0 | J13: =COUNTIFS('ISS-OSS Placements'!B$3:B$201,A13,'ISS-OSS Placements'!F$3:F$201,"*ISS*") -> 0 | K13: =COUNTIFS('ISS-OSS Placements'!B$3:B$201,A13,'ISS-OSS Placements'!F$3:F$201,"*OSS*") -> 0 | L13: =COUNTIFS('Student Supports'!B$3:B$201,A13,'Student Supports'!K$3:K$201,"Active") -> 0
I14: =COUNTIF('Referral Log'!D$3:D$201,A14) -> 0 | J14: =COUNTIFS('ISS-OSS Placements'!B$3:B$201,A14,'ISS-OSS Placements'!F$3:F$201,"*ISS*") -> 0 | K14: =COUNTIFS('ISS-OSS Placements'!B$3:B$201,A14,'ISS-OSS Placements'!F$3:F$201,"*OSS*") -> 0 | L14: =COUNTIFS('Student Supports'!B$3:B$201,A14,'Student Supports'!K$3:K$201,"Active") -> 0
I15: =COUNTIF('Referral Log'!D$3:D$201,A15) -> 0 | J15: =COUNTIFS('ISS-OSS Placements'!B$3:B$201,A15,'ISS-OSS Placements'!F$3:F$201,"*ISS*") -> 0 | K15: =COUNTIFS('ISS-OSS Placements'!B$3:B$201,A15,'ISS-OSS Placements'!F$3:F$201,"*OSS*") -> 0 | L15: =COUNTIFS('Student Supports'!B$3:B$201,A15,'Student Supports'!K$3:K$201,"Active") -> 0
I16: =COUNTIF('Referral Log'!D$3:D$201,A16) -> 0 | J16: =COUNTIFS('ISS-OSS Placements'!B$3:B$201,A16,'ISS-OSS Placements'!F$3:F$201,"*ISS*") -> 0 | K16: =COUNTIFS('ISS-OSS Placements'!B$3:B$201,A16,'ISS-OSS Placements'!F$3:F$201,"*OSS*") -> 0 | L16: =COUNTIFS('Student Supports'!B$3:B$201,A16,'Student Supports'!K$3:K$201,"Active") -> 0
I17: =COUNTIF('Referral Log'!D$3:D$201,A17) -> 0 | J17: =COUNTIFS('ISS-OSS Placements'!B$3:B$201,A17,'ISS-OSS Placements'!F$3:F$201,"*ISS*") -> 0 | K17: =COUNTIFS('ISS-OSS Placements'!B$3:B$201,A17,'ISS-OSS Placements'!F$3:F$201,"*OSS*") -> 0 | L17: =COUNTIFS('Student Supports'!B$3:B$201,A17,'Student Supports'!K$3:K$201,"Active") -> 0
I18: =COUNTIF('Referral Log'!D$3:D$201,A18) -> 0 | J18: =COUNTIFS('ISS-OSS Placements'!B$3:B$201,A18,'ISS-OSS Placements'!F$3:F$201,"*ISS*") -> 0 | K18: =COUNTIFS('ISS-OSS Placements'!B$3:B$201,A18,'ISS-OSS Placements'!F$3:F$201,"*OSS*") -> 0 | L18: =COUNTIFS('Student Supports'!B$3:B$201,A18,'Student Supports'!K$3:K$201,"Active") -> 0
I19: =COUNTIF('Referral Log'!D$3:D$201,A19) -> 0 | J19: =COUNTIFS('ISS-OSS Placements'!B$3:B$201,A19,'ISS-OSS Placements'!F$3:F$201,"*ISS*") -> 0 | K19: =COUNTIFS('ISS-OSS Placements'!B$3:B$201,A19,'ISS-OSS Placements'!F$3:F$201,"*OSS*") -> 0 | L19: =COUNTIFS('Student Supports'!B$3:B$201,A19,'Student Supports'!K$3:K$201,"Active") -> 0
... I101: =COUNTIF('Referral Log'!D$3:D$201,A101) -> 0 | J101: =COUNTIFS('ISS-OSS Placements'!B$3:B$201,A101,'ISS-OSS Placements'!F$3:F$201,"*ISS*") -> 0 | K101: =COUNTIFS('ISS-OSS Placements'!B$3:B$201,A101,'ISS-OSS Placements'!F$3:F$201,"*OSS*") -> 0 | L101: =COUNTIFS('Student Supports'!B$3:B$201,A101,'Student Supports'!K$3:K$201,"Active") -> 0

Sheet Referral Log
A1: REFERRAL LOG — One Row Per Behavioral Referral
A2: Referral ID | B2: Referral Date | C2: Campus | D2: Student ID | E2: Last Name ⚙ | F2: First Name ⚙ | G2: Grade ⚙ | H2: Offense Category | I2: Description (brief) | J2: Skill Gap Identified | K2: Reported By (Role) | L2: Reviewed By (Role) | M2: Status | N2: Outcome | O2: OSS/ISS Assigned? | P2: Referral # for Student ⚙ | Q2: Notes
A3: REF-001 | B3: 46031 | C3: Lincoln High | D3: NAV-001 | E3: =IFERROR(VLOOKUP(D3,Roster!$A$3:$N$101,2,FALSE),"") -> Torres | F3: =IFERROR(VLOOKUP(D3,Roster!$A$3:$N$101,3,FALSE),"") -> Miguel | G3: =IFERROR(VLOOKUP(D3,Roster!$A$3:$N$101,4,FALSE),"") -> 9th Grade | H3: Fighting | I3: Fight at lunch — mutual combat | J3: Peer Conflict Resolution | K3: Teacher | L3: Assistant Principal | M3: Resolved | N3: OSS Assigned | O3: Yes | P3: =IF(D3="","",COUNTIF(D$3:D3,D3)) -> 1
A4: REF-002 | B4: 46045 | C4: Lincoln High | D4: NAV-001 | E4: =IFERROR(VLOOKUP(D4,Roster!$A$3:$N$101,2,FALSE),"") -> Torres | F4: =IFERROR(VLOOKUP(D4,Roster!$A$3:$N$101,3,FALSE),"") -> Miguel | G4: =IFERROR(VLOOKUP(D4,Roster!$A$3:$N$101,4,FALSE),"") -> 9th Grade | H4: Fighting | I4: Second fight — hallway before 3rd period | J4: Peer Conflict Resolution | K4: Teacher | L4: Assistant Principal | M4: Resolved | N4: OSS Assigned | O4: Yes | P4: =IF(D4="","",COUNTIF(D$3:D4,D4)) -> 2 | Q4: 2nd referral — escalating pattern.
A5: REF-003 | B5: 46064 | C5: Lincoln High | D5: NAV-001 | E5: =IFERROR(VLOOKUP(D5,Roster!$A$3:$N$101,2,FALSE),"") -> Torres | F5: =IFERROR(VLOOKUP(D5,Roster!$A$3:$N$101,3,FALSE),"") -> Miguel | G5: =IFERROR(VLOOKUP(D5,Roster!$A$3:$N$101,4,FALSE),"") -> 9th Grade | H5: Defiance/Insubordination | I5: Refused to leave classroom; verbal outburst | J5: Impulse Control | K5: Teacher | L5: Assistant Principal | M5: Resolved | N5: OSS Assigned | O5: Yes | P5: =IF(D5="","",COUNTIF(D$3:D5,D5)) -> 3 | Q5: 3rd incident — DAEP escalation review.
A6: REF-004 | B6: 46038 | C6: Roosevelt Middle | D6: NAV-002 | E6: =IFERROR(VLOOKUP(D6,Roster!$A$3:$N$101,2,FALSE),"") -> Chen | F6: =IFERROR(VLOOKUP(D6,Roster!$A$3:$N$101,3,FALSE),"") -> Amy | G6: =IFERROR(VLOOKUP(D6,Roster!$A$3:$N$101,4,FALSE),"") -> 7th Grade | H6: Defiance/Insubordination | I6: Repeated class disruption | J6: Emotional Regulation | K6: Teacher | L6: Counselor | M6: In Progress | N6: Support Assigned | O6: No | P6: =IF(D6="","",COUNTIF(D$3:D6,D6)) -> 1 | Q6: CICO assigned 1/17.
A7: REF-005 | B7: 46059 | C7: Roosevelt Middle | D7: NAV-002 | E7: =IFERROR(VLOOKUP(D7,Roster!$A$3:$N$101,2,FALSE),"") -> Chen | F7: =IFERROR(VLOOKUP(D7,Roster!$A$3:$N$101,3,FALSE),"") -> Amy | G7: =IFERROR(VLOOKUP(D7,Roster!$A$3:$N$101,4,FALSE),"") -> 7th Grade | H7: Other | I7: Skipped CICO check-in twice | J7: Adult Communication | K7: Counselor | L7: Counselor | M7: Open | N7: Support Assigned | O7: No | P7: =IF(D7="","",COUNTIF(D$3:D7,D7)) -> 2
A8: REF-006 | B8: 46033 | C8: Lincoln High | D8: NAV-003 | E8: =IFERROR(VLOOKUP(D8,Roster!$A$3:$N$101,2,FALSE),"") -> Jackson | F8: =IFERROR(VLOOKUP(D8,Roster!$A$3:$N$101,3,FALSE),"") -> DeShawn | G8: =IFERROR(VLOOKUP(D8,Roster!$A$3:$N$101,4,FALSE),"") -> 10th Grade | H8: Defiance/Insubordination | I8: Shutdown/refusal during transition | J8: Emotional Regulation | K8: Teacher | L8: SPED Coordinator | M8: Resolved | N8: Support Assigned | O8: No | P8: =IF(D8="","",COUNTIF(D$3:D8,D8)) -> 1 | Q8: BIP reviewed — updated triggers.
A9: REF-007 | B9: 46083 | C9: Jefferson Middle | D9: NAV-004 | E9: =IFERROR(VLOOKUP(D9,Roster!$A$3:$N$101,2,FALSE),"") -> Martinez | F9: =IFERROR(VLOOKUP(D9,Roster!$A$3:$N$101,3,FALSE),"") -> Sofia | G9: =IFERROR(VLOOKUP(D9,Roster!$A$3:$N$101,4,FALSE),"") -> 6th Grade | H9: Truancy | I9: Left campus during lunch | J9: Executive Functioning | K9: Teacher | L9: Counselor | M9: Open | N9: No Action Taken | O9: No | P9: =IF(D9="","",COUNTIF(D$3:D9,D9)) -> 1 | Q9: First referral. Monitoring.
E10: =IFERROR(VLOOKUP(D10,Roster!$A$3:$N$101,2,FALSE),"") | F10: =IFERROR(VLOOKUP(D10,Roster!$A$3:$N$101,3,FALSE),"") | G10: =IFERROR(VLOOKUP(D10,Roster!$A$3:$N$101,4,FALSE),"") | P10: =IF(D10="","",COUNTIF(D$3:D10,D10))
E11: =IFERROR(VLOOKUP(D11,Roster!$A$3:$N$101,2,FALSE),"") | F11: =IFERROR(VLOOKUP(D11,Roster!$A$3:$N$101,3,FALSE),"") | G11: =IFERROR(VLOOKUP(D11,Roster!$A$3:$N$101,4,FALSE),"") | P11: =IF(D11="","",COUNTIF(D$3:D11,D11))
E12: =IFERROR(VLOOKUP(D12,Roster!$A$3:$N$101,2,FALSE),"") | F12: =IFERROR(VLOOKUP(D12,Roster!$A$3:$N$101,3,FALSE),"") | G12: =IFERROR(VLOOKUP(D12,Roster!$A$3:$N$101,4,FALSE),"") | P12: =IF(D12="","",COUNTIF(D$3:D12,D12))
E13: =IFERROR(VLOOKUP(D13,Roster!$A$3:$N$101,2,FALSE),"") | F13: =IFERROR(VLOOKUP(D13,Roster!$A$3:$N$101,3,FALSE),"") | G13: =IFERROR(VLOOKUP(D13,Roster!$A$3:$N$101,4,FALSE),"") | P13: =IF(D13="","",COUNTIF(D$3:D13,D13))
E14: =IFERROR(VLOOKUP(D14,Roster!$A$3:$N$101,2,FALSE),"") | F14: =IFERROR(VLOOKUP(D14,Roster!$A$3:$N$101,3,FALSE),"") | G14: =IFERROR(VLOOKUP(D14,Roster!$A$3:$N$101,4,FALSE),"") | P14: =IF(D14="","",COUNTIF(D$3:D14,D14))
E15: =IFERROR(VLOOKUP(D15,Roster!$A$3:$N$101,2,FALSE),"") | F15: =IFERROR(VLOOKUP(D15,Roster!$A$3:$N$101,3,FALSE),"") | G15: =IFERROR(VLOOKUP(D15,Roster!$A$3:$N$101,4,FALSE),"") | P15: =IF(D15="","",COUNTIF(D$3:D15,D15))
E16: =IFERROR(VLOOKUP(D16,Roster!$A$3:$N$101,2,FALSE),"") | F16: =IFERROR(VLOOKUP(D16,Roster!$A$3:$N$101,3,FALSE),"") | G16: =IFERROR(VLOOKUP(D16,Roster!$A$3:$N$101,4,FALSE),"") | P16: =IF(D16="","",COUNTIF(D$3:D16,D16))
E17: =IFERROR(VLOOKUP(D17,Roster!$A$3:$N$101,2,FALSE),"") | F17: =IFERROR(VLOOKUP(D17,Roster!$A$3:$N$101,3,FALSE),"") | G17: =IFERROR(VLOOKUP(D17,Roster!$A$3:$N$101,4,FALSE),"") | P17: =IF(D17="","",COUNTIF(D$3:D17,D17))
E18: =IFERROR(VLOOKUP(D18,Roster!$A$3:$N$101,2,FALSE),"") | F18: =IFERROR(VLOOKUP(D18,Roster!$A$3:$N$101,3,FALSE),"") | G18: =IFERROR(VLOOKUP(D18,Roster!$A$3:$N$101,4,FALSE),"") | P18: =IF(D18="","",COUNTIF(D$3:D18,D18))
E19: =IFERROR(VLOOKUP(D19,Roster!$A$3:$N$101,2,FALSE),"") | F19: =IFERROR(VLOOKUP(D19,Roster!$A$3:$N$101,3,FALSE),"") | G19: =IFERROR(VLOOKUP(D19,Roster!$A$3:$N$101,4,FALSE),"") | P19: =IF(D19="","",COUNTIF(D$3:D19,D19))
E20: =IFERROR(VLOOKUP(D20,Roster!$A$3:$N$101,2,FALSE),"") | F20: =IFERROR(VLOOKUP(D20,Roster!$A$3:$N$101,3,FALSE),"") | G20: =IFERROR(VLOOKUP(D20,Roster!$A$3:$N$101,4,FALSE),"") | P20: =IF(D20="","",COUNTIF(D$3:D20,D20))
E21: =IFERROR(VLOOKUP(D21,Roster!$A$3:$N$101,2,FALSE),"") | F21: =IFERROR(VLOOKUP(D21,Roster!$A$3:$N$101,3,FALSE),"") | G21: =IFERROR(VLOOKUP(D21,Roster!$A$3:$N$101,4,FALSE),"") | P21: =IF(D21="","",COUNTIF(D$3:D21,D21))
... E201: =IFERROR(VLOOKUP(D201,Roster!$A$3:$N$101,2,FALSE),"") | F201: =IFERROR(VLOOKUP(D201,Roster!$A$3:$N$101,3,FALSE),"") | G201: =IFERROR(VLOOKUP(D201,Roster!$A$3:$N$101,4,FALSE),"") | P201: =IF(D201="","",COUNTIF(D$3:D201,D201))

Sheet ISS-OSS Placements
A1: ISS / OSS PLACEMENTS — One Row Per Suspension
A2: Placement ID | B2: Student ID | C2: Last Name ⚙ | D2: First Name ⚙ | E2: Grade ⚙ | F2: Placement Type | G2: Start Date | H2: End Date (actual) | I2: Authorized Days | J2: Days Elapsed ⚙ | K2: Days Remaining ⚙ | L2: Referral ID (cross-ref) | M2: Assigned By (Role) | N2: Parent Notified? | O2: Notification Date | P2: Return Date | Q2: OSS Count (90d) ⚙ | R2: Notes
A3: PLC-001 | B3: NAV-001 | C3: =IFERROR(VLOOKUP(B3,Roster!$A$3:$N$101,2,FALSE),"") -> Torres | D3: =IFERROR(VLOOKUP(B3,Roster!$A$3:$N$101,3,FALSE),"") -> Miguel | E3: =IFERROR(VLOOKUP(B3,Roster!$A$3:$N$101,4,FALSE),"") -> 9th Grade | F3: OSS — Out-of-School Suspension | G3: 46037 | H3: 46044 | I3: 5 | J3: =IF(G3="","",IF(H3="",TODAY()-G3,H3-G3)) -> 7 | K3: =IF(I3="","",MAX(0,I3-J3)) -> 0 | L3: REF-001 | M3: Assistant Principal | N3: Yes | O3: 46037 | P3: 46045 | Q3: =IF(B3="","",IF(COUNTIFS(B$3:B$201,B3,F$3:F$201,"*OSS*",G$3:G$201,">="&(TODAY()-90))>=3,"🚨 ESCALATE — "&COUNTIFS(B$3:B$201,B3,F$3:F$201,"*OSS*",G$3:G$201,">="&(TODAY()-90))&" OSS in 90d",TEXT(COUNTIFS(B$3:B$201,B3,F$3:F$201,"*OSS*",G$3:G$201,">="&(TODAY()-90)),"0"))) -> 0
A4: PLC-002 | B4: NAV-001 | C4: =IFERROR(VLOOKUP(B4,Roster!$A$3:$N$101,2,FALSE),"") -> Torres | D4: =IFERROR(VLOOKUP(B4,Roster!$A$3:$N$101,3,FALSE),"") -> Miguel | E4: =IFERROR(VLOOKUP(B4,Roster!$A$3:$N$101,4,FALSE),"") -> 9th Grade | F4: OSS — Out-of-School Suspension | G4: 46051 | H4: 46058 | I4: 5 | J4: =IF(G4="","",IF(H4="",TODAY()-G4,H4-G4)) -> 7 | K4: =IF(I4="","",MAX(0,I4-J4)) -> 0 | L4: REF-002 | M4: Assistant Principal | N4: Yes | O4: 46051 | P4: 46059 | Q4: =IF(B4="","",IF(COUNTIFS(B$3:B$201,B4,F$3:F$201,"*OSS*",G$3:G$201,">="&(TODAY()-90))>=3,"🚨 ESCALATE — "&COUNTIFS(B$3:B$201,B4,F$3:F$201,"*OSS*",G$3:G$201,">="&(TODAY()-90))&" OSS in 90d",TEXT(COUNTIFS(B$3:B$201,B4,F$3:F$201,"*OSS*",G$3:G$201,">="&(TODAY()-90)),"0"))) -> 0 | R4: Second OSS — escalation warning issued.
A5: PLC-003 | B5: NAV-001 | C5: =IFERROR(VLOOKUP(B5,Roster!$A$3:$N$101,2,FALSE),"") -> Torres | D5: =IFERROR(VLOOKUP(B5,Roster!$A$3:$N$101,3,FALSE),"") -> Miguel | E5: =IFERROR(VLOOKUP(B5,Roster!$A$3:$N$101,4,FALSE),"") -> 9th Grade | F5: OSS — Out-of-School Suspension | G5: 46072 | I5: 5 | J5: =IF(G5="","",IF(H5="",TODAY()-G5,H5-G5)) -> 145 | K5: =IF(I5="","",MAX(0,I5-J5)) -> 0 | L5: REF-003 | M5: Assistant Principal | N5: Yes | O5: 46072 | Q5: =IF(B5="","",IF(COUNTIFS(B$3:B$201,B5,F$3:F$201,"*OSS*",G$3:G$201,">="&(TODAY()-90))>=3,"🚨 ESCALATE — "&COUNTIFS(B$3:B$201,B5,F$3:F$201,"*OSS*",G$3:G$201,">="&(TODAY()-90))&" OSS in 90d",TEXT(COUNTIFS(B$3:B$201,B5,F$3:F$201,"*OSS*",G$3:G$201,">="&(TODAY()-90)),"0"))) -> 0 | R5: 3rd OSS in 90 days — DAEP escalation review.
A6: PLC-004 | B6: NAV-002 | C6: =IFERROR(VLOOKUP(B6,Roster!$A$3:$N$101,2,FALSE),"") -> Chen | D6: =IFERROR(VLOOKUP(B6,Roster!$A$3:$N$101,3,FALSE),"") -> Amy | E6: =IFERROR(VLOOKUP(B6,Roster!$A$3:$N$101,4,FALSE),"") -> 7th Grade | F6: ISS — In-School Suspension | G6: 46041 | H6: 46043 | I6: 2 | J6: =IF(G6="","",IF(H6="",TODAY()-G6,H6-G6)) -> 2 | K6: =IF(I6="","",MAX(0,I6-J6)) -> 0 | L6: REF-004 | M6: Counselor | N6: Yes | O6: 46041 | P6: 46044 | Q6: =IF(B6="","",IF(COUNTIFS(B$3:B$201,B6,F$3:F$201,"*OSS*",G$3:G$201,">="&(TODAY()-90))>=3,"🚨 ESCALATE — "&COUNTIFS(B$3:B$201,B6,F$3:F$201,"*OSS*",G$3:G$201,">="&(TODAY()-90))&" OSS in 90d",TEXT(COUNTIFS(B$3:B$201,B6,F$3:F$201,"*OSS*",G$3:G$201,">="&(TODAY()-90)),"0"))) -> 0
C7: =IFERROR(VLOOKUP(B7,Roster!$A$3:$N$101,2,FALSE),"") | D7: =IFERROR(VLOOKUP(B7,Roster!$A$3:$N$101,3,FALSE),"") | E7: =IFERROR(VLOOKUP(B7,Roster!$A$3:$N$101,4,FALSE),"") | J7: =IF(G7="","",IF(H7="",TODAY()-G7,H7-G7)) | K7: =IF(I7="","",MAX(0,I7-J7)) | Q7: =IF(B7="","",IF(COUNTIFS(B$3:B$201,B7,F$3:F$201,"*OSS*",G$3:G$201,">="&(TODAY()-90))>=3,"🚨 ESCALATE — "&COUNTIFS(B$3:B$201,B7,F$3:F$201,"*OSS*",G$3:G$201,">="&(TODAY()-90))&" OSS in 90d",TEXT(COUNTIFS(B$3:B$201,B7,F$3:F$201,"*OSS*",G$3:G$201,">="&(TODAY()-90)),"0")))
C8: =IFERROR(VLOOKUP(B8,Roster!$A$3:$N$101,2,FALSE),"") | D8: =IFERROR(VLOOKUP(B8,Roster!$A$3:$N$101,3,FALSE),"") | E8: =IFERROR(VLOOKUP(B8,Roster!$A$3:$N$101,4,FALSE),"") | J8: =IF(G8="","",IF(H8="",TODAY()-G8,H8-G8)) | K8: =IF(I8="","",MAX(0,I8-J8)) | Q8: =IF(B8="","",IF(COUNTIFS(B$3:B$201,B8,F$3:F$201,"*OSS*",G$3:G$201,">="&(TODAY()-90))>=3,"🚨 ESCALATE — "&COUNTIFS(B$3:B$201,B8,F$3:F$201,"*OSS*",G$3:G$201,">="&(TODAY()-90))&" OSS in 90d",TEXT(COUNTIFS(B$3:B$201,B8,F$3:F$201,"*OSS*",G$3:G$201,">="&(TODAY()-90)),"0")))
C9: =IFERROR(VLOOKUP(B9,Roster!$A$3:$N$101,2,FALSE),"") | D9: =IFERROR(VLOOKUP(B9,Roster!$A$3:$N$101,3,FALSE),"") | E9: =IFERROR(VLOOKUP(B9,Roster!$A$3:$N$101,4,FALSE),"") | J9: =IF(G9="","",IF(H9="",TODAY()-G9,H9-G9)) | K9: =IF(I9="","",MAX(0,I9-J9)) | Q9: =IF(B9="","",IF(COUNTIFS(B$3:B$201,B9,F$3:F$201,"*OSS*",G$3:G$201,">="&(TODAY()-90))>=3,"🚨 ESCALATE — "&COUNTIFS(B$3:B$201,B9,F$3:F$201,"*OSS*",G$3:G$201,">="&(TODAY()-90))&" OSS in 90d",TEXT(COUNTIFS(B$3:B$201,B9,F$3:F$201,"*OSS*",G$3:G$201,">="&(TODAY()-90)),"0")))
C10: =IFERROR(VLOOKUP(B10,Roster!$A$3:$N$101,2,FALSE),"") | D10: =IFERROR(VLOOKUP(B10,Roster!$A$3:$N$101,3,FALSE),"") | E10: =IFERROR(VLOOKUP(B10,Roster!$A$3:$N$101,4,FALSE),"") | J10: =IF(G10="","",IF(H10="",TODAY()-G10,H10-G10)) | K10: =IF(I10="","",MAX(0,I10-J10)) | Q10: =IF(B10="","",IF(COUNTIFS(B$3:B$201,B10,F$3:F$201,"*OSS*",G$3:G$201,">="&(TODAY()-90))>=3,"🚨 ESCALATE — "&COUNTIFS(B$3:B$201,B10,F$3:F$201,"*OSS*",G$3:G$201,">="&(TODAY()-90))&" OSS in 90d",TEXT(COUNTIFS(B$3:B$201,B10,F$3:F$201,"*OSS*",G$3:G$201,">="&(TODAY()-90)),"0")))
C11: =IFERROR(VLOOKUP(B11,Roster!$A$3:$N$101,2,FALSE),"") | D11: =IFERROR(VLOOKUP(B11,Roster!$A$3:$N$101,3,FALSE),"") | E11: =IFERROR(VLOOKUP(B11,Roster!$A$3:$N$101,4,FALSE),"") | J11: =IF(G11="","",IF(H11="",TODAY()-G11,H11-G11)) | K11: =IF(I11="","",MAX(0,I11-J11)) | Q11: =IF(B11="","",IF(COUNTIFS(B$3:B$201,B11,F$3:F$201,"*OSS*",G$3:G$201,">="&(TODAY()-90))>=3,"🚨 ESCALATE — "&COUNTIFS(B$3:B$201,B11,F$3:F$201,"*OSS*",G$3:G$201,">="&(TODAY()-90))&" OSS in 90d",TEXT(COUNTIFS(B$3:B$201,B11,F$3:F$201,"*OSS*",G$3:G$201,">="&(TODAY()-90)),"0")))
C12: =IFERROR(VLOOKUP(B12,Roster!$A$3:$N$101,2,FALSE),"") | D12: =IFERROR(VLOOKUP(B12,Roster!$A$3:$N$101,3,FALSE),"") | E12: =IFERROR(VLOOKUP(B12,Roster!$A$3:$N$101,4,FALSE),"") | J12: =IF(G12="","",IF(H12="",TODAY()-G12,H12-G12)) | K12: =IF(I12="","",MAX(0,I12-J12)) | Q12: =IF(B12="","",IF(COUNTIFS(B$3:B$201,B12,F$3:F$201,"*OSS*",G$3:G$201,">="&(TODAY()-90))>=3,"🚨 ESCALATE — "&COUNTIFS(B$3:B$201,B12,F$3:F$201,"*OSS*",G$3:G$201,">="&(TODAY()-90))&" OSS in 90d",TEXT(COUNTIFS(B$3:B$201,B12,F$3:F$201,"*OSS*",G$3:G$201,">="&(TODAY()-90)),"0")))
C13: =IFERROR(VLOOKUP(B13,Roster!$A$3:$N$101,2,FALSE),"") | D13: =IFERROR(VLOOKUP(B13,Roster!$A$3:$N$101,3,FALSE),"") | E13: =IFERROR(VLOOKUP(B13,Roster!$A$3:$N$101,4,FALSE),"") | J13: =IF(G13="","",IF(H13="",TODAY()-G13,H13-G13)) | K13: =IF(I13="","",MAX(0,I13-J13)) | Q13: =IF(B13="","",IF(COUNTIFS(B$3:B$201,B13,F$3:F$201,"*OSS*",G$3:G$201,">="&(TODAY()-90))>=3,"🚨 ESCALATE — "&COUNTIFS(B$3:B$201,B13,F$3:F$201,"*OSS*",G$3:G$201,">="&(TODAY()-90))&" OSS in 90d",TEXT(COUNTIFS(B$3:B$201,B13,F$3:F$201,"*OSS*",G$3:G$201,">="&(TODAY()-90)),"0")))
C14: =IFERROR(VLOOKUP(B14,Roster!$A$3:$N$101,2,FALSE),"") | D14: =IFERROR(VLOOKUP(B14,Roster!$A$3:$N$101,3,FALSE),"") | E14: =IFERROR(VLOOKUP(B14,Roster!$A$3:$N$101,4,FALSE),"") | J14: =IF(G14="","",IF(H14="",TODAY()-G14,H14-G14)) | K14: =IF(I14="","",MAX(0,I14-J14)) | Q14: =IF(B14="","",IF(COUNTIFS(B$3:B$201,B14,F$3:F$201,"*OSS*",G$3:G$201,">="&(TODAY()-90))>=3,"🚨 ESCALATE — "&COUNTIFS(B$3:B$201,B14,F$3:F$201,"*OSS*",G$3:G$201,">="&(TODAY()-90))&" OSS in 90d",TEXT(COUNTIFS(B$3:B$201,B14,F$3:F$201,"*OSS*",G$3:G$201,">="&(TODAY()-90)),"0")))
C15: =IFERROR(VLOOKUP(B15,Roster!$A$3:$N$101,2,FALSE),"") | D15: =IFERROR(VLOOKUP(B15,Roster!$A$3:$N$101,3,FALSE),"") | E15: =IFERROR(VLOOKUP(B15,Roster!$A$3:$N$101,4,FALSE),"") | J15: =IF(G15="","",IF(H15="",TODAY()-G15,H15-G15)) | K15: =IF(I15="","",MAX(0,I15-J15)) | Q15: =IF(B15="","",IF(COUNTIFS(B$3:B$201,B15,F$3:F$201,"*OSS*",G$3:G$201,">="&(TODAY()-90))>=3,"🚨 ESCALATE — "&COUNTIFS(B$3:B$201,B15,F$3:F$201,"*OSS*",G$3:G$201,">="&(TODAY()-90))&" OSS in 90d",TEXT(COUNTIFS(B$3:B$201,B15,F$3:F$201,"*OSS*",G$3:G$201,">="&(TODAY()-90)),"0")))
C16: =IFERROR(VLOOKUP(B16,Roster!$A$3:$N$101,2,FALSE),"") | D16: =IFERROR(VLOOKUP(B16,Roster!$A$3:$N$101,3,FALSE),"") | E16: =IFERROR(VLOOKUP(B16,Roster!$A$3:$N$101,4,FALSE),"") | J16: =IF(G16="","",IF(H16="",TODAY()-G16,H16-G16)) | K16: =IF(I16="","",MAX(0,I16-J16)) | Q16: =IF(B16="","",IF(COUNTIFS(B$3:B$201,B16,F$3:F$201,"*OSS*",G$3:G$201,">="&(TODAY()-90))>=3,"🚨 ESCALATE — "&COUNTIFS(B$3:B$201,B16,F$3:F$201,"*OSS*",G$3:G$201,">="&(TODAY()-90))&" OSS in 90d",TEXT(COUNTIFS(B$3:B$201,B16,F$3:F$201,"*OSS*",G$3:G$201,">="&(TODAY()-90)),"0")))
C17: =IFERROR(VLOOKUP(B17,Roster!$A$3:$N$101,2,FALSE),"") | D17: =IFERROR(VLOOKUP(B17,Roster!$A$3:$N$101,3,FALSE),"") | E17: =IFERROR(VLOOKUP(B17,Roster!$A$3:$N$101,4,FALSE),"") | J17: =IF(G17="","",IF(H17="",TODAY()-G17,H17-G17)) | K17: =IF(I17="","",MAX(0,I17-J17)) | Q17: =IF(B17="","",IF(COUNTIFS(B$3:B$201,B17,F$3:F$201,"*OSS*",G$3:G$201,">="&(TODAY()-90))>=3,"🚨 ESCALATE — "&COUNTIFS(B$3:B$201,B17,F$3:F$201,"*OSS*",G$3:G$201,">="&(TODAY()-90))&" OSS in 90d",TEXT(COUNTIFS(B$3:B$201,B17,F$3:F$201,"*OSS*",G$3:G$201,">="&(TODAY()-90)),"0")))
C18: =IFERROR(VLOOKUP(B18,Roster!$A$3:$N$101,2,FALSE),"") | D18: =IFERROR(VLOOKUP(B18,Roster!$A$3:$N$101,3,FALSE),"") | E18: =IFERROR(VLOOKUP(B18,Roster!$A$3:$N$101,4,FALSE),"") | J18: =IF(G18="","",IF(H18="",TODAY()-G18,H18-G18)) | K18: =IF(I18="","",MAX(0,I18-J18)) | Q18: =IF(B18="","",IF(COUNTIFS(B$3:B$201,B18,F$3:F$201,"*OSS*",G$3:G$201,">="&(TODAY()-90))>=3,"🚨 ESCALATE — "&COUNTIFS(B$3:B$201,B18,F$3:F$201,"*OSS*",G$3:G$201,">="&(TODAY()-90))&" OSS in 90d",TEXT(COUNTIFS(B$3:B$201,B18,F$3:F$201,"*OSS*",G$3:G$201,">="&(TODAY()-90)),"0")))
... C201: =IFERROR(VLOOKUP(B201,Roster!$A$3:$N$101,2,FALSE),"") | D201: =IFERROR(VLOOKUP(B201,Roster!$A$3:$N$101,3,FALSE),"") | E201: =IFERROR(VLOOKUP(B201,Roster!$A$3:$N$101,4,FALSE),"") | J201: =IF(G201="","",IF(H201="",TODAY()-G201,H201-G201)) | K201: =IF(I201="","",MAX(0,I201-J201)) | Q201: =IF(B201="","",IF(COUNTIFS(B$3:B$201,B201,F$3:F$201,"*OSS*",G$3:G$201,">="&(TODAY()-90))>=3,"🚨 ESCALATE — "&COUNTIFS(B$3:B$201,B201,F$3:F$201,"*OSS*",G$3:G$201,">="&(TODAY()-90))&" OSS in 90d",TEXT(COUNTIFS(B$3:B$201,B201,F$3:F$201,"*OSS*",G$3:G$201,">="&(TODAY()-90)),"0")))

Sheet Student Supports
A1: STUDENT SUPPORTS — Interventions Assigned to Students
A2: Support ID | B2: Student ID | C2: Last Name ⚙ | D2: First Name ⚙ | E2: Grade ⚙ | F2: Support Type | G2: Start Date | H2: End Date | I2: Assigned To (Staff Name) | J2: Assigned By (Role) | K2: Status | L2: Incidents Before (30d) | M2: Incidents After (30d) | N2: Reduction ⚙ | O2: Effective? ⚙ | P2: Referral ID (cross-ref) | Q2: Notes
A3: SUP-001 | B3: NAV-002 | C3: =IFERROR(VLOOKUP(B3,Roster!$A$3:$N$101,2,FALSE),"") -> Chen | D3: =IFERROR(VLOOKUP(B3,Roster!$A$3:$N$101,3,FALSE),"") -> Amy | E3: =IFERROR(VLOOKUP(B3,Roster!$A$3:$N$101,4,FALSE),"") -> 7th Grade | F3: CICO (Check-In / Check-Out) | G3: 46039 | I3: Ms. Johnson | J3: Counselor | K3: Active | L3: 3 | M3: 1 | N3: =IF(OR(L3="",L3=0,M3=""),"",(L3-M3)/L3) -> 0.66666667 | O3: =IF(N3="","",IF(N3>0,"Yes","No")) -> Yes | P3: REF-004 | Q3: Daily CICO with Ms. Johnson. Showing improvement.
A4: SUP-002 | B4: NAV-003 | C4: =IFERROR(VLOOKUP(B4,Roster!$A$3:$N$101,2,FALSE),"") -> Jackson | D4: =IFERROR(VLOOKUP(B4,Roster!$A$3:$N$101,3,FALSE),"") -> DeShawn | E4: =IFERROR(VLOOKUP(B4,Roster!$A$3:$N$101,4,FALSE),"") -> 10th Grade | F4: Social Skills Group | G4: 46034 | H4: 46076 | I4: Mr. Lee | J4: SPED Coordinator | K4: Completed | L4: 5 | M4: 2 | N4: =IF(OR(L4="",L4=0,M4=""),"",(L4-M4)/L4) -> 0.6 | O4: =IF(N4="","",IF(N4>0,"Yes","No")) -> Yes | P4: REF-006 | Q4: Completed 6-week group.
A5: SUP-003 | B5: NAV-005 | C5: =IFERROR(VLOOKUP(B5,Roster!$A$3:$N$101,2,FALSE),"") -> Patel | D5: =IFERROR(VLOOKUP(B5,Roster!$A$3:$N$101,3,FALSE),"") -> Raj | E5: =IFERROR(VLOOKUP(B5,Roster!$A$3:$N$101,4,FALSE),"") -> 8th Grade | F5: Behavior Contract | G5: 46055 | I5: Mr. Davis | J5: Counselor | K5: Active | L5: 4 | N5: =IF(OR(L5="",L5=0,M5=""),"",(L5-M5)/L5) | O5: =IF(N5="","",IF(N5>0,"Yes","No")) | Q5: Active contract — weekly check-ins.
C6: =IFERROR(VLOOKUP(B6,Roster!$A$3:$N$101,2,FALSE),"") | D6: =IFERROR(VLOOKUP(B6,Roster!$A$3:$N$101,3,FALSE),"") | E6: =IFERROR(VLOOKUP(B6,Roster!$A$3:$N$101,4,FALSE),"") | N6: =IF(OR(L6="",L6=0,M6=""),"",(L6-M6)/L6) | O6: =IF(N6="","",IF(N6>0,"Yes","No"))
C7: =IFERROR(VLOOKUP(B7,Roster!$A$3:$N$101,2,FALSE),"") | D7: =IFERROR(VLOOKUP(B7,Roster!$A$3:$N$101,3,FALSE),"") | E7: =IFERROR(VLOOKUP(B7,Roster!$A$3:$N$101,4,FALSE),"") | N7: =IF(OR(L7="",L7=0,M7=""),"",(L7-M7)/L7) | O7: =IF(N7="","",IF(N7>0,"Yes","No"))
C8: =IFERROR(VLOOKUP(B8,Roster!$A$3:$N$101,2,FALSE),"") | D8: =IFERROR(VLOOKUP(B8,Roster!$A$3:$N$101,3,FALSE),"") | E8: =IFERROR(VLOOKUP(B8,Roster!$A$3:$N$101,4,FALSE),"") | N8: =IF(OR(L8="",L8=0,M8=""),"",(L8-M8)/L8) | O8: =IF(N8="","",IF(N8>0,"Yes","No"))
C9: =IFERROR(VLOOKUP(B9,Roster!$A$3:$N$101,2,FALSE),"") | D9: =IFERROR(VLOOKUP(B9,Roster!$A$3:$N$101,3,FALSE),"") | E9: =IFERROR(VLOOKUP(B9,Roster!$A$3:$N$101,4,FALSE),"") | N9: =IF(OR(L9="",L9=0,M9=""),"",(L9-M9)/L9) | O9: =IF(N9="","",IF(N9>0,"Yes","No"))
C10: =IFERROR(VLOOKUP(B10,Roster!$A$3:$N$101,2,FALSE),"") | D10: =IFERROR(VLOOKUP(B10,Roster!$A$3:$N$101,3,FALSE),"") | E10: =IFERROR(VLOOKUP(B10,Roster!$A$3:$N$101,4,FALSE),"") | N10: =IF(OR(L10="",L10=0,M10=""),"",(L10-M10)/L10) | O10: =IF(N10="","",IF(N10>0,"Yes","No"))
C11: =IFERROR(VLOOKUP(B11,Roster!$A$3:$N$101,2,FALSE),"") | D11: =IFERROR(VLOOKUP(B11,Roster!$A$3:$N$101,3,FALSE),"") | E11: =IFERROR(VLOOKUP(B11,Roster!$A$3:$N$101,4,FALSE),"") | N11: =IF(OR(L11="",L11=0,M11=""),"",(L11-M11)/L11) | O11: =IF(N11="","",IF(N11>0,"Yes","No"))
C12: =IFERROR(VLOOKUP(B12,Roster!$A$3:$N$101,2,FALSE),"") | D12: =IFERROR(VLOOKUP(B12,Roster!$A$3:$N$101,3,FALSE),"") | E12: =IFERROR(VLOOKUP(B12,Roster!$A$3:$N$101,4,FALSE),"") | N12: =IF(OR(L12="",L12=0,M12=""),"",(L12-M12)/L12) | O12: =IF(N12="","",IF(N12>0,"Yes","No"))
C13: =IFERROR(VLOOKUP(B13,Roster!$A$3:$N$101,2,FALSE),"") | D13: =IFERROR(VLOOKUP(B13,Roster!$A$3:$N$101,3,FALSE),"") | E13: =IFERROR(VLOOKUP(B13,Roster!$A$3:$N$101,4,FALSE),"") | N13: =IF(OR(L13="",L13=0,M13=""),"",(L13-M13)/L13) | O13: =IF(N13="","",IF(N13>0,"Yes","No"))
C14: =IFERROR(VLOOKUP(B14,Roster!$A$3:$N$101,2,FALSE),"") | D14: =IFERROR(VLOOKUP(B14,Roster!$A$3:$N$101,3,FALSE),"") | E14: =IFERROR(VLOOKUP(B14,Roster!$A$3:$N$101,4,FALSE),"") | N14: =IF(OR(L14="",L14=0,M14=""),"",(L14-M14)/L14) | O14: =IF(N14="","",IF(N14>0,"Yes","No"))
C15: =IFERROR(VLOOKUP(B15,Roster!$A$3:$N$101,2,FALSE),"") | D15: =IFERROR(VLOOKUP(B15,Roster!$A$3:$N$101,3,FALSE),"") | E15: =IFERROR(VLOOKUP(B15,Roster!$A$3:$N$101,4,FALSE),"") | N15: =IF(OR(L15="",L15=0,M15=""),"",(L15-M15)/L15) | O15: =IF(N15="","",IF(N15>0,"Yes","No"))
C16: =IFERROR(VLOOKUP(B16,Roster!$A$3:$N$101,2,FALSE),"") | D16: =IFERROR(VLOOKUP(B16,Roster!$A$3:$N$101,3,FALSE),"") | E16: =IFERROR(VLOOKUP(B16,Roster!$A$3:$N$101,4,FALSE),"") | N16: =IF(OR(L16="",L16=0,M16=""),"",(L16-M16)/L16) | O16: =IF(N16="","",IF(N16>0,"Yes","No"))
C17: =IFERROR(VLOOKUP(B17,Roster!$A$3:$N$101,2,FALSE),"") | D17: =IFERROR(VLOOKUP(B17,Roster!$A$3:$N$101,3,FALSE),"") | E17: =IFERROR(VLOOKUP(B17,Roster!$A$3:$N$101,4,FALSE),"") | N17: =IF(OR(L17="",L17=0,M17=""),"",(L17-M17)/L17) | O17: =IF(N17="","",IF(N17>0,"Yes","No"))
... C201: =IFERROR(VLOOKUP(B201,Roster!$A$3:$N$101,2,FALSE),"") | D201: =IFERROR(VLOOKUP(B201,Roster!$A$3:$N$101,3,FALSE),"") | E201: =IFERROR(VLOOKUP(B201,Roster!$A$3:$N$101,4,FALSE),"") | N201: =IF(OR(L201="",L201=0,M201=""),"",(L201-M201)/L201) | O201: =IF(N201="","",IF(N201>0,"Yes","No"))

Sheet Risk Score Calculator
A1: RISK SCORE CALCULATOR — Navigator Escalation Risk Engine (Manual Version)
A2: Enter student data below. Scores are calculated automatically. Navigator computes this in real time across all students automatically.
A4: HOW SCORES ARE CALCULATED
A5: Factor | B5: Points | C5: Notes
A6: Referral in last 14 days | B6: +30 | C6: Any referral in past 14 days
A7: 2+ referrals in last 14 days | B7: +15 | C7: Additional points for multiple recent referrals
A8: 2+ referrals in last 30 days | B8: +15 | C8: Frequency pattern indicator
A9: 5+ referrals in last 60 days | B9: +10 | C9: Chronic referral pattern
A10: OSS in last 30 days | B10: +25 | C10: Any out-of-school suspension
A11: 2+ OSS in last 30 days | B11: +10 | C11: Additional for repeated OSS
A12: ISS in last 30 days | B12: +10 | C12: In-school suspension
A13: Prior DAEP escalation (any time) | B13: +20 | C13: Student has been escalated to DAEP before
A14: Each active support assigned | B14: −12 | C14: Supports reduce risk score (protective factor)
A15: Score range | B15: 0–100 | C15: Capped: Low 0–34 | Medium 35–69 | High 70–100
A18: STUDENT RISK SCORING — Enter data manually for each student
A19: Student ID | B19: Student Name | C19: Refs (14d) | D19: Refs (30d) | E19: Refs (60d) | F19: OSS (30d) | G19: ISS (30d) | H19: Prior DAEP | I19: Active Supports | J19: Score ⚙ | K19: Risk Level ⚙
A20: NAV-001 | B20: Miguel Torres | C20: 1 | D20: 2 | E20: 3 | F20: 1 | G20: 0 | H20: No | I20: 0 | J20: =IF(A20="","",MIN(100,MAX(0,IF(C20>=1,30,0)+IF(C20>=2,15,0)+IF(D20>=2,15,0)+IF(E20>=5,10,0)+IF(F20>=1,25,0)+IF(F20>=2,10,0)+IF(G20>=1,10,0)+IF(H20="Yes",20,0)-(I20*12)))) -> 70 | K20: =IF(J20="","",IF(J20>=70,"High",IF(J20>=35,"Medium","Low"))) -> High
A21: NAV-002 | B21: Amy Chen | C21: 0 | D21: 1 | E21: 2 | F21: 0 | G21: 1 | H21: No | I21: 1 | J21: =IF(A21="","",MIN(100,MAX(0,IF(C21>=1,30,0)+IF(C21>=2,15,0)+IF(D21>=2,15,0)+IF(E21>=5,10,0)+IF(F21>=1,25,0)+IF(F21>=2,10,0)+IF(G21>=1,10,0)+IF(H21="Yes",20,0)-(I21*12)))) -> 0 | K21: =IF(J21="","",IF(J21>=70,"High",IF(J21>=35,"Medium","Low"))) -> Low
A22: NAV-005 | B22: Raj Patel | C22: 0 | D22: 0 | E22: 1 | F22: 0 | G22: 0 | H22: No | I22: 1 | J22: =IF(A22="","",MIN(100,MAX(0,IF(C22>=1,30,0)+IF(C22>=2,15,0)+IF(D22>=2,15,0)+IF(E22>=5,10,0)+IF(F22>=1,25,0)+IF(F22>=2,10,0)+IF(G22>=1,10,0)+IF(H22="Yes",20,0)-(I22*12)))) -> 0 | K22: =IF(J22="","",IF(J22>=70,"High",IF(J22>=35,"Medium","Low"))) -> Low
J23: =IF(A23="","",MIN(100,MAX(0,IF(C23>=1,30,0)+IF(C23>=2,15,0)+IF(D23>=2,15,0)+IF(E23>=5,10,0)+IF(F23>=1,25,0)+IF(F23>=2,10,0)+IF(G23>=1,10,0)+IF(H23="Yes",20,0)-(I23*12)))) | K23: =IF(J23="","",IF(J23>=70,"High",IF(J23>=35,"Medium","Low")))
J24: =IF(A24="","",MIN(100,MAX(0,IF(C24>=1,30,0)+IF(C24>=2,15,0)+IF(D24>=2,15,0)+IF(E24>=5,10,0)+IF(F24>=1,25,0)+IF(F24>=2,10,0)+IF(G24>=1,10,0)+IF(H24="Yes",20,0)-(I24*12)))) | K24: =IF(J24="","",IF(J24>=70,"High",IF(J24>=35,"Medium","Low")))
J25: =IF(A25="","",MIN(100,MAX(0,IF(C25>=1,30,0)+IF(C25>=2,15,0)+IF(D25>=2,15,0)+IF(E25>=5,10,0)+IF(F25>=1,25,0)+IF(F25>=2,10,0)+IF(G25>=1,10,0)+IF(H25="Yes",20,0)-(I25*12)))) | K25: =IF(J25="","",IF(J25>=70,"High",IF(J25>=35,"Medium","Low")))
J26: =IF(A26="","",MIN(100,MAX(0,IF(C26>=1,30,0)+IF(C26>=2,15,0)+IF(D26>=2,15,0)+IF(E26>=5,10,0)+IF(F26>=1,25,0)+IF(F26>=2,10,0)+IF(G26>=1,10,0)+IF(H26="Yes",20,0)-(I26*12)))) | K26: =IF(J26="","",IF(J26>=70,"High",IF(J26>=35,"Medium","Low")))
J27: =IF(A27="","",MIN(100,MAX(0,IF(C27>=1,30,0)+IF(C27>=2,15,0)+IF(D27>=2,15,0)+IF(E27>=5,10,0)+IF(F27>=1,25,0)+IF(F27>=2,10,0)+IF(G27>=1,10,0)+IF(H27="Yes",20,0)-(I27*12)))) | K27: =IF(J27="","",IF(J27>=70,"High",IF(J27>=35,"Medium","Low")))
J28: =IF(A28="","",MIN(100,MAX(0,IF(C28>=1,30,0)+IF(C28>=2,15,0)+IF(D28>=2,15,0)+IF(E28>=5,10,0)+IF(F28>=1,25,0)+IF(F28>=2,10,0)+IF(G28>=1,10,0)+IF(H28="Yes",20,0)-(I28*12)))) | K28: =IF(J28="","",IF(J28>=70,"High",IF(J28>=35,"Medium","Low")))
J29: =IF(A29="","",MIN(100,MAX(0,IF(C29>=1,30,0)+IF(C29>=2,15,0)+IF(D29>=2,15,0)+IF(E29>=5,10,0)+IF(F29>=1,25,0)+IF(F29>=2,10,0)+IF(G29>=1,10,0)+IF(H29="Yes",20,0)-(I29*12)))) | K29: =IF(J29="","",IF(J29>=70,"High",IF(J29>=35,"Medium","Low")))
J30: =IF(A30="","",MIN(100,MAX(0,IF(C30>=1,30,0)+IF(C30>=2,15,0)+IF(D30>=2,15,0)+IF(E30>=5,10,0)+IF(F30>=1,25,0)+IF(F30>=2,10,0)+IF(G30>=1,10,0)+IF(H30="Yes",20,0)-(I30*12)))) | K30: =IF(J30="","",IF(J30>=70,"High",IF(J30>=35,"Medium","Low")))
J31: =IF(A31="","",MIN(100,MAX(0,IF(C31>=1,30,0)+IF(C31>=2,15,0)+IF(D31>=2,15,0)+IF(E31>=5,10,0)+IF(F31>=1,25,0)+IF(F31>=2,10,0)+IF(G31>=1,10,0)+IF(H31="Yes",20,0)-(I31*12)))) | K31: =IF(J31="","",IF(J31>=70,"High",IF(J31>=35,"Medium","Low")))
J32: =IF(A32="","",MIN(100,MAX(0,IF(C32>=1,30,0)+IF(C32>=2,15,0)+IF(D32>=2,15,0)+IF(E32>=5,10,0)+IF(F32>=1,25,0)+IF(F32>=2,10,0)+IF(G32>=1,10,0)+IF(H32="Yes",20,0)-(I32*12)))) | K32: =IF(J32="","",IF(J32>=70,"High",IF(J32>=35,"Medium","Low")))
J33: =IF(A33="","",MIN(100,MAX(0,IF(C33>=1,30,0)+IF(C33>=2,15,0)+IF(D33>=2,15,0)+IF(E33>=5,10,0)+IF(F33>=1,25,0)+IF(F33>=2,10,0)+IF(G33>=1,10,0)+IF(H33="Yes",20,0)-(I33*12)))) | K33: =IF(J33="","",IF(J33>=70,"High",IF(J33>=35,"Medium","Low")))
J34: =IF(A34="","",MIN(100,MAX(0,IF(C34>=1,30,0)+IF(C34>=2,15,0)+IF(D34>=2,15,0)+IF(E34>=5,10,0)+IF(F34>=1,25,0)+IF(F34>=2,10,0)+IF(G34>=1,10,0)+IF(H34="Yes",20,0)-(I34*12)))) | K34: =IF(J34="","",IF(J34>=70,"High",IF(J34>=35,"Medium","Low")))
... J69: =IF(A69="","",MIN(100,MAX(0,IF(C69>=1,30,0)+IF(C69>=2,15,0)+IF(D69>=2,15,0)+IF(E69>=5,10,0)+IF(F69>=1,25,0)+IF(F69>=2,10,0)+IF(G69>=1,10,0)+IF(H69="Yes",20,0)-(I69*12)))) | K69: =IF(J69="","",IF(J69>=70,"High",IF(J69>=35,"Medium","Low")))

Sheet Dashboard
A1: DASHBOARD — Auto-Summary (No Data Entry Needed)
A2: ="Reflects data as of: "&TEXT(TODAY(),"MM/DD/YYYY") -> Reflects data as of: 07/14/2026
A4: KEY METRICS — CURRENT SCHOOL YEAR
A5: Students Being Monitored | B5: =MAX(0,COUNTA(Roster!B:B)-2) -> 4
A6: Total Referrals (YTD) | B6: =MAX(0,COUNTA('Referral Log'!A:A)-2) -> 7
A7: Open Referrals | B7: =COUNTIF('Referral Log'!M:M,"Open") -> 2
A8: Escalated to DAEP | B8: =COUNTIF('Referral Log'!N:N,"Escalated to DAEP") -> 0
A9: Active ISS Placements | B9: =COUNTIF('ISS-OSS Placements'!K:K,">"&0) -> 0
A10: Active OSS Placements | B10: =COUNTIFS('ISS-OSS Placements'!F:F,"OSS — Out-of-School Suspension",'ISS-OSS Placements'!H:H,"") -> 1
A11: Students with 3+ OSS (90d) | B11: =COUNTIF('ISS-OSS Placements'!Q:Q,">="&3) -> 0
A12: Active Supports | B12: =COUNTIF('Student Supports'!K:K,"Active") -> 2
A13: Supports Completed | B13: =COUNTIF('Student Supports'!K:K,"Completed") -> 1
A14: ⚠ High Risk Students | B14: =COUNTIF('Risk Score Calculator'!K:K,"🔴 HIGH") -> 0
A16: REFERRALS BY OFFENSE CATEGORY (YTD)
A17: Fighting | B17: =COUNTIF('Referral Log'!H:H,"Fighting") -> 2 | C17: =REPT("|",B17) -> ||
A18: Drugs/Alcohol | B18: =COUNTIF('Referral Log'!H:H,"Drugs/Alcohol") -> 0 | C18: =REPT("|",B18)
A19: Weapons | B19: =COUNTIF('Referral Log'!H:H,"Weapons") -> 0 | C19: =REPT("|",B19)
A20: Harassment/Bullying | B20: =COUNTIF('Referral Log'!H:H,"Harassment/Bullying") -> 0 | C20: =REPT("|",B20)
A21: Truancy | B21: =COUNTIF('Referral Log'!H:H,"Truancy") -> 1 | C21: =REPT("|",B21) -> |
A22: Defiance/Insubordination | B22: =COUNTIF('Referral Log'!H:H,"Defiance/Insubordination") -> 3 | C22: =REPT("|",B22) -> |||
A23: Theft | B23: =COUNTIF('Referral Log'!H:H,"Theft") -> 0 | C23: =REPT("|",B23)
A24: Vandalism | B24: =COUNTIF('Referral Log'!H:H,"Vandalism") -> 0 | C24: =REPT("|",B24)
A25: Sexual Offense | B25: =COUNTIF('Referral Log'!H:H,"Sexual Offense") -> 0 | C25: =REPT("|",B25)
A26: Gang-Related Activity | B26: =COUNTIF('Referral Log'!H:H,"Gang-Related Activity") -> 0 | C26: =REPT("|",B26)
A27: Other | B27: =COUNTIF('Referral Log'!H:H,"Other") -> 1 | C27: =REPT("|",B27) -> |
A29: REFERRALS BY SKILL GAP (YTD)
A30: Emotional Regulation | B30: =COUNTIF('Referral Log'!J:J,"Emotional Regulation") -> 2 | C30: =REPT("|",B30) -> ||
A31: Executive Functioning | B31: =COUNTIF('Referral Log'!J:J,"Executive Functioning") -> 1 | C31: =REPT("|",B31) -> |
A32: Peer Conflict Resolution | B32: =COUNTIF('Referral Log'!J:J,"Peer Conflict Resolution") -> 2 | C32: =REPT("|",B32) -> ||
A33: Academic Frustration Tolerance | B33: =COUNTIF('Referral Log'!J:J,"Academic Frustration Tolerance") -> 0 | C33: =REPT("|",B33)
A34: Impulse Control | B34: =COUNTIF('Referral Log'!J:J,"Impulse Control") -> 1 | C34: =REPT("|",B34) -> |
A35: Adult Communication | B35: =COUNTIF('Referral Log'!J:J,"Adult Communication") -> 1 | C35: =REPT("|",B35) -> |
A37: SUPPORTS BY TYPE (YTD)
A38: CICO (Check-In / Check-Out) | B38: =COUNTIF('Student Supports'!F:F,"CICO (Check-In / Check-Out)") -> 1
A39: Counseling Referral | B39: =COUNTIF('Student Supports'!F:F,"Counseling Referral") -> 0
A40: Peer Mediation | B40: =COUNTIF('Student Supports'!F:F,"Peer Mediation") -> 0
A41: Social Skills Group | B41: =COUNTIF('Student Supports'!F:F,"Social Skills Group") -> 1
A42: Behavior Contract | B42: =COUNTIF('Student Supports'!F:F,"Behavior Contract") -> 1
A43: Academic Support | B43: =COUNTIF('Student Supports'!F:F,"Academic Support") -> 0
A44: Mindfulness Protocol | B44: =COUNTIF('Student Supports'!F:F,"Mindfulness Protocol") -> 0
...

Sheet 🚨 Risk Alert Board
A1: 🚨 WEEKLY RISK ALERT BOARD — Navigator Behavior Tracker
A2: ="As of: "&TEXT(TODAY(),"MMMM D, YYYY") -> As of: July 14, 2026
A3: Print this tab for your Monday morning behavior briefing. All data auto-updates from your other tabs.
A5: 🚨 OSS ESCALATION FLAGS (3+ OSS in 90 days)
A6: Student ID | B6: Last Name | C6: First Name | D6: Grade | E6: Campus | F6: OSS Count (90d) | G6: Status
A7: =IF('ISS-OSS Placements'!B3="","",IF(COUNTIFS('ISS-OSS Placements'!$B:$B,'ISS-OSS Placements'!B3,'ISS-OSS Placements'!$F:$F,"OSS — Out-of-School Suspension",'ISS-OSS Placements'!$G:$G,">="&(TODAY()-90))>=3,'ISS-OSS Placements'!B3,"")) | B7: =IF('ISS-OSS Placements'!B3="","",IF(COUNTIFS('ISS-OSS Placements'!$B:$B,'ISS-OSS Placements'!B3,'ISS-OSS Placements'!$F:$F,"OSS — Out-of-School Suspension",'ISS-OSS Placements'!$G:$G,">="&(TODAY()-90))>=3,'ISS-OSS Placements'!C3,"")) | C7: =IF('ISS-OSS Placements'!B3="","",IF(COUNTIFS('ISS-OSS Placements'!$B:$B,'ISS-OSS Placements'!B3,'ISS-OSS Placements'!$F:$F,"OSS — Out-of-School Suspension",'ISS-OSS Placements'!$G:$G,">="&(TODAY()-90))>=3,'ISS-OSS Placements'!D3,"")) | D7: =IF('ISS-OSS Placements'!B3="","",IF(COUNTIFS('ISS-OSS Placements'!$B:$B,'ISS-OSS Placements'!B3,'ISS-OSS Placements'!$F:$F,"OSS — Out-of-School Suspension",'ISS-OSS Placements'!$G:$G,">="&(TODAY()-90))>=3,'ISS-OSS Placements'!E3,"")) | F7: ='ISS-OSS Placements'!Q3 -> 0 | G7: Review for DAEP referral
A8: =IF('ISS-OSS Placements'!B4="","",IF(COUNTIFS('ISS-OSS Placements'!$B:$B,'ISS-OSS Placements'!B4,'ISS-OSS Placements'!$F:$F,"OSS — Out-of-School Suspension",'ISS-OSS Placements'!$G:$G,">="&(TODAY()-90))>=3,'ISS-OSS Placements'!B4,"")) | B8: =IF('ISS-OSS Placements'!B4="","",IF(COUNTIFS('ISS-OSS Placements'!$B:$B,'ISS-OSS Placements'!B4,'ISS-OSS Placements'!$F:$F,"OSS — Out-of-School Suspension",'ISS-OSS Placements'!$G:$G,">="&(TODAY()-90))>=3,'ISS-OSS Placements'!C4,"")) | C8: =IF('ISS-OSS Placements'!B4="","",IF(COUNTIFS('ISS-OSS Placements'!$B:$B,'ISS-OSS Placements'!B4,'ISS-OSS Placements'!$F:$F,"OSS — Out-of-School Suspension",'ISS-OSS Placements'!$G:$G,">="&(TODAY()-90))>=3,'ISS-OSS Placements'!D4,"")) | D8: =IF('ISS-OSS Placements'!B4="","",IF(COUNTIFS('ISS-OSS Placements'!$B:$B,'ISS-OSS Placements'!B4,'ISS-OSS Placements'!$F:$F,"OSS — Out-of-School Suspension",'ISS-OSS Placements'!$G:$G,">="&(TODAY()-90))>=3,'ISS-OSS Placements'!E4,"")) | F8: ='ISS-OSS Placements'!Q4 -> 0 | G8: Review for DAEP referral
A9: =IF('ISS-OSS Placements'!B5="","",IF(COUNTIFS('ISS-OSS Placements'!$B:$B,'ISS-OSS Placements'!B5,'ISS-OSS Placements'!$F:$F,"OSS — Out-of-School Suspension",'ISS-OSS Placements'!$G:$G,">="&(TODAY()-90))>=3,'ISS-OSS Placements'!B5,"")) | B9: =IF('ISS-OSS Placements'!B5="","",IF(COUNTIFS('ISS-OSS Placements'!$B:$B,'ISS-OSS Placements'!B5,'ISS-OSS Placements'!$F:$F,"OSS — Out-of-School Suspension",'ISS-OSS Placements'!$G:$G,">="&(TODAY()-90))>=3,'ISS-OSS Placements'!C5,"")) | C9: =IF('ISS-OSS Placements'!B5="","",IF(COUNTIFS('ISS-OSS Placements'!$B:$B,'ISS-OSS Placements'!B5,'ISS-OSS Placements'!$F:$F,"OSS — Out-of-School Suspension",'ISS-OSS Placements'!$G:$G,">="&(TODAY()-90))>=3,'ISS-OSS Placements'!D5,"")) | D9: =IF('ISS-OSS Placements'!B5="","",IF(COUNTIFS('ISS-OSS Placements'!$B:$B,'ISS-OSS Placements'!B5,'ISS-OSS Placements'!$F:$F,"OSS — Out-of-School Suspension",'ISS-OSS Placements'!$G:$G,">="&(TODAY()-90))>=3,'ISS-OSS Placements'!E5,"")) | F9: ='ISS-OSS Placements'!Q5 -> 0 | G9: Review for DAEP referral
A10: =IF('ISS-OSS Placements'!B6="","",IF(COUNTIFS('ISS-OSS Placements'!$B:$B,'ISS-OSS Placements'!B6,'ISS-OSS Placements'!$F:$F,"OSS — Out-of-School Suspension",'ISS-OSS Placements'!$G:$G,">="&(TODAY()-90))>=3,'ISS-OSS Placements'!B6,"")) | B10: =IF('ISS-OSS Placements'!B6="","",IF(COUNTIFS('ISS-OSS Placements'!$B:$B,'ISS-OSS Placements'!B6,'ISS-OSS Placements'!$F:$F,"OSS — Out-of-School Suspension",'ISS-OSS Placements'!$G:$G,">="&(TODAY()-90))>=3,'ISS-OSS Placements'!C6,"")) | C10: =IF('ISS-OSS Placements'!B6="","",IF(COUNTIFS('ISS-OSS Placements'!$B:$B,'ISS-OSS Placements'!B6,'ISS-OSS Placements'!$F:$F,"OSS — Out-of-School Suspension",'ISS-OSS Placements'!$G:$G,">="&(TODAY()-90))>=3,'ISS-OSS Placements'!D6,"")) | D10: =IF('ISS-OSS Placements'!B6="","",IF(COUNTIFS('ISS-OSS Placements'!$B:$B,'ISS-OSS Placements'!B6,'ISS-OSS Placements'!$F:$F,"OSS — Out-of-School Suspension",'ISS-OSS Placements'!$G:$G,">="&(TODAY()-90))>=3,'ISS-OSS Placements'!E6,"")) | F10: ='ISS-OSS Placements'!Q6 -> 0 | G10: Review for DAEP referral
A11: =IF('ISS-OSS Placements'!B7="","",IF(COUNTIFS('ISS-OSS Placements'!$B:$B,'ISS-OSS Placements'!B7,'ISS-OSS Placements'!$F:$F,"OSS — Out-of-School Suspension",'ISS-OSS Placements'!$G:$G,">="&(TODAY()-90))>=3,'ISS-OSS Placements'!B7,"")) | B11: =IF('ISS-OSS Placements'!B7="","",IF(COUNTIFS('ISS-OSS Placements'!$B:$B,'ISS-OSS Placements'!B7,'ISS-OSS Placements'!$F:$F,"OSS — Out-of-School Suspension",'ISS-OSS Placements'!$G:$G,">="&(TODAY()-90))>=3,'ISS-OSS Placements'!C7,"")) | C11: =IF('ISS-OSS Placements'!B7="","",IF(COUNTIFS('ISS-OSS Placements'!$B:$B,'ISS-OSS Placements'!B7,'ISS-OSS Placements'!$F:$F,"OSS — Out-of-School Suspension",'ISS-OSS Placements'!$G:$G,">="&(TODAY()-90))>=3,'ISS-OSS Placements'!D7,"")) | D11: =IF('ISS-OSS Placements'!B7="","",IF(COUNTIFS('ISS-OSS Placements'!$B:$B,'ISS-OSS Placements'!B7,'ISS-OSS Placements'!$F:$F,"OSS — Out-of-School Suspension",'ISS-OSS Placements'!$G:$G,">="&(TODAY()-90))>=3,'ISS-OSS Placements'!E7,"")) | F11: ='ISS-OSS Placements'!Q7 | G11: Review for DAEP referral
A12: =IF('ISS-OSS Placements'!B8="","",IF(COUNTIFS('ISS-OSS Placements'!$B:$B,'ISS-OSS Placements'!B8,'ISS-OSS Placements'!$F:$F,"OSS — Out-of-School Suspension",'ISS-OSS Placements'!$G:$G,">="&(TODAY()-90))>=3,'ISS-OSS Placements'!B8,"")) | B12: =IF('ISS-OSS Placements'!B8="","",IF(COUNTIFS('ISS-OSS Placements'!$B:$B,'ISS-OSS Placements'!B8,'ISS-OSS Placements'!$F:$F,"OSS — Out-of-School Suspension",'ISS-OSS Placements'!$G:$G,">="&(TODAY()-90))>=3,'ISS-OSS Placements'!C8,"")) | C12: =IF('ISS-OSS Placements'!B8="","",IF(COUNTIFS('ISS-OSS Placements'!$B:$B,'ISS-OSS Placements'!B8,'ISS-OSS Placements'!$F:$F,"OSS — Out-of-School Suspension",'ISS-OSS Placements'!$G:$G,">="&(TODAY()-90))>=3,'ISS-OSS Placements'!D8,"")) | D12: =IF('ISS-OSS Placements'!B8="","",IF(COUNTIFS('ISS-OSS Placements'!$B:$B,'ISS-OSS Placements'!B8,'ISS-OSS Placements'!$F:$F,"OSS — Out-of-School Suspension",'ISS-OSS Placements'!$G:$G,">="&(TODAY()-90))>=3,'ISS-OSS Placements'!E8,"")) | F12: ='ISS-OSS Placements'!Q8 | G12: Review for DAEP referral
A13: =IF('ISS-OSS Placements'!B9="","",IF(COUNTIFS('ISS-OSS Placements'!$B:$B,'ISS-OSS Placements'!B9,'ISS-OSS Placements'!$F:$F,"OSS — Out-of-School Suspension",'ISS-OSS Placements'!$G:$G,">="&(TODAY()-90))>=3,'ISS-OSS Placements'!B9,"")) | B13: =IF('ISS-OSS Placements'!B9="","",IF(COUNTIFS('ISS-OSS Placements'!$B:$B,'ISS-OSS Placements'!B9,'ISS-OSS Placements'!$F:$F,"OSS — Out-of-School Suspension",'ISS-OSS Placements'!$G:$G,">="&(TODAY()-90))>=3,'ISS-OSS Placements'!C9,"")) | C13: =IF('ISS-OSS Placements'!B9="","",IF(COUNTIFS('ISS-OSS Placements'!$B:$B,'ISS-OSS Placements'!B9,'ISS-OSS Placements'!$F:$F,"OSS — Out-of-School Suspension",'ISS-OSS Placements'!$G:$G,">="&(TODAY()-90))>=3,'ISS-OSS Placements'!D9,"")) | D13: =IF('ISS-OSS Placements'!B9="","",IF(COUNTIFS('ISS-OSS Placements'!$B:$B,'ISS-OSS Placements'!B9,'ISS-OSS Placements'!$F:$F,"OSS — Out-of-School Suspension",'ISS-OSS Placements'!$G:$G,">="&(TODAY()-90))>=3,'ISS-OSS Placements'!E9,"")) | F13: ='ISS-OSS Placements'!Q9 | G13: Review for DAEP referral
A14: =IF('ISS-OSS Placements'!B10="","",IF(COUNTIFS('ISS-OSS Placements'!$B:$B,'ISS-OSS Placements'!B10,'ISS-OSS Placements'!$F:$F,"OSS — Out-of-School Suspension",'ISS-OSS Placements'!$G:$G,">="&(TODAY()-90))>=3,'ISS-OSS Placements'!B10,"")) | B14: =IF('ISS-OSS Placements'!B10="","",IF(COUNTIFS('ISS-OSS Placements'!$B:$B,'ISS-OSS Placements'!B10,'ISS-OSS Placements'!$F:$F,"OSS — Out-of-School Suspension",'ISS-OSS Placements'!$G:$G,">="&(TODAY()-90))>=3,'ISS-OSS Placements'!C10,"")) | C14: =IF('ISS-OSS Placements'!B10="","",IF(COUNTIFS('ISS-OSS Placements'!$B:$B,'ISS-OSS Placements'!B10,'ISS-OSS Placements'!$F:$F,"OSS — Out-of-School Suspension",'ISS-OSS Placements'!$G:$G,">="&(TODAY()-90))>=3,'ISS-OSS Placements'!D10,"")) | D14: =IF('ISS-OSS Placements'!B10="","",IF(COUNTIFS('ISS-OSS Placements'!$B:$B,'ISS-OSS Placements'!B10,'ISS-OSS Placements'!$F:$F,"OSS — Out-of-School Suspension",'ISS-OSS Placements'!$G:$G,">="&(TODAY()-90))>=3,'ISS-OSS Placements'!E10,"")) | F14: ='ISS-OSS Placements'!Q10 | G14: Review for DAEP referral
A15: =IF('ISS-OSS Placements'!B11="","",IF(COUNTIFS('ISS-OSS Placements'!$B:$B,'ISS-OSS Placements'!B11,'ISS-OSS Placements'!$F:$F,"OSS — Out-of-School Suspension",'ISS-OSS Placements'!$G:$G,">="&(TODAY()-90))>=3,'ISS-OSS Placements'!B11,"")) | B15: =IF('ISS-OSS Placements'!B11="","",IF(COUNTIFS('ISS-OSS Placements'!$B:$B,'ISS-OSS Placements'!B11,'ISS-OSS Placements'!$F:$F,"OSS — Out-of-School Suspension",'ISS-OSS Placements'!$G:$G,">="&(TODAY()-90))>=3,'ISS-OSS Placements'!C11,"")) | C15: =IF('ISS-OSS Placements'!B11="","",IF(COUNTIFS('ISS-OSS Placements'!$B:$B,'ISS-OSS Placements'!B11,'ISS-OSS Placements'!$F:$F,"OSS — Out-of-School Suspension",'ISS-OSS Placements'!$G:$G,">="&(TODAY()-90))>=3,'ISS-OSS Placements'!D11,"")) | D15: =IF('ISS-OSS Placements'!B11="","",IF(COUNTIFS('ISS-OSS Placements'!$B:$B,'ISS-OSS Placements'!B11,'ISS-OSS Placements'!$F:$F,"OSS — Out-of-School Suspension",'ISS-OSS Placements'!$G:$G,">="&(TODAY()-90))>=3,'ISS-OSS Placements'!E11,"")) | F15: ='ISS-OSS Placements'!Q11 | G15: Review for DAEP referral
A16: =IF('ISS-OSS Placements'!B12="","",IF(COUNTIFS('ISS-OSS Placements'!$B:$B,'ISS-OSS Placements'!B12,'ISS-OSS Placements'!$F:$F,"OSS — Out-of-School Suspension",'ISS-OSS Placements'!$G:$G,">="&(TODAY()-90))>=3,'ISS-OSS Placements'!B12,"")) | B16: =IF('ISS-OSS Placements'!B12="","",IF(COUNTIFS('ISS-OSS Placements'!$B:$B,'ISS-OSS Placements'!B12,'ISS-OSS Placements'!$F:$F,"OSS — Out-of-School Suspension",'ISS-OSS Placements'!$G:$G,">="&(TODAY()-90))>=3,'ISS-OSS Placements'!C12,"")) | C16: =IF('ISS-OSS Placements'!B12="","",IF(COUNTIFS('ISS-OSS Placements'!$B:$B,'ISS-OSS Placements'!B12,'ISS-OSS Placements'!$F:$F,"OSS — Out-of-School Suspension",'ISS-OSS Placements'!$G:$G,">="&(TODAY()-90))>=3,'ISS-OSS Placements'!D12,"")) | D16: =IF('ISS-OSS Placements'!B12="","",IF(COUNTIFS('ISS-OSS Placements'!$B:$B,'ISS-OSS Placements'!B12,'ISS-OSS Placements'!$F:$F,"OSS — Out-of-School Suspension",'ISS-OSS Placements'!$G:$G,">="&(TODAY()-90))>=3,'ISS-OSS Placements'!E12,"")) | F16: ='ISS-OSS Placements'!Q12 | G16: Review for DAEP referral
A18: 📋 OPEN REFERRALS (no outcome assigned yet)
A19: Referral ID | B19: Date | C19: Student ID | D19: Last Name | E19: Offense | F19: Skill Gap | G19: Status
A20: =IF('Referral Log'!A3="","",IF('Referral Log'!M3="Open",'Referral Log'!A3,"")) | B20: =IF('Referral Log'!A3="","",IF('Referral Log'!M3="Open",'Referral Log'!B3,"")) | C20: =IF('Referral Log'!A3="","",IF('Referral Log'!M3="Open",'Referral Log'!D3,"")) | D20: =IF('Referral Log'!A3="","",IF('Referral Log'!M3="Open",'Referral Log'!E3,"")) | E20: =IF('Referral Log'!A3="","",IF('Referral Log'!M3="Open",'Referral Log'!H3,"")) | F20: =IF('Referral Log'!A3="","",IF('Referral Log'!M3="Open",'Referral Log'!J3,"")) | G20: =IF('Referral Log'!A3="","",IF('Referral Log'!M3="Open",'Referral Log'!M3,""))
A21: =IF('Referral Log'!A4="","",IF('Referral Log'!M4="Open",'Referral Log'!A4,"")) | B21: =IF('Referral Log'!A4="","",IF('Referral Log'!M4="Open",'Referral Log'!B4,"")) | C21: =IF('Referral Log'!A4="","",IF('Referral Log'!M4="Open",'Referral Log'!D4,"")) | D21: =IF('Referral Log'!A4="","",IF('Referral Log'!M4="Open",'Referral Log'!E4,"")) | E21: =IF('Referral Log'!A4="","",IF('Referral Log'!M4="Open",'Referral Log'!H4,"")) | F21: =IF('Referral Log'!A4="","",IF('Referral Log'!M4="Open",'Referral Log'!J4,"")) | G21: =IF('Referral Log'!A4="","",IF('Referral Log'!M4="Open",'Referral Log'!M4,""))
A22: =IF('Referral Log'!A5="","",IF('Referral Log'!M5="Open",'Referral Log'!A5,"")) | B22: =IF('Referral Log'!A5="","",IF('Referral Log'!M5="Open",'Referral Log'!B5,"")) | C22: =IF('Referral Log'!A5="","",IF('Referral Log'!M5="Open",'Referral Log'!D5,"")) | D22: =IF('Referral Log'!A5="","",IF('Referral Log'!M5="Open",'Referral Log'!E5,"")) | E22: =IF('Referral Log'!A5="","",IF('Referral Log'!M5="Open",'Referral Log'!H5,"")) | F22: =IF('Referral Log'!A5="","",IF('Referral Log'!M5="Open",'Referral Log'!J5,"")) | G22: =IF('Referral Log'!A5="","",IF('Referral Log'!M5="Open",'Referral Log'!M5,""))
A23: =IF('Referral Log'!A6="","",IF('Referral Log'!M6="Open",'Referral Log'!A6,"")) | B23: =IF('Referral Log'!A6="","",IF('Referral Log'!M6="Open",'Referral Log'!B6,"")) | C23: =IF('Referral Log'!A6="","",IF('Referral Log'!M6="Open",'Referral Log'!D6,"")) | D23: =IF('Referral Log'!A6="","",IF('Referral Log'!M6="Open",'Referral Log'!E6,"")) | E23: =IF('Referral Log'!A6="","",IF('Referral Log'!M6="Open",'Referral Log'!H6,"")) | F23: =IF('Referral Log'!A6="","",IF('Referral Log'!M6="Open",'Referral Log'!J6,"")) | G23: =IF('Referral Log'!A6="","",IF('Referral Log'!M6="Open",'Referral Log'!M6,""))
A24: =IF('Referral Log'!A7="","",IF('Referral Log'!M7="Open",'Referral Log'!A7,"")) -> REF-005 | B24: =IF('Referral Log'!A7="","",IF('Referral Log'!M7="Open",'Referral Log'!B7,"")) -> 46059 | C24: =IF('Referral Log'!A7="","",IF('Referral Log'!M7="Open",'Referral Log'!D7,"")) -> NAV-002 | D24: =IF('Referral Log'!A7="","",IF('Referral Log'!M7="Open",'Referral Log'!E7,"")) -> Chen | E24: =IF('Referral Log'!A7="","",IF('Referral Log'!M7="Open",'Referral Log'!H7,"")) -> Other | F24: =IF('Referral Log'!A7="","",IF('Referral Log'!M7="Open",'Referral Log'!J7,"")) -> Adult Communication | G24: =IF('Referral Log'!A7="","",IF('Referral Log'!M7="Open",'Referral Log'!M7,"")) -> Open
A25: =IF('Referral Log'!A8="","",IF('Referral Log'!M8="Open",'Referral Log'!A8,"")) | B25: =IF('Referral Log'!A8="","",IF('Referral Log'!M8="Open",'Referral Log'!B8,"")) | C25: =IF('Referral Log'!A8="","",IF('Referral Log'!M8="Open",'Referral Log'!D8,"")) | D25: =IF('Referral Log'!A8="","",IF('Referral Log'!M8="Open",'Referral Log'!E8,"")) | E25: =IF('Referral Log'!A8="","",IF('Referral Log'!M8="Open",'Referral Log'!H8,"")) | F25: =IF('Referral Log'!A8="","",IF('Referral Log'!M8="Open",'Referral Log'!J8,"")) | G25: =IF('Referral Log'!A8="","",IF('Referral Log'!M8="Open",'Referral Log'!M8,""))
A26: =IF('Referral Log'!A9="","",IF('Referral Log'!M9="Open",'Referral Log'!A9,"")) -> REF-007 | B26: =IF('Referral Log'!A9="","",IF('Referral Log'!M9="Open",'Referral Log'!B9,"")) -> 46083 | C26: =IF('Referral Log'!A9="","",IF('Referral Log'!M9="Open",'Referral Log'!D9,"")) -> NAV-004 | D26: =IF('Referral Log'!A9="","",IF('Referral Log'!M9="Open",'Referral Log'!E9,"")) -> Martinez | E26: =IF('Referral Log'!A9="","",IF('Referral Log'!M9="Open",'Referral Log'!H9,"")) -> Truancy | F26: =IF('Referral Log'!A9="","",IF('Referral Log'!M9="Open",'Referral Log'!J9,"")) -> Executive Functioning | G26: =IF('Referral Log'!A9="","",IF('Referral Log'!M9="Open",'Referral Log'!M9,"")) -> Open
A27: =IF('Referral Log'!A10="","",IF('Referral Log'!M10="Open",'Referral Log'!A10,"")) | B27: =IF('Referral Log'!A10="","",IF('Referral Log'!M10="Open",'Referral Log'!B10,"")) | C27: =IF('Referral Log'!A10="","",IF('Referral Log'!M10="Open",'Referral Log'!D10,"")) | D27: =IF('Referral Log'!A10="","",IF('Referral Log'!M10="Open",'Referral Log'!E10,"")) | E27: =IF('Referral Log'!A10="","",IF('Referral Log'!M10="Open",'Referral Log'!H10,"")) | F27: =IF('Referral Log'!A10="","",IF('Referral Log'!M10="Open",'Referral Log'!J10,"")) | G27: =IF('Referral Log'!A10="","",IF('Referral Log'!M10="Open",'Referral Log'!M10,""))
A28: =IF('Referral Log'!A11="","",IF('Referral Log'!M11="Open",'Referral Log'!A11,"")) | B28: =IF('Referral Log'!A11="","",IF('Referral Log'!M11="Open",'Referral Log'!B11,"")) | C28: =IF('Referral Log'!A11="","",IF('Referral Log'!M11="Open",'Referral Log'!D11,"")) | D28: =IF('Referral Log'!A11="","",IF('Referral Log'!M11="Open",'Referral Log'!E11,"")) | E28: =IF('Referral Log'!A11="","",IF('Referral Log'!M11="Open",'Referral Log'!H11,"")) | F28: =IF('Referral Log'!A11="","",IF('Referral Log'!M11="Open",'Referral Log'!J11,"")) | G28: =IF('Referral Log'!A11="","",IF('Referral Log'!M11="Open",'Referral Log'!M11,""))
A29: =IF('Referral Log'!A12="","",IF('Referral Log'!M12="Open",'Referral Log'!A12,"")) | B29: =IF('Referral Log'!A12="","",IF('Referral Log'!M12="Open",'Referral Log'!B12,"")) | C29: =IF('Referral Log'!A12="","",IF('Referral Log'!M12="Open",'Referral Log'!D12,"")) | D29: =IF('Referral Log'!A12="","",IF('Referral Log'!M12="Open",'Referral Log'!E12,"")) | E29: =IF('Referral Log'!A12="","",IF('Referral Log'!M12="Open",'Referral Log'!H12,"")) | F29: =IF('Referral Log'!A12="","",IF('Referral Log'!M12="Open",'Referral Log'!J12,"")) | G29: =IF('Referral Log'!A12="","",IF('Referral Log'!M12="Open",'Referral Log'!M12,""))
A31: 📊 SNAPSHOT COUNTS
A32: Active Supports | B32: =COUNTIF('Student Supports'!K:K,"Active") -> 2
A33: Open Referrals | B33: =COUNTIF('Referral Log'!M:M,"Open") -> 2
A34: Students w/ 3+ OSS (90d) | B34: =SUMPRODUCT((COUNTIFS('ISS-OSS Placements'!$B:$B,IF('ISS-OSS Placements'!$B:$B<>"",Roster!$A:$A,"NOMATCH"),'ISS-OSS Placements'!$F:$F,"OSS — Out-of-School Suspension",'ISS-OSS Placements'!$G:$G,">="&(TODAY()-90))>=3)*1) -> 0
A35: Total Referrals (YTD) | B35: =MAX(0,COUNTA('Referral Log'!A:A)-2) -> 7
A36: Completed Supports | B36: =COUNTIF('Student Supports'!K:K,"Completed") -> 1
A38: ─── Generated by Navigator — Student Behavior Tracker | Clear Path Education Group, LLC | clearpathedgroup.com ───

Sheet Reference
A1: REFERENCE — RTI/MTSS Framework, Behavior Intervention, and Escalation Thresholds
A2: Clear Path Education Group, LLC | clearpathedgroup.com | For organizational use only
A4: RTI / MTSS TIER FRAMEWORK
A5: Tier | B5: Description | C5: Student Population | D5: Typical Supports
A6: Tier 1 — Universal | B6: Core instruction and prevention for all students | C6: ~80% of students | D6: PBIS, classroom management, social-emotional learning curriculum
A7: Tier 2 — Targeted | B7: Small-group and strategic interventions for at-risk students | C7: ~15% of students | D7: CICO, social skills groups, academic support, counseling check-ins
A8: Tier 3 — Intensive | B8: Individualized, intensive support for highest-need students | C8: ~5% of students | D8: Behavior contracts, individual counseling, FBA/BIP, potential SPED evaluation
A10: NAVIGATOR RISK SCORE — ESCALATION THRESHOLDS
A11: Threshold | B11: Score Impact | C11: What It Means | D11: Recommended Response
A12: Referral in past 14 days | B12: +30 points | C12: Recent behavior event | D12: Assign support within 3 business days
A13: 2+ referrals in 14 days | B13: +15 additional | C13: Acute pattern emerging | D13: Counselor meeting within 1 business day
A14: 2+ referrals in 30 days | B14: +15 additional | C14: Frequency pattern | D14: Initiate Tier 2 intervention
A15: 5+ referrals in 60 days | B15: +10 additional | C15: Chronic pattern | D15: FBA consideration, possible ARD referral
