Workbook

Sheet Cover
A1: TEC Consequence Decision Matrix & Restorative Alternatives — Texas Edition
A2: Clear Path Education Group, LLC · clearpathedgroup.com
A3: Built for Texas campus administrators, CBCs, and counselors.
A4: The Texas Education Code tells you what you CAN do — this tool tells you what you SHOULD do. Every TEC §37 offense mapped to mandatory consequences, discretionary options, and research-backed restorative alternatives. Make better decisions faster, document them completely, and build a campus culture that actually changes behavior.
A6: ▸ DISTRICT & CAMPUS INFORMATION
B7: District Name
B8: Campus Name
B9: Department / Team
B10: Coordinator
B11: School Year | C11: 2025–2026
B12: Prepared By
A14: ▸ HOW TO USE THIS TRACKER
B15: 1. TEC Decision Matrix | C15: Every TEC §37 offense in one row. Mandatory vs. discretionary, consequence range, restorative alternatives, SPED flags, and required documentation.
B16: 2. Restorative Protocols | C16: 18 research-backed restorative and proactive alternatives. Step-by-step instructions, facilitator roles, time required, and success indicators.
B17: 3. Offense Lookup | C17: Enter an offense type and instantly see: TEC section, consequence options, restorative alternatives, SPED flags, and required documents.
B18: 4. CBC Workflow | C18: Campus Behavior Coordinator decision log. Documents the TEC §37.0012 required review: alternatives considered, SPED review, decision rationale.
B19: 5. SPED Safeguards | C19: Every TEC offense mapped to SPED/504 considerations: MDR triggers, 10-day rule tracking, FAPE requirements, ARD implications.
B20: 6. Parent Communication | C20: Required parent notice log by offense type. Documents method, date, and content — builds the audit trail you need for compliance.
B21: 7. Documentation Checklist | C21: Per-incident checklist of every required document by TEC section. Never miss a required form again.
B22: 8. Dashboard | C22: Campus-wide offense patterns, alternative consequence usage rates, SPED compliance flags, and CBC documentation completeness.
A24: ⚠ FOR ORGANIZATIONAL USE ONLY — Not legal advice. Consult district counsel for all placement and consequence decisions.
A26: 🚀 Ready to scale? Visit clearpathedgroup.com to upgrade to the full platform

Sheet TEC Decision Matrix
A1: TEC §37 Consequence Decision Matrix — Texas Edition
A2: Every TEC §37 offense. Mandatory vs. discretionary. Restorative alternatives. SPED flags. Required documentation. All in one row.
A3: ⚠ This matrix is a decision-support tool — not legal advice. Consult district counsel. Each row represents TEA/TEC guidance as of 2025.
A4: TEC Section | B4: Offense Category | C4: Specific Offense | D4: Consequence Type | E4: Minimum Consequence | F4: Maximum Consequence | G4: Days Range | H4: DAEP Required? | I4: Expulsion Eligible? | J4: SPED MDR Required? | K4: SPED 10-Day Rule? | L4: Alt 1 — Restorative | M4: Alt 2 — Proactive | N4: Alt 3 — Support-Based | O4: Required Documentation | P4: Parent Notice Required? | Q4: Notice Timeline | R4: CBC Required? | S4: Conference Required? | T4: Notes / TEA Guidance
A5: TEC §37.002(b) | B5: Teacher Removal | C5: Documented: student interferes with teacher's ability to teach OR student engages in conduct that is unruly, disruptive, or abusive | D5: Discretionary | E5: Teacher Removal to Reset Space | F5: ISS / Counselor Referral | G5: 1–3 days ISS | H5: No | I5: No | J5: Only if SPED pattern | K5: Yes — track | L5: Restorative Circle — Student + Teacher (counselor-facilitated) — addresses root cause of classroom conflict | M5: Behavior Contract with Daily Check-In — student and teacher agree on behavioral expectations with measurable goals | N5: Counselor Individual Sessions — 4-week plan addressing root cause (dysregulation, academic frustration, peer dynamics) | O5: Written Referral; Parent Contact Log | P5: Yes | Q5: Same day — verbal | R5: Recommended | S5: Yes — student, parent, teacher | T5: Teacher must document each removal. CBC must review if student is repeatedly removed.
A6: TEC §37.002(d) | B6: Teacher Removal — Mandatory | C6: Teacher MUST remove: student commits sexual assault, causes serious bodily injury, exhibits behavior that teacher reasonably believes poses a threat | D6: Mandatory | E6: Removal to Admin — immediate | F6: DAEP or campus alternative placement | G6: Until admin determination | H6: Likely | I6: Possible | J6: Yes — if SPED | K6: Yes — track cumulative | L6: Threat Assessment Protocol — safety-first; restorative work begins only after safety is confirmed | M6: Parent-Student-Admin Conference + written safety agreement before any return to classroom | N6: FBA + BIP Development if behavior is recurring | O6: Written Referral; Incident Report; Parent Notification | P6: Yes | Q6: Same day — written | R6: Yes | S6: Yes — required | T6: Admin must determine placement within 3 school days of removal. Cannot return student to same class without teacher consent.
A7: TEC §37.005 | B7: Suspension — General | C7: Conduct not covered by §37.006 or §37.007 that violates student code of conduct and is grounds for suspension per district policy | D7: Discretionary | E7: Warning / Parent Contact | F7: OSS — max 3 days per occurrence | G7: 1–3 days OSS | H7: No | I7: No | J7: Only if SPED + pattern | K7: Yes — track | L7: Parent-Student-Admin Conference + written behavior agreement as condition of return to campus | M7: ISS Alternative: structured in-school placement with assigned intervention track instead of OSS | N7: Community Service on Campus: student contributes positively to school community during ISS | O7: Parent Notification Form; Conference Summary | P7: Yes | Q7: Same day — verbal or written | R7: Recommended | S7: Recommended | T7: OSS suspends learning without changing behavior. Consider ISS + intervention as first response for Tier 1-2 offenses.
A8: TEC §37.005(c) | B8: Suspension — SPED Student | C8: Student with disability may be suspended up to 3 days without triggering IDEA change-of-placement rules — but cumulative days count | D8: Discretionary | E8: Parent Contact + Plan Review | F8: OSS max 3 days — cumulative days track toward 10 | G8: 1–3 days (track cumulative) | H8: No | I8: No | J8: Yes — track cumulative days | K8: YES — mandatory | L8: Coordinate with ARD team before suspension if possible; document that suspension is not related to disability | M8: Offer ISS with FAPE-compliant services as alternative — student receives educational benefit, days still count but learning continues | N8: FBA/BIP Review — if behavior is related to disability, suspension alone is never sufficient | O8: Parent Notification; IEP/ARD Notes; CBC Decision Log | P8: Yes | Q8: Before placement | R8: Yes | S8: Yes — ARD team may need to convene | T8: If cumulative days reach 10, MDR is required. FAPE must continue during any removal over 10 days.
A9: TEC §37.006(a) | B9: Mandatory DAEP — Felony Conduct | C9: Student engages in conduct punishable as a felony, regardless of whether charges are filed | D9: Mandatory | E9: DAEP placement — mandatory | F9: DAEP — up to end of year or beyond | G9: Until conditions met | H9: YES | I9: Possible | J9: Yes if SPED — MDR within 10 days | K9: YES — mandatory | L9: Restorative work WITHIN DAEP: facilitated accountability conference with affected party (does not reduce placement) | M9: Weekly parent update calls + written progress summary every 2 weeks during placement | N9: Counselor-led sessions at DAEP campus: Track H crisis support + Track F behavioral skills building | O9: Placement Order; Written Referral; Parent Notification; Conference Summary | P9: Yes | Q9: Before placement begins | R9: Yes | S9: Yes — required | T9: MDR required if student has IEP/504. Even during mandatory placement, restorative work should begin. Develop re-entry plan from Day 1.
A10: TEC §37.006(a)(2) | B10: Mandatory DAEP — Assault (Staff) | C10: Student commits assault resulting in bodily injury to school employee, causes school employee to fear imminent bodily injury | D10: Mandatory | E10: DAEP placement | F10: DAEP — minimum until end of semester in which incident occurs | G10: Until end of semester minimum | H10: YES | I10: YES | J10: Yes if SPED — MDR within 10 days | K10: YES — mandatory | L10: Accountability Circle (after safety clearance): student meets with CBC, counselor, and staff member with support | M10: Anger Management + Behavioral Skills (Track F) during DAEP placement — daily structured sessions | N10: Family Engagement Plan: family receives weekly updates; family conference required before re-entry | O10: Placement Order; Incident Report; Police Report if applicable; Parent Notification; MDR if SPED | P10: Yes | Q10: Before placement | R10: Yes | S10: Yes — required | T10: Student may NOT be placed in a program with students assigned to DAEP for non-assault reasons per §37.006(h).
A11: TEC §37.006(b) | B11: Mandatory DAEP — Drug/Alcohol | C11: Possession/use/distribution of controlled substance, alcohol, or dangerous drug on school property or at school-sponsored event | D11: Mandatory | E11: DAEP placement | F11: DAEP — discretionary length | G11: Varies — minimum 1 semester for distribution | H11: YES | I11: YES — distribution | J11: Yes if SPED | K11: YES — track | L11: Substance Awareness Education assigned within DAEP — district or community-based program | M11: Parent-Student counselor conference on Day 1 of placement — substance risk assessment | N11: Community referral: connect family with community substance support resources | O11: Placement Order; Parent Notification; CBC Decision Log; MDR if SPED | P11: Yes | Q11: Before placement | R11: Yes | S11: Yes | T11: Distribution is expulsion-eligible under §37.007(e). Campus counsel should be consulted immediately.
A12: TEC §37.006(c) | B12: Mandatory DAEP — Retaliation | C12: Student retaliates against school employee or volunteer by making a threat or causing bodily injury | D12: Mandatory | E12: DAEP placement | F12: DAEP — until end of year | G12: Until end of year | H12: YES | I12: YES | J12: Yes if SPED — MDR | K12: YES — mandatory | L12: Threat Assessment Protocol first — safety confirmation before any restorative work begins | M12: CBC-facilitated individual accountability plan: student documents understanding of harm caused | N12: Trauma-informed counseling (Track H): explore what drove the retaliation; address root cause | O12: Threat Assessment Record; Placement Order; Incident Report; Parent Notification | P12: Yes | Q12: Before placement | R12: Yes | S12: Yes — required | T12: Threat assessment team must convene. Document all steps. Coordinate with law enforcement if threat credible.
A13: TEC §37.007(a) | B13: Discretionary DAEP — Serious Misconduct | C13: Conduct occurring on campus/event that is not §37.006 but is so serious campus safety is threatened — at district discretion | D13: Discretionary | E13: ISS or OSS | F13: DAEP — discretionary | G13: Varies by severity and pattern | H13: Discretionary | I13: No | J13: Yes if SPED — review pattern | K13: YES — track cumulative | L13: Restorative Circle: student + affected parties + counselor — structured accountability and repair | M13: Graduated response: escalate from ISS → DAEP only if restorative alternative is tried and documented | N13: Behavior Support Plan: individualized plan with measurable goals before DAEP considered | O13: Written Referral; CBC Decision Log (alternatives documented); Parent Notification | P13: Yes | Q13: Within 24 hours | R13: Yes | S13: Yes — required | T13: CBC must document that alternatives to DAEP were considered. TEC requires this review. Undocumented decisions create legal risk.
A14: TEC §37.007(b)(1) | B14: Discretionary DAEP — Off-Campus Felony | C14: Student engages in conduct off campus that would be a felony if committed by an adult and poses a continuing danger | D14: Discretionary | E14: No required campus response | F14: DAEP — discretionary if danger exists | G14: Until danger resolved | H14: Discretionary | I14: Possible | J14: Yes if SPED | K14: YES — track | L14: Risk assessment first: Threat Assessment Team convenes to determine actual campus danger level | M14: Conditional return plan: student may return with structured monitoring, check-ins, behavior contract | N14: Family Engagement Plan: coordinate with family and outside supports | O14: CBC Decision Log; Threat Assessment Record; Parent Notification | P14: Yes | Q14: Within 24 hours | R14: Yes | S14: Yes | T14: Campus is not required to act on off-campus conduct unless it poses a continuing danger. Document the danger finding explicitly.
A15: TEC §37.007(c) | B15: Discretionary DAEP — Aggravated Robbery or Terroristic Threat | C15: Student commits aggravated robbery or makes terroristic threat off campus | D15: Discretionary | E15: Contact campus counsel immediately | F15: DAEP — strongly recommended | G15: Until criminal process resolved | H15: Discretionary | I15: YES | J15: Yes if SPED — MDR if DAEP used | K15: YES — mandatory if DAEP | L15: Threat Assessment Protocol — immediate team convening | M15: Conditional return plan with law enforcement coordination | N15: Intensive counseling (Track H) + FBA/BIP during any placement | O15: Threat Assessment Record; CBC Decision Log; Parent Notification; Counsel notification | P15: Yes | Q15: Before any placement | R15: Yes | S15: Yes — required | T15: Consult district legal counsel before any action. Document all steps. Coordinate with law enforcement throughout.
... A22: TEC §37.006(f) | B22: Affirmative Defense — Self-Defense | C22: Student who acts in self-defense cannot be removed to DAEP for that conduct. But campus must still investigate. | D22: Affirmative Defense — applies to §37.006(a)(2) assault cases | E22: Investigation required — no automatic placement | F22: Alternative consequence if self-defense confirmed | G22: Case-by-case | H22: No — if self-defense confirmed | I22: No | J22: Yes if SPED — still investigate | K22: Track if any removal occurs | L22: Restorative Circle for the original conflict: address what led to the altercation even if this student acted in self-defense | M22: Safety plan: what does this student need to feel safe at school? | N22: Counselor meeting: process the incident; build de-escalation skills for future conflicts | O22: Investigation Report; CBC Decision Log documenting self-defense finding | P22: Yes | Q22: Within 24 hours | R22: Yes | S22: Yes — investigate before any action | T22: Document the self-defense investigation explicitly. Cannot remove a student who acted in lawful self-defense without legal exposure.
A23: 🚀 Upgrade to the full platform · clearpathedgroup.com · Clear Path Education Group, LLC

Sheet Restorative Protocols
A1: Restorative & Proactive Protocols — Step-by-Step Reference
A2: 18 protocols. Each row is a complete implementation guide — assign the right protocol from the TEC Decision Matrix tab.
A3: Protocol ID | B3: Protocol Name | C3: Best For (Offense Types) | D3: Tier | E3: Time Required | F3: Facilitator | G3: Student Prep Required | H3: Parent Involved? | I3: Affected Party Involved? | J3: Step 1 | K3: Step 2 | L3: Step 3 | M3: Step 4 | N3: Step 5 | O3: Required Documentation | P3: Success Indicators | Q3: Research Basis | R3: Notes
A4: RP-01 | B4: Restorative Circle (Dyadic) | C4: Peer conflict, minor assault, bullying (perpetrator) | D4: Tier 2–3 | E4: 60–90 min total | F4: Counselor or trained CBC | G4: Student writes account of incident + impact on others | H4: Optional | I4: Yes | J4: Pre-conference: Meet with each party separately. Explain the process. Confirm willingness to participate. Safety check. | K4: Opening: Facilitator sets norms. Each person shares their perspective without interruption. | L4: Impact sharing: Affected party describes harm experienced. Student who caused harm listens fully. | M4: Accountability: Student who caused harm acknowledges impact. Brainstorm repair options together. | N4: Agreement: Create written repair agreement. Both parties sign. CBC countersigns. Follow-up date set. | O4: Restorative Agreement (signed by all parties); Facilitator notes; CBC sign-off | P4: Both parties report feeling heard; agreement terms are realistic and specific; no retaliation within 30 days | Q4: Gonzalez (2012): schools using RP reduce suspensions by 44%. IIRP research database. | R4: Do not proceed if either party is unwilling or if safety cannot be confirmed.
A5: RP-02 | B5: Restorative Circle (Whole Class) | C5: Class disruption pattern, bullying affecting group, trust breakdown between student and class | D5: Tier 1–2 | E5: 45–60 min | F5: Counselor + Teacher | G5: Teacher prepares class with circle norms | H5: No | I5: Group | J5: Teacher and counselor co-facilitate. Set community agreements: confidentiality, respect, no blame. | K5: Circle question 1: What has been happening in our classroom that isn't working? | L5: Circle question 2: How has it affected you personally? | M5: Circle question 3: What do we need from each other to make this classroom feel safe and productive? | N5: Create 3–5 class agreements. Post in classroom. Review in 2 weeks. | O5: Counselor notes; Class Agreement document; Teacher follow-up log | P5: Improved classroom climate report from teacher at 2-week follow-up; no further incidents involving same group | Q5: Costello, Wachtel & Wachtel (2009): Restorative Circles build social capital and reduce exclusionary discipline. | R5: Requires trained facilitator. Do not use when one student's behavior is the sole issue — use RP-01 instead.
A6: RP-03 | B6: Mediated Conversation | C6: Peer conflict, verbal altercation, social media conflict | D6: Tier 1–2 | E6: 30–45 min | F6: Counselor | G6: Each student writes 3 sentences: what happened, how I feel, what I need | H6: Optional | I6: Yes (both students) | J6: Separate pre-meetings: counselor meets with each student to review their written statement and explain the process. | K6: Joint meeting: each student reads their statement without interruption. Counselor reflects back. | L6: Counselor asks: What do you need from this person to move forward? | M6: Negotiated agreement: agree on 1–3 specific behavioral commitments each. | N6: Written agreement signed by both students. Counselor files copy. Follow-up in 1 week. | O6: Mediation Summary; Signed Agreement; Counselor follow-up note | P6: Both students can articulate the other's perspective; no further incidents between same students within 30 days | Q6: Johnson & Johnson (2009): peer mediation reduces aggressive incidents by 38% in middle school. | R6: Both students must be willing. Counselor should not proceed if one party is coerced.
A7: RP-04 | B7: Written Apology + Repair Plan | C7: Minor offense with identifiable harm; first offense; Tier 1 | D7: Tier 1 | E7: 30–45 min | F7: Teacher or Counselor | G7: Student writes draft apology before meeting | H7: Optional | I7: Indirectly | J7: Student writes structured apology: (1) What I did, (2) Why it was wrong, (3) How it affected you, (4) What I will do differently. | K7: Counselor reviews draft with student. Coach for specificity and accountability language. | L7: Student presents apology to affected party (in writing or in person, based on comfort level of affected party). | M7: Student writes 'repair plan': one specific action they will take to make things better. | N7: Counselor files completed apology and repair plan. Share copy with admin and parent. | O7: Completed Apology (signed); Repair Plan; Counselor note | P7: Affected party reports feeling acknowledged; student can articulate why their behavior was harmful | Q7: Braithwaite (2002): Reintegrative shaming theory — public accountability paired with community support reduces reoffending. | R7: Apology must be voluntary and genuine to be effective. Forced apologies can backfire.
A8: RP-05 | B8: Parent-Student-Admin Conference + Agreement | C8: Any Tier 2+ offense; repeated Tier 1; before DAEP consideration | D8: Tier 2–3 | E8: 45–60 min | F8: CBC or Principal | G8: Student writes reflection on incident before meeting | H8: Yes — required | I8: No | J8: Admin reviews incident facts, prior history, and any SPED considerations before meeting. | K8: Conference: student shares their perspective. Parent shares concerns. Admin shares school's perspective. | L8: Collaborative problem-solving: What does this student need to succeed? What will the school provide? What will the family provide? | M8: Written behavior agreement: 3–5 specific, measurable commitments. Roles for student, parent, and school named. | N8: Signed agreement filed. Follow-up meeting or call scheduled within 30 days. | O8: Conference Summary; Signed Behavior Agreement; Parent Notification Form | P8: Family reports feeling heard and respected; student can state their commitments; no repeat offense within 30 days | Q8: Epstein (2011): Family involvement is the single strongest predictor of behavior change in school settings. | R8: This conference satisfies the TEC §37.009 requirement when DAEP placement is being considered.
A9: RP-06 | B9: Behavior Contract with Daily Check-In | C9: Pattern behavior (2–3 same offense); Tier 2; as condition of return from ISS | D9: Tier 2 | E9: Initial: 20 min setup; 5 min/day ongoing | F9: Counselor or designated mentor | G9: Student co-creates contract goals | H9: Yes | I9: No | J9: Student and counselor identify: (1) specific trigger behaviors, (2) alternative responses to use instead. | K9: Contract drafted: 3 specific, observable goals. 'I will ___' not 'I will not ___'. Positive framing. | L9: Contract signed by student, counselor, parent, and admin. Copy to homeroom teacher. | M9: Daily 5-min check-in with designated adult: Did I meet my goals today? What was hard? What helped? | N9: Weekly review at 4 weeks: goals met → celebrate + reduce check-in frequency. Not met → revise plan. | O9: Signed Behavior Contract; Daily Check-In Log; Weekly Review Notes | P9: Student meets goals on 80%+ of school days by week 4; self-reports improved confidence in behavior management | Q9: Sugai & Horner (2002): Behavior contracts are core Tier 2 PBIS intervention with strong evidence base. | R9: Check-in must be consistent. If the adult changes frequently, effectiveness drops significantly.
A10: RP-07 | B10: Threat Assessment Protocol | C10: Any threat — written, verbal, or gestural; social media threats; Tier 3–4 | D10: Tier 3–4 | E10: Variable — team-driven | F10: Threat Assessment Team (admin + counselor + SPED if applicable) | G10: N/A — student may be removed during process | H10: Yes — required | I10: No | J10: Remove student from situation. Notify CBC and principal immediately. Contact law enforcement if credible imminent threat. | K10: Threat Assessment Team convenes within 24 hours: evaluate nature and credibility of threat (substantive vs. transient). | L10: Student interview (with parent present). Review prior history, mental health indicators, stressors. | M10: Determine threat level. Assign safety plan. Connect to counseling and outside resources as needed. | N10: Create written safety plan. Share with all staff who interact with student. Set re-evaluation date. | O10: Threat Assessment Record; Safety Plan; Parent Notification; Law Enforcement Report if applicable | P10: Threat is resolved (transient) or managed (substantive); student is connected to appropriate support | Q10: Cornell & Sheras (2006): Virginia Threat Assessment Guidelines — most validated school threat assessment model. | R10: All staff who receive a threat must report to admin immediately. Document the report time and method.
A11: RP-08 | B11: Community Service on Campus | C11: Tier 1–2 offenses with property/environmental harm; vandalism; general misconduct | D11: Tier 1–2 | E11: 1–5 days, during ISS or after school | F11: Any trusted adult supervisor | G11: Student reflects on connection between offense and service | H11: Yes | I11: Indirectly | J11: CBC identifies service assignment connected to the offense (vandalism → clean/repair; disruption → help younger students). | K11: Student meets with supervisor. Explain purpose: this is not punishment — it is contribution. | L11: Student completes service. Daily reflection: What did I do today? Who did I help? What did I learn? | M11: Final reflection: What is different about how I see this school after serving it? | N11: Present completed reflection to CBC or counselor. Acknowledge contribution. | O11: Service Log; Daily Reflection; Final Reflection; CBC Sign-Off | P11: Student can articulate connection between service and offense; reports feeling more connected to school community | Q11: Bazemore & Schiff (2005): Community service as reparation — most effective when personally meaningful to student. | R11: Generic service (picking up trash with no reflection) has weak effect. The reflection component is essential.
A12: RP-09 | B12: Mentoring Assignment (30-Day Plan) | C12: First DAEP return; Tier 2 pattern; student identified as Tier 2 MTSS risk | D12: Tier 2 | E12: 15 min/day for 30 days | F12: Trusted adult (teacher, coach, counselor, admin) | G12: Student completes brief interest inventory to match with mentor | H12: Yes | I12: No | J12: CBC or counselor identifies mentor based on student interest and trust. Confirm mentor availability. | K12: Mentor and student meet for intake: What are you good at? What's hard about school right now? What's one goal? | L12: Daily 15-min check-in: 1 positive observation + 1 area to strengthen. Student logs in journal. | M12: Week 3 review: is mentoring working? Adjust frequency or mentor if needed. | N12: 30-day celebration: acknowledge growth. Transition to bi-weekly check-ins if going well. | O12: Mentoring Log; Student Journal; 30-Day Review Summary | P12: Student attends school more consistently; no new referrals in 30 days; student names mentor as trusted adult | Q12: Balfanz et al. (2014): One trusted adult relationship is the single strongest protective factor against dropout. | R12: Mentor must be consistent. Do not assign a mentor who travels frequently or has inconsistent availability.
A13: RP-10 | B13: Academic Support + Catch-Up Plan | C13: Any placement where student misses instruction; academic frustration as root cause | D13: Tier 1–4 (universal) | E13: Daily during placement + 2-week follow-up | F13: Subject teachers + counselor | G13: Student completes learning inventory: what do I understand? where am I stuck? | H13: Yes | I13: No | J13: On Day 1 of any placement: counselor contacts each teacher for assignment list and priority learning targets. | K13: Student works on assignments during ISS with structured time for each subject. | L13: Teacher check-in (by phone, email, or brief visit): one positive + one area of focus for this student. | M13: CBC ensures no student accumulates more than 3 days of missing work without a catch-up plan. | N13: Return-to-class plan: for multi-day absence, teacher provides 2-week extended deadline schedule. | O13: Academic Catch-Up Plan; Teacher Contact Log; Completion Checklist | P13: Student returns with no more than 1 day of outstanding work; teacher reports student is re-engaged academically | Q13: Balfanz et al. (2014): Academic disengagement during discipline placements is a top driver of dropout. | R13: This is not optional. Every student in any placement needs an academic catch-up plan by end of Day 1.
A14: 🚀 Upgrade to the full platform · clearpathedgroup.com · Clear Path Education Group, LLC

Sheet Offense Lookup
A1: ⚡ Offense Lookup — Instant Decision Support for Administrators
A2: Select an offense from the dropdown in column B. Columns C–H auto-populate from the TEC Decision Matrix.
A3: ⚠ Results auto-populate from your TEC Decision Matrix tab. All data is live — if you update the matrix, this updates too.
A4: SELECT OFFENSE BELOW — Use the dropdown ▼ in column B
B5: Offense Type (select ▼) | C5: TEC Section | D5: Consequence Options (Mandatory / Discretionary) | E5: Restorative Alternatives | F5: Required Documentation | G5: SPED Flags | H5: CBC Required?
C6: =IFERROR(VLOOKUP(B6,$B$33:$H$53,2,FALSE()),IF(B6="","— select offense above —","Not found")) -> — select offense above — | D6: =IFERROR(VLOOKUP(B6,$B$33:$H$53,3,FALSE()),IF(B6="","— select offense above —","Not found")) -> — select offense above — | E6: =IFERROR(VLOOKUP(B6,$B$33:$H$53,4,FALSE()),IF(B6="","— select offense above —","Not found")) -> — select offense above — | F6: =IFERROR(VLOOKUP(B6,$B$33:$H$53,5,FALSE()),IF(B6="","— select offense above —","Not found")) -> — select offense above — | G6: =IFERROR(VLOOKUP(B6,$B$33:$H$53,6,FALSE()),IF(B6="","— select offense above —","Not found")) -> — select offense above — | H6: =IFERROR(VLOOKUP(B6,$B$33:$H$53,7,FALSE()),IF(B6="","— select offense above —","Not found")) -> — select offense above —
C7: =IFERROR(VLOOKUP(B7,$B$33:$H$53,2,FALSE()),IF(B7="","— select offense above —","Not found")) -> — select offense above — | D7: =IFERROR(VLOOKUP(B7,$B$33:$H$53,3,FALSE()),IF(B7="","— select offense above —","Not found")) -> — select offense above — | E7: =IFERROR(VLOOKUP(B7,$B$33:$H$53,4,FALSE()),IF(B7="","— select offense above —","Not found")) -> — select offense above — | F7: =IFERROR(VLOOKUP(B7,$B$33:$H$53,5,FALSE()),IF(B7="","— select offense above —","Not found")) -> — select offense above — | G7: =IFERROR(VLOOKUP(B7,$B$33:$H$53,6,FALSE()),IF(B7="","— select offense above —","Not found")) -> — select offense above — | H7: =IFERROR(VLOOKUP(B7,$B$33:$H$53,7,FALSE()),IF(B7="","— select offense above —","Not found")) -> — select offense above —
C8: =IFERROR(VLOOKUP(B8,$B$33:$H$53,2,FALSE()),IF(B8="","— select offense above —","Not found")) -> — select offense above — | D8: =IFERROR(VLOOKUP(B8,$B$33:$H$53,3,FALSE()),IF(B8="","— select offense above —","Not found")) -> — select offense above — | E8: =IFERROR(VLOOKUP(B8,$B$33:$H$53,4,FALSE()),IF(B8="","— select offense above —","Not found")) -> — select offense above — | F8: =IFERROR(VLOOKUP(B8,$B$33:$H$53,5,FALSE()),IF(B8="","— select offense above —","Not found")) -> — select offense above — | G8: =IFERROR(VLOOKUP(B8,$B$33:$H$53,6,FALSE()),IF(B8="","— select offense above —","Not found")) -> — select offense above — | H8: =IFERROR(VLOOKUP(B8,$B$33:$H$53,7,FALSE()),IF(B8="","— select offense above —","Not found")) -> — select offense above —
C9: =IFERROR(VLOOKUP(B9,$B$33:$H$53,2,FALSE()),IF(B9="","— select offense above —","Not found")) -> — select offense above — | D9: =IFERROR(VLOOKUP(B9,$B$33:$H$53,3,FALSE()),IF(B9="","— select offense above —","Not found")) -> — select offense above — | E9: =IFERROR(VLOOKUP(B9,$B$33:$H$53,4,FALSE()),IF(B9="","— select offense above —","Not found")) -> — select offense above — | F9: =IFERROR(VLOOKUP(B9,$B$33:$H$53,5,FALSE()),IF(B9="","— select offense above —","Not found")) -> — select offense above — | G9: =IFERROR(VLOOKUP(B9,$B$33:$H$53,6,FALSE()),IF(B9="","— select offense above —","Not found")) -> — select offense above — | H9: =IFERROR(VLOOKUP(B9,$B$33:$H$53,7,FALSE()),IF(B9="","— select offense above —","Not found")) -> — select offense above —
C10: =IFERROR(VLOOKUP(B10,$B$33:$H$53,2,FALSE()),IF(B10="","— select offense above —","Not found")) -> — select offense above — | D10: =IFERROR(VLOOKUP(B10,$B$33:$H$53,3,FALSE()),IF(B10="","— select offense above —","Not found")) -> — select offense above — | E10: =IFERROR(VLOOKUP(B10,$B$33:$H$53,4,FALSE()),IF(B10="","— select offense above —","Not found")) -> — select offense above — | F10: =IFERROR(VLOOKUP(B10,$B$33:$H$53,5,FALSE()),IF(B10="","— select offense above —","Not found")) -> — select offense above — | G10: =IFERROR(VLOOKUP(B10,$B$33:$H$53,6,FALSE()),IF(B10="","— select offense above —","Not found")) -> — select offense above — | H10: =IFERROR(VLOOKUP(B10,$B$33:$H$53,7,FALSE()),IF(B10="","— select offense above —","Not found")) -> — select offense above —
C11: =IFERROR(VLOOKUP(B11,$B$33:$H$53,2,FALSE()),IF(B11="","— select offense above —","Not found")) -> — select offense above — | D11: =IFERROR(VLOOKUP(B11,$B$33:$H$53,3,FALSE()),IF(B11="","— select offense above —","Not found")) -> — select offense above — | E11: =IFERROR(VLOOKUP(B11,$B$33:$H$53,4,FALSE()),IF(B11="","— select offense above —","Not found")) -> — select offense above — | F11: =IFERROR(VLOOKUP(B11,$B$33:$H$53,5,FALSE()),IF(B11="","— select offense above —","Not found")) -> — select offense above — | G11: =IFERROR(VLOOKUP(B11,$B$33:$H$53,6,FALSE()),IF(B11="","— select offense above —","Not found")) -> — select offense above — | H11: =IFERROR(VLOOKUP(B11,$B$33:$H$53,7,FALSE()),IF(B11="","— select offense above —","Not found")) -> — select offense above —
C12: =IFERROR(VLOOKUP(B12,$B$33:$H$53,2,FALSE()),IF(B12="","— select offense above —","Not found")) -> — select offense above — | D12: =IFERROR(VLOOKUP(B12,$B$33:$H$53,3,FALSE()),IF(B12="","— select offense above —","Not found")) -> — select offense above — | E12: =IFERROR(VLOOKUP(B12,$B$33:$H$53,4,FALSE()),IF(B12="","— select offense above —","Not found")) -> — select offense above — | F12: =IFERROR(VLOOKUP(B12,$B$33:$H$53,5,FALSE()),IF(B12="","— select offense above —","Not found")) -> — select offense above — | G12: =IFERROR(VLOOKUP(B12,$B$33:$H$53,6,FALSE()),IF(B12="","— select offense above —","Not found")) -> — select offense above — | H12: =IFERROR(VLOOKUP(B12,$B$33:$H$53,7,FALSE()),IF(B12="","— select offense above —","Not found")) -> — select offense above —
C13: =IFERROR(VLOOKUP(B13,$B$33:$H$53,2,FALSE()),IF(B13="","— select offense above —","Not found")) -> — select offense above — | D13: =IFERROR(VLOOKUP(B13,$B$33:$H$53,3,FALSE()),IF(B13="","— select offense above —","Not found")) -> — select offense above — | E13: =IFERROR(VLOOKUP(B13,$B$33:$H$53,4,FALSE()),IF(B13="","— select offense above —","Not found")) -> — select offense above — | F13: =IFERROR(VLOOKUP(B13,$B$33:$H$53,5,FALSE()),IF(B13="","— select offense above —","Not found")) -> — select offense above — | G13: =IFERROR(VLOOKUP(B13,$B$33:$H$53,6,FALSE()),IF(B13="","— select offense above —","Not found")) -> — select offense above — | H13: =IFERROR(VLOOKUP(B13,$B$33:$H$53,7,FALSE()),IF(B13="","— select offense above —","Not found")) -> — select offense above —
C14: =IFERROR(VLOOKUP(B14,$B$33:$H$53,2,FALSE()),IF(B14="","— select offense above —","Not found")) -> — select offense above — | D14: =IFERROR(VLOOKUP(B14,$B$33:$H$53,3,FALSE()),IF(B14="","— select offense above —","Not found")) -> — select offense above — | E14: =IFERROR(VLOOKUP(B14,$B$33:$H$53,4,FALSE()),IF(B14="","— select offense above —","Not found")) -> — select offense above — | F14: =IFERROR(VLOOKUP(B14,$B$33:$H$53,5,FALSE()),IF(B14="","— select offense above —","Not found")) -> — select offense above — | G14: =IFERROR(VLOOKUP(B14,$B$33:$H$53,6,FALSE()),IF(B14="","— select offense above —","Not found")) -> — select offense above — | H14: =IFERROR(VLOOKUP(B14,$B$33:$H$53,7,FALSE()),IF(B14="","— select offense above —","Not found")) -> — select offense above —
C15: =IFERROR(VLOOKUP(B15,$B$33:$H$53,2,FALSE()),IF(B15="","— select offense above —","Not found")) -> — select offense above — | D15: =IFERROR(VLOOKUP(B15,$B$33:$H$53,3,FALSE()),IF(B15="","— select offense above —","Not found")) -> — select offense above — | E15: =IFERROR(VLOOKUP(B15,$B$33:$H$53,4,FALSE()),IF(B15="","— select offense above —","Not found")) -> — select offense above — | F15: =IFERROR(VLOOKUP(B15,$B$33:$H$53,5,FALSE()),IF(B15="","— select offense above —","Not found")) -> — select offense above — | G15: =IFERROR(VLOOKUP(B15,$B$33:$H$53,6,FALSE()),IF(B15="","— select offense above —","Not found")) -> — select offense above — | H15: =IFERROR(VLOOKUP(B15,$B$33:$H$53,7,FALSE()),IF(B15="","— select offense above —","Not found")) -> — select offense above —
C16: =IFERROR(VLOOKUP(B16,$B$33:$H$53,2,FALSE()),IF(B16="","— select offense above —","Not found")) -> — select offense above — | D16: =IFERROR(VLOOKUP(B16,$B$33:$H$53,3,FALSE()),IF(B16="","— select offense above —","Not found")) -> — select offense above — | E16: =IFERROR(VLOOKUP(B16,$B$33:$H$53,4,FALSE()),IF(B16="","— select offense above —","Not found")) -> — select offense above — | F16: =IFERROR(VLOOKUP(B16,$B$33:$H$53,5,FALSE()),IF(B16="","— select offense above —","Not found")) -> — select offense above — | G16: =IFERROR(VLOOKUP(B16,$B$33:$H$53,6,FALSE()),IF(B16="","— select offense above —","Not found")) -> — select offense above — | H16: =IFERROR(VLOOKUP(B16,$B$33:$H$53,7,FALSE()),IF(B16="","— select offense above —","Not found")) -> — select offense above —
C17: =IFERROR(VLOOKUP(B17,$B$33:$H$53,2,FALSE()),IF(B17="","— select offense above —","Not found")) -> — select offense above — | D17: =IFERROR(VLOOKUP(B17,$B$33:$H$53,3,FALSE()),IF(B17="","— select offense above —","Not found")) -> — select offense above — | E17: =IFERROR(VLOOKUP(B17,$B$33:$H$53,4,FALSE()),IF(B17="","— select offense above —","Not found")) -> — select offense above — | F17: =IFERROR(VLOOKUP(B17,$B$33:$H$53,5,FALSE()),IF(B17="","— select offense above —","Not found")) -> — select offense above — | G17: =IFERROR(VLOOKUP(B17,$B$33:$H$53,6,FALSE()),IF(B17="","— select offense above —","Not found")) -> — select offense above — | H17: =IFERROR(VLOOKUP(B17,$B$33:$H$53,7,FALSE()),IF(B17="","— select offense above —","Not found")) -> — select offense above —
... C25: =IFERROR(VLOOKUP(B25,$B$33:$H$53,2,FALSE()),IF(B25="","— select offense above —","Not found")) -> — select offense above — | D25: =IFERROR(VLOOKUP(B25,$B$33:$H$53,3,FALSE()),IF(B25="","— select offense above —","Not found")) -> — select offense above — | E25: =IFERROR(VLOOKUP(B25,$B$33:$H$53,4,FALSE()),IF(B25="","— select offense above —","Not found")) -> — select offense above — | F25: =IFERROR(VLOOKUP(B25,$B$33:$H$53,5,FALSE()),IF(B25="","— select offense above —","Not found")) -> — select offense above — | G25: =IFERROR(VLOOKUP(B25,$B$33:$H$53,6,FALSE()),IF(B25="","— select offense above —","Not found")) -> — select offense above — | H25: =IFERROR(VLOOKUP(B25,$B$33:$H$53,7,FALSE()),IF(B25="","— select offense above —","Not found")) -> — select offense above —
A26: 🚀 Upgrade to the full platform · clearpathedgroup.com · Clear Path Education Group, LLC | C26: =IFERROR(VLOOKUP(B26,$B$33:$H$53,2,FALSE()),IF(B26="","— select offense above —","Not found")) -> — select offense above — | D26: =IFERROR(VLOOKUP(B26,$B$33:$H$53,3,FALSE()),IF(B26="","— select offense above —","Not found")) -> — select offense above — | E26: =IFERROR(VLOOKUP(B26,$B$33:$H$53,4,FALSE()),IF(B26="","— select offense above —","Not found")) -> — select offense above — | F26: =IFERROR(VLOOKUP(B26,$B$33:$H$53,5,FALSE()),IF(B26="","— select offense above —","Not found")) -> — select offense above — | G26: =IFERROR(VLOOKUP(B26,$B$33:$H$53,6,FALSE()),IF(B26="","— select offense above —","Not found")) -> — select offense above — | H26: =IFERROR(VLOOKUP(B26,$B$33:$H$53,7,FALSE()),IF(B26="","— select offense above —","Not found")) -> — select offense above —
B31: — REFERENCE TABLE (do not edit) —
B32: Offense Key | C32: TEC Section | D32: Consequence Options | E32: Restorative Alternatives | F32: Required Documentation | G32: SPED Flags | H32: CBC Required?
B33: Assault — Bodily Injury (staff) | C33: TEC §37.006(a)(2) | D33: Mandatory DAEP; Law Enforcement Referral required | E33: Threat Assessment Protocol (RP-07); Accountability Circle during DAEP placement | F33: Incident Report; Placement Order; Law Enforcement Report; Parent Notification; MDR if SPED | G33: IEP — IDEA: MDR within 10 days; FAPE must continue at DAEP | H33: Yes
B34: Assault — Bodily Injury (student) | C34: TEC §37.006(a) | D34: Mandatory DAEP | E34: Restorative Circle RP-01 WITHIN DAEP (does not replace placement); Counselor Track H | F34: Incident Report; Placement Order; Parent Notification; MDR if SPED | G34: IEP — IDEA: MDR within 10 days; FAPE must continue | H34: Yes
B35: Assault — Threat / Fear of Injury | C35: TEC §37.006(a) | D35: Mandatory DAEP or ISS following threat assessment | E35: Threat Assessment RP-07; Mediated Conversation RP-03 if transient threat determined | F35: Threat Assessment Record; CBC Decision Log; Parent Notification | G35: Review IEP if SPED; track cumulative days | H35: Yes
B36: Bullying / Cyberbullying | C36: TEC §37.0832 | D36: ISS; OSS; DAEP at discretion | E36: Restorative Circle RP-01; Empathy Mapping; Mentoring RP-09 | F36: Written Referral; Parent Notification; Counselor Notes | G36: IEP — review if behavior relates to disability | H36: Recommended
B37: Controlled Substance — Possession | C37: TEC §37.006(b) | D37: Mandatory DAEP | E37: Substance Awareness Education during DAEP; Community Referral | F37: Placement Order; Parent Notification; MDR if SPED | G37: MDR required if IEP/504; FAPE must continue at DAEP | H37: Yes
B38: Controlled Substance — Distribution | C38: TEC §37.006(b)/§37.007(e) | D38: Mandatory DAEP; Expulsion-eligible; Law Enforcement | E38: No alternative replaces placement; JJAEP as expulsion alternative | F38: Law Enforcement Report; Expulsion Referral; MDR if SPED; Counsel Notification | G38: MDR required; Consult legal counsel immediately | H38: Yes
B39: Dangerous Weapon — Possession | C39: TEC §37.006(a) | D39: Mandatory DAEP; Law Enforcement if firearm-adjacent | E39: No alternative to placement; begin Re-Entry Plan on Day 1 | F39: Placement Order; Incident Report; Law Enforcement Report if applicable | G39: MDR required if IEP/504; FAPE must continue | H39: Yes
B40: Firearm — Possession | C40: TEC §37.007(e)(1) | D40: Mandatory Expulsion — minimum 1 year (GFSA) | E40: JJAEP as expulsion alternative; re-entry plan built during expulsion | F40: Law Enforcement Report; Expulsion Order; MDR if SPED; Counsel Notification | G40: MDR required; FAPE must continue in JJAEP; Consult counsel | H40: Yes
B41: Defiance / Insubordination | C41: Campus Policy / TEC §37.002 | D41: Warning → Detention → ISS (graduated) | E41: Behavior Contract + Daily Check-In RP-06; Parent-Admin Conference RP-05 | F41: Written Referral; Parent Contact Log; Conference Summary | G41: Review IEP accommodations — may be disability-related | H41: Recommended
B42: Disruption of Class | C42: TEC §37.002 / Campus Policy | D42: Teacher Removal; Detention; ISS | E42: Restorative Circle RP-02 (whole class); Mediated Conversation RP-03 | F42: Written Referral; Teacher Documentation | G42: Review IEP — may need BIP update if recurring | H42: If pattern
B43: Fighting — Minor Physical Altercation | C43: TEC §37.005 / §37.007(a) | D43: ISS 1–3 days; OSS; DAEP for pattern | E43: Restorative Circle RP-01; Mediated Conversation RP-03; Behavior Contract RP-06 | F43: Incident Report; Parent Notification; CBC Decision Log | G43: Track cumulative days if SPED | H43: Yes
... B53: Other — Campus Policy | C53: Campus Code of Conduct | D53: Per campus policy — graduated response recommended | E53: Review Decision Matrix; Consider ISS + Intervention Track first | F53: Written Referral; CBC Decision Log | G53: Review SPED status before any removal | H53: Recommended

Sheet CBC Workflow
A1: CBC Workflow — TEC §37.0012 Required Decision Log
A2: Complete one row per incident where DAEP or expulsion is being considered. This log documents required TEC §37.0012 alternative consideration.
A3: ⚠ Failure to document this review creates legal exposure. Every DAEP/expulsion recommendation must have a completed CBC Workflow row.
A4: Incident ID | B4: Date | C4: Student ID | D4: Campus | E4: Offense | F4: TEC Reference | G4: Step 1: Alternatives Considered? | H4: Alternatives Reviewed | I4: Step 2: SPED Review Done? | J4: Step 3: Pattern Review? | K4: Prior Incidents (90 days) | L4: Step 4: Decision Made | M4: Rationale Documented? | N4: Parent Notified? | O4: Notification Date | P4: Notification Method | Q4: Step 5: Consequence Assigned | R4: Alternative Assigned (if any) | S4: Step 6: Follow-Up Scheduled? | T4: Follow-Up Date | U4: CBC Signature / Initials | V4: Notes
A155: 🚀 Upgrade to the full platform · clearpathedgroup.com · Clear Path Education Group, LLC

Sheet SPED Safeguards
A1: SPED Safeguards — Per-Offense IDEA & 504 Compliance Reference
A2: Every TEC §37 offense mapped to SPED/504 considerations. Use this tab when the student has an IEP, 504 Plan, or ARD history.
A3: TEC Section | B3: Offense Type | C3: SPED Consideration | D3: MDR Required? | E3: 10-Day Rule? | F3: FAPE Must Continue? | G3: ARD Action Required | H3: Notes / TEA Guidance
A4: TEC §37.005 | B4: Any suspension (ISS or OSS) | C4: Each removal day counts toward the 10-school-day cumulative total. At day 10: FAPE obligation triggers, MDR required if pattern constitutes change of placement. | D4: Only if change of placement | E4: YES — track every day | F4: Triggers at day 11+ | G4: Review cumulative days at each new removal. Notify SPED coordinator at day 7. | H4: Suspension alone never addresses the IEP behavioral goals. Ensure BIP is in place.
A5: TEC §37.006(a) | B5: Mandatory DAEP — Felony / Assault | C5: DAEP constitutes a change of placement. MDR must occur within 10 school days of placement decision. If behavior is manifestation of disability, cannot proceed with DAEP without IEP team agreement. | D5: YES — within 10 school days | E5: YES — counts as change of placement | F5: YES — must continue at DAEP campus | G5: ARD must convene within 10 school days to conduct MDR | H5: District must provide services at DAEP that allow student to progress toward IEP goals.
A6: TEC §37.006(b) | B6: Mandatory DAEP — Drug/Alcohol | C6: Same as above — DAEP triggers MDR requirement. Special exception: if student was not identified as SPED at time of incident AND district had no basis to believe student had a disability, MDR is not required. | D6: YES unless exception applies | E6: YES | F6: YES | G6: ARD to conduct MDR; determine if substance use is related to disability | H6: Special circumstance exception (IDEA §615(k)(4)): document that district had no prior knowledge of disability if applicable.
A7: TEC §37.007(a)-(c) | B7: Discretionary DAEP | C7: Discretionary placement still triggers MDR requirement if student has IEP/504. CBC must consult with SPED coordinator before making recommendation. | D7: YES if IEP/504 | E7: YES | F7: YES | G7: Pre-placement ARD consultation required; MDR at or before placement | H7: CBC Decision Log must note that SPED coordinator was consulted before placement decision.
A8: TEC §37.007(e)(1) | B8: Mandatory Expulsion — Firearm | C8: Special circumstances exception: student with disability can still be expelled for firearm offense, but services must continue. JJAEP must provide FAPE. | D8: YES — within 10 school days | E8: YES — change of placement | F8: YES — even during expulsion | G8: Emergency ARD; MDR; JJAEP IEP coordination | H8: IDEA allows expulsion for dangerous behavior regardless of manifestation, but FAPE must continue. JJAEP must receive and implement the IEP.
A9: TEC §37.007(e)(2) | B9: Mandatory Expulsion — Drug Distribution | C9: Same as firearm — special circumstances. Services must continue even if behavior is manifestation of disability. | D9: YES | E9: YES | F9: YES | G9: Emergency ARD; coordinate with JJAEP | H9: Document that the special circumstances determination was reviewed by legal counsel.
A10: Any — 10-Day Rule | B10: Cumulative Removal Tracking | C10: Once a student with a disability has been removed for more than 10 school days in a year, the district must provide FAPE during each additional removal. A pattern of removals (similar conduct, same circumstances) may constitute a change of placement even before 10 days. | D10: Pattern-based MDR possible before day 10 | E10: YES — track from day 1 | F10: Triggers at day 11 OR pattern determination | G10: Set alert at day 7 — CBC must notify SPED coordinator | H10: Use the Student Roster tab cumulative day counter. Never rely on memory alone.
A11: Any — MDR Process | B11: Manifestation Determination Review | C11: MDR must occur within 10 school days. Team determines: (1) Was the conduct caused by or had direct substantial relationship to disability? (2) Was conduct a direct result of district's failure to implement IEP? If YES to either: cannot proceed with DAEP/expulsion except under special circumstances. | D11: Within 10 school days of decision | E11: N/A — MDR is the review | F11: FAPE continues regardless of MDR outcome | G11: ARD team conducts MDR; documents findings; revises BIP if needed | H11: If district fails to conduct timely MDR, any placement is legally vulnerable to reversal. Document date MDR was initiated immediately.
A12: Any — FBA/BIP | B12: Functional Behavioral Assessment & Behavior Intervention Plan | C12: When a student with a disability is removed for behavior, the IEP team must review/revise the BIP (or create an FBA if no BIP exists). This is not optional — it is required under IDEA when removal is for behavior related to disability. | D12: Triggers FBA/BIP review requirement | E12: N/A — ongoing obligation | F12: N/A — proactive requirement | G12: IEP team must convene to review/revise FBA and BIP within placement period | H12: A BIP that was created 2 years ago and has never been revised does not satisfy IDEA requirements. Update it.
A13: Any — 504 | B13: Section 504 Plan — All Offenses | C13: Students with 504 plans have similar (though not identical) protections. District must conduct a §504 review before significant discipline change. 504 plans may include behavioral accommodations that were not followed — document whether accommodations were in place at time of incident. | D13: Review required (not MDR) before DAEP | E13: Track cumulative days — FAPE obligation similar | F13: 504 services must continue if removal is extended | G13: 504 coordinator must be notified; review whether 504 accommodations were in place | H13: 504 compliance violations can result in OCR complaints. Always document that accommodations were implemented.
A14: 🚀 Upgrade to the full platform · clearpathedgroup.com · Clear Path Education Group, LLC

Sheet Parent Communication
A1: Parent Communication Log — Required Notices by TEC Section
A2: Log every parent contact related to discipline. TEC requires specific notices — this log is your audit trail.
A3: Log ID | B3: Date | C3: Student ID | D3: Student Last Name | E3: Campus | F3: Offense / Reason | G3: TEC-Required Notice? | H3: Notice Deadline | I3: Notification Method | J3: Contact Name | K3: Contact Relationship | L3: Summary of Communication | M3: Follow-Up Required? | N3: CBC / Staff Initials
A204: 🚀 Upgrade to the full platform · clearpathedgroup.com · Clear Path Education Group, LLC

Sheet Documentation Checklist
A1: Documentation Checklist — Required Documents by Incident & TEC Section
A2: Check off each document as it is completed. ⚙ Auto-counts documents complete. Red = incomplete package.
A3: Checklist ID | B3: Incident Date | C3: Student ID | D3: TEC Section | E3: Offense Summary | F3: Doc 1: Written Referral | G3: Doc 2: Parent Notification | H3: Doc 3: Conference Summary | I3: Doc 4: Placement Order | J3: Doc 5: CBC Decision Log | K3: Doc 6: MDR (if SPED) | L3: Doc 7: BIP/FBA Review | M3: Doc 8: Alternative Considered | N3: ⚙ Docs Complete | O3: ⚙ Docs Remaining | P3: Notes
N4: =IF(C4="","",IF(F4="Yes",1,0)+IF(G4="Yes",1,0)+IF(H4="Yes",1,0)+IF(I4="Yes",1,0)+IF(J4="Yes",1,0)+IF(K4="Yes",1,0)+IF(L4="Yes",1,0)+IF(M4="Yes",1,0)) | O4: =IF(C4="","",8-N4)
N5: =IF(C5="","",IF(F5="Yes",1,0)+IF(G5="Yes",1,0)+IF(H5="Yes",1,0)+IF(I5="Yes",1,0)+IF(J5="Yes",1,0)+IF(K5="Yes",1,0)+IF(L5="Yes",1,0)+IF(M5="Yes",1,0)) | O5: =IF(C5="","",8-N5)
N6: =IF(C6="","",IF(F6="Yes",1,0)+IF(G6="Yes",1,0)+IF(H6="Yes",1,0)+IF(I6="Yes",1,0)+IF(J6="Yes",1,0)+IF(K6="Yes",1,0)+IF(L6="Yes",1,0)+IF(M6="Yes",1,0)) | O6: =IF(C6="","",8-N6)
N7: =IF(C7="","",IF(F7="Yes",1,0)+IF(G7="Yes",1,0)+IF(H7="Yes",1,0)+IF(I7="Yes",1,0)+IF(J7="Yes",1,0)+IF(K7="Yes",1,0)+IF(L7="Yes",1,0)+IF(M7="Yes",1,0)) | O7: =IF(C7="","",8-N7)
N8: =IF(C8="","",IF(F8="Yes",1,0)+IF(G8="Yes",1,0)+IF(H8="Yes",1,0)+IF(I8="Yes",1,0)+IF(J8="Yes",1,0)+IF(K8="Yes",1,0)+IF(L8="Yes",1,0)+IF(M8="Yes",1,0)) | O8: =IF(C8="","",8-N8)
N9: =IF(C9="","",IF(F9="Yes",1,0)+IF(G9="Yes",1,0)+IF(H9="Yes",1,0)+IF(I9="Yes",1,0)+IF(J9="Yes",1,0)+IF(K9="Yes",1,0)+IF(L9="Yes",1,0)+IF(M9="Yes",1,0)) | O9: =IF(C9="","",8-N9)
N10: =IF(C10="","",IF(F10="Yes",1,0)+IF(G10="Yes",1,0)+IF(H10="Yes",1,0)+IF(I10="Yes",1,0)+IF(J10="Yes",1,0)+IF(K10="Yes",1,0)+IF(L10="Yes",1,0)+IF(M10="Yes",1,0)) | O10: =IF(C10="","",8-N10)
N11: =IF(C11="","",IF(F11="Yes",1,0)+IF(G11="Yes",1,0)+IF(H11="Yes",1,0)+IF(I11="Yes",1,0)+IF(J11="Yes",1,0)+IF(K11="Yes",1,0)+IF(L11="Yes",1,0)+IF(M11="Yes",1,0)) | O11: =IF(C11="","",8-N11)
N12: =IF(C12="","",IF(F12="Yes",1,0)+IF(G12="Yes",1,0)+IF(H12="Yes",1,0)+IF(I12="Yes",1,0)+IF(J12="Yes",1,0)+IF(K12="Yes",1,0)+IF(L12="Yes",1,0)+IF(M12="Yes",1,0)) | O12: =IF(C12="","",8-N12)
N13: =IF(C13="","",IF(F13="Yes",1,0)+IF(G13="Yes",1,0)+IF(H13="Yes",1,0)+IF(I13="Yes",1,0)+IF(J13="Yes",1,0)+IF(K13="Yes",1,0)+IF(L13="Yes",1,0)+IF(M13="Yes",1,0)) | O13: =IF(C13="","",8-N13)
N14: =IF(C14="","",IF(F14="Yes",1,0)+IF(G14="Yes",1,0)+IF(H14="Yes",1,0)+IF(I14="Yes",1,0)+IF(J14="Yes",1,0)+IF(K14="Yes",1,0)+IF(L14="Yes",1,0)+IF(M14="Yes",1,0)) | O14: =IF(C14="","",8-N14)
N15: =IF(C15="","",IF(F15="Yes",1,0)+IF(G15="Yes",1,0)+IF(H15="Yes",1,0)+IF(I15="Yes",1,0)+IF(J15="Yes",1,0)+IF(K15="Yes",1,0)+IF(L15="Yes",1,0)+IF(M15="Yes",1,0)) | O15: =IF(C15="","",8-N15)
... N153: =IF(C153="","",IF(F153="Yes",1,0)+IF(G153="Yes",1,0)+IF(H153="Yes",1,0)+IF(I153="Yes",1,0)+IF(J153="Yes",1,0)+IF(K153="Yes",1,0)+IF(L153="Yes",1,0)+IF(M153="Yes",1,0)) | O153: =IF(C153="","",8-N153)
A154: 🚀 Upgrade to the full platform · clearpathedgroup.com · Clear Path Education Group, LLC

Sheet Dashboard
A1: Consequence Decision Matrix — Campus Dashboard
A2: ="Dashboard refreshed: "&TEXT(TODAY(),"MMMM D, YYYY") -> Dashboard refreshed: July 14, 2026
A3: INCIDENT OVERVIEW
A4: Total Incidents Logged (CBC Workflow) | B4: =COUNTA('CBC Workflow'!A5:A154) -> 0
A5: DAEP Placements This Year | B5: =COUNTIF('CBC Workflow'!Q5:Q154,"DAEP*") -> 0
A6: Expulsion Referrals | B6: =COUNTIF('CBC Workflow'!Q5:Q154,"Expulsion*") -> 0
A7: SPED Students in CBC Log | B7: =COUNTIF('SPED Safeguards'!D4:D13,"YES*") -> 5
A9: ALTERNATIVE CONSEQUENCE USAGE
A10: Restorative Alternative Used | B10: =COUNTIF('CBC Workflow'!R5:R154,"<>""") -> 150
A11: Alternatives NOT Considered | B11: =COUNTIF('CBC Workflow'!G5:G154,"No") -> 0
A12: Rationale Not Documented | B12: =COUNTIF('CBC Workflow'!M5:M154,"No") -> 0
A13: Follow-Ups Scheduled | B13: =COUNTIF('CBC Workflow'!S5:S154,"Yes") -> 0
A15: DOCUMENTATION COMPLIANCE
A16: Incidents with Complete Doc Package | B16: =COUNTIF('Documentation Checklist'!N4:N153,8) -> 0
A17: Incidents with Incomplete Docs | B17: =COUNTIFS('Documentation Checklist'!C4:C153,"<>""",'Documentation Checklist'!N4:N153,"<>"&8) -> 150
A18: Parent Notices Overdue | B18: =COUNTIFS('Parent Communication'!G4:G203,"Yes",'Parent Communication'!H4:H203,"<"&TODAY(),'Parent Communication'!L4:L203,"") -> 0
A19: Parent Follow-Ups Needed | B19: =COUNTIF('Parent Communication'!M4:M203,"Yes") -> 0
A21: SPED & COMPLIANCE FLAGS
A22: SPED Students — MDR Required | B22: =COUNTIF('SPED Safeguards'!D4:D13,"YES*") -> 5
A23: CBC Rows with No SPED Review | B23: =COUNTIF('CBC Workflow'!I5:I154,"No") -> 0
A24: Restorative Circles Completed (RP-01) | B24: =COUNTIF('CBC Workflow'!R5:R154,"Restorative Circle*") -> 0
A25: Behavior Contracts Assigned | B25: =COUNTIF('CBC Workflow'!R5:R154,"Behavior Contract*") -> 0
A27: 🚀 Automate this across all campuses at clearpathedgroup.com/waypoint · Clear Path Education Group, LLC

Sheet Reference
A1: Reference — TEC §37 Text Summaries, TEA Guidance, & Research
A2: Clear Path Education Group, LLC · For organizational use only — not legal advice
A3: TEC §37 KEY SECTIONS SUMMARY
B4: §37.002 | C4: Teacher removal. Teacher may remove a student who substantially disrupts class. Teacher MUST remove for assault/serious threat. Admin must place within 3 days.
B5: §37.0012 | C5: Campus Behavior Coordinator. CBC must consider alternatives before DAEP/expulsion. Must document decision. Cannot use DAEP for academic failure or truancy alone.
B6: §37.005 | C6: Suspension. Maximum 3 days per occurrence. Cannot be used as regular discipline. Cannot suspend for academic failure, minor disruption, or truancy (2023 amendment).
B7: §37.006 | C7: Mandatory DAEP. Specific offenses require DAEP: felony conduct, assault on staff, drug/alcohol possession, retaliation against school employee.
B8: §37.007 | C8: Discretionary DAEP. District MAY place for serious misconduct, off-campus felony, aggravated robbery, terroristic threat. CBC must document alternatives considered.
B9: §37.007(e) | C9: Mandatory Expulsion. Firearm possession requires minimum 1-year expulsion (GFSA). Drug distribution and other specific felonies require expulsion referral.
B10: §37.0081 | C10: JJAEP Alternative. Student who would be expelled may be placed in JJAEP instead. JJAEP must provide FAPE for SPED students.
B11: §37.009 | C11: Conference Requirement. District MUST hold conference before DAEP placement. Student and parent must have opportunity to be heard.
B12: §37.0832 | C12: Bullying. Requires investigation, parent notification, and protective action. May result in transfer of bully or victim to different class/campus.
A14: 2023 TEC AMENDMENTS — KEY CHANGES
B15: SB 11 (2023) | C15: Requires districts to conduct threat assessments. Establishes threat assessment teams. Threat assessment training required for CBC and admin.
B16: HB 3928 (2021) | C16: Dyslexia — annual review required for all identified students. 504 plans with dyslexia must include MDT verification.
B17: Suspension Reform (2023) | C17: Prohibits suspension for: academic failure (making Fs), truancy, tardiness, dress code first offense, profanity not directed at person, and minor campus policy violations.
A19: RESTORATIVE PRACTICES — EVIDENCE BASE
B20: Gonzalez (2012) | C20: Schools implementing restorative practices reported 44% reduction in ISS/OSS and significant improvement in school climate scores.
B21: IIRP Research | C21: Reintegrative shaming theory: accountability paired with community support reduces reoffending more effectively than punitive isolation.
B22: Durlak et al. (2011) | C22: CASEL meta-analysis: SEL programs reduce behavior incidents by 25% and improve academic outcomes by 11% across K-12 settings.
B23: Balfanz et al. (2014) | C23: Students who return from suspensions/DAEP without re-entry planning re-offend within 30 days at 3x the rate of students with structured re-entry.
B24: Cornell & Sheras (2006) | C24: Virginia Threat Assessment Guidelines: structured threat assessment reduces both false alarms and missed genuine threats compared to zero-tolerance policies.
A25: 🚀 Upgrade to the full platform · clearpathedgroup.com · Clear Path Education Group, LLC

Sheet Lists
A1: OffenseTypes | B1: ConsequenceTypes | C1: ConsequenceOptions | D1: RestorativeOptions | E1: YesNo | F1: YesNoNA | G1: NoticeTimelines | H1: ComplianceStatus | I1: DocTypes | J1: StaffRoles | K1: NotificationMethods | L1: SpedFlags
A2: Assault — Bodily Injury (staff) | B2: Mandatory | C2: Warning / Verbal Redirection | D2: Restorative Circle — Student + Affected Party | E2: Yes | F2: Yes | G2: Same day — verbal | H2: Complete | I2: Written Referral | J2: Principal | K2: Phone Call | L2: None
A3: Assault — Bodily Injury (student) | B3: Discretionary | C3: Parent Contact | D3: Restorative Circle — Whole Class | E3: No | F3: No | G3: Same day — written | H3: In Progress | I3: Parent Notification Form | J3: AP | K3: Email | L3: IEP — IDEA (MDR may apply)
